Workbook

Sheet TỔNG HỢP
A1: TỔNG HỢP CÔNG NỢ KHÁCH HÀNG
A2: Số dương = khách còn nợ công ty; số âm (đỏ) = công ty đang nợ lại khách (khách trả dư). Tất cả số liệu tự tính từ CHI TIẾT HÀNG, THANH TOÁN và SỔ CÔNG NỢ.
A4: KHÁCH CÒN NỢ CÔNG TY | D4: CÔNG TY NỢ LẠI KHÁCH | G4: SỐ KHÁCH ĐANG NỢ | J4: PHÁT SINH SAU CK (TẤT CẢ KỲ)
A5: =SUMIF(J9:J20,">0") -> 33198983 | D5: =-SUMIF(J9:J20,"<0") -> 112500 | G5: =COUNTIF(J9:J20,">0") -> 2 | J5: =SUM(G9:G20) -> 113969593
A7: ▶ CÔNG NỢ TỪNG KHÁCH
A8: STT | B8: Khách hàng | C8: Biên bản gần nhất | D8: Nợ đầu kỳ (kỳ đầu tiên) | E8: Phát sinh (giá gốc) | F8: Tiền chiết khấu | G8: Phát sinh sau CK | H8: Hàng trả lại sau CK | I8: Đã thanh toán | J8: NỢ HIỆN TẠI | K8: Tình trạng | L8: Lưu ý
A9: =IF($B9="","",ROW()-8) -> 1 | B9: Hiền Xuân | C9: =IF($B9="","",_xlfn.MAXIFS('SỔ CÔNG NỢ'!$B$5:$B$51,'SỔ CÔNG NỢ'!$A$5:$A$51,$B9)) -> 46204 | D9: =IF($B9="","",SUMIFS('SỔ CÔNG NỢ'!$C$5:$C$51,'SỔ CÔNG NỢ'!$A$5:$A$51,$B9,'SỔ CÔNG NỢ'!$B$5:$B$51,_xlfn.MINIFS('SỔ CÔNG NỢ'!$B$5:$B$51,'SỔ CÔNG NỢ'!$A$5:$A$51,$B9))) -> 63600 | E9: =IF($B9="","",SUMIFS('SỔ CÔNG NỢ'!$D$5:$D$51,'SỔ CÔNG NỢ'!$A$5:$A$51,$B9)) -> 83852350 | F9: =IF($B9="","",SUMIFS('SỔ CÔNG NỢ'!$F$5:$F$51,'SỔ CÔNG NỢ'!$A$5:$A$51,$B9)) -> 51988457 | G9: =IF($B9="","",SUMIFS('SỔ CÔNG NỢ'!$G$5:$G$51,'SỔ CÔNG NỢ'!$A$5:$A$51,$B9)) -> 31863893 | H9: =IF($B9="","",SUMIFS('SỔ CÔNG NỢ'!$I$5:$I$51,'SỔ CÔNG NỢ'!$A$5:$A$51,$B9)) -> 1746860 | I9: =IF($B9="","",SUMIFS('SỔ CÔNG NỢ'!$K$5:$K$51,'SỔ CÔNG NỢ'!$A$5:$A$51,$B9)) -> 30060000 | J9: =IF($B9="","",SUMIFS('SỔ CÔNG NỢ'!$L$5:$L$51,'SỔ CÔNG NỢ'!$A$5:$A$51,$B9,'SỔ CÔNG NỢ'!$B$5:$B$51,C9)) -> 120633 | K9: =IF($B9="","",IF(J9>0,"Khách còn nợ",IF(J9<0,"Công ty nợ khách","Hết nợ"))) -> Khách còn nợ | L9: =IF($B9="","",IF(C9<MAX('SỔ CÔNG NỢ'!$B$5:$B$51),"⚠ Chưa có biên bản sau tháng "&TEXT(C9,"mm/yyyy")&" (sổ có đến "&TEXT(MAX('SỔ CÔNG NỢ'!$B$5:$B$51),"mm/yyyy")&")","")) -> ⚠ Chưa có biên bản sau tháng 07/2026 (sổ có đến 09/2026)
A10: =IF($B10="","",ROW()-8) -> 2 | B10: Hòa Hiệp | C10: =IF($B10="","",_xlfn.MAXIFS('SỔ CÔNG NỢ'!$B$5:$B$51,'SỔ CÔNG NỢ'!$A$5:$A$51,$B10)) -> 46174 | D10: =IF($B10="","",SUMIFS('SỔ CÔNG NỢ'!$C$5:$C$51,'SỔ CÔNG NỢ'!$A$5:$A$51,$B10,'SỔ CÔNG NỢ'!$B$5:$B$51,_xlfn.MINIFS('SỔ CÔNG NỢ'!$B$5:$B$51,'SỔ CÔNG NỢ'!$A$5:$A$51,$B10))) -> 0 | E10: =IF($B10="","",SUMIFS('SỔ CÔNG NỢ'!$D$5:$D$51,'SỔ CÔNG NỢ'!$A$5:$A$51,$B10)) -> 3750000 | F10: =IF($B10="","",SUMIFS('SỔ CÔNG NỢ'!$F$5:$F$51,'SỔ CÔNG NỢ'!$A$5:$A$51,$B10)) -> 2362500 | G10: =IF($B10="","",SUMIFS('SỔ CÔNG NỢ'!$G$5:$G$51,'SỔ CÔNG NỢ'!$A$5:$A$51,$B10)) -> 1387500 | H10: =IF($B10="","",SUMIFS('SỔ CÔNG NỢ'!$I$5:$I$51,'SỔ CÔNG NỢ'!$A$5:$A$51,$B10)) -> 0 | I10: =IF($B10="","",SUMIFS('SỔ CÔNG NỢ'!$K$5:$K$51,'SỔ CÔNG NỢ'!$A$5:$A$51,$B10)) -> 1500000 | J10: =IF($B10="","",SUMIFS('SỔ CÔNG NỢ'!$L$5:$L$51,'SỔ CÔNG NỢ'!$A$5:$A$51,$B10,'SỔ CÔNG NỢ'!$B$5:$B$51,C10)) -> -112500 | K10: =IF($B10="","",IF(J10>0,"Khách còn nợ",IF(J10<0,"Công ty nợ khách","Hết nợ"))) -> Công ty nợ khách | L10: =IF($B10="","",IF(C10<MAX('SỔ CÔNG NỢ'!$B$5:$B$51),"⚠ Chưa có biên bản sau tháng "&TEXT(C10,"mm/yyyy")&" (sổ có đến "&TEXT(MAX('SỔ CÔNG NỢ'!$B$5:$B$51),"mm/yyyy")&")","")) -> ⚠ Chưa có biên bản sau tháng 06/2026 (sổ có đến 09/2026)
A11: =IF($B11="","",ROW()-8) -> 3 | B11: Hà Liên | C11: =IF($B11="","",_xlfn.MAXIFS('SỔ CÔNG NỢ'!$B$5:$B$51,'SỔ CÔNG NỢ'!$A$5:$A$51,$B11)) -> 46266 | D11: =IF($B11="","",SUMIFS('SỔ CÔNG NỢ'!$C$5:$C$51,'SỔ CÔNG NỢ'!$A$5:$A$51,$B11,'SỔ CÔNG NỢ'!$B$5:$B$51,_xlfn.MINIFS('SỔ CÔNG NỢ'!$B$5:$B$51,'SỔ CÔNG NỢ'!$A$5:$A$51,$B11))) -> 890150 | E11: =IF($B11="","",SUMIFS('SỔ CÔNG NỢ'!$D$5:$D$51,'SỔ CÔNG NỢ'!$A$5:$A$51,$B11)) -> 201795500 | F11: =IF($B11="","",SUMIFS('SỔ CÔNG NỢ'!$F$5:$F$51,'SỔ CÔNG NỢ'!$A$5:$A$51,$B11)) -> 121077300 | G11: =IF($B11="","",SUMIFS('SỔ CÔNG NỢ'!$G$5:$G$51,'SỔ CÔNG NỢ'!$A$5:$A$51,$B11)) -> 80718200 | H11: =IF($B11="","",SUMIFS('SỔ CÔNG NỢ'!$I$5:$I$51,'SỔ CÔNG NỢ'!$A$5:$A$51,$B11)) -> 0 | I11: =IF($B11="","",SUMIFS('SỔ CÔNG NỢ'!$K$5:$K$51,'SỔ CÔNG NỢ'!$A$5:$A$51,$B11)) -> 48530000 | J11: =IF($B11="","",SUMIFS('SỔ CÔNG NỢ'!$L$5:$L$51,'SỔ CÔNG NỢ'!$A$5:$A$51,$B11,'SỔ CÔNG NỢ'!$B$5:$B$51,C11)) -> 33078350 | K11: =IF($B11="","",IF(J11>0,"Khách còn nợ",IF(J11<0,"Công ty nợ khách","Hết nợ"))) -> Khách còn nợ | L11: =IF($B11="","",IF(C11<MAX('SỔ CÔNG NỢ'!$B$5:$B$51),"⚠ Chưa có biên bản sau tháng "&TEXT(C11,"mm/yyyy")&" (sổ có đến "&TEXT(MAX('SỔ CÔNG NỢ'!$B$5:$B$51),"mm/yyyy")&")",""))
A12: =IF($B12="","",ROW()-8) | C12: =IF($B12="","",_xlfn.MAXIFS('SỔ CÔNG NỢ'!$B$5:$B$51,'SỔ CÔNG NỢ'!$A$5:$A$51,$B12)) | D12: =IF($B12="","",SUMIFS('SỔ CÔNG NỢ'!$C$5:$C$51,'SỔ CÔNG NỢ'!$A$5:$A$51,$B12,'SỔ CÔNG NỢ'!$B$5:$B$51,_xlfn.MINIFS('SỔ CÔNG NỢ'!$B$5:$B$51,'SỔ CÔNG NỢ'!$A$5:$A$51,$B12))) | E12: =IF($B12="","",SUMIFS('SỔ CÔNG NỢ'!$D$5:$D$51,'SỔ CÔNG NỢ'!$A$5:$A$51,$B12)) | F12: =IF($B12="","",SUMIFS('SỔ CÔNG NỢ'!$F$5:$F$51,'SỔ CÔNG NỢ'!$A$5:$A$51,$B12)) | G12: =IF($B12="","",SUMIFS('SỔ CÔNG NỢ'!$G$5:$G$51,'SỔ CÔNG NỢ'!$A$5:$A$51,$B12)) | H12: =IF($B12="","",SUMIFS('SỔ CÔNG NỢ'!$I$5:$I$51,'SỔ CÔNG NỢ'!$A$5:$A$51,$B12)) | I12: =IF($B12="","",SUMIFS('SỔ CÔNG NỢ'!$K$5:$K$51,'SỔ CÔNG NỢ'!$A$5:$A$51,$B12)) | J12: =IF($B12="","",SUMIFS('SỔ CÔNG NỢ'!$L$5:$L$51,'SỔ CÔNG NỢ'!$A$5:$A$51,$B12,'SỔ CÔNG NỢ'!$B$5:$B$51,C12)) | K12: =IF($B12="","",IF(J12>0,"Khách còn nợ",IF(J12<0,"Công ty nợ khách","Hết nợ"))) | L12: =IF($B12="","",IF(C12<MAX('SỔ CÔNG NỢ'!$B$5:$B$51),"⚠ Chưa có biên bản sau tháng "&TEXT(C12,"mm/yyyy")&" (sổ có đến "&TEXT(MAX('SỔ CÔNG NỢ'!$B$5:$B$51),"mm/yyyy")&")",""))
A13: =IF($B13="","",ROW()-8) | C13: =IF($B13="","",_xlfn.MAXIFS('SỔ CÔNG NỢ'!$B$5:$B$51,'SỔ CÔNG NỢ'!$A$5:$A$51,$B13)) | D13: =IF($B13="","",SUMIFS('SỔ CÔNG NỢ'!$C$5:$C$51,'SỔ CÔNG NỢ'!$A$5:$A$51,$B13,'SỔ CÔNG NỢ'!$B$5:$B$51,_xlfn.MINIFS('SỔ CÔNG NỢ'!$B$5:$B$51,'SỔ CÔNG NỢ'!$A$5:$A$51,$B13))) | E13: =IF($B13="","",SUMIFS('SỔ CÔNG NỢ'!$D$5:$D$51,'SỔ CÔNG NỢ'!$A$5:$A$51,$B13)) | F13: =IF($B13="","",SUMIFS('SỔ CÔNG NỢ'!$F$5:$F$51,'SỔ CÔNG NỢ'!$A$5:$A$51,$B13)) | G13: =IF($B13="","",SUMIFS('SỔ CÔNG NỢ'!$G$5:$G$51,'SỔ CÔNG NỢ'!$A$5:$A$51,$B13)) | H13: =IF($B13="","",SUMIFS('SỔ CÔNG NỢ'!$I$5:$I$51,'SỔ CÔNG NỢ'!$A$5:$A$51,$B13)) | I13: =IF($B13="","",SUMIFS('SỔ CÔNG NỢ'!$K$5:$K$51,'SỔ CÔNG NỢ'!$A$5:$A$51,$B13)) | J13: =IF($B13="","",SUMIFS('SỔ CÔNG NỢ'!$L$5:$L$51,'SỔ CÔNG NỢ'!$A$5:$A$51,$B13,'SỔ CÔNG NỢ'!$B$5:$B$51,C13)) | K13: =IF($B13="","",IF(J13>0,"Khách còn nợ",IF(J13<0,"Công ty nợ khách","Hết nợ"))) | L13: =IF($B13="","",IF(C13<MAX('SỔ CÔNG NỢ'!$B$5:$B$51),"⚠ Chưa có biên bản sau tháng "&TEXT(C13,"mm/yyyy")&" (sổ có đến "&TEXT(MAX('SỔ CÔNG NỢ'!$B$5:$B$51),"mm/yyyy")&")",""))
A14: =IF($B14="","",ROW()-8) | C14: =IF($B14="","",_xlfn.MAXIFS('SỔ CÔNG NỢ'!$B$5:$B$51,'SỔ CÔNG NỢ'!$A$5:$A$51,$B14)) | D14: =IF($B14="","",SUMIFS('SỔ CÔNG NỢ'!$C$5:$C$51,'SỔ CÔNG NỢ'!$A$5:$A$51,$B14,'SỔ CÔNG NỢ'!$B$5:$B$51,_xlfn.MINIFS('SỔ CÔNG NỢ'!$B$5:$B$51,'SỔ CÔNG NỢ'!$A$5:$A$51,$B14))) | E14: =IF($B14="","",SUMIFS('SỔ CÔNG NỢ'!$D$5:$D$51,'SỔ CÔNG NỢ'!$A$5:$A$51,$B14)) | F14: =IF($B14="","",SUMIFS('SỔ CÔNG NỢ'!$F$5:$F$51,'SỔ CÔNG NỢ'!$A$5:$A$51,$B14)) | G14: =IF($B14="","",SUMIFS('SỔ CÔNG NỢ'!$G$5:$G$51,'SỔ CÔNG NỢ'!$A$5:$A$51,$B14)) | H14: =IF($B14="","",SUMIFS('SỔ CÔNG NỢ'!$I$5:$I$51,'SỔ CÔNG NỢ'!$A$5:$A$51,$B14)) | I14: =IF($B14="","",SUMIFS('SỔ CÔNG NỢ'!$K$5:$K$51,'SỔ CÔNG NỢ'!$A$5:$A$51,$B14)) | J14: =IF($B14="","",SUMIFS('SỔ CÔNG NỢ'!$L$5:$L$51,'SỔ CÔNG NỢ'!$A$5:$A$51,$B14,'SỔ CÔNG NỢ'!$B$5:$B$51,C14)) | K14: =IF($B14="","",IF(J14>0,"Khách còn nợ",IF(J14<0,"Công ty nợ khách","Hết nợ"))) | L14: =IF($B14="","",IF(C14<MAX('SỔ CÔNG NỢ'!$B$5:$B$51),"⚠ Chưa có biên bản sau tháng "&TEXT(C14,"mm/yyyy")&" (sổ có đến "&TEXT(MAX('SỔ CÔNG NỢ'!$B$5:$B$51),"mm/yyyy")&")",""))
A15: =IF($B15="","",ROW()-8) | C15: =IF($B15="","",_xlfn.MAXIFS('SỔ CÔNG NỢ'!$B$5:$B$51,'SỔ CÔNG NỢ'!$A$5:$A$51,$B15)) | D15: =IF($B15="","",SUMIFS('SỔ CÔNG NỢ'!$C$5:$C$51,'SỔ CÔNG NỢ'!$A$5:$A$51,$B15,'SỔ CÔNG NỢ'!$B$5:$B$51,_xlfn.MINIFS('SỔ CÔNG NỢ'!$B$5:$B$51,'SỔ CÔNG NỢ'!$A$5:$A$51,$B15))) | E15: =IF($B15="","",SUMIFS('SỔ CÔNG NỢ'!$D$5:$D$51,'SỔ CÔNG NỢ'!$A$5:$A$51,$B15)) | F15: =IF($B15="","",SUMIFS('SỔ CÔNG NỢ'!$F$5:$F$51,'SỔ CÔNG NỢ'!$A$5:$A$51,$B15)) | G15: =IF($B15="","",SUMIFS('SỔ CÔNG NỢ'!$G$5:$G$51,'SỔ CÔNG NỢ'!$A$5:$A$51,$B15)) | H15: =IF($B15="","",SUMIFS('SỔ CÔNG NỢ'!$I$5:$I$51,'SỔ CÔNG NỢ'!$A$5:$A$51,$B15)) | I15: =IF($B15="","",SUMIFS('SỔ CÔNG NỢ'!$K$5:$K$51,'SỔ CÔNG NỢ'!$A$5:$A$51,$B15)) | J15: =IF($B15="","",SUMIFS('SỔ CÔNG NỢ'!$L$5:$L$51,'SỔ CÔNG NỢ'!$A$5:$A$51,$B15,'SỔ CÔNG NỢ'!$B$5:$B$51,C15)) | K15: =IF($B15="","",IF(J15>0,"Khách còn nợ",IF(J15<0,"Công ty nợ khách","Hết nợ"))) | L15: =IF($B15="","",IF(C15<MAX('SỔ CÔNG NỢ'!$B$5:$B$51),"⚠ Chưa có biên bản sau tháng "&TEXT(C15,"mm/yyyy")&" (sổ có đến "&TEXT(MAX('SỔ CÔNG NỢ'!$B$5:$B$51),"mm/yyyy")&")",""))
A16: =IF($B16="","",ROW()-8) | C16: =IF($B16="","",_xlfn.MAXIFS('SỔ CÔNG NỢ'!$B$5:$B$51,'SỔ CÔNG NỢ'!$A$5:$A$51,$B16)) | D16: =IF($B16="","",SUMIFS('SỔ CÔNG NỢ'!$C$5:$C$51,'SỔ CÔNG NỢ'!$A$5:$A$51,$B16,'SỔ CÔNG NỢ'!$B$5:$B$51,_xlfn.MINIFS('SỔ CÔNG NỢ'!$B$5:$B$51,'SỔ CÔNG NỢ'!$A$5:$A$51,$B16))) | E16: =IF($B16="","",SUMIFS('SỔ CÔNG NỢ'!$D$5:$D$51,'SỔ CÔNG NỢ'!$A$5:$A$51,$B16)) | F16: =IF($B16="","",SUMIFS('SỔ CÔNG NỢ'!$F$5:$F$51,'SỔ CÔNG NỢ'!$A$5:$A$51,$B16)) | G16: =IF($B16="","",SUMIFS('SỔ CÔNG NỢ'!$G$5:$G$51,'SỔ CÔNG NỢ'!$A$5:$A$51,$B16)) | H16: =IF($B16="","",SUMIFS('SỔ CÔNG NỢ'!$I$5:$I$51,'SỔ CÔNG NỢ'!$A$5:$A$51,$B16)) | I16: =IF($B16="","",SUMIFS('SỔ CÔNG NỢ'!$K$5:$K$51,'SỔ CÔNG NỢ'!$A$5:$A$51,$B16)) | J16: =IF($B16="","",SUMIFS('SỔ CÔNG NỢ'!$L$5:$L$51,'SỔ CÔNG NỢ'!$A$5:$A$51,$B16,'SỔ CÔNG NỢ'!$B$5:$B$51,C16)) | K16: =IF($B16="","",IF(J16>0,"Khách còn nợ",IF(J16<0,"Công ty nợ khách","Hết nợ"))) | L16: =IF($B16="","",IF(C16<MAX('SỔ CÔNG NỢ'!$B$5:$B$51),"⚠ Chưa có biên bản sau tháng "&TEXT(C16,"mm/yyyy")&" (sổ có đến "&TEXT(MAX('SỔ CÔNG NỢ'!$B$5:$B$51),"mm/yyyy")&")",""))
A17: =IF($B17="","",ROW()-8) | C17: =IF($B17="","",_xlfn.MAXIFS('SỔ CÔNG NỢ'!$B$5:$B$51,'SỔ CÔNG NỢ'!$A$5:$A$51,$B17)) | D17: =IF($B17="","",SUMIFS('SỔ CÔNG NỢ'!$C$5:$C$51,'SỔ CÔNG NỢ'!$A$5:$A$51,$B17,'SỔ CÔNG NỢ'!$B$5:$B$51,_xlfn.MINIFS('SỔ CÔNG NỢ'!$B$5:$B$51,'SỔ CÔNG NỢ'!$A$5:$A$51,$B17))) | E17: =IF($B17="","",SUMIFS('SỔ CÔNG NỢ'!$D$5:$D$51,'SỔ CÔNG NỢ'!$A$5:$A$51,$B17)) | F17: =IF($B17="","",SUMIFS('SỔ CÔNG NỢ'!$F$5:$F$51,'SỔ CÔNG NỢ'!$A$5:$A$51,$B17)) | G17: =IF($B17="","",SUMIFS('SỔ CÔNG NỢ'!$G$5:$G$51,'SỔ CÔNG NỢ'!$A$5:$A$51,$B17)) | H17: =IF($B17="","",SUMIFS('SỔ CÔNG NỢ'!$I$5:$I$51,'SỔ CÔNG NỢ'!$A$5:$A$51,$B17)) | I17: =IF($B17="","",SUMIFS('SỔ CÔNG NỢ'!$K$5:$K$51,'SỔ CÔNG NỢ'!$A$5:$A$51,$B17)) | J17: =IF($B17="","",SUMIFS('SỔ CÔNG NỢ'!$L$5:$L$51,'SỔ CÔNG NỢ'!$A$5:$A$51,$B17,'SỔ CÔNG NỢ'!$B$5:$B$51,C17)) | K17: =IF($B17="","",IF(J17>0,"Khách còn nợ",IF(J17<0,"Công ty nợ khách","Hết nợ"))) | L17: =IF($B17="","",IF(C17<MAX('SỔ CÔNG NỢ'!$B$5:$B$51),"⚠ Chưa có biên bản sau tháng "&TEXT(C17,"mm/yyyy")&" (sổ có đến "&TEXT(MAX('SỔ CÔNG NỢ'!$B$5:$B$51),"mm/yyyy")&")",""))
A18: =IF($B18="","",ROW()-8) | C18: =IF($B18="","",_xlfn.MAXIFS('SỔ CÔNG NỢ'!$B$5:$B$51,'SỔ CÔNG NỢ'!$A$5:$A$51,$B18)) | D18: =IF($B18="","",SUMIFS('SỔ CÔNG NỢ'!$C$5:$C$51,'SỔ CÔNG NỢ'!$A$5:$A$51,$B18,'SỔ CÔNG NỢ'!$B$5:$B$51,_xlfn.MINIFS('SỔ CÔNG NỢ'!$B$5:$B$51,'SỔ CÔNG NỢ'!$A$5:$A$51,$B18))) | E18: =IF($B18="","",SUMIFS('SỔ CÔNG NỢ'!$D$5:$D$51,'SỔ CÔNG NỢ'!$A$5:$A$51,$B18)) | F18: =IF($B18="","",SUMIFS('SỔ CÔNG NỢ'!$F$5:$F$51,'SỔ CÔNG NỢ'!$A$5:$A$51,$B18)) | G18: =IF($B18="","",SUMIFS('SỔ CÔNG NỢ'!$G$5:$G$51,'SỔ CÔNG NỢ'!$A$5:$A$51,$B18)) | H18: =IF($B18="","",SUMIFS('SỔ CÔNG NỢ'!$I$5:$I$51,'SỔ CÔNG NỢ'!$A$5:$A$51,$B18)) | I18: =IF($B18="","",SUMIFS('SỔ CÔNG NỢ'!$K$5:$K$51,'SỔ CÔNG NỢ'!$A$5:$A$51,$B18)) | J18: =IF($B18="","",SUMIFS('SỔ CÔNG NỢ'!$L$5:$L$51,'SỔ CÔNG NỢ'!$A$5:$A$51,$B18,'SỔ CÔNG NỢ'!$B$5:$B$51,C18)) | K18: =IF($B18="","",IF(J18>0,"Khách còn nợ",IF(J18<0,"Công ty nợ khách","Hết nợ"))) | L18: =IF($B18="","",IF(C18<MAX('SỔ CÔNG NỢ'!$B$5:$B$51),"⚠ Chưa có biên bản sau tháng "&TEXT(C18,"mm/yyyy")&" (sổ có đến "&TEXT(MAX('SỔ CÔNG NỢ'!$B$5:$B$51),"mm/yyyy")&")",""))
A19: =IF($B19="","",ROW()-8) | C19: =IF($B19="","",_xlfn.MAXIFS('SỔ CÔNG NỢ'!$B$5:$B$51,'SỔ CÔNG NỢ'!$A$5:$A$51,$B19)) | D19: =IF($B19="","",SUMIFS('SỔ CÔNG NỢ'!$C$5:$C$51,'SỔ CÔNG NỢ'!$A$5:$A$51,$B19,'SỔ CÔNG NỢ'!$B$5:$B$51,_xlfn.MINIFS('SỔ CÔNG NỢ'!$B$5:$B$51,'SỔ CÔNG NỢ'!$A$5:$A$51,$B19))) | E19: =IF($B19="","",SUMIFS('SỔ CÔNG NỢ'!$D$5:$D$51,'SỔ CÔNG NỢ'!$A$5:$A$51,$B19)) | F19: =IF($B19="","",SUMIFS('SỔ CÔNG NỢ'!$F$5:$F$51,'SỔ CÔNG NỢ'!$A$5:$A$51,$B19)) | G19: =IF($B19="","",SUMIFS('SỔ CÔNG NỢ'!$G$5:$G$51,'SỔ CÔNG NỢ'!$A$5:$A$51,$B19)) | H19: =IF($B19="","",SUMIFS('SỔ CÔNG NỢ'!$I$5:$I$51,'SỔ CÔNG NỢ'!$A$5:$A$51,$B19)) | I19: =IF($B19="","",SUMIFS('SỔ CÔNG NỢ'!$K$5:$K$51,'SỔ CÔNG NỢ'!$A$5:$A$51,$B19)) | J19: =IF($B19="","",SUMIFS('SỔ CÔNG NỢ'!$L$5:$L$51,'SỔ CÔNG NỢ'!$A$5:$A$51,$B19,'SỔ CÔNG NỢ'!$B$5:$B$51,C19)) | K19: =IF($B19="","",IF(J19>0,"Khách còn nợ",IF(J19<0,"Công ty nợ khách","Hết nợ"))) | L19: =IF($B19="","",IF(C19<MAX('SỔ CÔNG NỢ'!$B$5:$B$51),"⚠ Chưa có biên bản sau tháng "&TEXT(C19,"mm/yyyy")&" (sổ có đến "&TEXT(MAX('SỔ CÔNG NỢ'!$B$5:$B$51),"mm/yyyy")&")",""))
A20: =IF($B20="","",ROW()-8) | C20: =IF($B20="","",_xlfn.MAXIFS('SỔ CÔNG NỢ'!$B$5:$B$51,'SỔ CÔNG NỢ'!$A$5:$A$51,$B20)) | D20: =IF($B20="","",SUMIFS('SỔ CÔNG NỢ'!$C$5:$C$51,'SỔ CÔNG NỢ'!$A$5:$A$51,$B20,'SỔ CÔNG NỢ'!$B$5:$B$51,_xlfn.MINIFS('SỔ CÔNG NỢ'!$B$5:$B$51,'SỔ CÔNG NỢ'!$A$5:$A$51,$B20))) | E20: =IF($B20="","",SUMIFS('SỔ CÔNG NỢ'!$D$5:$D$51,'SỔ CÔNG NỢ'!$A$5:$A$51,$B20)) | F20: =IF($B20="","",SUMIFS('SỔ CÔNG NỢ'!$F$5:$F$51,'SỔ CÔNG NỢ'!$A$5:$A$51,$B20)) | G20: =IF($B20="","",SUMIFS('SỔ CÔNG NỢ'!$G$5:$G$51,'SỔ CÔNG NỢ'!$A$5:$A$51,$B20)) | H20: =IF($B20="","",SUMIFS('SỔ CÔNG NỢ'!$I$5:$I$51,'SỔ CÔNG NỢ'!$A$5:$A$51,$B20)) | I20: =IF($B20="","",SUMIFS('SỔ CÔNG NỢ'!$K$5:$K$51,'SỔ CÔNG NỢ'!$A$5:$A$51,$B20)) | J20: =IF($B20="","",SUMIFS('SỔ CÔNG NỢ'!$L$5:$L$51,'SỔ CÔNG NỢ'!$A$5:$A$51,$B20,'SỔ CÔNG NỢ'!$B$5:$B$51,C20)) | K20: =IF($B20="","",IF(J20>0,"Khách còn nợ",IF(J20<0,"Công ty nợ khách","Hết nợ"))) | L20: =IF($B20="","",IF(C20<MAX('SỔ CÔNG NỢ'!$B$5:$B$51),"⚠ Chưa có biên bản sau tháng "&TEXT(C20,"mm/yyyy")&" (sổ có đến "&TEXT(MAX('SỔ CÔNG NỢ'!$B$5:$B$51),"mm/yyyy")&")",""))
B21: TỔNG | D21: =SUM(D9:D20) -> 953750 | E21: =SUM(E9:E20) -> 289397850 | F21: =SUM(F9:F20) -> 175428257 | G21: =SUM(G9:G20) -> 113969593 | H21: =SUM(H9:H20) -> 1746860 | I21: =SUM(I9:I20) -> 80090000 | J21: =SUM(J9:J20) -> 33086483
A24: Tháng bắt đầu của các bảng bên dưới:
C25: 46174
A27: ▶ NỢ CUỐI KỲ THEO THÁNG (số âm = công ty nợ khách)
B28: Khách hàng | C28: =$C$25 -> 46174 | D28: =EDATE(C28,1) -> 46204 | E28: =EDATE(D28,1) -> 46235 | F28: =EDATE(E28,1) -> 46266 | G28: =EDATE(F28,1) -> 46296 | H28: =EDATE(G28,1) -> 46327 | I28: =EDATE(H28,1) -> 46357
B29: =IF($B9="","",$B9) -> Hiền Xuân | C29: =IF($B29="","",IF(COUNTIFS('SỔ CÔNG NỢ'!$A$5:$A$51,$B29,'SỔ CÔNG NỢ'!$B$5:$B$51,C$28)=0,"",SUMIFS('SỔ CÔNG NỢ'!$L$5:$L$51,'SỔ CÔNG NỢ'!$A$5:$A$51,$B29,'SỔ CÔNG NỢ'!$B$5:$B$51,C$28))) | D29: =IF($B29="","",IF(COUNTIFS('SỔ CÔNG NỢ'!$A$5:$A$51,$B29,'SỔ CÔNG NỢ'!$B$5:$B$51,D$28)=0,"",SUMIFS('SỔ CÔNG NỢ'!$L$5:$L$51,'SỔ CÔNG NỢ'!$A$5:$A$51,$B29,'SỔ CÔNG NỢ'!$B$5:$B$51,D$28))) -> 120633 | E29: =IF($B29="","",IF(COUNTIFS('SỔ CÔNG NỢ'!$A$5:$A$51,$B29,'SỔ CÔNG NỢ'!$B$5:$B$51,E$28)=0,"",SUMIFS('SỔ CÔNG NỢ'!$L$5:$L$51,'SỔ CÔNG NỢ'!$A$5:$A$51,$B29,'SỔ CÔNG NỢ'!$B$5:$B$51,E$28))) | F29: =IF($B29="","",IF(COUNTIFS('SỔ CÔNG NỢ'!$A$5:$A$51,$B29,'SỔ CÔNG NỢ'!$B$5:$B$51,F$28)=0,"",SUMIFS('SỔ CÔNG NỢ'!$L$5:$L$51,'SỔ CÔNG NỢ'!$A$5:$A$51,$B29,'SỔ CÔNG NỢ'!$B$5:$B$51,F$28))) | G29: =IF($B29="","",IF(COUNTIFS('SỔ CÔNG NỢ'!$A$5:$A$51,$B29,'SỔ CÔNG NỢ'!$B$5:$B$51,G$28)=0,"",SUMIFS('SỔ CÔNG NỢ'!$L$5:$L$51,'SỔ CÔNG NỢ'!$A$5:$A$51,$B29,'SỔ CÔNG NỢ'!$B$5:$B$51,G$28))) | H29: =IF($B29="","",IF(COUNTIFS('SỔ CÔNG NỢ'!$A$5:$A$51,$B29,'SỔ CÔNG NỢ'!$B$5:$B$51,H$28)=0,"",SUMIFS('SỔ CÔNG NỢ'!$L$5:$L$51,'SỔ CÔNG NỢ'!$A$5:$A$51,$B29,'SỔ CÔNG NỢ'!$B$5:$B$51,H$28))) | I29: =IF($B29="","",IF(COUNTIFS('SỔ CÔNG NỢ'!$A$5:$A$51,$B29,'SỔ CÔNG NỢ'!$B$5:$B$51,I$28)=0,"",SUMIFS('SỔ CÔNG NỢ'!$L$5:$L$51,'SỔ CÔNG NỢ'!$A$5:$A$51,$B29,'SỔ CÔNG NỢ'!$B$5:$B$51,I$28)))
B30: =IF($B10="","",$B10) -> Hòa Hiệp | C30: =IF($B30="","",IF(COUNTIFS('SỔ CÔNG NỢ'!$A$5:$A$51,$B30,'SỔ CÔNG NỢ'!$B$5:$B$51,C$28)=0,"",SUMIFS('SỔ CÔNG NỢ'!$L$5:$L$51,'SỔ CÔNG NỢ'!$A$5:$A$51,$B30,'SỔ CÔNG NỢ'!$B$5:$B$51,C$28))) -> -112500 | D30: =IF($B30="","",IF(COUNTIFS('SỔ CÔNG NỢ'!$A$5:$A$51,$B30,'SỔ CÔNG NỢ'!$B$5:$B$51,D$28)=0,"",SUMIFS('SỔ CÔNG NỢ'!$L$5:$L$51,'SỔ CÔNG NỢ'!$A$5:$A$51,$B30,'SỔ CÔNG NỢ'!$B$5:$B$51,D$28))) | E30: =IF($B30="","",IF(COUNTIFS('SỔ CÔNG NỢ'!$A$5:$A$51,$B30,'SỔ CÔNG NỢ'!$B$5:$B$51,E$28)=0,"",SUMIFS('SỔ CÔNG NỢ'!$L$5:$L$51,'SỔ CÔNG NỢ'!$A$5:$A$51,$B30,'SỔ CÔNG NỢ'!$B$5:$B$51,E$28))) | F30: =IF($B30="","",IF(COUNTIFS('SỔ CÔNG NỢ'!$A$5:$A$51,$B30,'SỔ CÔNG NỢ'!$B$5:$B$51,F$28)=0,"",SUMIFS('SỔ CÔNG NỢ'!$L$5:$L$51,'SỔ CÔNG NỢ'!$A$5:$A$51,$B30,'SỔ CÔNG NỢ'!$B$5:$B$51,F$28))) | G30: =IF($B30="","",IF(COUNTIFS('SỔ CÔNG NỢ'!$A$5:$A$51,$B30,'SỔ CÔNG NỢ'!$B$5:$B$51,G$28)=0,"",SUMIFS('SỔ CÔNG NỢ'!$L$5:$L$51,'SỔ CÔNG NỢ'!$A$5:$A$51,$B30,'SỔ CÔNG NỢ'!$B$5:$B$51,G$28))) | H30: =IF($B30="","",IF(COUNTIFS('SỔ CÔNG NỢ'!$A$5:$A$51,$B30,'SỔ CÔNG NỢ'!$B$5:$B$51,H$28)=0,"",SUMIFS('SỔ CÔNG NỢ'!$L$5:$L$51,'SỔ CÔNG NỢ'!$A$5:$A$51,$B30,'SỔ CÔNG NỢ'!$B$5:$B$51,H$28))) | I30: =IF($B30="","",IF(COUNTIFS('SỔ CÔNG NỢ'!$A$5:$A$51,$B30,'SỔ CÔNG NỢ'!$B$5:$B$51,I$28)=0,"",SUMIFS('SỔ CÔNG NỢ'!$L$5:$L$51,'SỔ CÔNG NỢ'!$A$5:$A$51,$B30,'SỔ CÔNG NỢ'!$B$5:$B$51,I$28)))
B31: =IF($B11="","",$B11) -> Hà Liên | C31: =IF($B31="","",IF(COUNTIFS('SỔ CÔNG NỢ'!$A$5:$A$51,$B31,'SỔ CÔNG NỢ'!$B$5:$B$51,C$28)=0,"",SUMIFS('SỔ CÔNG NỢ'!$L$5:$L$51,'SỔ CÔNG NỢ'!$A$5:$A$51,$B31,'SỔ CÔNG NỢ'!$B$5:$B$51,C$28))) -> 10078550 | D31: =IF($B31="","",IF(COUNTIFS('SỔ CÔNG NỢ'!$A$5:$A$51,$B31,'SỔ CÔNG NỢ'!$B$5:$B$51,D$28)=0,"",SUMIFS('SỔ CÔNG NỢ'!$L$5:$L$51,'SỔ CÔNG NỢ'!$A$5:$A$51,$B31,'SỔ CÔNG NỢ'!$B$5:$B$51,D$28))) -> 10478590 | E31: =IF($B31="","",IF(COUNTIFS('SỔ CÔNG NỢ'!$A$5:$A$51,$B31,'SỔ CÔNG NỢ'!$B$5:$B$51,E$28)=0,"",SUMIFS('SỔ CÔNG NỢ'!$L$5:$L$51,'SỔ CÔNG NỢ'!$A$5:$A$51,$B31,'SỔ CÔNG NỢ'!$B$5:$B$51,E$28))) -> -7095410 | F31: =IF($B31="","",IF(COUNTIFS('SỔ CÔNG NỢ'!$A$5:$A$51,$B31,'SỔ CÔNG NỢ'!$B$5:$B$51,F$28)=0,"",SUMIFS('SỔ CÔNG NỢ'!$L$5:$L$51,'SỔ CÔNG NỢ'!$A$5:$A$51,$B31,'SỔ CÔNG NỢ'!$B$5:$B$51,F$28))) -> 33078350 | G31: =IF($B31="","",IF(COUNTIFS('SỔ CÔNG NỢ'!$A$5:$A$51,$B31,'SỔ CÔNG NỢ'!$B$5:$B$51,G$28)=0,"",SUMIFS('SỔ CÔNG NỢ'!$L$5:$L$51,'SỔ CÔNG NỢ'!$A$5:$A$51,$B31,'SỔ CÔNG NỢ'!$B$5:$B$51,G$28))) | H31: =IF($B31="","",IF(COUNTIFS('SỔ CÔNG NỢ'!$A$5:$A$51,$B31,'SỔ CÔNG NỢ'!$B$5:$B$51,H$28)=0,"",SUMIFS('SỔ CÔNG NỢ'!$L$5:$L$51,'SỔ CÔNG NỢ'!$A$5:$A$51,$B31,'SỔ CÔNG NỢ'!$B$5:$B$51,H$28))) | I31: =IF($B31="","",IF(COUNTIFS('SỔ CÔNG NỢ'!$A$5:$A$51,$B31,'SỔ CÔNG NỢ'!$B$5:$B$51,I$28)=0,"",SUMIFS('SỔ CÔNG NỢ'!$L$5:$L$51,'SỔ CÔNG NỢ'!$A$5:$A$51,$B31,'SỔ CÔNG NỢ'!$B$5:$B$51,I$28)))
B32: =IF($B12="","",$B12) | C32: =IF($B32="","",IF(COUNTIFS('SỔ CÔNG NỢ'!$A$5:$A$51,$B32,'SỔ CÔNG NỢ'!$B$5:$B$51,C$28)=0,"",SUMIFS('SỔ CÔNG NỢ'!$L$5:$L$51,'SỔ CÔNG NỢ'!$A$5:$A$51,$B32,'SỔ CÔNG NỢ'!$B$5:$B$51,C$28))) | D32: =IF($B32="","",IF(COUNTIFS('SỔ CÔNG NỢ'!$A$5:$A$51,$B32,'SỔ CÔNG NỢ'!$B$5:$B$51,D$28)=0,"",SUMIFS('SỔ CÔNG NỢ'!$L$5:$L$51,'SỔ CÔNG NỢ'!$A$5:$A$51,$B32,'SỔ CÔNG NỢ'!$B$5:$B$51,D$28))) | E32: =IF($B32="","",IF(COUNTIFS('SỔ CÔNG NỢ'!$A$5:$A$51,$B32,'SỔ CÔNG NỢ'!$B$5:$B$51,E$28)=0,"",SUMIFS('SỔ CÔNG NỢ'!$L$5:$L$51,'SỔ CÔNG NỢ'!$A$5:$A$51,$B32,'SỔ CÔNG NỢ'!$B$5:$B$51,E$28))) | F32: =IF($B32="","",IF(COUNTIFS('SỔ CÔNG NỢ'!$A$5:$A$51,$B32,'SỔ CÔNG NỢ'!$B$5:$B$51,F$28)=0,"",SUMIFS('SỔ CÔNG NỢ'!$L$5:$L$51,'SỔ CÔNG NỢ'!$A$5:$A$51,$B32,'SỔ CÔNG NỢ'!$B$5:$B$51,F$28))) | G32: =IF($B32="","",IF(COUNTIFS('SỔ CÔNG NỢ'!$A$5:$A$51,$B32,'SỔ CÔNG NỢ'!$B$5:$B$51,G$28)=0,"",SUMIFS('SỔ CÔNG NỢ'!$L$5:$L$51,'SỔ CÔNG NỢ'!$A$5:$A$51,$B32,'SỔ CÔNG NỢ'!$B$5:$B$51,G$28))) | H32: =IF($B32="","",IF(COUNTIFS('SỔ CÔNG NỢ'!$A$5:$A$51,$B32,'SỔ CÔNG NỢ'!$B$5:$B$51,H$28)=0,"",SUMIFS('SỔ CÔNG NỢ'!$L$5:$L$51,'SỔ CÔNG NỢ'!$A$5:$A$51,$B32,'SỔ CÔNG NỢ'!$B$5:$B$51,H$28))) | I32: =IF($B32="","",IF(COUNTIFS('SỔ CÔNG NỢ'!$A$5:$A$51,$B32,'SỔ CÔNG NỢ'!$B$5:$B$51,I$28)=0,"",SUMIFS('SỔ CÔNG NỢ'!$L$5:$L$51,'SỔ CÔNG NỢ'!$A$5:$A$51,$B32,'SỔ CÔNG NỢ'!$B$5:$B$51,I$28)))
B33: =IF($B13="","",$B13) | C33: =IF($B33="","",IF(COUNTIFS('SỔ CÔNG NỢ'!$A$5:$A$51,$B33,'SỔ CÔNG NỢ'!$B$5:$B$51,C$28)=0,"",SUMIFS('SỔ CÔNG NỢ'!$L$5:$L$51,'SỔ CÔNG NỢ'!$A$5:$A$51,$B33,'SỔ CÔNG NỢ'!$B$5:$B$51,C$28))) | D33: =IF($B33="","",IF(COUNTIFS('SỔ CÔNG NỢ'!$A$5:$A$51,$B33,'SỔ CÔNG NỢ'!$B$5:$B$51,D$28)=0,"",SUMIFS('SỔ CÔNG NỢ'!$L$5:$L$51,'SỔ CÔNG NỢ'!$A$5:$A$51,$B33,'SỔ CÔNG NỢ'!$B$5:$B$51,D$28))) | E33: =IF($B33="","",IF(COUNTIFS('SỔ CÔNG NỢ'!$A$5:$A$51,$B33,'SỔ CÔNG NỢ'!$B$5:$B$51,E$28)=0,"",SUMIFS('SỔ CÔNG NỢ'!$L$5:$L$51,'SỔ CÔNG NỢ'!$A$5:$A$51,$B33,'SỔ CÔNG NỢ'!$B$5:$B$51,E$28))) | F33: =IF($B33="","",IF(COUNTIFS('SỔ CÔNG NỢ'!$A$5:$A$51,$B33,'SỔ CÔNG NỢ'!$B$5:$B$51,F$28)=0,"",SUMIFS('SỔ CÔNG NỢ'!$L$5:$L$51,'SỔ CÔNG NỢ'!$A$5:$A$51,$B33,'SỔ CÔNG NỢ'!$B$5:$B$51,F$28))) | G33: =IF($B33="","",IF(COUNTIFS('SỔ CÔNG NỢ'!$A$5:$A$51,$B33,'SỔ CÔNG NỢ'!$B$5:$B$51,G$28)=0,"",SUMIFS('SỔ CÔNG NỢ'!$L$5:$L$51,'SỔ CÔNG NỢ'!$A$5:$A$51,$B33,'SỔ CÔNG NỢ'!$B$5:$B$51,G$28))) | H33: =IF($B33="","",IF(COUNTIFS('SỔ CÔNG NỢ'!$A$5:$A$51,$B33,'SỔ CÔNG NỢ'!$B$5:$B$51,H$28)=0,"",SUMIFS('SỔ CÔNG NỢ'!$L$5:$L$51,'SỔ CÔNG NỢ'!$A$5:$A$51,$B33,'SỔ CÔNG NỢ'!$B$5:$B$51,H$28))) | I33: =IF($B33="","",IF(COUNTIFS('SỔ CÔNG NỢ'!$A$5:$A$51,$B33,'SỔ CÔNG NỢ'!$B$5:$B$51,I$28)=0,"",SUMIFS('SỔ CÔNG NỢ'!$L$5:$L$51,'SỔ CÔNG NỢ'!$A$5:$A$51,$B33,'SỔ CÔNG NỢ'!$B$5:$B$51,I$28)))
B34: =IF($B14="","",$B14) | C34: =IF($B34="","",IF(COUNTIFS('SỔ CÔNG NỢ'!$A$5:$A$51,$B34,'SỔ CÔNG NỢ'!$B$5:$B$51,C$28)=0,"",SUMIFS('SỔ CÔNG NỢ'!$L$5:$L$51,'SỔ CÔNG NỢ'!$A$5:$A$51,$B34,'SỔ CÔNG NỢ'!$B$5:$B$51,C$28))) | D34: =IF($B34="","",IF(COUNTIFS('SỔ CÔNG NỢ'!$A$5:$A$51,$B34,'SỔ CÔNG NỢ'!$B$5:$B$51,D$28)=0,"",SUMIFS('SỔ CÔNG NỢ'!$L$5:$L$51,'SỔ CÔNG NỢ'!$A$5:$A$51,$B34,'SỔ CÔNG NỢ'!$B$5:$B$51,D$28))) | E34: =IF($B34="","",IF(COUNTIFS('SỔ CÔNG NỢ'!$A$5:$A$51,$B34,'SỔ CÔNG NỢ'!$B$5:$B$51,E$28)=0,"",SUMIFS('SỔ CÔNG NỢ'!$L$5:$L$51,'SỔ CÔNG NỢ'!$A$5:$A$51,$B34,'SỔ CÔNG NỢ'!$B$5:$B$51,E$28))) | F34: =IF($B34="","",IF(COUNTIFS('SỔ CÔNG NỢ'!$A$5:$A$51,$B34,'SỔ CÔNG NỢ'!$B$5:$B$51,F$28)=0,"",SUMIFS('SỔ CÔNG NỢ'!$L$5:$L$51,'SỔ CÔNG NỢ'!$A$5:$A$51,$B34,'SỔ CÔNG NỢ'!$B$5:$B$51,F$28))) | G34: =IF($B34="","",IF(COUNTIFS('SỔ CÔNG NỢ'!$A$5:$A$51,$B34,'SỔ CÔNG NỢ'!$B$5:$B$51,G$28)=0,"",SUMIFS('SỔ CÔNG NỢ'!$L$5:$L$51,'SỔ CÔNG NỢ'!$A$5:$A$51,$B34,'SỔ CÔNG NỢ'!$B$5:$B$51,G$28))) | H34: =IF($B34="","",IF(COUNTIFS('SỔ CÔNG NỢ'!$A$5:$A$51,$B34,'SỔ CÔNG NỢ'!$B$5:$B$51,H$28)=0,"",SUMIFS('SỔ CÔNG NỢ'!$L$5:$L$51,'SỔ CÔNG NỢ'!$A$5:$A$51,$B34,'SỔ CÔNG NỢ'!$B$5:$B$51,H$28))) | I34: =IF($B34="","",IF(COUNTIFS('SỔ CÔNG NỢ'!$A$5:$A$51,$B34,'SỔ CÔNG NỢ'!$B$5:$B$51,I$28)=0,"",SUMIFS('SỔ CÔNG NỢ'!$L$5:$L$51,'SỔ CÔNG NỢ'!$A$5:$A$51,$B34,'SỔ CÔNG NỢ'!$B$5:$B$51,I$28)))
B35: =IF($B15="","",$B15) | C35: =IF($B35="","",IF(COUNTIFS('SỔ CÔNG NỢ'!$A$5:$A$51,$B35,'SỔ CÔNG NỢ'!$B$5:$B$51,C$28)=0,"",SUMIFS('SỔ CÔNG NỢ'!$L$5:$L$51,'SỔ CÔNG NỢ'!$A$5:$A$51,$B35,'SỔ CÔNG NỢ'!$B$5:$B$51,C$28))) | D35: =IF($B35="","",IF(COUNTIFS('SỔ CÔNG NỢ'!$A$5:$A$51,$B35,'SỔ CÔNG NỢ'!$B$5:$B$51,D$28)=0,"",SUMIFS('SỔ CÔNG NỢ'!$L$5:$L$51,'SỔ CÔNG NỢ'!$A$5:$A$51,$B35,'SỔ CÔNG NỢ'!$B$5:$B$51,D$28))) | E35: =IF($B35="","",IF(COUNTIFS('SỔ CÔNG NỢ'!$A$5:$A$51,$B35,'SỔ CÔNG NỢ'!$B$5:$B$51,E$28)=0,"",SUMIFS('SỔ CÔNG NỢ'!$L$5:$L$51,'SỔ CÔNG NỢ'!$A$5:$A$51,$B35,'SỔ CÔNG NỢ'!$B$5:$B$51,E$28))) | F35: =IF($B35="","",IF(COUNTIFS('SỔ CÔNG NỢ'!$A$5:$A$51,$B35,'SỔ CÔNG NỢ'!$B$5:$B$51,F$28)=0,"",SUMIFS('SỔ CÔNG NỢ'!$L$5:$L$51,'SỔ CÔNG NỢ'!$A$5:$A$51,$B35,'SỔ CÔNG NỢ'!$B$5:$B$51,F$28))) | G35: =IF($B35="","",IF(COUNTIFS('SỔ CÔNG NỢ'!$A$5:$A$51,$B35,'SỔ CÔNG NỢ'!$B$5:$B$51,G$28)=0,"",SUMIFS('SỔ CÔNG NỢ'!$L$5:$L$51,'SỔ CÔNG NỢ'!$A$5:$A$51,$B35,'SỔ CÔNG NỢ'!$B$5:$B$51,G$28))) | H35: =IF($B35="","",IF(COUNTIFS('SỔ CÔNG NỢ'!$A$5:$A$51,$B35,'SỔ CÔNG NỢ'!$B$5:$B$51,H$28)=0,"",SUMIFS('SỔ CÔNG NỢ'!$L$5:$L$51,'SỔ CÔNG NỢ'!$A$5:$A$51,$B35,'SỔ CÔNG NỢ'!$B$5:$B$51,H$28))) | I35: =IF($B35="","",IF(COUNTIFS('SỔ CÔNG NỢ'!$A$5:$A$51,$B35,'SỔ CÔNG NỢ'!$B$5:$B$51,I$28)=0,"",SUMIFS('SỔ CÔNG NỢ'!$L$5:$L$51,'SỔ CÔNG NỢ'!$A$5:$A$51,$B35,'SỔ CÔNG NỢ'!$B$5:$B$51,I$28)))
B36: =IF($B16="","",$B16) | C36: =IF($B36="","",IF(COUNTIFS('SỔ CÔNG NỢ'!$A$5:$A$51,$B36,'SỔ CÔNG NỢ'!$B$5:$B$51,C$28)=0,"",SUMIFS('SỔ CÔNG NỢ'!$L$5:$L$51,'SỔ CÔNG NỢ'!$A$5:$A$51,$B36,'SỔ CÔNG NỢ'!$B$5:$B$51,C$28))) | D36: =IF($B36="","",IF(COUNTIFS('SỔ CÔNG NỢ'!$A$5:$A$51,$B36,'SỔ CÔNG NỢ'!$B$5:$B$51,D$28)=0,"",SUMIFS('SỔ CÔNG NỢ'!$L$5:$L$51,'SỔ CÔNG NỢ'!$A$5:$A$51,$B36,'SỔ CÔNG NỢ'!$B$5:$B$51,D$28))) | E36: =IF($B36="","",IF(COUNTIFS('SỔ CÔNG NỢ'!$A$5:$A$51,$B36,'SỔ CÔNG NỢ'!$B$5:$B$51,E$28)=0,"",SUMIFS('SỔ CÔNG NỢ'!$L$5:$L$51,'SỔ CÔNG NỢ'!$A$5:$A$51,$B36,'SỔ CÔNG NỢ'!$B$5:$B$51,E$28))) | F36: =IF($B36="","",IF(COUNTIFS('SỔ CÔNG NỢ'!$A$5:$A$51,$B36,'SỔ CÔNG NỢ'!$B$5:$B$51,F$28)=0,"",SUMIFS('SỔ CÔNG NỢ'!$L$5:$L$51,'SỔ CÔNG NỢ'!$A$5:$A$51,$B36,'SỔ CÔNG NỢ'!$B$5:$B$51,F$28))) | G36: =IF($B36="","",IF(COUNTIFS('SỔ CÔNG NỢ'!$A$5:$A$51,$B36,'SỔ CÔNG NỢ'!$B$5:$B$51,G$28)=0,"",SUMIFS('SỔ CÔNG NỢ'!$L$5:$L$51,'SỔ CÔNG NỢ'!$A$5:$A$51,$B36,'SỔ CÔNG NỢ'!$B$5:$B$51,G$28))) | H36: =IF($B36="","",IF(COUNTIFS('SỔ CÔNG NỢ'!$A$5:$A$51,$B36,'SỔ CÔNG NỢ'!$B$5:$B$51,H$28)=0,"",SUMIFS('SỔ CÔNG NỢ'!$L$5:$L$51,'SỔ CÔNG NỢ'!$A$5:$A$51,$B36,'SỔ CÔNG NỢ'!$B$5:$B$51,H$28))) | I36: =IF($B36="","",IF(COUNTIFS('SỔ CÔNG NỢ'!$A$5:$A$51,$B36,'SỔ CÔNG NỢ'!$B$5:$B$51,I$28)=0,"",SUMIFS('SỔ CÔNG NỢ'!$L$5:$L$51,'SỔ CÔNG NỢ'!$A$5:$A$51,$B36,'SỔ CÔNG NỢ'!$B$5:$B$51,I$28)))
B37: =IF($B17="","",$B17) | C37: =IF($B37="","",IF(COUNTIFS('SỔ CÔNG NỢ'!$A$5:$A$51,$B37,'SỔ CÔNG NỢ'!$B$5:$B$51,C$28)=0,"",SUMIFS('SỔ CÔNG NỢ'!$L$5:$L$51,'SỔ CÔNG NỢ'!$A$5:$A$51,$B37,'SỔ CÔNG NỢ'!$B$5:$B$51,C$28))) | D37: =IF($B37="","",IF(COUNTIFS('SỔ CÔNG NỢ'!$A$5:$A$51,$B37,'SỔ CÔNG NỢ'!$B$5:$B$51,D$28)=0,"",SUMIFS('SỔ CÔNG NỢ'!$L$5:$L$51,'SỔ CÔNG NỢ'!$A$5:$A$51,$B37,'SỔ CÔNG NỢ'!$B$5:$B$51,D$28))) | E37: =IF($B37="","",IF(COUNTIFS('SỔ CÔNG NỢ'!$A$5:$A$51,$B37,'SỔ CÔNG NỢ'!$B$5:$B$51,E$28)=0,"",SUMIFS('SỔ CÔNG NỢ'!$L$5:$L$51,'SỔ CÔNG NỢ'!$A$5:$A$51,$B37,'SỔ CÔNG NỢ'!$B$5:$B$51,E$28))) | F37: =IF($B37="","",IF(COUNTIFS('SỔ CÔNG NỢ'!$A$5:$A$51,$B37,'SỔ CÔNG NỢ'!$B$5:$B$51,F$28)=0,"",SUMIFS('SỔ CÔNG NỢ'!$L$5:$L$51,'SỔ CÔNG NỢ'!$A$5:$A$51,$B37,'SỔ CÔNG NỢ'!$B$5:$B$51,F$28))) | G37: =IF($B37="","",IF(COUNTIFS('SỔ CÔNG NỢ'!$A$5:$A$51,$B37,'SỔ CÔNG NỢ'!$B$5:$B$51,G$28)=0,"",SUMIFS('SỔ CÔNG NỢ'!$L$5:$L$51,'SỔ CÔNG NỢ'!$A$5:$A$51,$B37,'SỔ CÔNG NỢ'!$B$5:$B$51,G$28))) | H37: =IF($B37="","",IF(COUNTIFS('SỔ CÔNG NỢ'!$A$5:$A$51,$B37,'SỔ CÔNG NỢ'!$B$5:$B$51,H$28)=0,"",SUMIFS('SỔ CÔNG NỢ'!$L$5:$L$51,'SỔ CÔNG NỢ'!$A$5:$A$51,$B37,'SỔ CÔNG NỢ'!$B$5:$B$51,H$28))) | I37: =IF($B37="","",IF(COUNTIFS('SỔ CÔNG NỢ'!$A$5:$A$51,$B37,'SỔ CÔNG NỢ'!$B$5:$B$51,I$28)=0,"",SUMIFS('SỔ CÔNG NỢ'!$L$5:$L$51,'SỔ CÔNG NỢ'!$A$5:$A$51,$B37,'SỔ CÔNG NỢ'!$B$5:$B$51,I$28)))
B38: =IF($B18="","",$B18) | C38: =IF($B38="","",IF(COUNTIFS('SỔ CÔNG NỢ'!$A$5:$A$51,$B38,'SỔ CÔNG NỢ'!$B$5:$B$51,C$28)=0,"",SUMIFS('SỔ CÔNG NỢ'!$L$5:$L$51,'SỔ CÔNG NỢ'!$A$5:$A$51,$B38,'SỔ CÔNG NỢ'!$B$5:$B$51,C$28))) | D38: =IF($B38="","",IF(COUNTIFS('SỔ CÔNG NỢ'!$A$5:$A$51,$B38,'SỔ CÔNG NỢ'!$B$5:$B$51,D$28)=0,"",SUMIFS('SỔ CÔNG NỢ'!$L$5:$L$51,'SỔ CÔNG NỢ'!$A$5:$A$51,$B38,'SỔ CÔNG NỢ'!$B$5:$B$51,D$28))) | E38: =IF($B38="","",IF(COUNTIFS('SỔ CÔNG NỢ'!$A$5:$A$51,$B38,'SỔ CÔNG NỢ'!$B$5:$B$51,E$28)=0,"",SUMIFS('SỔ CÔNG NỢ'!$L$5:$L$51,'SỔ CÔNG NỢ'!$A$5:$A$51,$B38,'SỔ CÔNG NỢ'!$B$5:$B$51,E$28))) | F38: =IF($B38="","",IF(COUNTIFS('SỔ CÔNG NỢ'!$A$5:$A$51,$B38,'SỔ CÔNG NỢ'!$B$5:$B$51,F$28)=0,"",SUMIFS('SỔ CÔNG NỢ'!$L$5:$L$51,'SỔ CÔNG NỢ'!$A$5:$A$51,$B38,'SỔ CÔNG NỢ'!$B$5:$B$51,F$28))) | G38: =IF($B38="","",IF(COUNTIFS('SỔ CÔNG NỢ'!$A$5:$A$51,$B38,'SỔ CÔNG NỢ'!$B$5:$B$51,G$28)=0,"",SUMIFS('SỔ CÔNG NỢ'!$L$5:$L$51,'SỔ CÔNG NỢ'!$A$5:$A$51,$B38,'SỔ CÔNG NỢ'!$B$5:$B$51,G$28))) | H38: =IF($B38="","",IF(COUNTIFS('SỔ CÔNG NỢ'!$A$5:$A$51,$B38,'SỔ CÔNG NỢ'!$B$5:$B$51,H$28)=0,"",SUMIFS('SỔ CÔNG NỢ'!$L$5:$L$51,'SỔ CÔNG NỢ'!$A$5:$A$51,$B38,'SỔ CÔNG NỢ'!$B$5:$B$51,H$28))) | I38: =IF($B38="","",IF(COUNTIFS('SỔ CÔNG NỢ'!$A$5:$A$51,$B38,'SỔ CÔNG NỢ'!$B$5:$B$51,I$28)=0,"",SUMIFS('SỔ CÔNG NỢ'!$L$5:$L$51,'SỔ CÔNG NỢ'!$A$5:$A$51,$B38,'SỔ CÔNG NỢ'!$B$5:$B$51,I$28)))
B39: =IF($B19="","",$B19) | C39: =IF($B39="","",IF(COUNTIFS('SỔ CÔNG NỢ'!$A$5:$A$51,$B39,'SỔ CÔNG NỢ'!$B$5:$B$51,C$28)=0,"",SUMIFS('SỔ CÔNG NỢ'!$L$5:$L$51,'SỔ CÔNG NỢ'!$A$5:$A$51,$B39,'SỔ CÔNG NỢ'!$B$5:$B$51,C$28))) | D39: =IF($B39="","",IF(COUNTIFS('SỔ CÔNG NỢ'!$A$5:$A$51,$B39,'SỔ CÔNG NỢ'!$B$5:$B$51,D$28)=0,"",SUMIFS('SỔ CÔNG NỢ'!$L$5:$L$51,'SỔ CÔNG NỢ'!$A$5:$A$51,$B39,'SỔ CÔNG NỢ'!$B$5:$B$51,D$28))) | E39: =IF($B39="","",IF(COUNTIFS('SỔ CÔNG NỢ'!$A$5:$A$51,$B39,'SỔ CÔNG NỢ'!$B$5:$B$51,E$28)=0,"",SUMIFS('SỔ CÔNG NỢ'!$L$5:$L$51,'SỔ CÔNG NỢ'!$A$5:$A$51,$B39,'SỔ CÔNG NỢ'!$B$5:$B$51,E$28))) | F39: =IF($B39="","",IF(COUNTIFS('SỔ CÔNG NỢ'!$A$5:$A$51,$B39,'SỔ CÔNG NỢ'!$B$5:$B$51,F$28)=0,"",SUMIFS('SỔ CÔNG NỢ'!$L$5:$L$51,'SỔ CÔNG NỢ'!$A$5:$A$51,$B39,'SỔ CÔNG NỢ'!$B$5:$B$51,F$28))) | G39: =IF($B39="","",IF(COUNTIFS('SỔ CÔNG NỢ'!$A$5:$A$51,$B39,'SỔ CÔNG NỢ'!$B$5:$B$51,G$28)=0,"",SUMIFS('SỔ CÔNG NỢ'!$L$5:$L$51,'SỔ CÔNG NỢ'!$A$5:$A$51,$B39,'SỔ CÔNG NỢ'!$B$5:$B$51,G$28))) | H39: =IF($B39="","",IF(COUNTIFS('SỔ CÔNG NỢ'!$A$5:$A$51,$B39,'SỔ CÔNG NỢ'!$B$5:$B$51,H$28)=0,"",SUMIFS('SỔ CÔNG NỢ'!$L$5:$L$51,'SỔ CÔNG NỢ'!$A$5:$A$51,$B39,'SỔ CÔNG NỢ'!$B$5:$B$51,H$28))) | I39: =IF($B39="","",IF(COUNTIFS('SỔ CÔNG NỢ'!$A$5:$A$51,$B39,'SỔ CÔNG NỢ'!$B$5:$B$51,I$28)=0,"",SUMIFS('SỔ CÔNG NỢ'!$L$5:$L$51,'SỔ CÔNG NỢ'!$A$5:$A$51,$B39,'SỔ CÔNG NỢ'!$B$5:$B$51,I$28)))
B40: =IF($B20="","",$B20) | C40: =IF($B40="","",IF(COUNTIFS('SỔ CÔNG NỢ'!$A$5:$A$51,$B40,'SỔ CÔNG NỢ'!$B$5:$B$51,C$28)=0,"",SUMIFS('SỔ CÔNG NỢ'!$L$5:$L$51,'SỔ CÔNG NỢ'!$A$5:$A$51,$B40,'SỔ CÔNG NỢ'!$B$5:$B$51,C$28))) | D40: =IF($B40="","",IF(COUNTIFS('SỔ CÔNG NỢ'!$A$5:$A$51,$B40,'SỔ CÔNG NỢ'!$B$5:$B$51,D$28)=0,"",SUMIFS('SỔ CÔNG NỢ'!$L$5:$L$51,'SỔ CÔNG NỢ'!$A$5:$A$51,$B40,'SỔ CÔNG NỢ'!$B$5:$B$51,D$28))) | E40: =IF($B40="","",IF(COUNTIFS('SỔ CÔNG NỢ'!$A$5:$A$51,$B40,'SỔ CÔNG NỢ'!$B$5:$B$51,E$28)=0,"",SUMIFS('SỔ CÔNG NỢ'!$L$5:$L$51,'SỔ CÔNG NỢ'!$A$5:$A$51,$B40,'SỔ CÔNG NỢ'!$B$5:$B$51,E$28))) | F40: =IF($B40="","",IF(COUNTIFS('SỔ CÔNG NỢ'!$A$5:$A$51,$B40,'SỔ CÔNG NỢ'!$B$5:$B$51,F$28)=0,"",SUMIFS('SỔ CÔNG NỢ'!$L$5:$L$51,'SỔ CÔNG NỢ'!$A$5:$A$51,$B40,'SỔ CÔNG NỢ'!$B$5:$B$51,F$28))) | G40: =IF($B40="","",IF(COUNTIFS('SỔ CÔNG NỢ'!$A$5:$A$51,$B40,'SỔ CÔNG NỢ'!$B$5:$B$51,G$28)=0,"",SUMIFS('SỔ CÔNG NỢ'!$L$5:$L$51,'SỔ CÔNG NỢ'!$A$5:$A$51,$B40,'SỔ CÔNG NỢ'!$B$5:$B$51,G$28))) | H40: =IF($B40="","",IF(COUNTIFS('SỔ CÔNG NỢ'!$A$5:$A$51,$B40,'SỔ CÔNG NỢ'!$B$5:$B$51,H$28)=0,"",SUMIFS('SỔ CÔNG NỢ'!$L$5:$L$51,'SỔ CÔNG NỢ'!$A$5:$A$51,$B40,'SỔ CÔNG NỢ'!$B$5:$B$51,H$28))) | I40: =IF($B40="","",IF(COUNTIFS('SỔ CÔNG NỢ'!$A$5:$A$51,$B40,'SỔ CÔNG NỢ'!$B$5:$B$51,I$28)=0,"",SUMIFS('SỔ CÔNG NỢ'!$L$5:$L$51,'SỔ CÔNG NỢ'!$A$5:$A$51,$B40,'SỔ CÔNG NỢ'!$B$5:$B$51,I$28)))
B41: TỔNG | C41: =SUM(C29:C40) -> 9966050 | D41: =SUM(D29:D40) -> 10599223 | E41: =SUM(E29:E40) -> -7095410 | F41: =SUM(F29:F40) -> 33078350 | G41: =SUM(G29:G40) -> 0 | H41: =SUM(H29:H40) -> 0 | I41: =SUM(I29:I40) -> 0
A44: ▶ PHÁT SINH SAU CHIẾT KHẤU THEO THÁNG
B45: Khách hàng | C45: =$C$25 -> 46174 | D45: =EDATE(C45,1) -> 46204 | E45: =EDATE(D45,1) -> 46235 | F45: =EDATE(E45,1) -> 46266 | G45: =EDATE(F45,1) -> 46296 | H45: =EDATE(G45,1) -> 46327 | I45: =EDATE(H45,1) -> 46357
B46: =IF($B9="","",$B9) -> Hiền Xuân | C46: =IF($B46="","",IF(COUNTIFS('SỔ CÔNG NỢ'!$A$5:$A$51,$B46,'SỔ CÔNG NỢ'!$B$5:$B$51,C$45)=0,"",SUMIFS('SỔ CÔNG NỢ'!$G$5:$G$51,'SỔ CÔNG NỢ'!$A$5:$A$51,$B46,'SỔ CÔNG NỢ'!$B$5:$B$51,C$45))) | D46: =IF($B46="","",IF(COUNTIFS('SỔ CÔNG NỢ'!$A$5:$A$51,$B46,'SỔ CÔNG NỢ'!$B$5:$B$51,D$45)=0,"",SUMIFS('SỔ CÔNG NỢ'!$G$5:$G$51,'SỔ CÔNG NỢ'!$A$5:$A$51,$B46,'SỔ CÔNG NỢ'!$B$5:$B$51,D$45))) -> 31863893 | E46: =IF($B46="","",IF(COUNTIFS('SỔ CÔNG NỢ'!$A$5:$A$51,$B46,'SỔ CÔNG NỢ'!$B$5:$B$51,E$45)=0,"",SUMIFS('SỔ CÔNG NỢ'!$G$5:$G$51,'SỔ CÔNG NỢ'!$A$5:$A$51,$B46,'SỔ CÔNG NỢ'!$B$5:$B$51,E$45))) | F46: =IF($B46="","",IF(COUNTIFS('SỔ CÔNG NỢ'!$A$5:$A$51,$B46,'SỔ CÔNG NỢ'!$B$5:$B$51,F$45)=0,"",SUMIFS('SỔ CÔNG NỢ'!$G$5:$G$51,'SỔ CÔNG NỢ'!$A$5:$A$51,$B46,'SỔ CÔNG NỢ'!$B$5:$B$51,F$45))) | G46: =IF($B46="","",IF(COUNTIFS('SỔ CÔNG NỢ'!$A$5:$A$51,$B46,'SỔ CÔNG NỢ'!$B$5:$B$51,G$45)=0,"",SUMIFS('SỔ CÔNG NỢ'!$G$5:$G$51,'SỔ CÔNG NỢ'!$A$5:$A$51,$B46,'SỔ CÔNG NỢ'!$B$5:$B$51,G$45))) | H46: =IF($B46="","",IF(COUNTIFS('SỔ CÔNG NỢ'!$A$5:$A$51,$B46,'SỔ CÔNG NỢ'!$B$5:$B$51,H$45)=0,"",SUMIFS('SỔ CÔNG NỢ'!$G$5:$G$51,'SỔ CÔNG NỢ'!$A$5:$A$51,$B46,'SỔ CÔNG NỢ'!$B$5:$B$51,H$45))) | I46: =IF($B46="","",IF(COUNTIFS('SỔ CÔNG NỢ'!$A$5:$A$51,$B46,'SỔ CÔNG NỢ'!$B$5:$B$51,I$45)=0,"",SUMIFS('SỔ CÔNG NỢ'!$G$5:$G$51,'SỔ CÔNG NỢ'!$A$5:$A$51,$B46,'SỔ CÔNG NỢ'!$B$5:$B$51,I$45)))
B47: =IF($B10="","",$B10) -> Hòa Hiệp | C47: =IF($B47="","",IF(COUNTIFS('SỔ CÔNG NỢ'!$A$5:$A$51,$B47,'SỔ CÔNG NỢ'!$B$5:$B$51,C$45)=0,"",SUMIFS('SỔ CÔNG NỢ'!$G$5:$G$51,'SỔ CÔNG NỢ'!$A$5:$A$51,$B47,'SỔ CÔNG NỢ'!$B$5:$B$51,C$45))) -> 1387500 | D47: =IF($B47="","",IF(COUNTIFS('SỔ CÔNG NỢ'!$A$5:$A$51,$B47,'SỔ CÔNG NỢ'!$B$5:$B$51,D$45)=0,"",SUMIFS('SỔ CÔNG NỢ'!$G$5:$G$51,'SỔ CÔNG NỢ'!$A$5:$A$51,$B47,'SỔ CÔNG NỢ'!$B$5:$B$51,D$45))) | E47: =IF($B47="","",IF(COUNTIFS('SỔ CÔNG NỢ'!$A$5:$A$51,$B47,'SỔ CÔNG NỢ'!$B$5:$B$51,E$45)=0,"",SUMIFS('SỔ CÔNG NỢ'!$G$5:$G$51,'SỔ CÔNG NỢ'!$A$5:$A$51,$B47,'SỔ CÔNG NỢ'!$B$5:$B$51,E$45))) | F47: =IF($B47="","",IF(COUNTIFS('SỔ CÔNG NỢ'!$A$5:$A$51,$B47,'SỔ CÔNG NỢ'!$B$5:$B$51,F$45)=0,"",SUMIFS('SỔ CÔNG NỢ'!$G$5:$G$51,'SỔ CÔNG NỢ'!$A$5:$A$51,$B47,'SỔ CÔNG NỢ'!$B$5:$B$51,F$45))) | G47: =IF($B47="","",IF(COUNTIFS('SỔ CÔNG NỢ'!$A$5:$A$51,$B47,'SỔ CÔNG NỢ'!$B$5:$B$51,G$45)=0,"",SUMIFS('SỔ CÔNG NỢ'!$G$5:$G$51,'SỔ CÔNG NỢ'!$A$5:$A$51,$B47,'SỔ CÔNG NỢ'!$B$5:$B$51,G$45))) | H47: =IF($B47="","",IF(COUNTIFS('SỔ CÔNG NỢ'!$A$5:$A$51,$B47,'SỔ CÔNG NỢ'!$B$5:$B$51,H$45)=0,"",SUMIFS('SỔ CÔNG NỢ'!$G$5:$G$51,'SỔ CÔNG NỢ'!$A$5:$A$51,$B47,'SỔ CÔNG NỢ'!$B$5:$B$51,H$45))) | I47: =IF($B47="","",IF(COUNTIFS('SỔ CÔNG NỢ'!$A$5:$A$51,$B47,'SỔ CÔNG NỢ'!$B$5:$B$51,I$45)=0,"",SUMIFS('SỔ CÔNG NỢ'!$G$5:$G$51,'SỔ CÔNG NỢ'!$A$5:$A$51,$B47,'SỔ CÔNG NỢ'!$B$5:$B$51,I$45)))
...

Sheet SỔ CÔNG NỢ
A1: SỔ CÔNG NỢ THEO KHÁCH – THEO THÁNG
A2: Số dương = khách còn nợ công ty. Số âm (đỏ) = khách trả dư, công ty đang nợ lại khách. Chị chỉ nhập: tên khách, tháng, % chiết khấu (và nợ đầu kỳ của tháng đầu tiên).
A4: Khách hàng | B4: Tháng | C4: Nợ đầu kỳ | D4: Phát sinh (giá gốc) | E4: % chiết khấu | F4: Tiền chiết khấu | G4: Phát sinh sau chiết khấu | H4: Hàng trả lại (giá gốc) | I4: Hàng trả lại sau chiết khấu | J4: TỔNG NỢ PHẢI THANH TOÁN | K4: Khách đã thanh toán | L4: NỢ CUỐI KỲ | M4: Theo biên bản (đối chiếu) | N4: Chênh lệch (phải = 0) | O4: Ghi chú
A5: Hiền Xuân | B5: 46204 | C5: 63600 | D5: =IF(OR($A5="",$B5=""),"",SUMIFS('CHI TIẾT HÀNG'!$L$5:$L$1004,'CHI TIẾT HÀNG'!$A$5:$A$1004,$A5,'CHI TIẾT HÀNG'!$C$5:$C$1004,$B5,'CHI TIẾT HÀNG'!$D$5:$D$1004,"Bán")) -> 83852350 | E5: 0.62 | F5: =IF(OR($A5="",$B5=""),"",ROUND(D5*E5,0)) -> 51988457 | G5: =IF(OR($A5="",$B5=""),"",D5-F5) -> 31863893 | H5: =IF(OR($A5="",$B5=""),"",SUMIFS('CHI TIẾT HÀNG'!$L$5:$L$1004,'CHI TIẾT HÀNG'!$A$5:$A$1004,$A5,'CHI TIẾT HÀNG'!$C$5:$C$1004,$B5,'CHI TIẾT HÀNG'!$D$5:$D$1004,"Trả lại")) -> 4597000 | I5: =IF(OR($A5="",$B5=""),"",H5-ROUND(H5*E5,0)) -> 1746860 | J5: =IF(OR($A5="",$B5=""),"",C5+G5-I5) -> 30180633 | K5: =IF(OR($A5="",$B5=""),"",SUMIFS('THANH TOÁN'!$D$5:$D$404,'THANH TOÁN'!$A$5:$A$404,$A5,'THANH TOÁN'!$C$5:$C$404,$B5)) -> 30060000 | L5: =IF(OR($A5="",$B5=""),"",J5-K5) -> 120633 | M5: 120633 | N5: =IF(OR($A5="",M5=""),"",L5-M5) -> 0 | O5: Có 1 thùng ISG06 khách trả lại 30/07
A6: Hòa Hiệp | B6: 46174 | C6: 0 | D6: =IF(OR($A6="",$B6=""),"",SUMIFS('CHI TIẾT HÀNG'!$L$5:$L$1004,'CHI TIẾT HÀNG'!$A$5:$A$1004,$A6,'CHI TIẾT HÀNG'!$C$5:$C$1004,$B6,'CHI TIẾT HÀNG'!$D$5:$D$1004,"Bán")) -> 3750000 | E6: 0.63 | F6: =IF(OR($A6="",$B6=""),"",ROUND(D6*E6,0)) -> 2362500 | G6: =IF(OR($A6="",$B6=""),"",D6-F6) -> 1387500 | H6: =IF(OR($A6="",$B6=""),"",SUMIFS('CHI TIẾT HÀNG'!$L$5:$L$1004,'CHI TIẾT HÀNG'!$A$5:$A$1004,$A6,'CHI TIẾT HÀNG'!$C$5:$C$1004,$B6,'CHI TIẾT HÀNG'!$D$5:$D$1004,"Trả lại")) -> 0 | I6: =IF(OR($A6="",$B6=""),"",H6-ROUND(H6*E6,0)) -> 0 | J6: =IF(OR($A6="",$B6=""),"",C6+G6-I6) -> 1387500 | K6: =IF(OR($A6="",$B6=""),"",SUMIFS('THANH TOÁN'!$D$5:$D$404,'THANH TOÁN'!$A$5:$A$404,$A6,'THANH TOÁN'!$C$5:$C$404,$B6)) -> 1500000 | L6: =IF(OR($A6="",$B6=""),"",J6-K6) -> -112500 | M6: -112500 | N6: =IF(OR($A6="",M6=""),"",L6-M6) -> 0 | O6: Khách thanh toán dư 112.500 đ (đã trả 1.500.000 so với 1.387.500 phải trả)
A7: Hà Liên | B7: 46174 | C7: 890150 | D7: =IF(OR($A7="",$B7=""),"",SUMIFS('CHI TIẾT HÀNG'!$L$5:$L$1004,'CHI TIẾT HÀNG'!$A$5:$A$1004,$A7,'CHI TIẾT HÀNG'!$C$5:$C$1004,$B7,'CHI TIẾT HÀNG'!$D$5:$D$1004,"Bán")) -> 22971000 | E7: 0.6 | F7: =IF(OR($A7="",$B7=""),"",ROUND(D7*E7,0)) -> 13782600 | G7: =IF(OR($A7="",$B7=""),"",D7-F7) -> 9188400 | H7: =IF(OR($A7="",$B7=""),"",SUMIFS('CHI TIẾT HÀNG'!$L$5:$L$1004,'CHI TIẾT HÀNG'!$A$5:$A$1004,$A7,'CHI TIẾT HÀNG'!$C$5:$C$1004,$B7,'CHI TIẾT HÀNG'!$D$5:$D$1004,"Trả lại")) -> 0 | I7: =IF(OR($A7="",$B7=""),"",H7-ROUND(H7*E7,0)) -> 0 | J7: =IF(OR($A7="",$B7=""),"",C7+G7-I7) -> 10078550 | K7: =IF(OR($A7="",$B7=""),"",SUMIFS('THANH TOÁN'!$D$5:$D$404,'THANH TOÁN'!$A$5:$A$404,$A7,'THANH TOÁN'!$C$5:$C$404,$B7)) -> 0 | L7: =IF(OR($A7="",$B7=""),"",J7-K7) -> 10078550 | M7: 10078550 | N7: =IF(OR($A7="",M7=""),"",L7-M7) -> 0
A8: Hà Liên | B8: 46204 | C8: =IF(OR($A8="",$B8=""),"",SUMIFS('SỔ CÔNG NỢ'!$L$5:$L$51,'SỔ CÔNG NỢ'!$A$5:$A$51,$A8,'SỔ CÔNG NỢ'!$B$5:$B$51,EDATE($B8,-1))) -> 10078550 | D8: =IF(OR($A8="",$B8=""),"",SUMIFS('CHI TIẾT HÀNG'!$L$5:$L$1004,'CHI TIẾT HÀNG'!$A$5:$A$1004,$A8,'CHI TIẾT HÀNG'!$C$5:$C$1004,$B8,'CHI TIẾT HÀNG'!$D$5:$D$1004,"Bán")) -> 39225100 | E8: 0.6 | F8: =IF(OR($A8="",$B8=""),"",ROUND(D8*E8,0)) -> 23535060 | G8: =IF(OR($A8="",$B8=""),"",D8-F8) -> 15690040 | H8: =IF(OR($A8="",$B8=""),"",SUMIFS('CHI TIẾT HÀNG'!$L$5:$L$1004,'CHI TIẾT HÀNG'!$A$5:$A$1004,$A8,'CHI TIẾT HÀNG'!$C$5:$C$1004,$B8,'CHI TIẾT HÀNG'!$D$5:$D$1004,"Trả lại")) -> 0 | I8: =IF(OR($A8="",$B8=""),"",H8-ROUND(H8*E8,0)) -> 0 | J8: =IF(OR($A8="",$B8=""),"",C8+G8-I8) -> 25768590 | K8: =IF(OR($A8="",$B8=""),"",SUMIFS('THANH TOÁN'!$D$5:$D$404,'THANH TOÁN'!$A$5:$A$404,$A8,'THANH TOÁN'!$C$5:$C$404,$B8)) -> 15290000 | L8: =IF(OR($A8="",$B8=""),"",J8-K8) -> 10478590 | M8: 10478590 | N8: =IF(OR($A8="",M8=""),"",L8-M8) -> 0
A9: Hà Liên | B9: 46235 | C9: =IF(OR($A9="",$B9=""),"",SUMIFS('SỔ CÔNG NỢ'!$L$5:$L$51,'SỔ CÔNG NỢ'!$A$5:$A$51,$A9,'SỔ CÔNG NỢ'!$B$5:$B$51,EDATE($B9,-1))) -> 10478590 | D9: =IF(OR($A9="",$B9=""),"",SUMIFS('CHI TIẾT HÀNG'!$L$5:$L$1004,'CHI TIẾT HÀNG'!$A$5:$A$1004,$A9,'CHI TIẾT HÀNG'!$C$5:$C$1004,$B9,'CHI TIẾT HÀNG'!$D$5:$D$1004,"Bán")) -> 39165000 | E9: 0.6 | F9: =IF(OR($A9="",$B9=""),"",ROUND(D9*E9,0)) -> 23499000 | G9: =IF(OR($A9="",$B9=""),"",D9-F9) -> 15666000 | H9: =IF(OR($A9="",$B9=""),"",SUMIFS('CHI TIẾT HÀNG'!$L$5:$L$1004,'CHI TIẾT HÀNG'!$A$5:$A$1004,$A9,'CHI TIẾT HÀNG'!$C$5:$C$1004,$B9,'CHI TIẾT HÀNG'!$D$5:$D$1004,"Trả lại")) -> 0 | I9: =IF(OR($A9="",$B9=""),"",H9-ROUND(H9*E9,0)) -> 0 | J9: =IF(OR($A9="",$B9=""),"",C9+G9-I9) -> 26144590 | K9: =IF(OR($A9="",$B9=""),"",SUMIFS('THANH TOÁN'!$D$5:$D$404,'THANH TOÁN'!$A$5:$A$404,$A9,'THANH TOÁN'!$C$5:$C$404,$B9)) -> 33240000 | L9: =IF(OR($A9="",$B9=""),"",J9-K9) -> -7095410 | M9: -7095410 | N9: =IF(OR($A9="",M9=""),"",L9-M9) -> 0 | O9: Khách thanh toán 33.240.000 > nợ 26.144.590 → công ty nợ lại 7.095.410
A10: Hà Liên | B10: 46266 | C10: =IF(OR($A10="",$B10=""),"",SUMIFS('SỔ CÔNG NỢ'!$L$5:$L$51,'SỔ CÔNG NỢ'!$A$5:$A$51,$A10,'SỔ CÔNG NỢ'!$B$5:$B$51,EDATE($B10,-1))) -> -7095410 | D10: =IF(OR($A10="",$B10=""),"",SUMIFS('CHI TIẾT HÀNG'!$L$5:$L$1004,'CHI TIẾT HÀNG'!$A$5:$A$1004,$A10,'CHI TIẾT HÀNG'!$C$5:$C$1004,$B10,'CHI TIẾT HÀNG'!$D$5:$D$1004,"Bán")) -> 100434400 | E10: 0.6 | F10: =IF(OR($A10="",$B10=""),"",ROUND(D10*E10,0)) -> 60260640 | G10: =IF(OR($A10="",$B10=""),"",D10-F10) -> 40173760 | H10: =IF(OR($A10="",$B10=""),"",SUMIFS('CHI TIẾT HÀNG'!$L$5:$L$1004,'CHI TIẾT HÀNG'!$A$5:$A$1004,$A10,'CHI TIẾT HÀNG'!$C$5:$C$1004,$B10,'CHI TIẾT HÀNG'!$D$5:$D$1004,"Trả lại")) -> 0 | I10: =IF(OR($A10="",$B10=""),"",H10-ROUND(H10*E10,0)) -> 0 | J10: =IF(OR($A10="",$B10=""),"",C10+G10-I10) -> 33078350 | K10: =IF(OR($A10="",$B10=""),"",SUMIFS('THANH TOÁN'!$D$5:$D$404,'THANH TOÁN'!$A$5:$A$404,$A10,'THANH TOÁN'!$C$5:$C$404,$B10)) -> 0 | L10: =IF(OR($A10="",$B10=""),"",J10-K10) -> 33078350 | M10: 33078350 | N10: =IF(OR($A10="",M10=""),"",L10-M10) -> 0 | O10: Biên bản ghi nhầm tiêu đề "Tháng 8"; chưa ghi khoản thanh toán nào; đầu kỳ −7.095.410 do kỳ trước khách trả dư
C11: =IF(OR($A11="",$B11=""),"",SUMIFS('SỔ CÔNG NỢ'!$L$5:$L$51,'SỔ CÔNG NỢ'!$A$5:$A$51,$A11,'SỔ CÔNG NỢ'!$B$5:$B$51,EDATE($B11,-1))) | D11: =IF(OR($A11="",$B11=""),"",SUMIFS('CHI TIẾT HÀNG'!$L$5:$L$1004,'CHI TIẾT HÀNG'!$A$5:$A$1004,$A11,'CHI TIẾT HÀNG'!$C$5:$C$1004,$B11,'CHI TIẾT HÀNG'!$D$5:$D$1004,"Bán")) | F11: =IF(OR($A11="",$B11=""),"",ROUND(D11*E11,0)) | G11: =IF(OR($A11="",$B11=""),"",D11-F11) | H11: =IF(OR($A11="",$B11=""),"",SUMIFS('CHI TIẾT HÀNG'!$L$5:$L$1004,'CHI TIẾT HÀNG'!$A$5:$A$1004,$A11,'CHI TIẾT HÀNG'!$C$5:$C$1004,$B11,'CHI TIẾT HÀNG'!$D$5:$D$1004,"Trả lại")) | I11: =IF(OR($A11="",$B11=""),"",H11-ROUND(H11*E11,0)) | J11: =IF(OR($A11="",$B11=""),"",C11+G11-I11) | K11: =IF(OR($A11="",$B11=""),"",SUMIFS('THANH TOÁN'!$D$5:$D$404,'THANH TOÁN'!$A$5:$A$404,$A11,'THANH TOÁN'!$C$5:$C$404,$B11)) | L11: =IF(OR($A11="",$B11=""),"",J11-K11) | N11: =IF(OR($A11="",M11=""),"",L11-M11)
C12: =IF(OR($A12="",$B12=""),"",SUMIFS('SỔ CÔNG NỢ'!$L$5:$L$51,'SỔ CÔNG NỢ'!$A$5:$A$51,$A12,'SỔ CÔNG NỢ'!$B$5:$B$51,EDATE($B12,-1))) | D12: =IF(OR($A12="",$B12=""),"",SUMIFS('CHI TIẾT HÀNG'!$L$5:$L$1004,'CHI TIẾT HÀNG'!$A$5:$A$1004,$A12,'CHI TIẾT HÀNG'!$C$5:$C$1004,$B12,'CHI TIẾT HÀNG'!$D$5:$D$1004,"Bán")) | F12: =IF(OR($A12="",$B12=""),"",ROUND(D12*E12,0)) | G12: =IF(OR($A12="",$B12=""),"",D12-F12) | H12: =IF(OR($A12="",$B12=""),"",SUMIFS('CHI TIẾT HÀNG'!$L$5:$L$1004,'CHI TIẾT HÀNG'!$A$5:$A$1004,$A12,'CHI TIẾT HÀNG'!$C$5:$C$1004,$B12,'CHI TIẾT HÀNG'!$D$5:$D$1004,"Trả lại")) | I12: =IF(OR($A12="",$B12=""),"",H12-ROUND(H12*E12,0)) | J12: =IF(OR($A12="",$B12=""),"",C12+G12-I12) | K12: =IF(OR($A12="",$B12=""),"",SUMIFS('THANH TOÁN'!$D$5:$D$404,'THANH TOÁN'!$A$5:$A$404,$A12,'THANH TOÁN'!$C$5:$C$404,$B12)) | L12: =IF(OR($A12="",$B12=""),"",J12-K12) | N12: =IF(OR($A12="",M12=""),"",L12-M12)
C13: =IF(OR($A13="",$B13=""),"",SUMIFS('SỔ CÔNG NỢ'!$L$5:$L$51,'SỔ CÔNG NỢ'!$A$5:$A$51,$A13,'SỔ CÔNG NỢ'!$B$5:$B$51,EDATE($B13,-1))) | D13: =IF(OR($A13="",$B13=""),"",SUMIFS('CHI TIẾT HÀNG'!$L$5:$L$1004,'CHI TIẾT HÀNG'!$A$5:$A$1004,$A13,'CHI TIẾT HÀNG'!$C$5:$C$1004,$B13,'CHI TIẾT HÀNG'!$D$5:$D$1004,"Bán")) | F13: =IF(OR($A13="",$B13=""),"",ROUND(D13*E13,0)) | G13: =IF(OR($A13="",$B13=""),"",D13-F13) | H13: =IF(OR($A13="",$B13=""),"",SUMIFS('CHI TIẾT HÀNG'!$L$5:$L$1004,'CHI TIẾT HÀNG'!$A$5:$A$1004,$A13,'CHI TIẾT HÀNG'!$C$5:$C$1004,$B13,'CHI TIẾT HÀNG'!$D$5:$D$1004,"Trả lại")) | I13: =IF(OR($A13="",$B13=""),"",H13-ROUND(H13*E13,0)) | J13: =IF(OR($A13="",$B13=""),"",C13+G13-I13) | K13: =IF(OR($A13="",$B13=""),"",SUMIFS('THANH TOÁN'!$D$5:$D$404,'THANH TOÁN'!$A$5:$A$404,$A13,'THANH TOÁN'!$C$5:$C$404,$B13)) | L13: =IF(OR($A13="",$B13=""),"",J13-K13) | N13: =IF(OR($A13="",M13=""),"",L13-M13)
C14: =IF(OR($A14="",$B14=""),"",SUMIFS('SỔ CÔNG NỢ'!$L$5:$L$51,'SỔ CÔNG NỢ'!$A$5:$A$51,$A14,'SỔ CÔNG NỢ'!$B$5:$B$51,EDATE($B14,-1))) | D14: =IF(OR($A14="",$B14=""),"",SUMIFS('CHI TIẾT HÀNG'!$L$5:$L$1004,'CHI TIẾT HÀNG'!$A$5:$A$1004,$A14,'CHI TIẾT HÀNG'!$C$5:$C$1004,$B14,'CHI TIẾT HÀNG'!$D$5:$D$1004,"Bán")) | F14: =IF(OR($A14="",$B14=""),"",ROUND(D14*E14,0)) | G14: =IF(OR($A14="",$B14=""),"",D14-F14) | H14: =IF(OR($A14="",$B14=""),"",SUMIFS('CHI TIẾT HÀNG'!$L$5:$L$1004,'CHI TIẾT HÀNG'!$A$5:$A$1004,$A14,'CHI TIẾT HÀNG'!$C$5:$C$1004,$B14,'CHI TIẾT HÀNG'!$D$5:$D$1004,"Trả lại")) | I14: =IF(OR($A14="",$B14=""),"",H14-ROUND(H14*E14,0)) | J14: =IF(OR($A14="",$B14=""),"",C14+G14-I14) | K14: =IF(OR($A14="",$B14=""),"",SUMIFS('THANH TOÁN'!$D$5:$D$404,'THANH TOÁN'!$A$5:$A$404,$A14,'THANH TOÁN'!$C$5:$C$404,$B14)) | L14: =IF(OR($A14="",$B14=""),"",J14-K14) | N14: =IF(OR($A14="",M14=""),"",L14-M14)
C15: =IF(OR($A15="",$B15=""),"",SUMIFS('SỔ CÔNG NỢ'!$L$5:$L$51,'SỔ CÔNG NỢ'!$A$5:$A$51,$A15,'SỔ CÔNG NỢ'!$B$5:$B$51,EDATE($B15,-1))) | D15: =IF(OR($A15="",$B15=""),"",SUMIFS('CHI TIẾT HÀNG'!$L$5:$L$1004,'CHI TIẾT HÀNG'!$A$5:$A$1004,$A15,'CHI TIẾT HÀNG'!$C$5:$C$1004,$B15,'CHI TIẾT HÀNG'!$D$5:$D$1004,"Bán")) | F15: =IF(OR($A15="",$B15=""),"",ROUND(D15*E15,0)) | G15: =IF(OR($A15="",$B15=""),"",D15-F15) | H15: =IF(OR($A15="",$B15=""),"",SUMIFS('CHI TIẾT HÀNG'!$L$5:$L$1004,'CHI TIẾT HÀNG'!$A$5:$A$1004,$A15,'CHI TIẾT HÀNG'!$C$5:$C$1004,$B15,'CHI TIẾT HÀNG'!$D$5:$D$1004,"Trả lại")) | I15: =IF(OR($A15="",$B15=""),"",H15-ROUND(H15*E15,0)) | J15: =IF(OR($A15="",$B15=""),"",C15+G15-I15) | K15: =IF(OR($A15="",$B15=""),"",SUMIFS('THANH TOÁN'!$D$5:$D$404,'THANH TOÁN'!$A$5:$A$404,$A15,'THANH TOÁN'!$C$5:$C$404,$B15)) | L15: =IF(OR($A15="",$B15=""),"",J15-K15) | N15: =IF(OR($A15="",M15=""),"",L15-M15)
C16: =IF(OR($A16="",$B16=""),"",SUMIFS('SỔ CÔNG NỢ'!$L$5:$L$51,'SỔ CÔNG NỢ'!$A$5:$A$51,$A16,'SỔ CÔNG NỢ'!$B$5:$B$51,EDATE($B16,-1))) | D16: =IF(OR($A16="",$B16=""),"",SUMIFS('CHI TIẾT HÀNG'!$L$5:$L$1004,'CHI TIẾT HÀNG'!$A$5:$A$1004,$A16,'CHI TIẾT HÀNG'!$C$5:$C$1004,$B16,'CHI TIẾT HÀNG'!$D$5:$D$1004,"Bán")) | F16: =IF(OR($A16="",$B16=""),"",ROUND(D16*E16,0)) | G16: =IF(OR($A16="",$B16=""),"",D16-F16) | H16: =IF(OR($A16="",$B16=""),"",SUMIFS('CHI TIẾT HÀNG'!$L$5:$L$1004,'CHI TIẾT HÀNG'!$A$5:$A$1004,$A16,'CHI TIẾT HÀNG'!$C$5:$C$1004,$B16,'CHI TIẾT HÀNG'!$D$5:$D$1004,"Trả lại")) | I16: =IF(OR($A16="",$B16=""),"",H16-ROUND(H16*E16,0)) | J16: =IF(OR($A16="",$B16=""),"",C16+G16-I16) | K16: =IF(OR($A16="",$B16=""),"",SUMIFS('THANH TOÁN'!$D$5:$D$404,'THANH TOÁN'!$A$5:$A$404,$A16,'THANH TOÁN'!$C$5:$C$404,$B16)) | L16: =IF(OR($A16="",$B16=""),"",J16-K16) | N16: =IF(OR($A16="",M16=""),"",L16-M16)
C17: =IF(OR($A17="",$B17=""),"",SUMIFS('SỔ CÔNG NỢ'!$L$5:$L$51,'SỔ CÔNG NỢ'!$A$5:$A$51,$A17,'SỔ CÔNG NỢ'!$B$5:$B$51,EDATE($B17,-1))) | D17: =IF(OR($A17="",$B17=""),"",SUMIFS('CHI TIẾT HÀNG'!$L$5:$L$1004,'CHI TIẾT HÀNG'!$A$5:$A$1004,$A17,'CHI TIẾT HÀNG'!$C$5:$C$1004,$B17,'CHI TIẾT HÀNG'!$D$5:$D$1004,"Bán")) | F17: =IF(OR($A17="",$B17=""),"",ROUND(D17*E17,0)) | G17: =IF(OR($A17="",$B17=""),"",D17-F17) | H17: =IF(OR($A17="",$B17=""),"",SUMIFS('CHI TIẾT HÀNG'!$L$5:$L$1004,'CHI TIẾT HÀNG'!$A$5:$A$1004,$A17,'CHI TIẾT HÀNG'!$C$5:$C$1004,$B17,'CHI TIẾT HÀNG'!$D$5:$D$1004,"Trả lại")) | I17: =IF(OR($A17="",$B17=""),"",H17-ROUND(H17*E17,0)) | J17: =IF(OR($A17="",$B17=""),"",C17+G17-I17) | K17: =IF(OR($A17="",$B17=""),"",SUMIFS('THANH TOÁN'!$D$5:$D$404,'THANH TOÁN'!$A$5:$A$404,$A17,'THANH TOÁN'!$C$5:$C$404,$B17)) | L17: =IF(OR($A17="",$B17=""),"",J17-K17) | N17: =IF(OR($A17="",M17=""),"",L17-M17)
C18: =IF(OR($A18="",$B18=""),"",SUMIFS('SỔ CÔNG NỢ'!$L$5:$L$51,'SỔ CÔNG NỢ'!$A$5:$A$51,$A18,'SỔ CÔNG NỢ'!$B$5:$B$51,EDATE($B18,-1))) | D18: =IF(OR($A18="",$B18=""),"",SUMIFS('CHI TIẾT HÀNG'!$L$5:$L$1004,'CHI TIẾT HÀNG'!$A$5:$A$1004,$A18,'CHI TIẾT HÀNG'!$C$5:$C$1004,$B18,'CHI TIẾT HÀNG'!$D$5:$D$1004,"Bán")) | F18: =IF(OR($A18="",$B18=""),"",ROUND(D18*E18,0)) | G18: =IF(OR($A18="",$B18=""),"",D18-F18) | H18: =IF(OR($A18="",$B18=""),"",SUMIFS('CHI TIẾT HÀNG'!$L$5:$L$1004,'CHI TIẾT HÀNG'!$A$5:$A$1004,$A18,'CHI TIẾT HÀNG'!$C$5:$C$1004,$B18,'CHI TIẾT HÀNG'!$D$5:$D$1004,"Trả lại")) | I18: =IF(OR($A18="",$B18=""),"",H18-ROUND(H18*E18,0)) | J18: =IF(OR($A18="",$B18=""),"",C18+G18-I18) | K18: =IF(OR($A18="",$B18=""),"",SUMIFS('THANH TOÁN'!$D$5:$D$404,'THANH TOÁN'!$A$5:$A$404,$A18,'THANH TOÁN'!$C$5:$C$404,$B18)) | L18: =IF(OR($A18="",$B18=""),"",J18-K18) | N18: =IF(OR($A18="",M18=""),"",L18-M18)
C19: =IF(OR($A19="",$B19=""),"",SUMIFS('SỔ CÔNG NỢ'!$L$5:$L$51,'SỔ CÔNG NỢ'!$A$5:$A$51,$A19,'SỔ CÔNG NỢ'!$B$5:$B$51,EDATE($B19,-1))) | D19: =IF(OR($A19="",$B19=""),"",SUMIFS('CHI TIẾT HÀNG'!$L$5:$L$1004,'CHI TIẾT HÀNG'!$A$5:$A$1004,$A19,'CHI TIẾT HÀNG'!$C$5:$C$1004,$B19,'CHI TIẾT HÀNG'!$D$5:$D$1004,"Bán")) | F19: =IF(OR($A19="",$B19=""),"",ROUND(D19*E19,0)) | G19: =IF(OR($A19="",$B19=""),"",D19-F19) | H19: =IF(OR($A19="",$B19=""),"",SUMIFS('CHI TIẾT HÀNG'!$L$5:$L$1004,'CHI TIẾT HÀNG'!$A$5:$A$1004,$A19,'CHI TIẾT HÀNG'!$C$5:$C$1004,$B19,'CHI TIẾT HÀNG'!$D$5:$D$1004,"Trả lại")) | I19: =IF(OR($A19="",$B19=""),"",H19-ROUND(H19*E19,0)) | J19: =IF(OR($A19="",$B19=""),"",C19+G19-I19) | K19: =IF(OR($A19="",$B19=""),"",SUMIFS('THANH TOÁN'!$D$5:$D$404,'THANH TOÁN'!$A$5:$A$404,$A19,'THANH TOÁN'!$C$5:$C$404,$B19)) | L19: =IF(OR($A19="",$B19=""),"",J19-K19) | N19: =IF(OR($A19="",M19=""),"",L19-M19)
C20: =IF(OR($A20="",$B20=""),"",SUMIFS('SỔ CÔNG NỢ'!$L$5:$L$51,'SỔ CÔNG NỢ'!$A$5:$A$51,$A20,'SỔ CÔNG NỢ'!$B$5:$B$51,EDATE($B20,-1))) | D20: =IF(OR($A20="",$B20=""),"",SUMIFS('CHI TIẾT HÀNG'!$L$5:$L$1004,'CHI TIẾT HÀNG'!$A$5:$A$1004,$A20,'CHI TIẾT HÀNG'!$C$5:$C$1004,$B20,'CHI TIẾT HÀNG'!$D$5:$D$1004,"Bán")) | F20: =IF(OR($A20="",$B20=""),"",ROUND(D20*E20,0)) | G20: =IF(OR($A20="",$B20=""),"",D20-F20) | H20: =IF(OR($A20="",$B20=""),"",SUMIFS('CHI TIẾT HÀNG'!$L$5:$L$1004,'CHI TIẾT HÀNG'!$A$5:$A$1004,$A20,'CHI TIẾT HÀNG'!$C$5:$C$1004,$B20,'CHI TIẾT HÀNG'!$D$5:$D$1004,"Trả lại")) | I20: =IF(OR($A20="",$B20=""),"",H20-ROUND(H20*E20,0)) | J20: =IF(OR($A20="",$B20=""),"",C20+G20-I20) | K20: =IF(OR($A20="",$B20=""),"",SUMIFS('THANH TOÁN'!$D$5:$D$404,'THANH TOÁN'!$A$5:$A$404,$A20,'THANH TOÁN'!$C$5:$C$404,$B20)) | L20: =IF(OR($A20="",$B20=""),"",J20-K20) | N20: =IF(OR($A20="",M20=""),"",L20-M20)
C21: =IF(OR($A21="",$B21=""),"",SUMIFS('SỔ CÔNG NỢ'!$L$5:$L$51,'SỔ CÔNG NỢ'!$A$5:$A$51,$A21,'SỔ CÔNG NỢ'!$B$5:$B$51,EDATE($B21,-1))) | D21: =IF(OR($A21="",$B21=""),"",SUMIFS('CHI TIẾT HÀNG'!$L$5:$L$1004,'CHI TIẾT HÀNG'!$A$5:$A$1004,$A21,'CHI TIẾT HÀNG'!$C$5:$C$1004,$B21,'CHI TIẾT HÀNG'!$D$5:$D$1004,"Bán")) | F21: =IF(OR($A21="",$B21=""),"",ROUND(D21*E21,0)) | G21: =IF(OR($A21="",$B21=""),"",D21-F21) | H21: =IF(OR($A21="",$B21=""),"",SUMIFS('CHI TIẾT HÀNG'!$L$5:$L$1004,'CHI TIẾT HÀNG'!$A$5:$A$1004,$A21,'CHI TIẾT HÀNG'!$C$5:$C$1004,$B21,'CHI TIẾT HÀNG'!$D$5:$D$1004,"Trả lại")) | I21: =IF(OR($A21="",$B21=""),"",H21-ROUND(H21*E21,0)) | J21: =IF(OR($A21="",$B21=""),"",C21+G21-I21) | K21: =IF(OR($A21="",$B21=""),"",SUMIFS('THANH TOÁN'!$D$5:$D$404,'THANH TOÁN'!$A$5:$A$404,$A21,'THANH TOÁN'!$C$5:$C$404,$B21)) | L21: =IF(OR($A21="",$B21=""),"",J21-K21) | N21: =IF(OR($A21="",M21=""),"",L21-M21)
C22: =IF(OR($A22="",$B22=""),"",SUMIFS('SỔ CÔNG NỢ'!$L$5:$L$51,'SỔ CÔNG NỢ'!$A$5:$A$51,$A22,'SỔ CÔNG NỢ'!$B$5:$B$51,EDATE($B22,-1))) | D22: =IF(OR($A22="",$B22=""),"",SUMIFS('CHI TIẾT HÀNG'!$L$5:$L$1004,'CHI TIẾT HÀNG'!$A$5:$A$1004,$A22,'CHI TIẾT HÀNG'!$C$5:$C$1004,$B22,'CHI TIẾT HÀNG'!$D$5:$D$1004,"Bán")) | F22: =IF(OR($A22="",$B22=""),"",ROUND(D22*E22,0)) | G22: =IF(OR($A22="",$B22=""),"",D22-F22) | H22: =IF(OR($A22="",$B22=""),"",SUMIFS('CHI TIẾT HÀNG'!$L$5:$L$1004,'CHI TIẾT HÀNG'!$A$5:$A$1004,$A22,'CHI TIẾT HÀNG'!$C$5:$C$1004,$B22,'CHI TIẾT HÀNG'!$D$5:$D$1004,"Trả lại")) | I22: =IF(OR($A22="",$B22=""),"",H22-ROUND(H22*E22,0)) | J22: =IF(OR($A22="",$B22=""),"",C22+G22-I22) | K22: =IF(OR($A22="",$B22=""),"",SUMIFS('THANH TOÁN'!$D$5:$D$404,'THANH TOÁN'!$A$5:$A$404,$A22,'THANH TOÁN'!$C$5:$C$404,$B22)) | L22: =IF(OR($A22="",$B22=""),"",J22-K22) | N22: =IF(OR($A22="",M22=""),"",L22-M22)
... C51: =IF(OR($A51="",$B51=""),"",SUMIFS('SỔ CÔNG NỢ'!$L$5:$L$51,'SỔ CÔNG NỢ'!$A$5:$A$51,$A51,'SỔ CÔNG NỢ'!$B$5:$B$51,EDATE($B51,-1))) | D51: =IF(OR($A51="",$B51=""),"",SUMIFS('CHI TIẾT HÀNG'!$L$5:$L$1004,'CHI TIẾT HÀNG'!$A$5:$A$1004,$A51,'CHI TIẾT HÀNG'!$C$5:$C$1004,$B51,'CHI TIẾT HÀNG'!$D$5:$D$1004,"Bán")) | F51: =IF(OR($A51="",$B51=""),"",ROUND(D51*E51,0)) | G51: =IF(OR($A51="",$B51=""),"",D51-F51) | H51: =IF(OR($A51="",$B51=""),"",SUMIFS('CHI TIẾT HÀNG'!$L$5:$L$1004,'CHI TIẾT HÀNG'!$A$5:$A$1004,$A51,'CHI TIẾT HÀNG'!$C$5:$C$1004,$B51,'CHI TIẾT HÀNG'!$D$5:$D$1004,"Trả lại")) | I51: =IF(OR($A51="",$B51=""),"",H51-ROUND(H51*E51,0)) | J51: =IF(OR($A51="",$B51=""),"",C51+G51-I51) | K51: =IF(OR($A51="",$B51=""),"",SUMIFS('THANH TOÁN'!$D$5:$D$404,'THANH TOÁN'!$A$5:$A$404,$A51,'THANH TOÁN'!$C$5:$C$404,$B51)) | L51: =IF(OR($A51="",$B51=""),"",J51-K51) | N51: =IF(OR($A51="",M51=""),"",L51-M51)
A53: Cột "Theo biên bản" là số cuối kỳ ghi trên biên bản đối chiếu gửi khách (chỉ để so sánh). Tháng mới: gõ tên khách + tháng + % chiết khấu, bỏ trống cột này.

Sheet CHI TIẾT HÀNG
A1: CHI TIẾT HÀNG BÁN / TRẢ LẠI THEO KHÁCH
A2: Mỗi dòng = 1 mặt hàng trên biên bản đối chiếu. Hàng khách trả lại ghi Loại = "Trả lại". Cột xám tự tính.
A4: Khách hàng | B4: Ngày | C4: Kỳ (tháng) | D4: Loại | E4: Mã SP | F4: Dung tích | G4: Tên hàng hoá | H4: Mã màu / ghi chú | I4: Số lượng | J4: Đơn giá (VNĐ) | K4: Hệ số (màu */**) | L4: Thành tiền (VNĐ) | M4: Kiểm tra / lưu ý
A5: Hiền Xuân | B5: 46214 | C5: =IF(B5="","",DATE(YEAR(B5),MONTH(B5),1)) -> 46204 | D5: Bán | E5: IL5 | F5: 18L | G5: SƠN LÓT NỘI THẤT KHÁNG KIỀM SILVER | H5: Lót Trong | I5: 6 | J5: 2185000 | K5: 1 | L5: =IF(I5="","",I5*N(J5)*IF(K5="",1,K5)) -> 13110000
A6: Hiền Xuân | B6: 46214 | C6: =IF(B6="","",DATE(YEAR(B6),MONTH(B6),1)) -> 46204 | D6: Bán | E6: EL5 | F6: 18L | G6: SƠN LÓT NGOẠI THẤT KHÁNG KIỀM SILVER | H6: Lót Ngoái | I6: 1 | J6: 3097000 | K6: 1 | L6: =IF(I6="","",I6*N(J6)*IF(K6="",1,K6)) -> 3097000
A7: Hiền Xuân | B7: 46214 | C7: =IF(B7="","",DATE(YEAR(B7),MONTH(B7),1)) -> 46204 | D7: Bán | E7: ESG10 | F7: 18L | G7: SƠN NGOẠI THẤTCAO CẤP BÓNG MỜ IMPERIA | H7: Màu Ngoài | I7: 2 | J7: 5331000 | K7: 1 | L7: =IF(I7="","",I7*N(J7)*IF(K7="",1,K7)) -> 10662000
A8: Hiền Xuân | B8: 46214 | C8: =IF(B8="","",DATE(YEAR(B8),MONTH(B8),1)) -> 46204 | D8: Bán | E8: ISG06 | F8: 18L | G8: SƠN NỘI THẤTCAO CẤP BÓNG MỜ IMPERIA | H8: Màu Trong | I8: 7 | J8: 4597000 | K8: 1 | L8: =IF(I8="","",I8*N(J8)*IF(K8="",1,K8)) -> 32179000
A9: Hiền Xuân | B9: 46214 | C9: =IF(B9="","",DATE(YEAR(B9),MONTH(B9),1)) -> 46204 | D9: Bán | E9: CT12 | F9: 18L | G9: SƠN CHỐNG THẤM ĐA NĂNG IMPERIA | H9: Chống Thấm | I9: 1 | J9: 4106000 | K9: 1 | L9: =IF(I9="","",I9*N(J9)*IF(K9="",1,K9)) -> 4106000
A10: Hiền Xuân | B10: 46226 | C10: =IF(B10="","",DATE(YEAR(B10),MONTH(B10),1)) -> 46204 | D10: Bán | E10: ISG06 | F10: 18L | G10: SƠN NỘI THẤTCAO CẤP BÓNG MỜ IMPERIA | I10: 1 | J10: 4597000 | K10: 1 | L10: =IF(I10="","",I10*N(J10)*IF(K10="",1,K10)) -> 4597000
A11: Hiền Xuân | B11: 46226 | C11: =IF(B11="","",DATE(YEAR(B11),MONTH(B11),1)) -> 46204 | D11: Bán | E11: EL5 | F11: 18L | G11: SƠN LÓT NGOẠI THẤT KHÁNG KIỀM SILVER | H11: LÓT NGOÀI | I11: 2 | J11: 3097000 | K11: 1 | L11: =IF(I11="","",I11*N(J11)*IF(K11="",1,K11)) -> 6194000
A12: Hiền Xuân | B12: 46226 | C12: =IF(B12="","",DATE(YEAR(B12),MONTH(B12),1)) -> 46204 | D12: Bán | E12: ESG10 | F12: 18L | G12: SƠN NGOẠI THẤTCAO CẤP BÓNG MỜ IMPERIA | H12: 310-B3 | I12: 1 | J12: 409000 | K12: 1.15 | L12: =IF(I12="","",I12*N(J12)*IF(K12="",1,K12)) -> 470350 | M12: Đơn giá 409,000 là giá 1L, nhưng dung tích ghi 18L (giá 18L = 5,331,000) – nghi bán thiếu tiền
A13: Hiền Xuân | B13: 46227 | C13: =IF(B13="","",DATE(YEAR(B13),MONTH(B13),1)) -> 46204 | D13: Bán | E13: CT12 | F13: 18L | G13: SƠN CHỐNG THẤM ĐA NĂNG IMPERIA | H13: Chống Thấm | I13: 1 | J13: 4106000 | K13: 1 | L13: =IF(I13="","",I13*N(J13)*IF(K13="",1,K13)) -> 4106000
A14: Hiền Xuân | B14: 46227 | C14: =IF(B14="","",DATE(YEAR(B14),MONTH(B14),1)) -> 46204 | D14: Bán | E14: ESG10 | F14: 18L | G14: SƠN NGOẠI THẤTCAO CẤP BÓNG MỜ IMPERIA | H14: 333 | I14: 1 | J14: 5331000 | K14: 1 | L14: =IF(I14="","",I14*N(J14)*IF(K14="",1,K14)) -> 5331000
A15: Hiền Xuân | B15: 46233 | C15: =IF(B15="","",DATE(YEAR(B15),MONTH(B15),1)) -> 46204 | D15: Trả lại | E15: ISG06 | F15: 18L | G15: SƠN NỘI THẤTCAO CẤP BÓNG MỜ IMPERIA | H15: 333 | I15: 1 | J15: 4597000 | K15: 1 | L15: =IF(I15="","",I15*N(J15)*IF(K15="",1,K15)) -> 4597000
A16: Hòa Hiệp | B16: 46187 | C16: =IF(B16="","",DATE(YEAR(B16),MONTH(B16),1)) -> 46174 | D16: Bán | E16: IG05 | F16: 5L | G16: SƠN NỘI THẤT SIÊU BÓNG CAO CẤP IMPERIA | I16: 1 | J16: 1875000 | K16: 1 | L16: =IF(I16="","",I16*N(J16)*IF(K16="",1,K16)) -> 1875000
A17: Hòa Hiệp | B17: 46194 | C17: =IF(B17="","",DATE(YEAR(B17),MONTH(B17),1)) -> 46174 | D17: Bán | E17: IG05 | F17: 5L | G17: SƠN NỘI THẤT SIÊU BÓNG CAO CẤP IMPERIA | I17: 1 | J17: 1875000 | K17: 1 | L17: =IF(I17="","",I17*N(J17)*IF(K17="",1,K17)) -> 1875000
A18: Hà Liên | B18: 46188 | C18: =IF(B18="","",DATE(YEAR(B18),MONTH(B18),1)) -> 46174 | D18: Bán | E18: PI04 | F18: 18L | G18: SƠN LÓT NỘI THẤT KHÁNG KIỀM CAO CẤP IMPERIA | I18: 2 | J18: 3012000 | K18: 1 | L18: =IF(I18="","",I18*N(J18)*IF(K18="",1,K18)) -> 6024000
A19: Hà Liên | B19: 46188 | C19: =IF(B19="","",DATE(YEAR(B19),MONTH(B19),1)) -> 46174 | D19: Bán | E19: ETM | F19: 18L | G19: SƠN CHỐNG THẤM MÀU | H19: 309 | I19: 1 | J19: 4821000 | K19: 1 | L19: =IF(I19="","",I19*N(J19)*IF(K19="",1,K19)) -> 4821000
A20: Hà Liên | B20: 46188 | C20: =IF(B20="","",DATE(YEAR(B20),MONTH(B20),1)) -> 46174 | D20: Bán | E20: ISG06 | F20: 5L | G20: SƠN NỘI THẤTCAO CẤP BÓNG MỜ IMPERIA | H20: 357 | I20: 2 | J20: 1302000 | K20: 1 | L20: =IF(I20="","",I20*N(J20)*IF(K20="",1,K20)) -> 2604000
A21: Hà Liên | B21: 46188 | C21: =IF(B21="","",DATE(YEAR(B21),MONTH(B21),1)) -> 46174 | D21: Bán | E21: ISG06 | F21: 5L | G21: SƠN NỘI THẤTCAO CẤP BÓNG MỜ IMPERIA | H21: b1 | I21: 1 | J21: 1302000 | K21: 1 | L21: =IF(I21="","",I21*N(J21)*IF(K21="",1,K21)) -> 1302000
A22: Hà Liên | B22: 46189 | C22: =IF(B22="","",DATE(YEAR(B22),MONTH(B22),1)) -> 46174 | D22: Bán | E22: PI04 | F22: 18L | G22: SƠN LÓT NỘI THẤT KHÁNG KIỀM CAO CẤP IMPERIA | I22: 1 | J22: 3012000 | K22: 1 | L22: =IF(I22="","",I22*N(J22)*IF(K22="",1,K22)) -> 3012000
A23: Hà Liên | B23: 46189 | C23: =IF(B23="","",DATE(YEAR(B23),MONTH(B23),1)) -> 46174 | D23: Bán | E23: ISG06 | F23: 5L | G23: SƠN NỘI THẤTCAO CẤP BÓNG MỜ IMPERIA | H23: 357 | I23: 2 | J23: 1302000 | K23: 1 | L23: =IF(I23="","",I23*N(J23)*IF(K23="",1,K23)) -> 2604000
A24: Hà Liên | B24: 46189 | C24: =IF(B24="","",DATE(YEAR(B24),MONTH(B24),1)) -> 46174 | D24: Bán | E24: ISG06 | F24: 5L | G24: SƠN NỘI THẤTCAO CẤP BÓNG MỜ IMPERIA | H24: b1 | I24: 2 | J24: 1302000 | K24: 1 | L24: =IF(I24="","",I24*N(J24)*IF(K24="",1,K24)) -> 2604000
A25: Hà Liên | B25: 46220 | C25: =IF(B25="","",DATE(YEAR(B25),MONTH(B25),1)) -> 46204 | D25: Bán | E25: ESG10 | F25: 18L | G25: SƠN NGOẠI THẤTCAO CẤP BÓNG MỜ IMPERIA | H25: 357 | I25: 1 | J25: 5331000 | K25: 1.1 | L25: =IF(I25="","",I25*N(J25)*IF(K25="",1,K25)) -> 5864100
A26: Hà Liên | B26: 46220 | C26: =IF(B26="","",DATE(YEAR(B26),MONTH(B26),1)) -> 46204 | D26: Bán | E26: ISG06 | F26: 18L | G26: SƠN NỘI THẤTCAO CẤP BÓNG MỜ IMPERIA | H26: 343 | I26: 1 | J26: 4597000 | K26: 1 | L26: =IF(I26="","",I26*N(J26)*IF(K26="",1,K26)) -> 4597000
A27: Hà Liên | B27: 46220 | C27: =IF(B27="","",DATE(YEAR(B27),MONTH(B27),1)) -> 46204 | D27: Bán | E27: ETM | F27: 18L | G27: SƠN CHỐNG THẤM MÀU | I27: 1 | J27: 4821000 | K27: 1 | L27: =IF(I27="","",I27*N(J27)*IF(K27="",1,K27)) -> 4821000
A28: Hà Liên | B28: 46220 | C28: =IF(B28="","",DATE(YEAR(B28),MONTH(B28),1)) -> 46204 | D28: Bán | E28: IEW | F28: 18L | G28: SƠN NỘI THẤT SIÊU TRẮNG IMPERIA | I28: 1 | J28: 2712000 | K28: 1 | L28: =IF(I28="","",I28*N(J28)*IF(K28="",1,K28)) -> 2712000 | M28: Đơn giá cao hơn bảng giá T4/2026 (2,465,000) 10%
A29: Hà Liên | B29: 46220 | C29: =IF(B29="","",DATE(YEAR(B29),MONTH(B29),1)) -> 46204 | D29: Bán | E29: ISG06 | F29: 5L | G29: SƠN NỘI THẤTCAO CẤP BÓNG MỜ IMPERIA | H29: 357 | I29: 2 | J29: 1302000 | K29: 1 | L29: =IF(I29="","",I29*N(J29)*IF(K29="",1,K29)) -> 2604000
