Workbook

Sheet TỔNG HỢP
A1: TỔNG HỢP CÔNG NỢ CÁC CỬA HÀNG
A2: Số dương = cửa hàng còn nợ công ty; số âm (đỏ) = công ty đang nợ lại cửa hàng. "Theo biên bản" là số đã ghi trên biên bản gửi khách; "Tính lại" là số em tự cộng trừ lại từ các khoản trên biên bản.
A4: CỬA HÀNG CÒN NỢ (theo biên bản) | C4: CÔNG TY NỢ LẠI CỬA HÀNG (theo BB) | E4: NỢ RÒNG THEO BIÊN BẢN | H4: NỢ RÒNG TÍNH LẠI | J4: SỐ BIÊN BẢN CÓ CHÊNH LỆCH
A5: =SUMIF(D9:D38,">0") -> 375377145 | C5: =-SUMIF(D9:D38,"<0") -> 14093922 | E5: =SUM(D9:D38) -> 361283223 | H5: =SUM(E9:E38) -> 3.7465707e+08 | J5: =COUNTIF('SỔ CÔNG NỢ'!$O$5:$O$111,">1")+COUNTIF('SỔ CÔNG NỢ'!$O$5:$O$111,"<-1") -> 6
A7: ▶ CÔNG NỢ TỪNG CỬA HÀNG (sắp theo số nợ giảm dần)
A8: STT | B8: Cửa hàng | C8: Biên bản gần nhất | D8: NỢ THEO BIÊN BẢN | E8: Nợ tính lại | F8: Chênh lệch | G8: Tình trạng | H8: Phát sinh sau CK (cộng dồn) | I8: Hàng trả lại sau CK | J8: Đã thanh toán (cộng dồn) | K8: Lưu ý
A9: =IF($B9="","",ROW()-8) -> 1 | B9: Thông Lan (Thiệu Vân) | C9: =IF($B9="","",_xlfn.MAXIFS('SỔ CÔNG NỢ'!$B$5:$B$111,'SỔ CÔNG NỢ'!$A$5:$A$111,$B9)) -> 46266 | D9: =IF($B9="","",SUMIFS('SỔ CÔNG NỢ'!$N$5:$N$111,'SỔ CÔNG NỢ'!$A$5:$A$111,$B9,'SỔ CÔNG NỢ'!$B$5:$B$111,$C9)) -> 61451055 | E9: =IF($B9="","",SUMIFS('SỔ CÔNG NỢ'!$M$5:$M$111,'SỔ CÔNG NỢ'!$A$5:$A$111,$B9,'SỔ CÔNG NỢ'!$B$5:$B$111,$C9)) -> 61451055 | F9: =IF($B9="","",D9-E9) -> 0 | G9: =IF($B9="","",IF(D9>0,"Còn nợ",IF(D9<0,"Công ty nợ lại","Hết nợ"))) -> Còn nợ | H9: =IF($B9="","",SUMIFS('SỔ CÔNG NỢ'!$G$5:$G$111,'SỔ CÔNG NỢ'!$A$5:$A$111,$B9)) -> 2624650 | I9: =IF($B9="","",SUMIFS('SỔ CÔNG NỢ'!$J$5:$J$111,'SỔ CÔNG NỢ'!$A$5:$A$111,$B9)) -> 0 | J9: =IF($B9="","",SUMIFS('SỔ CÔNG NỢ'!$K$5:$K$111,'SỔ CÔNG NỢ'!$A$5:$A$111,$B9)) -> 0 | K9: =IF($B9="","",IF(ABS(F9)>1,"⚠ Biên bản lệch số tính lại – xem SỔ CÔNG NỢ. ","")&IF(C9<MAX('SỔ CÔNG NỢ'!$B$5:$B$111),"⚠ Chưa có biên bản sau "&TEXT(C9,"mm/yyyy"),""))
A10: =IF($B10="","",ROW()-8) -> 2 | B10: Tuân Thuận | C10: =IF($B10="","",_xlfn.MAXIFS('SỔ CÔNG NỢ'!$B$5:$B$111,'SỔ CÔNG NỢ'!$A$5:$A$111,$B10)) -> 46266 | D10: =IF($B10="","",SUMIFS('SỔ CÔNG NỢ'!$N$5:$N$111,'SỔ CÔNG NỢ'!$A$5:$A$111,$B10,'SỔ CÔNG NỢ'!$B$5:$B$111,$C10)) -> 47835892 | E10: =IF($B10="","",SUMIFS('SỔ CÔNG NỢ'!$M$5:$M$111,'SỔ CÔNG NỢ'!$A$5:$A$111,$B10,'SỔ CÔNG NỢ'!$B$5:$B$111,$C10)) -> 47835892 | F10: =IF($B10="","",D10-E10) -> 0 | G10: =IF($B10="","",IF(D10>0,"Còn nợ",IF(D10<0,"Công ty nợ lại","Hết nợ"))) -> Còn nợ | H10: =IF($B10="","",SUMIFS('SỔ CÔNG NỢ'!$G$5:$G$111,'SỔ CÔNG NỢ'!$A$5:$A$111,$B10)) -> 191760280 | I10: =IF($B10="","",SUMIFS('SỔ CÔNG NỢ'!$J$5:$J$111,'SỔ CÔNG NỢ'!$A$5:$A$111,$B10)) -> 0 | J10: =IF($B10="","",SUMIFS('SỔ CÔNG NỢ'!$K$5:$K$111,'SỔ CÔNG NỢ'!$A$5:$A$111,$B10)) -> 108935000 | K10: =IF($B10="","",IF(ABS(F10)>1,"⚠ Biên bản lệch số tính lại – xem SỔ CÔNG NỢ. ","")&IF(C10<MAX('SỔ CÔNG NỢ'!$B$5:$B$111),"⚠ Chưa có biên bản sau "&TEXT(C10,"mm/yyyy"),""))
A11: =IF($B11="","",ROW()-8) -> 3 | B11: Anh Hưng (giao anh Hải, TP) | C11: =IF($B11="","",_xlfn.MAXIFS('SỔ CÔNG NỢ'!$B$5:$B$111,'SỔ CÔNG NỢ'!$A$5:$A$111,$B11)) -> 46235 | D11: =IF($B11="","",SUMIFS('SỔ CÔNG NỢ'!$N$5:$N$111,'SỔ CÔNG NỢ'!$A$5:$A$111,$B11,'SỔ CÔNG NỢ'!$B$5:$B$111,$C11)) -> 46455786 | E11: =IF($B11="","",SUMIFS('SỔ CÔNG NỢ'!$M$5:$M$111,'SỔ CÔNG NỢ'!$A$5:$A$111,$B11,'SỔ CÔNG NỢ'!$B$5:$B$111,$C11)) -> 46455786 | F11: =IF($B11="","",D11-E11) -> 0 | G11: =IF($B11="","",IF(D11>0,"Còn nợ",IF(D11<0,"Công ty nợ lại","Hết nợ"))) -> Còn nợ | H11: =IF($B11="","",SUMIFS('SỔ CÔNG NỢ'!$G$5:$G$111,'SỔ CÔNG NỢ'!$A$5:$A$111,$B11)) -> 45925964 | I11: =IF($B11="","",SUMIFS('SỔ CÔNG NỢ'!$J$5:$J$111,'SỔ CÔNG NỢ'!$A$5:$A$111,$B11)) -> 0 | J11: =IF($B11="","",SUMIFS('SỔ CÔNG NỢ'!$K$5:$K$111,'SỔ CÔNG NỢ'!$A$5:$A$111,$B11)) -> 0 | K11: =IF($B11="","",IF(ABS(F11)>1,"⚠ Biên bản lệch số tính lại – xem SỔ CÔNG NỢ. ","")&IF(C11<MAX('SỔ CÔNG NỢ'!$B$5:$B$111),"⚠ Chưa có biên bản sau "&TEXT(C11,"mm/yyyy"),"")) -> ⚠ Chưa có biên bản sau 08/2026
A12: =IF($B12="","",ROW()-8) -> 4 | B12: Nghị Hậu | C12: =IF($B12="","",_xlfn.MAXIFS('SỔ CÔNG NỢ'!$B$5:$B$111,'SỔ CÔNG NỢ'!$A$5:$A$111,$B12)) -> 46174 | D12: =IF($B12="","",SUMIFS('SỔ CÔNG NỢ'!$N$5:$N$111,'SỔ CÔNG NỢ'!$A$5:$A$111,$B12,'SỔ CÔNG NỢ'!$B$5:$B$111,$C12)) -> 33448535 | E12: =IF($B12="","",SUMIFS('SỔ CÔNG NỢ'!$M$5:$M$111,'SỔ CÔNG NỢ'!$A$5:$A$111,$B12,'SỔ CÔNG NỢ'!$B$5:$B$111,$C12)) -> 33448535 | F12: =IF($B12="","",D12-E12) -> 0 | G12: =IF($B12="","",IF(D12>0,"Còn nợ",IF(D12<0,"Công ty nợ lại","Hết nợ"))) -> Còn nợ | H12: =IF($B12="","",SUMIFS('SỔ CÔNG NỢ'!$G$5:$G$111,'SỔ CÔNG NỢ'!$A$5:$A$111,$B12)) -> 27770535 | I12: =IF($B12="","",SUMIFS('SỔ CÔNG NỢ'!$J$5:$J$111,'SỔ CÔNG NỢ'!$A$5:$A$111,$B12)) -> 0 | J12: =IF($B12="","",SUMIFS('SỔ CÔNG NỢ'!$K$5:$K$111,'SỔ CÔNG NỢ'!$A$5:$A$111,$B12)) -> 28000000 | K12: =IF($B12="","",IF(ABS(F12)>1,"⚠ Biên bản lệch số tính lại – xem SỔ CÔNG NỢ. ","")&IF(C12<MAX('SỔ CÔNG NỢ'!$B$5:$B$111),"⚠ Chưa có biên bản sau "&TEXT(C12,"mm/yyyy"),"")) -> ⚠ Chưa có biên bản sau 06/2026
A13: =IF($B13="","",ROW()-8) -> 5 | B13: Hà Liên | C13: =IF($B13="","",_xlfn.MAXIFS('SỔ CÔNG NỢ'!$B$5:$B$111,'SỔ CÔNG NỢ'!$A$5:$A$111,$B13)) -> 46266 | D13: =IF($B13="","",SUMIFS('SỔ CÔNG NỢ'!$N$5:$N$111,'SỔ CÔNG NỢ'!$A$5:$A$111,$B13,'SỔ CÔNG NỢ'!$B$5:$B$111,$C13)) -> 33078350 | E13: =IF($B13="","",SUMIFS('SỔ CÔNG NỢ'!$M$5:$M$111,'SỔ CÔNG NỢ'!$A$5:$A$111,$B13,'SỔ CÔNG NỢ'!$B$5:$B$111,$C13)) -> 33078350 | F13: =IF($B13="","",D13-E13) -> 0 | G13: =IF($B13="","",IF(D13>0,"Còn nợ",IF(D13<0,"Công ty nợ lại","Hết nợ"))) -> Còn nợ | H13: =IF($B13="","",SUMIFS('SỔ CÔNG NỢ'!$G$5:$G$111,'SỔ CÔNG NỢ'!$A$5:$A$111,$B13)) -> 80718200 | I13: =IF($B13="","",SUMIFS('SỔ CÔNG NỢ'!$J$5:$J$111,'SỔ CÔNG NỢ'!$A$5:$A$111,$B13)) -> 0 | J13: =IF($B13="","",SUMIFS('SỔ CÔNG NỢ'!$K$5:$K$111,'SỔ CÔNG NỢ'!$A$5:$A$111,$B13)) -> 48530000 | K13: =IF($B13="","",IF(ABS(F13)>1,"⚠ Biên bản lệch số tính lại – xem SỔ CÔNG NỢ. ","")&IF(C13<MAX('SỔ CÔNG NỢ'!$B$5:$B$111),"⚠ Chưa có biên bản sau "&TEXT(C13,"mm/yyyy"),""))
A14: =IF($B14="","",ROW()-8) -> 6 | B14: Chinh Ưng (Đông Lĩnh) | C14: =IF($B14="","",_xlfn.MAXIFS('SỔ CÔNG NỢ'!$B$5:$B$111,'SỔ CÔNG NỢ'!$A$5:$A$111,$B14)) -> 46266 | D14: =IF($B14="","",SUMIFS('SỔ CÔNG NỢ'!$N$5:$N$111,'SỔ CÔNG NỢ'!$A$5:$A$111,$B14,'SỔ CÔNG NỢ'!$B$5:$B$111,$C14)) -> 29985920 | E14: =IF($B14="","",SUMIFS('SỔ CÔNG NỢ'!$M$5:$M$111,'SỔ CÔNG NỢ'!$A$5:$A$111,$B14,'SỔ CÔNG NỢ'!$B$5:$B$111,$C14)) -> 29985920 | F14: =IF($B14="","",D14-E14) -> 0 | G14: =IF($B14="","",IF(D14>0,"Còn nợ",IF(D14<0,"Công ty nợ lại","Hết nợ"))) -> Còn nợ | H14: =IF($B14="","",SUMIFS('SỔ CÔNG NỢ'!$G$5:$G$111,'SỔ CÔNG NỢ'!$A$5:$A$111,$B14)) -> 23061840 | I14: =IF($B14="","",SUMIFS('SỔ CÔNG NỢ'!$J$5:$J$111,'SỔ CÔNG NỢ'!$A$5:$A$111,$B14)) -> 2532720 | J14: =IF($B14="","",SUMIFS('SỔ CÔNG NỢ'!$K$5:$K$111,'SỔ CÔNG NỢ'!$A$5:$A$111,$B14)) -> 0 | K14: =IF($B14="","",IF(ABS(F14)>1,"⚠ Biên bản lệch số tính lại – xem SỔ CÔNG NỢ. ","")&IF(C14<MAX('SỔ CÔNG NỢ'!$B$5:$B$111),"⚠ Chưa có biên bản sau "&TEXT(C14,"mm/yyyy"),""))
A15: =IF($B15="","",ROW()-8) -> 7 | B15: Cường Hà | C15: =IF($B15="","",_xlfn.MAXIFS('SỔ CÔNG NỢ'!$B$5:$B$111,'SỔ CÔNG NỢ'!$A$5:$A$111,$B15)) -> 46266 | D15: =IF($B15="","",SUMIFS('SỔ CÔNG NỢ'!$N$5:$N$111,'SỔ CÔNG NỢ'!$A$5:$A$111,$B15,'SỔ CÔNG NỢ'!$B$5:$B$111,$C15)) -> 21149210 | E15: =IF($B15="","",SUMIFS('SỔ CÔNG NỢ'!$M$5:$M$111,'SỔ CÔNG NỢ'!$A$5:$A$111,$B15,'SỔ CÔNG NỢ'!$B$5:$B$111,$C15)) -> 21149210 | F15: =IF($B15="","",D15-E15) -> 0 | G15: =IF($B15="","",IF(D15>0,"Còn nợ",IF(D15<0,"Công ty nợ lại","Hết nợ"))) -> Còn nợ | H15: =IF($B15="","",SUMIFS('SỔ CÔNG NỢ'!$G$5:$G$111,'SỔ CÔNG NỢ'!$A$5:$A$111,$B15)) -> 144851200 | I15: =IF($B15="","",SUMIFS('SỔ CÔNG NỢ'!$J$5:$J$111,'SỔ CÔNG NỢ'!$A$5:$A$111,$B15)) -> 0 | J15: =IF($B15="","",SUMIFS('SỔ CÔNG NỢ'!$K$5:$K$111,'SỔ CÔNG NỢ'!$A$5:$A$111,$B15)) -> 30000000 | K15: =IF($B15="","",IF(ABS(F15)>1,"⚠ Biên bản lệch số tính lại – xem SỔ CÔNG NỢ. ","")&IF(C15<MAX('SỔ CÔNG NỢ'!$B$5:$B$111),"⚠ Chưa có biên bản sau "&TEXT(C15,"mm/yyyy"),""))
A16: =IF($B16="","",ROW()-8) -> 8 | B16: Toàn Lanh | C16: =IF($B16="","",_xlfn.MAXIFS('SỔ CÔNG NỢ'!$B$5:$B$111,'SỔ CÔNG NỢ'!$A$5:$A$111,$B16)) -> 46204 | D16: =IF($B16="","",SUMIFS('SỔ CÔNG NỢ'!$N$5:$N$111,'SỔ CÔNG NỢ'!$A$5:$A$111,$B16,'SỔ CÔNG NỢ'!$B$5:$B$111,$C16)) -> 18143025 | E16: =IF($B16="","",SUMIFS('SỔ CÔNG NỢ'!$M$5:$M$111,'SỔ CÔNG NỢ'!$A$5:$A$111,$B16,'SỔ CÔNG NỢ'!$B$5:$B$111,$C16)) -> 18143025 | F16: =IF($B16="","",D16-E16) -> 0 | G16: =IF($B16="","",IF(D16>0,"Còn nợ",IF(D16<0,"Công ty nợ lại","Hết nợ"))) -> Còn nợ | H16: =IF($B16="","",SUMIFS('SỔ CÔNG NỢ'!$G$5:$G$111,'SỔ CÔNG NỢ'!$A$5:$A$111,$B16)) -> 77893825 | I16: =IF($B16="","",SUMIFS('SỔ CÔNG NỢ'!$J$5:$J$111,'SỔ CÔNG NỢ'!$A$5:$A$111,$B16)) -> 5950800 | J16: =IF($B16="","",SUMIFS('SỔ CÔNG NỢ'!$K$5:$K$111,'SỔ CÔNG NỢ'!$A$5:$A$111,$B16)) -> 53800000 | K16: =IF($B16="","",IF(ABS(F16)>1,"⚠ Biên bản lệch số tính lại – xem SỔ CÔNG NỢ. ","")&IF(C16<MAX('SỔ CÔNG NỢ'!$B$5:$B$111),"⚠ Chưa có biên bản sau "&TEXT(C16,"mm/yyyy"),"")) -> ⚠ Chưa có biên bản sau 07/2026
A17: =IF($B17="","",ROW()-8) -> 9 | B17: Chị Thu (Rừng Thông) | C17: =IF($B17="","",_xlfn.MAXIFS('SỔ CÔNG NỢ'!$B$5:$B$111,'SỔ CÔNG NỢ'!$A$5:$A$111,$B17)) -> 46174 | D17: =IF($B17="","",SUMIFS('SỔ CÔNG NỢ'!$N$5:$N$111,'SỔ CÔNG NỢ'!$A$5:$A$111,$B17,'SỔ CÔNG NỢ'!$B$5:$B$111,$C17)) -> 17142020 | E17: =IF($B17="","",SUMIFS('SỔ CÔNG NỢ'!$M$5:$M$111,'SỔ CÔNG NỢ'!$A$5:$A$111,$B17,'SỔ CÔNG NỢ'!$B$5:$B$111,$C17)) -> 17142020 | F17: =IF($B17="","",D17-E17) -> 0 | G17: =IF($B17="","",IF(D17>0,"Còn nợ",IF(D17<0,"Công ty nợ lại","Hết nợ"))) -> Còn nợ | H17: =IF($B17="","",SUMIFS('SỔ CÔNG NỢ'!$G$5:$G$111,'SỔ CÔNG NỢ'!$A$5:$A$111,$B17)) -> 17142020 | I17: =IF($B17="","",SUMIFS('SỔ CÔNG NỢ'!$J$5:$J$111,'SỔ CÔNG NỢ'!$A$5:$A$111,$B17)) -> 0 | J17: =IF($B17="","",SUMIFS('SỔ CÔNG NỢ'!$K$5:$K$111,'SỔ CÔNG NỢ'!$A$5:$A$111,$B17)) -> 0 | K17: =IF($B17="","",IF(ABS(F17)>1,"⚠ Biên bản lệch số tính lại – xem SỔ CÔNG NỢ. ","")&IF(C17<MAX('SỔ CÔNG NỢ'!$B$5:$B$111),"⚠ Chưa có biên bản sau "&TEXT(C17,"mm/yyyy"),"")) -> ⚠ Chưa có biên bản sau 06/2026
A18: =IF($B18="","",ROW()-8) -> 10 | B18: Anh Hùng (TP) | C18: =IF($B18="","",_xlfn.MAXIFS('SỔ CÔNG NỢ'!$B$5:$B$111,'SỔ CÔNG NỢ'!$A$5:$A$111,$B18)) -> 46266 | D18: =IF($B18="","",SUMIFS('SỔ CÔNG NỢ'!$N$5:$N$111,'SỔ CÔNG NỢ'!$A$5:$A$111,$B18,'SỔ CÔNG NỢ'!$B$5:$B$111,$C18)) -> 15821145 | E18: =IF($B18="","",SUMIFS('SỔ CÔNG NỢ'!$M$5:$M$111,'SỔ CÔNG NỢ'!$A$5:$A$111,$B18,'SỔ CÔNG NỢ'!$B$5:$B$111,$C18)) -> 15821145 | F18: =IF($B18="","",D18-E18) -> 0 | G18: =IF($B18="","",IF(D18>0,"Còn nợ",IF(D18<0,"Công ty nợ lại","Hết nợ"))) -> Còn nợ | H18: =IF($B18="","",SUMIFS('SỔ CÔNG NỢ'!$G$5:$G$111,'SỔ CÔNG NỢ'!$A$5:$A$111,$B18)) -> 15820464 | I18: =IF($B18="","",SUMIFS('SỔ CÔNG NỢ'!$J$5:$J$111,'SỔ CÔNG NỢ'!$A$5:$A$111,$B18)) -> 0 | J18: =IF($B18="","",SUMIFS('SỔ CÔNG NỢ'!$K$5:$K$111,'SỔ CÔNG NỢ'!$A$5:$A$111,$B18)) -> 0 | K18: =IF($B18="","",IF(ABS(F18)>1,"⚠ Biên bản lệch số tính lại – xem SỔ CÔNG NỢ. ","")&IF(C18<MAX('SỔ CÔNG NỢ'!$B$5:$B$111),"⚠ Chưa có biên bản sau "&TEXT(C18,"mm/yyyy"),""))
A19: =IF($B19="","",ROW()-8) -> 11 | B19: Tìm Mai (Hoàng Châu) | C19: =IF($B19="","",_xlfn.MAXIFS('SỔ CÔNG NỢ'!$B$5:$B$111,'SỔ CÔNG NỢ'!$A$5:$A$111,$B19)) -> 46204 | D19: =IF($B19="","",SUMIFS('SỔ CÔNG NỢ'!$N$5:$N$111,'SỔ CÔNG NỢ'!$A$5:$A$111,$B19,'SỔ CÔNG NỢ'!$B$5:$B$111,$C19)) -> 14318800 | E19: =IF($B19="","",SUMIFS('SỔ CÔNG NỢ'!$M$5:$M$111,'SỔ CÔNG NỢ'!$A$5:$A$111,$B19,'SỔ CÔNG NỢ'!$B$5:$B$111,$C19)) -> 14318800 | F19: =IF($B19="","",D19-E19) -> 0 | G19: =IF($B19="","",IF(D19>0,"Còn nợ",IF(D19<0,"Công ty nợ lại","Hết nợ"))) -> Còn nợ | H19: =IF($B19="","",SUMIFS('SỔ CÔNG NỢ'!$G$5:$G$111,'SỔ CÔNG NỢ'!$A$5:$A$111,$B19)) -> 14318800 | I19: =IF($B19="","",SUMIFS('SỔ CÔNG NỢ'!$J$5:$J$111,'SỔ CÔNG NỢ'!$A$5:$A$111,$B19)) -> 0 | J19: =IF($B19="","",SUMIFS('SỔ CÔNG NỢ'!$K$5:$K$111,'SỔ CÔNG NỢ'!$A$5:$A$111,$B19)) -> 0 | K19: =IF($B19="","",IF(ABS(F19)>1,"⚠ Biên bản lệch số tính lại – xem SỔ CÔNG NỢ. ","")&IF(C19<MAX('SỔ CÔNG NỢ'!$B$5:$B$111),"⚠ Chưa có biên bản sau "&TEXT(C19,"mm/yyyy"),"")) -> ⚠ Chưa có biên bản sau 07/2026
A20: =IF($B20="","",ROW()-8) -> 12 | B20: Tuấn Thanh | C20: =IF($B20="","",_xlfn.MAXIFS('SỔ CÔNG NỢ'!$B$5:$B$111,'SỔ CÔNG NỢ'!$A$5:$A$111,$B20)) -> 46266 | D20: =IF($B20="","",SUMIFS('SỔ CÔNG NỢ'!$N$5:$N$111,'SỔ CÔNG NỢ'!$A$5:$A$111,$B20,'SỔ CÔNG NỢ'!$B$5:$B$111,$C20)) -> 13171665 | E20: =IF($B20="","",SUMIFS('SỔ CÔNG NỢ'!$M$5:$M$111,'SỔ CÔNG NỢ'!$A$5:$A$111,$B20,'SỔ CÔNG NỢ'!$B$5:$B$111,$C20)) -> 13171665 | F20: =IF($B20="","",D20-E20) -> 0 | G20: =IF($B20="","",IF(D20>0,"Còn nợ",IF(D20<0,"Công ty nợ lại","Hết nợ"))) -> Còn nợ | H20: =IF($B20="","",SUMIFS('SỔ CÔNG NỢ'!$G$5:$G$111,'SỔ CÔNG NỢ'!$A$5:$A$111,$B20)) -> 13172400 | I20: =IF($B20="","",SUMIFS('SỔ CÔNG NỢ'!$J$5:$J$111,'SỔ CÔNG NỢ'!$A$5:$A$111,$B20)) -> 0 | J20: =IF($B20="","",SUMIFS('SỔ CÔNG NỢ'!$K$5:$K$111,'SỔ CÔNG NỢ'!$A$5:$A$111,$B20)) -> 0 | K20: =IF($B20="","",IF(ABS(F20)>1,"⚠ Biên bản lệch số tính lại – xem SỔ CÔNG NỢ. ","")&IF(C20<MAX('SỔ CÔNG NỢ'!$B$5:$B$111),"⚠ Chưa có biên bản sau "&TEXT(C20,"mm/yyyy"),""))
... A31: =IF($B31="","",ROW()-8) -> 23 | B31: Anh Việt (Thiệu Vân) | C31: =IF($B31="","",_xlfn.MAXIFS('SỔ CÔNG NỢ'!$B$5:$B$111,'SỔ CÔNG NỢ'!$A$5:$A$111,$B31)) -> 46174 | D31: =IF($B31="","",SUMIFS('SỔ CÔNG NỢ'!$N$5:$N$111,'SỔ CÔNG NỢ'!$A$5:$A$111,$B31,'SỔ CÔNG NỢ'!$B$5:$B$111,$C31)) -> -9538000 | E31: =IF($B31="","",SUMIFS('SỔ CÔNG NỢ'!$M$5:$M$111,'SỔ CÔNG NỢ'!$A$5:$A$111,$B31,'SỔ CÔNG NỢ'!$B$5:$B$111,$C31)) -> -9538000 | F31: =IF($B31="","",D31-E31) -> 0 | G31: =IF($B31="","",IF(D31>0,"Còn nợ",IF(D31<0,"Công ty nợ lại","Hết nợ"))) -> Công ty nợ lại | H31: =IF($B31="","",SUMIFS('SỔ CÔNG NỢ'!$G$5:$G$111,'SỔ CÔNG NỢ'!$A$5:$A$111,$B31)) -> 462000 | I31: =IF($B31="","",SUMIFS('SỔ CÔNG NỢ'!$J$5:$J$111,'SỔ CÔNG NỢ'!$A$5:$A$111,$B31)) -> 0 | J31: =IF($B31="","",SUMIFS('SỔ CÔNG NỢ'!$K$5:$K$111,'SỔ CÔNG NỢ'!$A$5:$A$111,$B31)) -> 10000000 | K31: =IF($B31="","",IF(ABS(F31)>1,"⚠ Biên bản lệch số tính lại – xem SỔ CÔNG NỢ. ","")&IF(C31<MAX('SỔ CÔNG NỢ'!$B$5:$B$111),"⚠ Chưa có biên bản sau "&TEXT(C31,"mm/yyyy"),"")) -> ⚠ Chưa có biên bản sau 06/2026
A32: =IF($B32="","",ROW()-8) | C32: =IF($B32="","",_xlfn.MAXIFS('SỔ CÔNG NỢ'!$B$5:$B$111,'SỔ CÔNG NỢ'!$A$5:$A$111,$B32)) | D32: =IF($B32="","",SUMIFS('SỔ CÔNG NỢ'!$N$5:$N$111,'SỔ CÔNG NỢ'!$A$5:$A$111,$B32,'SỔ CÔNG NỢ'!$B$5:$B$111,$C32)) | E32: =IF($B32="","",SUMIFS('SỔ CÔNG NỢ'!$M$5:$M$111,'SỔ CÔNG NỢ'!$A$5:$A$111,$B32,'SỔ CÔNG NỢ'!$B$5:$B$111,$C32)) | F32: =IF($B32="","",D32-E32) | G32: =IF($B32="","",IF(D32>0,"Còn nợ",IF(D32<0,"Công ty nợ lại","Hết nợ"))) | H32: =IF($B32="","",SUMIFS('SỔ CÔNG NỢ'!$G$5:$G$111,'SỔ CÔNG NỢ'!$A$5:$A$111,$B32)) | I32: =IF($B32="","",SUMIFS('SỔ CÔNG NỢ'!$J$5:$J$111,'SỔ CÔNG NỢ'!$A$5:$A$111,$B32)) | J32: =IF($B32="","",SUMIFS('SỔ CÔNG NỢ'!$K$5:$K$111,'SỔ CÔNG NỢ'!$A$5:$A$111,$B32)) | K32: =IF($B32="","",IF(ABS(F32)>1,"⚠ Biên bản lệch số tính lại – xem SỔ CÔNG NỢ. ","")&IF(C32<MAX('SỔ CÔNG NỢ'!$B$5:$B$111),"⚠ Chưa có biên bản sau "&TEXT(C32,"mm/yyyy"),""))
A33: =IF($B33="","",ROW()-8) | C33: =IF($B33="","",_xlfn.MAXIFS('SỔ CÔNG NỢ'!$B$5:$B$111,'SỔ CÔNG NỢ'!$A$5:$A$111,$B33)) | D33: =IF($B33="","",SUMIFS('SỔ CÔNG NỢ'!$N$5:$N$111,'SỔ CÔNG NỢ'!$A$5:$A$111,$B33,'SỔ CÔNG NỢ'!$B$5:$B$111,$C33)) | E33: =IF($B33="","",SUMIFS('SỔ CÔNG NỢ'!$M$5:$M$111,'SỔ CÔNG NỢ'!$A$5:$A$111,$B33,'SỔ CÔNG NỢ'!$B$5:$B$111,$C33)) | F33: =IF($B33="","",D33-E33) | G33: =IF($B33="","",IF(D33>0,"Còn nợ",IF(D33<0,"Công ty nợ lại","Hết nợ"))) | H33: =IF($B33="","",SUMIFS('SỔ CÔNG NỢ'!$G$5:$G$111,'SỔ CÔNG NỢ'!$A$5:$A$111,$B33)) | I33: =IF($B33="","",SUMIFS('SỔ CÔNG NỢ'!$J$5:$J$111,'SỔ CÔNG NỢ'!$A$5:$A$111,$B33)) | J33: =IF($B33="","",SUMIFS('SỔ CÔNG NỢ'!$K$5:$K$111,'SỔ CÔNG NỢ'!$A$5:$A$111,$B33)) | K33: =IF($B33="","",IF(ABS(F33)>1,"⚠ Biên bản lệch số tính lại – xem SỔ CÔNG NỢ. ","")&IF(C33<MAX('SỔ CÔNG NỢ'!$B$5:$B$111),"⚠ Chưa có biên bản sau "&TEXT(C33,"mm/yyyy"),""))
A34: =IF($B34="","",ROW()-8) | C34: =IF($B34="","",_xlfn.MAXIFS('SỔ CÔNG NỢ'!$B$5:$B$111,'SỔ CÔNG NỢ'!$A$5:$A$111,$B34)) | D34: =IF($B34="","",SUMIFS('SỔ CÔNG NỢ'!$N$5:$N$111,'SỔ CÔNG NỢ'!$A$5:$A$111,$B34,'SỔ CÔNG NỢ'!$B$5:$B$111,$C34)) | E34: =IF($B34="","",SUMIFS('SỔ CÔNG NỢ'!$M$5:$M$111,'SỔ CÔNG NỢ'!$A$5:$A$111,$B34,'SỔ CÔNG NỢ'!$B$5:$B$111,$C34)) | F34: =IF($B34="","",D34-E34) | G34: =IF($B34="","",IF(D34>0,"Còn nợ",IF(D34<0,"Công ty nợ lại","Hết nợ"))) | H34: =IF($B34="","",SUMIFS('SỔ CÔNG NỢ'!$G$5:$G$111,'SỔ CÔNG NỢ'!$A$5:$A$111,$B34)) | I34: =IF($B34="","",SUMIFS('SỔ CÔNG NỢ'!$J$5:$J$111,'SỔ CÔNG NỢ'!$A$5:$A$111,$B34)) | J34: =IF($B34="","",SUMIFS('SỔ CÔNG NỢ'!$K$5:$K$111,'SỔ CÔNG NỢ'!$A$5:$A$111,$B34)) | K34: =IF($B34="","",IF(ABS(F34)>1,"⚠ Biên bản lệch số tính lại – xem SỔ CÔNG NỢ. ","")&IF(C34<MAX('SỔ CÔNG NỢ'!$B$5:$B$111),"⚠ Chưa có biên bản sau "&TEXT(C34,"mm/yyyy"),""))
A35: =IF($B35="","",ROW()-8) | C35: =IF($B35="","",_xlfn.MAXIFS('SỔ CÔNG NỢ'!$B$5:$B$111,'SỔ CÔNG NỢ'!$A$5:$A$111,$B35)) | D35: =IF($B35="","",SUMIFS('SỔ CÔNG NỢ'!$N$5:$N$111,'SỔ CÔNG NỢ'!$A$5:$A$111,$B35,'SỔ CÔNG NỢ'!$B$5:$B$111,$C35)) | E35: =IF($B35="","",SUMIFS('SỔ CÔNG NỢ'!$M$5:$M$111,'SỔ CÔNG NỢ'!$A$5:$A$111,$B35,'SỔ CÔNG NỢ'!$B$5:$B$111,$C35)) | F35: =IF($B35="","",D35-E35) | G35: =IF($B35="","",IF(D35>0,"Còn nợ",IF(D35<0,"Công ty nợ lại","Hết nợ"))) | H35: =IF($B35="","",SUMIFS('SỔ CÔNG NỢ'!$G$5:$G$111,'SỔ CÔNG NỢ'!$A$5:$A$111,$B35)) | I35: =IF($B35="","",SUMIFS('SỔ CÔNG NỢ'!$J$5:$J$111,'SỔ CÔNG NỢ'!$A$5:$A$111,$B35)) | J35: =IF($B35="","",SUMIFS('SỔ CÔNG NỢ'!$K$5:$K$111,'SỔ CÔNG NỢ'!$A$5:$A$111,$B35)) | K35: =IF($B35="","",IF(ABS(F35)>1,"⚠ Biên bản lệch số tính lại – xem SỔ CÔNG NỢ. ","")&IF(C35<MAX('SỔ CÔNG NỢ'!$B$5:$B$111),"⚠ Chưa có biên bản sau "&TEXT(C35,"mm/yyyy"),""))
A36: =IF($B36="","",ROW()-8) | C36: =IF($B36="","",_xlfn.MAXIFS('SỔ CÔNG NỢ'!$B$5:$B$111,'SỔ CÔNG NỢ'!$A$5:$A$111,$B36)) | D36: =IF($B36="","",SUMIFS('SỔ CÔNG NỢ'!$N$5:$N$111,'SỔ CÔNG NỢ'!$A$5:$A$111,$B36,'SỔ CÔNG NỢ'!$B$5:$B$111,$C36)) | E36: =IF($B36="","",SUMIFS('SỔ CÔNG NỢ'!$M$5:$M$111,'SỔ CÔNG NỢ'!$A$5:$A$111,$B36,'SỔ CÔNG NỢ'!$B$5:$B$111,$C36)) | F36: =IF($B36="","",D36-E36) | G36: =IF($B36="","",IF(D36>0,"Còn nợ",IF(D36<0,"Công ty nợ lại","Hết nợ"))) | H36: =IF($B36="","",SUMIFS('SỔ CÔNG NỢ'!$G$5:$G$111,'SỔ CÔNG NỢ'!$A$5:$A$111,$B36)) | I36: =IF($B36="","",SUMIFS('SỔ CÔNG NỢ'!$J$5:$J$111,'SỔ CÔNG NỢ'!$A$5:$A$111,$B36)) | J36: =IF($B36="","",SUMIFS('SỔ CÔNG NỢ'!$K$5:$K$111,'SỔ CÔNG NỢ'!$A$5:$A$111,$B36)) | K36: =IF($B36="","",IF(ABS(F36)>1,"⚠ Biên bản lệch số tính lại – xem SỔ CÔNG NỢ. ","")&IF(C36<MAX('SỔ CÔNG NỢ'!$B$5:$B$111),"⚠ Chưa có biên bản sau "&TEXT(C36,"mm/yyyy"),""))
A37: =IF($B37="","",ROW()-8) | C37: =IF($B37="","",_xlfn.MAXIFS('SỔ CÔNG NỢ'!$B$5:$B$111,'SỔ CÔNG NỢ'!$A$5:$A$111,$B37)) | D37: =IF($B37="","",SUMIFS('SỔ CÔNG NỢ'!$N$5:$N$111,'SỔ CÔNG NỢ'!$A$5:$A$111,$B37,'SỔ CÔNG NỢ'!$B$5:$B$111,$C37)) | E37: =IF($B37="","",SUMIFS('SỔ CÔNG NỢ'!$M$5:$M$111,'SỔ CÔNG NỢ'!$A$5:$A$111,$B37,'SỔ CÔNG NỢ'!$B$5:$B$111,$C37)) | F37: =IF($B37="","",D37-E37) | G37: =IF($B37="","",IF(D37>0,"Còn nợ",IF(D37<0,"Công ty nợ lại","Hết nợ"))) | H37: =IF($B37="","",SUMIFS('SỔ CÔNG NỢ'!$G$5:$G$111,'SỔ CÔNG NỢ'!$A$5:$A$111,$B37)) | I37: =IF($B37="","",SUMIFS('SỔ CÔNG NỢ'!$J$5:$J$111,'SỔ CÔNG NỢ'!$A$5:$A$111,$B37)) | J37: =IF($B37="","",SUMIFS('SỔ CÔNG NỢ'!$K$5:$K$111,'SỔ CÔNG NỢ'!$A$5:$A$111,$B37)) | K37: =IF($B37="","",IF(ABS(F37)>1,"⚠ Biên bản lệch số tính lại – xem SỔ CÔNG NỢ. ","")&IF(C37<MAX('SỔ CÔNG NỢ'!$B$5:$B$111),"⚠ Chưa có biên bản sau "&TEXT(C37,"mm/yyyy"),""))
A38: =IF($B38="","",ROW()-8) | C38: =IF($B38="","",_xlfn.MAXIFS('SỔ CÔNG NỢ'!$B$5:$B$111,'SỔ CÔNG NỢ'!$A$5:$A$111,$B38)) | D38: =IF($B38="","",SUMIFS('SỔ CÔNG NỢ'!$N$5:$N$111,'SỔ CÔNG NỢ'!$A$5:$A$111,$B38,'SỔ CÔNG NỢ'!$B$5:$B$111,$C38)) | E38: =IF($B38="","",SUMIFS('SỔ CÔNG NỢ'!$M$5:$M$111,'SỔ CÔNG NỢ'!$A$5:$A$111,$B38,'SỔ CÔNG NỢ'!$B$5:$B$111,$C38)) | F38: =IF($B38="","",D38-E38) | G38: =IF($B38="","",IF(D38>0,"Còn nợ",IF(D38<0,"Công ty nợ lại","Hết nợ"))) | H38: =IF($B38="","",SUMIFS('SỔ CÔNG NỢ'!$G$5:$G$111,'SỔ CÔNG NỢ'!$A$5:$A$111,$B38)) | I38: =IF($B38="","",SUMIFS('SỔ CÔNG NỢ'!$J$5:$J$111,'SỔ CÔNG NỢ'!$A$5:$A$111,$B38)) | J38: =IF($B38="","",SUMIFS('SỔ CÔNG NỢ'!$K$5:$K$111,'SỔ CÔNG NỢ'!$A$5:$A$111,$B38)) | K38: =IF($B38="","",IF(ABS(F38)>1,"⚠ Biên bản lệch số tính lại – xem SỔ CÔNG NỢ. ","")&IF(C38<MAX('SỔ CÔNG NỢ'!$B$5:$B$111),"⚠ Chưa có biên bản sau "&TEXT(C38,"mm/yyyy"),""))
B39: TỔNG (nợ ròng) | D39: =SUM(D9:D38) -> 361283223 | E39: =SUM(E9:E38) -> 3.7465707e+08 | F39: =SUM(F9:F38) -> -13373844 | H39: =SUM(H9:H38) -> 8.2345171e+08 | I39: =SUM(I9:I38) -> 24228160 | J39: =SUM(J9:J38) -> 382433880
A41: Tháng bắt đầu của các bảng theo tháng bên dưới:
C42: 46174
A44: ▶ NỢ CUỐI KỲ THEO BIÊN BẢN – THEO THÁNG (số âm = công ty nợ lại)
B45: Cửa hàng | C45: =$C$42 -> 46174 | D45: =EDATE(C45,1) -> 46204 | E45: =EDATE(D45,1) -> 46235 | F45: =EDATE(E45,1) -> 46266 | G45: =EDATE(F45,1) -> 46296 | H45: =EDATE(G45,1) -> 46327
B46: =IF($B9="","",$B9) -> Thông Lan (Thiệu Vân) | C46: =IF($B46="","",IF(COUNTIFS('SỔ CÔNG NỢ'!$A$5:$A$111,$B46,'SỔ CÔNG NỢ'!$B$5:$B$111,C$45)=0,"",SUMIFS('SỔ CÔNG NỢ'!$N$5:$N$111,'SỔ CÔNG NỢ'!$A$5:$A$111,$B46,'SỔ CÔNG NỢ'!$B$5:$B$111,C$45))) | D46: =IF($B46="","",IF(COUNTIFS('SỔ CÔNG NỢ'!$A$5:$A$111,$B46,'SỔ CÔNG NỢ'!$B$5:$B$111,D$45)=0,"",SUMIFS('SỔ CÔNG NỢ'!$N$5:$N$111,'SỔ CÔNG NỢ'!$A$5:$A$111,$B46,'SỔ CÔNG NỢ'!$B$5:$B$111,D$45))) -> 60982405 | E46: =IF($B46="","",IF(COUNTIFS('SỔ CÔNG NỢ'!$A$5:$A$111,$B46,'SỔ CÔNG NỢ'!$B$5:$B$111,E$45)=0,"",SUMIFS('SỔ CÔNG NỢ'!$N$5:$N$111,'SỔ CÔNG NỢ'!$A$5:$A$111,$B46,'SỔ CÔNG NỢ'!$B$5:$B$111,E$45))) | F46: =IF($B46="","",IF(COUNTIFS('SỔ CÔNG NỢ'!$A$5:$A$111,$B46,'SỔ CÔNG NỢ'!$B$5:$B$111,F$45)=0,"",SUMIFS('SỔ CÔNG NỢ'!$N$5:$N$111,'SỔ CÔNG NỢ'!$A$5:$A$111,$B46,'SỔ CÔNG NỢ'!$B$5:$B$111,F$45))) -> 61451055 | G46: =IF($B46="","",IF(COUNTIFS('SỔ CÔNG NỢ'!$A$5:$A$111,$B46,'SỔ CÔNG NỢ'!$B$5:$B$111,G$45)=0,"",SUMIFS('SỔ CÔNG NỢ'!$N$5:$N$111,'SỔ CÔNG NỢ'!$A$5:$A$111,$B46,'SỔ CÔNG NỢ'!$B$5:$B$111,G$45))) | H46: =IF($B46="","",IF(COUNTIFS('SỔ CÔNG NỢ'!$A$5:$A$111,$B46,'SỔ CÔNG NỢ'!$B$5:$B$111,H$45)=0,"",SUMIFS('SỔ CÔNG NỢ'!$N$5:$N$111,'SỔ CÔNG NỢ'!$A$5:$A$111,$B46,'SỔ CÔNG NỢ'!$B$5:$B$111,H$45)))
B47: =IF($B10="","",$B10) -> Tuân Thuận | C47: =IF($B47="","",IF(COUNTIFS('SỔ CÔNG NỢ'!$A$5:$A$111,$B47,'SỔ CÔNG NỢ'!$B$5:$B$111,C$45)=0,"",SUMIFS('SỔ CÔNG NỢ'!$N$5:$N$111,'SỔ CÔNG NỢ'!$A$5:$A$111,$B47,'SỔ CÔNG NỢ'!$B$5:$B$111,C$45))) -> 1632852 | D47: =IF($B47="","",IF(COUNTIFS('SỔ CÔNG NỢ'!$A$5:$A$111,$B47,'SỔ CÔNG NỢ'!$B$5:$B$111,D$45)=0,"",SUMIFS('SỔ CÔNG NỢ'!$N$5:$N$111,'SỔ CÔNG NỢ'!$A$5:$A$111,$B47,'SỔ CÔNG NỢ'!$B$5:$B$111,D$45))) -> -14149408 | E47: =IF($B47="","",IF(COUNTIFS('SỔ CÔNG NỢ'!$A$5:$A$111,$B47,'SỔ CÔNG NỢ'!$B$5:$B$111,E$45)=0,"",SUMIFS('SỔ CÔNG NỢ'!$N$5:$N$111,'SỔ CÔNG NỢ'!$A$5:$A$111,$B47,'SỔ CÔNG NỢ'!$B$5:$B$111,E$45))) -> 41354652 | F47: =IF($B47="","",IF(COUNTIFS('SỔ CÔNG NỢ'!$A$5:$A$111,$B47,'SỔ CÔNG NỢ'!$B$5:$B$111,F$45)=0,"",SUMIFS('SỔ CÔNG NỢ'!$N$5:$N$111,'SỔ CÔNG NỢ'!$A$5:$A$111,$B47,'SỔ CÔNG NỢ'!$B$5:$B$111,F$45))) -> 47835892 | G47: =IF($B47="","",IF(COUNTIFS('SỔ CÔNG NỢ'!$A$5:$A$111,$B47,'SỔ CÔNG NỢ'!$B$5:$B$111,G$45)=0,"",SUMIFS('SỔ CÔNG NỢ'!$N$5:$N$111,'SỔ CÔNG NỢ'!$A$5:$A$111,$B47,'SỔ CÔNG NỢ'!$B$5:$B$111,G$45))) | H47: =IF($B47="","",IF(COUNTIFS('SỔ CÔNG NỢ'!$A$5:$A$111,$B47,'SỔ CÔNG NỢ'!$B$5:$B$111,H$45)=0,"",SUMIFS('SỔ CÔNG NỢ'!$N$5:$N$111,'SỔ CÔNG NỢ'!$A$5:$A$111,$B47,'SỔ CÔNG NỢ'!$B$5:$B$111,H$45)))
B48: =IF($B11="","",$B11) -> Anh Hưng (giao anh Hải, TP) | C48: =IF($B48="","",IF(COUNTIFS('SỔ CÔNG NỢ'!$A$5:$A$111,$B48,'SỔ CÔNG NỢ'!$B$5:$B$111,C$45)=0,"",SUMIFS('SỔ CÔNG NỢ'!$N$5:$N$111,'SỔ CÔNG NỢ'!$A$5:$A$111,$B48,'SỔ CÔNG NỢ'!$B$5:$B$111,C$45))) -> 45122746 | D48: =IF($B48="","",IF(COUNTIFS('SỔ CÔNG NỢ'!$A$5:$A$111,$B48,'SỔ CÔNG NỢ'!$B$5:$B$111,D$45)=0,"",SUMIFS('SỔ CÔNG NỢ'!$N$5:$N$111,'SỔ CÔNG NỢ'!$A$5:$A$111,$B48,'SỔ CÔNG NỢ'!$B$5:$B$111,D$45))) | E48: =IF($B48="","",IF(COUNTIFS('SỔ CÔNG NỢ'!$A$5:$A$111,$B48,'SỔ CÔNG NỢ'!$B$5:$B$111,E$45)=0,"",SUMIFS('SỔ CÔNG NỢ'!$N$5:$N$111,'SỔ CÔNG NỢ'!$A$5:$A$111,$B48,'SỔ CÔNG NỢ'!$B$5:$B$111,E$45))) -> 46455786 | F48: =IF($B48="","",IF(COUNTIFS('SỔ CÔNG NỢ'!$A$5:$A$111,$B48,'SỔ CÔNG NỢ'!$B$5:$B$111,F$45)=0,"",SUMIFS('SỔ CÔNG NỢ'!$N$5:$N$111,'SỔ CÔNG NỢ'!$A$5:$A$111,$B48,'SỔ CÔNG NỢ'!$B$5:$B$111,F$45))) | G48: =IF($B48="","",IF(COUNTIFS('SỔ CÔNG NỢ'!$A$5:$A$111,$B48,'SỔ CÔNG NỢ'!$B$5:$B$111,G$45)=0,"",SUMIFS('SỔ CÔNG NỢ'!$N$5:$N$111,'SỔ CÔNG NỢ'!$A$5:$A$111,$B48,'SỔ CÔNG NỢ'!$B$5:$B$111,G$45))) | H48: =IF($B48="","",IF(COUNTIFS('SỔ CÔNG NỢ'!$A$5:$A$111,$B48,'SỔ CÔNG NỢ'!$B$5:$B$111,H$45)=0,"",SUMIFS('SỔ CÔNG NỢ'!$N$5:$N$111,'SỔ CÔNG NỢ'!$A$5:$A$111,$B48,'SỔ CÔNG NỢ'!$B$5:$B$111,H$45)))
B49: =IF($B12="","",$B12) -> Nghị Hậu | C49: =IF($B49="","",IF(COUNTIFS('SỔ CÔNG NỢ'!$A$5:$A$111,$B49,'SỔ CÔNG NỢ'!$B$5:$B$111,C$45)=0,"",SUMIFS('SỔ CÔNG NỢ'!$N$5:$N$111,'SỔ CÔNG NỢ'!$A$5:$A$111,$B49,'SỔ CÔNG NỢ'!$B$5:$B$111,C$45))) -> 33448535 | D49: =IF($B49="","",IF(COUNTIFS('SỔ CÔNG NỢ'!$A$5:$A$111,$B49,'SỔ CÔNG NỢ'!$B$5:$B$111,D$45)=0,"",SUMIFS('SỔ CÔNG NỢ'!$N$5:$N$111,'SỔ CÔNG NỢ'!$A$5:$A$111,$B49,'SỔ CÔNG NỢ'!$B$5:$B$111,D$45))) | E49: =IF($B49="","",IF(COUNTIFS('SỔ CÔNG NỢ'!$A$5:$A$111,$B49,'SỔ CÔNG NỢ'!$B$5:$B$111,E$45)=0,"",SUMIFS('SỔ CÔNG NỢ'!$N$5:$N$111,'SỔ CÔNG NỢ'!$A$5:$A$111,$B49,'SỔ CÔNG NỢ'!$B$5:$B$111,E$45))) | F49: =IF($B49="","",IF(COUNTIFS('SỔ CÔNG NỢ'!$A$5:$A$111,$B49,'SỔ CÔNG NỢ'!$B$5:$B$111,F$45)=0,"",SUMIFS('SỔ CÔNG NỢ'!$N$5:$N$111,'SỔ CÔNG NỢ'!$A$5:$A$111,$B49,'SỔ CÔNG NỢ'!$B$5:$B$111,F$45))) | G49: =IF($B49="","",IF(COUNTIFS('SỔ CÔNG NỢ'!$A$5:$A$111,$B49,'SỔ CÔNG NỢ'!$B$5:$B$111,G$45)=0,"",SUMIFS('SỔ CÔNG NỢ'!$N$5:$N$111,'SỔ CÔNG NỢ'!$A$5:$A$111,$B49,'SỔ CÔNG NỢ'!$B$5:$B$111,G$45))) | H49: =IF($B49="","",IF(COUNTIFS('SỔ CÔNG NỢ'!$A$5:$A$111,$B49,'SỔ CÔNG NỢ'!$B$5:$B$111,H$45)=0,"",SUMIFS('SỔ CÔNG NỢ'!$N$5:$N$111,'SỔ CÔNG NỢ'!$A$5:$A$111,$B49,'SỔ CÔNG NỢ'!$B$5:$B$111,H$45)))
B50: =IF($B13="","",$B13) -> Hà Liên | C50: =IF($B50="","",IF(COUNTIFS('SỔ CÔNG NỢ'!$A$5:$A$111,$B50,'SỔ CÔNG NỢ'!$B$5:$B$111,C$45)=0,"",SUMIFS('SỔ CÔNG NỢ'!$N$5:$N$111,'SỔ CÔNG NỢ'!$A$5:$A$111,$B50,'SỔ CÔNG NỢ'!$B$5:$B$111,C$45))) -> 10078550 | D50: =IF($B50="","",IF(COUNTIFS('SỔ CÔNG NỢ'!$A$5:$A$111,$B50,'SỔ CÔNG NỢ'!$B$5:$B$111,D$45)=0,"",SUMIFS('SỔ CÔNG NỢ'!$N$5:$N$111,'SỔ CÔNG NỢ'!$A$5:$A$111,$B50,'SỔ CÔNG NỢ'!$B$5:$B$111,D$45))) -> 10478590 | E50: =IF($B50="","",IF(COUNTIFS('SỔ CÔNG NỢ'!$A$5:$A$111,$B50,'SỔ CÔNG NỢ'!$B$5:$B$111,E$45)=0,"",SUMIFS('SỔ CÔNG NỢ'!$N$5:$N$111,'SỔ CÔNG NỢ'!$A$5:$A$111,$B50,'SỔ CÔNG NỢ'!$B$5:$B$111,E$45))) -> -7095410 | F50: =IF($B50="","",IF(COUNTIFS('SỔ CÔNG NỢ'!$A$5:$A$111,$B50,'SỔ CÔNG NỢ'!$B$5:$B$111,F$45)=0,"",SUMIFS('SỔ CÔNG NỢ'!$N$5:$N$111,'SỔ CÔNG NỢ'!$A$5:$A$111,$B50,'SỔ CÔNG NỢ'!$B$5:$B$111,F$45))) -> 33078350 | G50: =IF($B50="","",IF(COUNTIFS('SỔ CÔNG NỢ'!$A$5:$A$111,$B50,'SỔ CÔNG NỢ'!$B$5:$B$111,G$45)=0,"",SUMIFS('SỔ CÔNG NỢ'!$N$5:$N$111,'SỔ CÔNG NỢ'!$A$5:$A$111,$B50,'SỔ CÔNG NỢ'!$B$5:$B$111,G$45))) | H50: =IF($B50="","",IF(COUNTIFS('SỔ CÔNG NỢ'!$A$5:$A$111,$B50,'SỔ CÔNG NỢ'!$B$5:$B$111,H$45)=0,"",SUMIFS('SỔ CÔNG NỢ'!$N$5:$N$111,'SỔ CÔNG NỢ'!$A$5:$A$111,$B50,'SỔ CÔNG NỢ'!$B$5:$B$111,H$45)))
B51: =IF($B14="","",$B14) -> Chinh Ưng (Đông Lĩnh) | C51: =IF($B51="","",IF(COUNTIFS('SỔ CÔNG NỢ'!$A$5:$A$111,$B51,'SỔ CÔNG NỢ'!$B$5:$B$111,C$45)=0,"",SUMIFS('SỔ CÔNG NỢ'!$N$5:$N$111,'SỔ CÔNG NỢ'!$A$5:$A$111,$B51,'SỔ CÔNG NỢ'!$B$5:$B$111,C$45))) -> 19587680 | D51: =IF($B51="","",IF(COUNTIFS('SỔ CÔNG NỢ'!$A$5:$A$111,$B51,'SỔ CÔNG NỢ'!$B$5:$B$111,D$45)=0,"",SUMIFS('SỔ CÔNG NỢ'!$N$5:$N$111,'SỔ CÔNG NỢ'!$A$5:$A$111,$B51,'SỔ CÔNG NỢ'!$B$5:$B$111,D$45))) -> 22792080 | E51: =IF($B51="","",IF(COUNTIFS('SỔ CÔNG NỢ'!$A$5:$A$111,$B51,'SỔ CÔNG NỢ'!$B$5:$B$111,E$45)=0,"",SUMIFS('SỔ CÔNG NỢ'!$N$5:$N$111,'SỔ CÔNG NỢ'!$A$5:$A$111,$B51,'SỔ CÔNG NỢ'!$B$5:$B$111,E$45))) | F51: =IF($B51="","",IF(COUNTIFS('SỔ CÔNG NỢ'!$A$5:$A$111,$B51,'SỔ CÔNG NỢ'!$B$5:$B$111,F$45)=0,"",SUMIFS('SỔ CÔNG NỢ'!$N$5:$N$111,'SỔ CÔNG NỢ'!$A$5:$A$111,$B51,'SỔ CÔNG NỢ'!$B$5:$B$111,F$45))) -> 29985920 | G51: =IF($B51="","",IF(COUNTIFS('SỔ CÔNG NỢ'!$A$5:$A$111,$B51,'SỔ CÔNG NỢ'!$B$5:$B$111,G$45)=0,"",SUMIFS('SỔ CÔNG NỢ'!$N$5:$N$111,'SỔ CÔNG NỢ'!$A$5:$A$111,$B51,'SỔ CÔNG NỢ'!$B$5:$B$111,G$45))) | H51: =IF($B51="","",IF(COUNTIFS('SỔ CÔNG NỢ'!$A$5:$A$111,$B51,'SỔ CÔNG NỢ'!$B$5:$B$111,H$45)=0,"",SUMIFS('SỔ CÔNG NỢ'!$N$5:$N$111,'SỔ CÔNG NỢ'!$A$5:$A$111,$B51,'SỔ CÔNG NỢ'!$B$5:$B$111,H$45)))
B52: =IF($B15="","",$B15) -> Cường Hà | C52: =IF($B52="","",IF(COUNTIFS('SỔ CÔNG NỢ'!$A$5:$A$111,$B52,'SỔ CÔNG NỢ'!$B$5:$B$111,C$45)=0,"",SUMIFS('SỔ CÔNG NỢ'!$N$5:$N$111,'SỔ CÔNG NỢ'!$A$5:$A$111,$B52,'SỔ CÔNG NỢ'!$B$5:$B$111,C$45))) -> -49231650 | D52: =IF($B52="","",IF(COUNTIFS('SỔ CÔNG NỢ'!$A$5:$A$111,$B52,'SỔ CÔNG NỢ'!$B$5:$B$111,D$45)=0,"",SUMIFS('SỔ CÔNG NỢ'!$N$5:$N$111,'SỔ CÔNG NỢ'!$A$5:$A$111,$B52,'SỔ CÔNG NỢ'!$B$5:$B$111,D$45))) -> -41238850 | E52: =IF($B52="","",IF(COUNTIFS('SỔ CÔNG NỢ'!$A$5:$A$111,$B52,'SỔ CÔNG NỢ'!$B$5:$B$111,E$45)=0,"",SUMIFS('SỔ CÔNG NỢ'!$N$5:$N$111,'SỔ CÔNG NỢ'!$A$5:$A$111,$B52,'SỔ CÔNG NỢ'!$B$5:$B$111,E$45))) -> 4487290 | F52: =IF($B52="","",IF(COUNTIFS('SỔ CÔNG NỢ'!$A$5:$A$111,$B52,'SỔ CÔNG NỢ'!$B$5:$B$111,F$45)=0,"",SUMIFS('SỔ CÔNG NỢ'!$N$5:$N$111,'SỔ CÔNG NỢ'!$A$5:$A$111,$B52,'SỔ CÔNG NỢ'!$B$5:$B$111,F$45))) -> 21149210 | G52: =IF($B52="","",IF(COUNTIFS('SỔ CÔNG NỢ'!$A$5:$A$111,$B52,'SỔ CÔNG NỢ'!$B$5:$B$111,G$45)=0,"",SUMIFS('SỔ CÔNG NỢ'!$N$5:$N$111,'SỔ CÔNG NỢ'!$A$5:$A$111,$B52,'SỔ CÔNG NỢ'!$B$5:$B$111,G$45))) | H52: =IF($B52="","",IF(COUNTIFS('SỔ CÔNG NỢ'!$A$5:$A$111,$B52,'SỔ CÔNG NỢ'!$B$5:$B$111,H$45)=0,"",SUMIFS('SỔ CÔNG NỢ'!$N$5:$N$111,'SỔ CÔNG NỢ'!$A$5:$A$111,$B52,'SỔ CÔNG NỢ'!$B$5:$B$111,H$45)))
B53: =IF($B16="","",$B16) -> Toàn Lanh | C53: =IF($B53="","",IF(COUNTIFS('SỔ CÔNG NỢ'!$A$5:$A$111,$B53,'SỔ CÔNG NỢ'!$B$5:$B$111,C$45)=0,"",SUMIFS('SỔ CÔNG NỢ'!$N$5:$N$111,'SỔ CÔNG NỢ'!$A$5:$A$111,$B53,'SỔ CÔNG NỢ'!$B$5:$B$111,C$45))) -> 13520077 | D53: =IF($B53="","",IF(COUNTIFS('SỔ CÔNG NỢ'!$A$5:$A$111,$B53,'SỔ CÔNG NỢ'!$B$5:$B$111,D$45)=0,"",SUMIFS('SỔ CÔNG NỢ'!$N$5:$N$111,'SỔ CÔNG NỢ'!$A$5:$A$111,$B53,'SỔ CÔNG NỢ'!$B$5:$B$111,D$45))) -> 18143025 | E53: =IF($B53="","",IF(COUNTIFS('SỔ CÔNG NỢ'!$A$5:$A$111,$B53,'SỔ CÔNG NỢ'!$B$5:$B$111,E$45)=0,"",SUMIFS('SỔ CÔNG NỢ'!$N$5:$N$111,'SỔ CÔNG NỢ'!$A$5:$A$111,$B53,'SỔ CÔNG NỢ'!$B$5:$B$111,E$45))) | F53: =IF($B53="","",IF(COUNTIFS('SỔ CÔNG NỢ'!$A$5:$A$111,$B53,'SỔ CÔNG NỢ'!$B$5:$B$111,F$45)=0,"",SUMIFS('SỔ CÔNG NỢ'!$N$5:$N$111,'SỔ CÔNG NỢ'!$A$5:$A$111,$B53,'SỔ CÔNG NỢ'!$B$5:$B$111,F$45))) | G53: =IF($B53="","",IF(COUNTIFS('SỔ CÔNG NỢ'!$A$5:$A$111,$B53,'SỔ CÔNG NỢ'!$B$5:$B$111,G$45)=0,"",SUMIFS('SỔ CÔNG NỢ'!$N$5:$N$111,'SỔ CÔNG NỢ'!$A$5:$A$111,$B53,'SỔ CÔNG NỢ'!$B$5:$B$111,G$45))) | H53: =IF($B53="","",IF(COUNTIFS('SỔ CÔNG NỢ'!$A$5:$A$111,$B53,'SỔ CÔNG NỢ'!$B$5:$B$111,H$45)=0,"",SUMIFS('SỔ CÔNG NỢ'!$N$5:$N$111,'SỔ CÔNG NỢ'!$A$5:$A$111,$B53,'SỔ CÔNG NỢ'!$B$5:$B$111,H$45)))
B54: =IF($B17="","",$B17) -> Chị Thu (Rừng Thông) | C54: =IF($B54="","",IF(COUNTIFS('SỔ CÔNG NỢ'!$A$5:$A$111,$B54,'SỔ CÔNG NỢ'!$B$5:$B$111,C$45)=0,"",SUMIFS('SỔ CÔNG NỢ'!$N$5:$N$111,'SỔ CÔNG NỢ'!$A$5:$A$111,$B54,'SỔ CÔNG NỢ'!$B$5:$B$111,C$45))) -> 17142020 | D54: =IF($B54="","",IF(COUNTIFS('SỔ CÔNG NỢ'!$A$5:$A$111,$B54,'SỔ CÔNG NỢ'!$B$5:$B$111,D$45)=0,"",SUMIFS('SỔ CÔNG NỢ'!$N$5:$N$111,'SỔ CÔNG NỢ'!$A$5:$A$111,$B54,'SỔ CÔNG NỢ'!$B$5:$B$111,D$45))) | E54: =IF($B54="","",IF(COUNTIFS('SỔ CÔNG NỢ'!$A$5:$A$111,$B54,'SỔ CÔNG NỢ'!$B$5:$B$111,E$45)=0,"",SUMIFS('SỔ CÔNG NỢ'!$N$5:$N$111,'SỔ CÔNG NỢ'!$A$5:$A$111,$B54,'SỔ CÔNG NỢ'!$B$5:$B$111,E$45))) | F54: =IF($B54="","",IF(COUNTIFS('SỔ CÔNG NỢ'!$A$5:$A$111,$B54,'SỔ CÔNG NỢ'!$B$5:$B$111,F$45)=0,"",SUMIFS('SỔ CÔNG NỢ'!$N$5:$N$111,'SỔ CÔNG NỢ'!$A$5:$A$111,$B54,'SỔ CÔNG NỢ'!$B$5:$B$111,F$45))) | G54: =IF($B54="","",IF(COUNTIFS('SỔ CÔNG NỢ'!$A$5:$A$111,$B54,'SỔ CÔNG NỢ'!$B$5:$B$111,G$45)=0,"",SUMIFS('SỔ CÔNG NỢ'!$N$5:$N$111,'SỔ CÔNG NỢ'!$A$5:$A$111,$B54,'SỔ CÔNG NỢ'!$B$5:$B$111,G$45))) | H54: =IF($B54="","",IF(COUNTIFS('SỔ CÔNG NỢ'!$A$5:$A$111,$B54,'SỔ CÔNG NỢ'!$B$5:$B$111,H$45)=0,"",SUMIFS('SỔ CÔNG NỢ'!$N$5:$N$111,'SỔ CÔNG NỢ'!$A$5:$A$111,$B54,'SỔ CÔNG NỢ'!$B$5:$B$111,H$45)))
...

Sheet SỔ CÔNG NỢ
A1: SỔ CÔNG NỢ THEO KHÁCH – THEO THÁNG
A2: Số dương = khách còn nợ công ty; số âm (đỏ) = công ty nợ lại khách. Cột vàng = số ghi trên biên bản; cột xanh dương = tự tính lại để đối chiếu.
A4: Khách hàng | B4: Tháng | C4: Nợ đầu kỳ (theo biên bản) | D4: Phát sinh (giá gốc) | E4: Tiền chiết khấu | F4: % chiết khấu | G4: Phát sinh sau CK | H4: Hàng trả lại (giá gốc) | I4: CK hàng trả lại | J4: Hàng trả lại sau CK | K4: Khách đã thanh toán | L4: Nợ đầu kỳ (tính lại) | M4: NỢ CUỐI KỲ (TÍNH LẠI) | N4: Nợ cuối kỳ (theo biên bản) | O4: Chênh lệch (BB − tính lại) | P4: Ghi chú / vấn đề phát hiện
A5: Anh Giang (Đông Thanh) | B5: 46235 | C5: 0 | D5: 8212000 | E5: 5091440 | F5: 62% | G5: =IF(OR($A5="",$B5=""),"",D5-E5) -> 3120560 | H5: 0 | I5: 0 | J5: =IF(OR($A5="",$B5=""),"",H5-I5) -> 0 | K5: =IF(OR($A5="",$B5=""),"",SUMIFS('THANH TOÁN'!$D$5:$D$305,'THANH TOÁN'!$A$5:$A$305,$A5,'THANH TOÁN'!$B$5:$B$305,$B5,'THANH TOÁN'!$E$5:$E$305,"Có")) -> 0 | L5: =IF(OR($A5="",$B5=""),"",IF(_xlfn.MAXIFS('SỔ CÔNG NỢ'!$B$5:$B$111,'SỔ CÔNG NỢ'!$A$5:$A$111,$A5,'SỔ CÔNG NỢ'!$B$5:$B$111,"<"&$B5)=0,C5,SUMIFS('SỔ CÔNG NỢ'!$M$5:$M$111,'SỔ CÔNG NỢ'!$A$5:$A$111,$A5,'SỔ CÔNG NỢ'!$B$5:$B$111,_xlfn.MAXIFS('SỔ CÔNG NỢ'!$B$5:$B$111,'SỔ CÔNG NỢ'!$A$5:$A$111,$A5,'SỔ CÔNG NỢ'!$B$5:$B$111,"<"&$B5)))) -> 0 | M5: =IF(OR($A5="",$B5=""),"",L5+G5-J5-K5) -> 3120560 | N5: 5091440 | O5: =IF(OR($A5="",$B5="",N5=""),"",N5-M5) -> 1970880 | P5: Biên bản ghi "Tổng nợ phải thanh toán" 5.091.440 = đúng số TIỀN CHIẾT KHẤU, trong khi phát sinh sau chiết khấu là 3.120.560 → biên bản ghi nợ dư 1.970.880.
A6: Anh Duẩn (Lĩnh Lộc) | B6: 46174 | C6: 0 | D6: 1447000 | E6: 810320 | F6: 45-20% | G6: =IF(OR($A6="",$B6=""),"",D6-E6) -> 636680 | H6: 0 | I6: 0 | J6: =IF(OR($A6="",$B6=""),"",H6-I6) -> 0 | K6: =IF(OR($A6="",$B6=""),"",SUMIFS('THANH TOÁN'!$D$5:$D$305,'THANH TOÁN'!$A$5:$A$305,$A6,'THANH TOÁN'!$B$5:$B$305,$B6,'THANH TOÁN'!$E$5:$E$305,"Có")) -> 979440 | L6: =IF(OR($A6="",$B6=""),"",IF(_xlfn.MAXIFS('SỔ CÔNG NỢ'!$B$5:$B$111,'SỔ CÔNG NỢ'!$A$5:$A$111,$A6,'SỔ CÔNG NỢ'!$B$5:$B$111,"<"&$B6)=0,C6,SUMIFS('SỔ CÔNG NỢ'!$M$5:$M$111,'SỔ CÔNG NỢ'!$A$5:$A$111,$A6,'SỔ CÔNG NỢ'!$B$5:$B$111,_xlfn.MAXIFS('SỔ CÔNG NỢ'!$B$5:$B$111,'SỔ CÔNG NỢ'!$A$5:$A$111,$A6,'SỔ CÔNG NỢ'!$B$5:$B$111,"<"&$B6)))) -> 0 | M6: =IF(OR($A6="",$B6=""),"",L6+G6-J6-K6) -> -342760 | N6: -342760 | O6: =IF(OR($A6="",$B6="",N6=""),"",N6-M6) -> 0
A7: Anh Hùng (TP) | B7: 46174 | C7: 681 | D7: 31578800 | E7: 19578856 | F7: 62% | G7: =IF(OR($A7="",$B7=""),"",D7-E7) -> 11999944 | H7: 0 | I7: 0 | J7: =IF(OR($A7="",$B7=""),"",H7-I7) -> 0 | K7: =IF(OR($A7="",$B7=""),"",SUMIFS('THANH TOÁN'!$D$5:$D$305,'THANH TOÁN'!$A$5:$A$305,$A7,'THANH TOÁN'!$B$5:$B$305,$B7,'THANH TOÁN'!$E$5:$E$305,"Có")) -> 0 | L7: =IF(OR($A7="",$B7=""),"",IF(_xlfn.MAXIFS('SỔ CÔNG NỢ'!$B$5:$B$111,'SỔ CÔNG NỢ'!$A$5:$A$111,$A7,'SỔ CÔNG NỢ'!$B$5:$B$111,"<"&$B7)=0,C7,SUMIFS('SỔ CÔNG NỢ'!$M$5:$M$111,'SỔ CÔNG NỢ'!$A$5:$A$111,$A7,'SỔ CÔNG NỢ'!$B$5:$B$111,_xlfn.MAXIFS('SỔ CÔNG NỢ'!$B$5:$B$111,'SỔ CÔNG NỢ'!$A$5:$A$111,$A7,'SỔ CÔNG NỢ'!$B$5:$B$111,"<"&$B7)))) -> 681 | M7: =IF(OR($A7="",$B7=""),"",L7+G7-J7-K7) -> 12000625 | N7: 12000625 | O7: =IF(OR($A7="",$B7="",N7=""),"",N7-M7) -> 0
A8: Anh Hùng (TP) | B8: 46204 | C8: 12000625 | D8: 409000 | E8: 253580 | F8: 62% | G8: =IF(OR($A8="",$B8=""),"",D8-E8) -> 155420 | H8: 0 | I8: 0 | J8: =IF(OR($A8="",$B8=""),"",H8-I8) -> 0 | K8: =IF(OR($A8="",$B8=""),"",SUMIFS('THANH TOÁN'!$D$5:$D$305,'THANH TOÁN'!$A$5:$A$305,$A8,'THANH TOÁN'!$B$5:$B$305,$B8,'THANH TOÁN'!$E$5:$E$305,"Có")) -> 0 | L8: =IF(OR($A8="",$B8=""),"",IF(_xlfn.MAXIFS('SỔ CÔNG NỢ'!$B$5:$B$111,'SỔ CÔNG NỢ'!$A$5:$A$111,$A8,'SỔ CÔNG NỢ'!$B$5:$B$111,"<"&$B8)=0,C8,SUMIFS('SỔ CÔNG NỢ'!$M$5:$M$111,'SỔ CÔNG NỢ'!$A$5:$A$111,$A8,'SỔ CÔNG NỢ'!$B$5:$B$111,_xlfn.MAXIFS('SỔ CÔNG NỢ'!$B$5:$B$111,'SỔ CÔNG NỢ'!$A$5:$A$111,$A8,'SỔ CÔNG NỢ'!$B$5:$B$111,"<"&$B8)))) -> 12000625 | M8: =IF(OR($A8="",$B8=""),"",L8+G8-J8-K8) -> 12156045 | N8: 12156045 | O8: =IF(OR($A8="",$B8="",N8=""),"",N8-M8) -> 0
A9: Anh Hùng (TP) | B9: 46266 | C9: 12156045 | D9: 9645000 | E9: 5979900 | F9: 62% | G9: =IF(OR($A9="",$B9=""),"",D9-E9) -> 3665100 | H9: 0 | I9: 0 | J9: =IF(OR($A9="",$B9=""),"",H9-I9) -> 0 | K9: =IF(OR($A9="",$B9=""),"",SUMIFS('THANH TOÁN'!$D$5:$D$305,'THANH TOÁN'!$A$5:$A$305,$A9,'THANH TOÁN'!$B$5:$B$305,$B9,'THANH TOÁN'!$E$5:$E$305,"Có")) -> 0 | L9: =IF(OR($A9="",$B9=""),"",IF(_xlfn.MAXIFS('SỔ CÔNG NỢ'!$B$5:$B$111,'SỔ CÔNG NỢ'!$A$5:$A$111,$A9,'SỔ CÔNG NỢ'!$B$5:$B$111,"<"&$B9)=0,C9,SUMIFS('SỔ CÔNG NỢ'!$M$5:$M$111,'SỔ CÔNG NỢ'!$A$5:$A$111,$A9,'SỔ CÔNG NỢ'!$B$5:$B$111,_xlfn.MAXIFS('SỔ CÔNG NỢ'!$B$5:$B$111,'SỔ CÔNG NỢ'!$A$5:$A$111,$A9,'SỔ CÔNG NỢ'!$B$5:$B$111,"<"&$B9)))) -> 12156045 | M9: =IF(OR($A9="",$B9=""),"",L9+G9-J9-K9) -> 15821145 | N9: 15821145 | O9: =IF(OR($A9="",$B9="",N9=""),"",N9-M9) -> 0
A10: Anh Hưng (giao anh Hải, TP) | B10: 46174 | C10: 529822 | D10: 117349800 | E10: 72756876 | F10: 62% | G10: =IF(OR($A10="",$B10=""),"",D10-E10) -> 44592924 | H10: 0 | I10: 0 | J10: =IF(OR($A10="",$B10=""),"",H10-I10) -> 0 | K10: =IF(OR($A10="",$B10=""),"",SUMIFS('THANH TOÁN'!$D$5:$D$305,'THANH TOÁN'!$A$5:$A$305,$A10,'THANH TOÁN'!$B$5:$B$305,$B10,'THANH TOÁN'!$E$5:$E$305,"Có")) -> 0 | L10: =IF(OR($A10="",$B10=""),"",IF(_xlfn.MAXIFS('SỔ CÔNG NỢ'!$B$5:$B$111,'SỔ CÔNG NỢ'!$A$5:$A$111,$A10,'SỔ CÔNG NỢ'!$B$5:$B$111,"<"&$B10)=0,C10,SUMIFS('SỔ CÔNG NỢ'!$M$5:$M$111,'SỔ CÔNG NỢ'!$A$5:$A$111,$A10,'SỔ CÔNG NỢ'!$B$5:$B$111,_xlfn.MAXIFS('SỔ CÔNG NỢ'!$B$5:$B$111,'SỔ CÔNG NỢ'!$A$5:$A$111,$A10,'SỔ CÔNG NỢ'!$B$5:$B$111,"<"&$B10)))) -> 529822 | M10: =IF(OR($A10="",$B10=""),"",L10+G10-J10-K10) -> 45122746 | N10: 45122746 | O10: =IF(OR($A10="",$B10="",N10=""),"",N10-M10) -> 0
A11: Anh Hưng (giao anh Hải, TP) | B11: 46235 | C11: 45122746 | D11: 3508000 | E11: 2174960 | F11: 62% | G11: =IF(OR($A11="",$B11=""),"",D11-E11) -> 1333040 | H11: 0 | I11: 0 | J11: =IF(OR($A11="",$B11=""),"",H11-I11) -> 0 | K11: =IF(OR($A11="",$B11=""),"",SUMIFS('THANH TOÁN'!$D$5:$D$305,'THANH TOÁN'!$A$5:$A$305,$A11,'THANH TOÁN'!$B$5:$B$305,$B11,'THANH TOÁN'!$E$5:$E$305,"Có")) -> 0 | L11: =IF(OR($A11="",$B11=""),"",IF(_xlfn.MAXIFS('SỔ CÔNG NỢ'!$B$5:$B$111,'SỔ CÔNG NỢ'!$A$5:$A$111,$A11,'SỔ CÔNG NỢ'!$B$5:$B$111,"<"&$B11)=0,C11,SUMIFS('SỔ CÔNG NỢ'!$M$5:$M$111,'SỔ CÔNG NỢ'!$A$5:$A$111,$A11,'SỔ CÔNG NỢ'!$B$5:$B$111,_xlfn.MAXIFS('SỔ CÔNG NỢ'!$B$5:$B$111,'SỔ CÔNG NỢ'!$A$5:$A$111,$A11,'SỔ CÔNG NỢ'!$B$5:$B$111,"<"&$B11)))) -> 45122746 | M11: =IF(OR($A11="",$B11=""),"",L11+G11-J11-K11) -> 46455786 | N11: 46455786 | O11: =IF(OR($A11="",$B11="",N11=""),"",N11-M11) -> 0
A12: Tuấn Thanh | B12: 46266 | C12: -735 | D12: 32931000 | E12: 19758600 | F12: 60% | G12: =IF(OR($A12="",$B12=""),"",D12-E12) -> 13172400 | H12: 0 | I12: 0 | J12: =IF(OR($A12="",$B12=""),"",H12-I12) -> 0 | K12: =IF(OR($A12="",$B12=""),"",SUMIFS('THANH TOÁN'!$D$5:$D$305,'THANH TOÁN'!$A$5:$A$305,$A12,'THANH TOÁN'!$B$5:$B$305,$B12,'THANH TOÁN'!$E$5:$E$305,"Có")) -> 0 | L12: =IF(OR($A12="",$B12=""),"",IF(_xlfn.MAXIFS('SỔ CÔNG NỢ'!$B$5:$B$111,'SỔ CÔNG NỢ'!$A$5:$A$111,$A12,'SỔ CÔNG NỢ'!$B$5:$B$111,"<"&$B12)=0,C12,SUMIFS('SỔ CÔNG NỢ'!$M$5:$M$111,'SỔ CÔNG NỢ'!$A$5:$A$111,$A12,'SỔ CÔNG NỢ'!$B$5:$B$111,_xlfn.MAXIFS('SỔ CÔNG NỢ'!$B$5:$B$111,'SỔ CÔNG NỢ'!$A$5:$A$111,$A12,'SỔ CÔNG NỢ'!$B$5:$B$111,"<"&$B12)))) -> -735 | M12: =IF(OR($A12="",$B12=""),"",L12+G12-J12-K12) -> 13171665 | N12: 13171665 | O12: =IF(OR($A12="",$B12="",N12=""),"",N12-M12) -> 0
A13: Chú Giáp (Thiệu Thành) | B13: 46174 | C13: 6426350 | D13: 25326000 | E13: 15955380 | F13: 63% | G13: =IF(OR($A13="",$B13=""),"",D13-E13) -> 9370620 | H13: 12206000 | I13: 7689780 | J13: =IF(OR($A13="",$B13=""),"",H13-I13) -> 4516220 | K13: =IF(OR($A13="",$B13=""),"",SUMIFS('THANH TOÁN'!$D$5:$D$305,'THANH TOÁN'!$A$5:$A$305,$A13,'THANH TOÁN'!$B$5:$B$305,$B13,'THANH TOÁN'!$E$5:$E$305,"Có")) -> 6400000 | L13: =IF(OR($A13="",$B13=""),"",IF(_xlfn.MAXIFS('SỔ CÔNG NỢ'!$B$5:$B$111,'SỔ CÔNG NỢ'!$A$5:$A$111,$A13,'SỔ CÔNG NỢ'!$B$5:$B$111,"<"&$B13)=0,C13,SUMIFS('SỔ CÔNG NỢ'!$M$5:$M$111,'SỔ CÔNG NỢ'!$A$5:$A$111,$A13,'SỔ CÔNG NỢ'!$B$5:$B$111,_xlfn.MAXIFS('SỔ CÔNG NỢ'!$B$5:$B$111,'SỔ CÔNG NỢ'!$A$5:$A$111,$A13,'SỔ CÔNG NỢ'!$B$5:$B$111,"<"&$B13)))) -> 6426350 | M13: =IF(OR($A13="",$B13=""),"",L13+G13-J13-K13) -> 4880750 | N13: 1707190 | O13: =IF(OR($A13="",$B13="",N13=""),"",N13-M13) -> -3173560 | P13: Biên bản trừ tiền chiết khấu của hàng trả lại (7.689.780) thay vì giá trị sau chiết khấu (4.516.220) → nợ ghi thấp hơn 3.173.560.
A14: Chú Giáp (Thiệu Thành) | B14: 46204 | C14: 1707190 | D14: 0 | E14: 0 | F14: 65% | G14: =IF(OR($A14="",$B14=""),"",D14-E14) -> 0 | H14: 16634000 | I14: 10812100 | J14: =IF(OR($A14="",$B14=""),"",H14-I14) -> 5821900 | K14: =IF(OR($A14="",$B14=""),"",SUMIFS('THANH TOÁN'!$D$5:$D$305,'THANH TOÁN'!$A$5:$A$305,$A14,'THANH TOÁN'!$B$5:$B$305,$B14,'THANH TOÁN'!$E$5:$E$305,"Có")) -> 0 | L14: =IF(OR($A14="",$B14=""),"",IF(_xlfn.MAXIFS('SỔ CÔNG NỢ'!$B$5:$B$111,'SỔ CÔNG NỢ'!$A$5:$A$111,$A14,'SỔ CÔNG NỢ'!$B$5:$B$111,"<"&$B14)=0,C14,SUMIFS('SỔ CÔNG NỢ'!$M$5:$M$111,'SỔ CÔNG NỢ'!$A$5:$A$111,$A14,'SỔ CÔNG NỢ'!$B$5:$B$111,_xlfn.MAXIFS('SỔ CÔNG NỢ'!$B$5:$B$111,'SỔ CÔNG NỢ'!$A$5:$A$111,$A14,'SỔ CÔNG NỢ'!$B$5:$B$111,"<"&$B14)))) -> 4880750 | M14: =IF(OR($A14="",$B14=""),"",L14+G14-J14-K14) -> -941150 | N14: 7529090 | O14: =IF(OR($A14="",$B14="",N14=""),"",N14-M14) -> 8470240 | P14: Biên bản ghi 16.634.000 là "Phát sinh hàng nhập lại" (hàng trả lại ngày 16/07) nhưng lại CỘNG vào nợ (1.707.190 + 5.821.900 = 7.529.090). Hàng trả lại phải TRỪ nợ.
A15: Chinh Ưng (Đông Lĩnh) | B15: 46174 | C15: 9456800 | D15: 31659000 | E15: 18995400 | F15: 60% | G15: =IF(OR($A15="",$B15=""),"",D15-E15) -> 12663600 | H15: 6331800 | I15: 3799080 | J15: =IF(OR($A15="",$B15=""),"",H15-I15) -> 2532720 | K15: =IF(OR($A15="",$B15=""),"",SUMIFS('THANH TOÁN'!$D$5:$D$305,'THANH TOÁN'!$A$5:$A$305,$A15,'THANH TOÁN'!$B$5:$B$305,$B15,'THANH TOÁN'!$E$5:$E$305,"Có")) -> 0 | L15: =IF(OR($A15="",$B15=""),"",IF(_xlfn.MAXIFS('SỔ CÔNG NỢ'!$B$5:$B$111,'SỔ CÔNG NỢ'!$A$5:$A$111,$A15,'SỔ CÔNG NỢ'!$B$5:$B$111,"<"&$B15)=0,C15,SUMIFS('SỔ CÔNG NỢ'!$M$5:$M$111,'SỔ CÔNG NỢ'!$A$5:$A$111,$A15,'SỔ CÔNG NỢ'!$B$5:$B$111,_xlfn.MAXIFS('SỔ CÔNG NỢ'!$B$5:$B$111,'SỔ CÔNG NỢ'!$A$5:$A$111,$A15,'SỔ CÔNG NỢ'!$B$5:$B$111,"<"&$B15)))) -> 9456800 | M15: =IF(OR($A15="",$B15=""),"",L15+G15-J15-K15) -> 19587680 | N15: 19587680 | O15: =IF(OR($A15="",$B15="",N15=""),"",N15-M15) -> 0
A16: Chinh Ưng (Đông Lĩnh) | B16: 46204 | C16: 19587680 | D16: 8011000 | E16: 4806600 | F16: 60% | G16: =IF(OR($A16="",$B16=""),"",D16-E16) -> 3204400 | H16: 0 | I16: 0 | J16: =IF(OR($A16="",$B16=""),"",H16-I16) -> 0 | K16: =IF(OR($A16="",$B16=""),"",SUMIFS('THANH TOÁN'!$D$5:$D$305,'THANH TOÁN'!$A$5:$A$305,$A16,'THANH TOÁN'!$B$5:$B$305,$B16,'THANH TOÁN'!$E$5:$E$305,"Có")) -> 0 | L16: =IF(OR($A16="",$B16=""),"",IF(_xlfn.MAXIFS('SỔ CÔNG NỢ'!$B$5:$B$111,'SỔ CÔNG NỢ'!$A$5:$A$111,$A16,'SỔ CÔNG NỢ'!$B$5:$B$111,"<"&$B16)=0,C16,SUMIFS('SỔ CÔNG NỢ'!$M$5:$M$111,'SỔ CÔNG NỢ'!$A$5:$A$111,$A16,'SỔ CÔNG NỢ'!$B$5:$B$111,_xlfn.MAXIFS('SỔ CÔNG NỢ'!$B$5:$B$111,'SỔ CÔNG NỢ'!$A$5:$A$111,$A16,'SỔ CÔNG NỢ'!$B$5:$B$111,"<"&$B16)))) -> 19587680 | M16: =IF(OR($A16="",$B16=""),"",L16+G16-J16-K16) -> 22792080 | N16: 22792080 | O16: =IF(OR($A16="",$B16="",N16=""),"",N16-M16) -> 0
A17: Chinh Ưng (Đông Lĩnh) | B17: 46266 | C17: 22792080 | D17: 17984600 | E17: 10790760 | F17: 60% | G17: =IF(OR($A17="",$B17=""),"",D17-E17) -> 7193840 | H17: 0 | I17: 0 | J17: =IF(OR($A17="",$B17=""),"",H17-I17) -> 0 | K17: =IF(OR($A17="",$B17=""),"",SUMIFS('THANH TOÁN'!$D$5:$D$305,'THANH TOÁN'!$A$5:$A$305,$A17,'THANH TOÁN'!$B$5:$B$305,$B17,'THANH TOÁN'!$E$5:$E$305,"Có")) -> 0 | L17: =IF(OR($A17="",$B17=""),"",IF(_xlfn.MAXIFS('SỔ CÔNG NỢ'!$B$5:$B$111,'SỔ CÔNG NỢ'!$A$5:$A$111,$A17,'SỔ CÔNG NỢ'!$B$5:$B$111,"<"&$B17)=0,C17,SUMIFS('SỔ CÔNG NỢ'!$M$5:$M$111,'SỔ CÔNG NỢ'!$A$5:$A$111,$A17,'SỔ CÔNG NỢ'!$B$5:$B$111,_xlfn.MAXIFS('SỔ CÔNG NỢ'!$B$5:$B$111,'SỔ CÔNG NỢ'!$A$5:$A$111,$A17,'SỔ CÔNG NỢ'!$B$5:$B$111,"<"&$B17)))) -> 22792080 | M17: =IF(OR($A17="",$B17=""),"",L17+G17-J17-K17) -> 29985920 | N17: 29985920 | O17: =IF(OR($A17="",$B17="",N17=""),"",N17-M17) -> 0
A18: Chị Thu (Rừng Thông) | B18: 46174 | C18: 0 | D18: 42855050 | E18: 25713030 | F18: 60% | G18: =IF(OR($A18="",$B18=""),"",D18-E18) -> 17142020 | H18: 0 | I18: 0 | J18: =IF(OR($A18="",$B18=""),"",H18-I18) -> 0 | K18: =IF(OR($A18="",$B18=""),"",SUMIFS('THANH TOÁN'!$D$5:$D$305,'THANH TOÁN'!$A$5:$A$305,$A18,'THANH TOÁN'!$B$5:$B$305,$B18,'THANH TOÁN'!$E$5:$E$305,"Có")) -> 0 | L18: =IF(OR($A18="",$B18=""),"",IF(_xlfn.MAXIFS('SỔ CÔNG NỢ'!$B$5:$B$111,'SỔ CÔNG NỢ'!$A$5:$A$111,$A18,'SỔ CÔNG NỢ'!$B$5:$B$111,"<"&$B18)=0,C18,SUMIFS('SỔ CÔNG NỢ'!$M$5:$M$111,'SỔ CÔNG NỢ'!$A$5:$A$111,$A18,'SỔ CÔNG NỢ'!$B$5:$B$111,_xlfn.MAXIFS('SỔ CÔNG NỢ'!$B$5:$B$111,'SỔ CÔNG NỢ'!$A$5:$A$111,$A18,'SỔ CÔNG NỢ'!$B$5:$B$111,"<"&$B18)))) -> 0 | M18: =IF(OR($A18="",$B18=""),"",L18+G18-J18-K18) -> 17142020 | N18: 17142020 | O18: =IF(OR($A18="",$B18="",N18=""),"",N18-M18) -> 0
A19: Cô Khoa (Nông Cống) | B19: 46174 | C19: 0 | D19: 0 | E19: 0 | F19: 62% | G19: =IF(OR($A19="",$B19=""),"",D19-E19) -> 0 | H19: 5364000 | I19: 3325680 | J19: =IF(OR($A19="",$B19=""),"",H19-I19) -> 2038320 | K19: =IF(OR($A19="",$B19=""),"",SUMIFS('THANH TOÁN'!$D$5:$D$305,'THANH TOÁN'!$A$5:$A$305,$A19,'THANH TOÁN'!$B$5:$B$305,$B19,'THANH TOÁN'!$E$5:$E$305,"Có")) -> -1450000 | L19: =IF(OR($A19="",$B19=""),"",IF(_xlfn.MAXIFS('SỔ CÔNG NỢ'!$B$5:$B$111,'SỔ CÔNG NỢ'!$A$5:$A$111,$A19,'SỔ CÔNG NỢ'!$B$5:$B$111,"<"&$B19)=0,C19,SUMIFS('SỔ CÔNG NỢ'!$M$5:$M$111,'SỔ CÔNG NỢ'!$A$5:$A$111,$A19,'SỔ CÔNG NỢ'!$B$5:$B$111,_xlfn.MAXIFS('SỔ CÔNG NỢ'!$B$5:$B$111,'SỔ CÔNG NỢ'!$A$5:$A$111,$A19,'SỔ CÔNG NỢ'!$B$5:$B$111,"<"&$B19)))) -> 0 | M19: =IF(OR($A19="",$B19=""),"",L19+G19-J19-K19) -> -588320 | N19: -588320 | O19: =IF(OR($A19="",$B19="",N19=""),"",N19-M19) -> 0 | P19: Toàn bộ hàng trên biên bản là hàng khách trả lại (17/06). Ngày 30/07 công ty trả lại khách 1.450.000 (tính là thanh toán âm).
A20: Công Thành | B20: 46174 | C20: 0 | D20: 63170000 | E20: 41060500 | F20: 65% | G20: =IF(OR($A20="",$B20=""),"",D20-E20) -> 22109500 | H20: 0 | I20: 0 | J20: =IF(OR($A20="",$B20=""),"",H20-I20) -> 0 | K20: =IF(OR($A20="",$B20=""),"",SUMIFS('THANH TOÁN'!$D$5:$D$305,'THANH TOÁN'!$A$5:$A$305,$A20,'THANH TOÁN'!$B$5:$B$305,$B20,'THANH TOÁN'!$E$5:$E$305,"Có")) -> 0 | L20: =IF(OR($A20="",$B20=""),"",IF(_xlfn.MAXIFS('SỔ CÔNG NỢ'!$B$5:$B$111,'SỔ CÔNG NỢ'!$A$5:$A$111,$A20,'SỔ CÔNG NỢ'!$B$5:$B$111,"<"&$B20)=0,C20,SUMIFS('SỔ CÔNG NỢ'!$M$5:$M$111,'SỔ CÔNG NỢ'!$A$5:$A$111,$A20,'SỔ CÔNG NỢ'!$B$5:$B$111,_xlfn.MAXIFS('SỔ CÔNG NỢ'!$B$5:$B$111,'SỔ CÔNG NỢ'!$A$5:$A$111,$A20,'SỔ CÔNG NỢ'!$B$5:$B$111,"<"&$B20)))) -> 0 | M20: =IF(OR($A20="",$B20=""),"",L20+G20-J20-K20) -> 22109500 | N20: 22109500 | O20: =IF(OR($A20="",$B20="",N20=""),"",N20-M20) -> 0
A21: Công Thành | B21: 46204 | C21: 22109500 | D21: 14854000 | E21: 9655100 | F21: 65% | G21: =IF(OR($A21="",$B21=""),"",D21-E21) -> 5198900 | H21: 0 | I21: 0 | J21: =IF(OR($A21="",$B21=""),"",H21-I21) -> 0 | K21: =IF(OR($A21="",$B21=""),"",SUMIFS('THANH TOÁN'!$D$5:$D$305,'THANH TOÁN'!$A$5:$A$305,$A21,'THANH TOÁN'!$B$5:$B$305,$B21,'THANH TOÁN'!$E$5:$E$305,"Có")) -> 28600000 | L21: =IF(OR($A21="",$B21=""),"",IF(_xlfn.MAXIFS('SỔ CÔNG NỢ'!$B$5:$B$111,'SỔ CÔNG NỢ'!$A$5:$A$111,$A21,'SỔ CÔNG NỢ'!$B$5:$B$111,"<"&$B21)=0,C21,SUMIFS('SỔ CÔNG NỢ'!$M$5:$M$111,'SỔ CÔNG NỢ'!$A$5:$A$111,$A21,'SỔ CÔNG NỢ'!$B$5:$B$111,_xlfn.MAXIFS('SỔ CÔNG NỢ'!$B$5:$B$111,'SỔ CÔNG NỢ'!$A$5:$A$111,$A21,'SỔ CÔNG NỢ'!$B$5:$B$111,"<"&$B21)))) -> 22109500 | M21: =IF(OR($A21="",$B21=""),"",L21+G21-J21-K21) -> -1291600 | N21: -1291600 | O21: =IF(OR($A21="",$B21="",N21=""),"",N21-M21) -> 0
A22: Công Thành | B22: 46266 | C22: -1291600 | D22: 1262000 | E22: 820300 | F22: 65% | G22: =IF(OR($A22="",$B22=""),"",D22-E22) -> 441700 | H22: 0 | I22: 0 | J22: =IF(OR($A22="",$B22=""),"",H22-I22) -> 0 | K22: =IF(OR($A22="",$B22=""),"",SUMIFS('THANH TOÁN'!$D$5:$D$305,'THANH TOÁN'!$A$5:$A$305,$A22,'THANH TOÁN'!$B$5:$B$305,$B22,'THANH TOÁN'!$E$5:$E$305,"Có")) -> 0 | L22: =IF(OR($A22="",$B22=""),"",IF(_xlfn.MAXIFS('SỔ CÔNG NỢ'!$B$5:$B$111,'SỔ CÔNG NỢ'!$A$5:$A$111,$A22,'SỔ CÔNG NỢ'!$B$5:$B$111,"<"&$B22)=0,C22,SUMIFS('SỔ CÔNG NỢ'!$M$5:$M$111,'SỔ CÔNG NỢ'!$A$5:$A$111,$A22,'SỔ CÔNG NỢ'!$B$5:$B$111,_xlfn.MAXIFS('SỔ CÔNG NỢ'!$B$5:$B$111,'SỔ CÔNG NỢ'!$A$5:$A$111,$A22,'SỔ CÔNG NỢ'!$B$5:$B$111,"<"&$B22)))) -> -1291600 | M22: =IF(OR($A22="",$B22=""),"",L22+G22-J22-K22) -> -849900 | N22: -849900 | O22: =IF(OR($A22="",$B22="",N22=""),"",N22-M22) -> 0 | P22: Biên bản ghi tiêu đề "Tháng 8" nhưng hàng xuất ngày 10/09 → xếp vào tháng 9.
A23: Cường Hà | B23: 46174 | C23: -93701990 | D23: 111175850 | E23: 66705510 | F23: 60% | G23: =IF(OR($A23="",$B23=""),"",D23-E23) -> 44470340 | H23: 0 | I23: 0 | J23: =IF(OR($A23="",$B23=""),"",H23-I23) -> 0 | K23: =IF(OR($A23="",$B23=""),"",SUMIFS('THANH TOÁN'!$D$5:$D$305,'THANH TOÁN'!$A$5:$A$305,$A23,'THANH TOÁN'!$B$5:$B$305,$B23,'THANH TOÁN'!$E$5:$E$305,"Có")) -> 0 | L23: =IF(OR($A23="",$B23=""),"",IF(_xlfn.MAXIFS('SỔ CÔNG NỢ'!$B$5:$B$111,'SỔ CÔNG NỢ'!$A$5:$A$111,$A23,'SỔ CÔNG NỢ'!$B$5:$B$111,"<"&$B23)=0,C23,SUMIFS('SỔ CÔNG NỢ'!$M$5:$M$111,'SỔ CÔNG NỢ'!$A$5:$A$111,$A23,'SỔ CÔNG NỢ'!$B$5:$B$111,_xlfn.MAXIFS('SỔ CÔNG NỢ'!$B$5:$B$111,'SỔ CÔNG NỢ'!$A$5:$A$111,$A23,'SỔ CÔNG NỢ'!$B$5:$B$111,"<"&$B23)))) -> -93701990 | M23: =IF(OR($A23="",$B23=""),"",L23+G23-J23-K23) -> -49231650 | N23: -49231650 | O23: =IF(OR($A23="",$B23="",N23=""),"",N23-M23) -> 0
A24: Cường Hà | B24: 46204 | C24: -49231650 | D24: 19982000 | E24: 11989200 | F24: 60% | G24: =IF(OR($A24="",$B24=""),"",D24-E24) -> 7992800 | H24: 0 | I24: 0 | J24: =IF(OR($A24="",$B24=""),"",H24-I24) -> 0 | K24: =IF(OR($A24="",$B24=""),"",SUMIFS('THANH TOÁN'!$D$5:$D$305,'THANH TOÁN'!$A$5:$A$305,$A24,'THANH TOÁN'!$B$5:$B$305,$B24,'THANH TOÁN'!$E$5:$E$305,"Có")) -> 0 | L24: =IF(OR($A24="",$B24=""),"",IF(_xlfn.MAXIFS('SỔ CÔNG NỢ'!$B$5:$B$111,'SỔ CÔNG NỢ'!$A$5:$A$111,$A24,'SỔ CÔNG NỢ'!$B$5:$B$111,"<"&$B24)=0,C24,SUMIFS('SỔ CÔNG NỢ'!$M$5:$M$111,'SỔ CÔNG NỢ'!$A$5:$A$111,$A24,'SỔ CÔNG NỢ'!$B$5:$B$111,_xlfn.MAXIFS('SỔ CÔNG NỢ'!$B$5:$B$111,'SỔ CÔNG NỢ'!$A$5:$A$111,$A24,'SỔ CÔNG NỢ'!$B$5:$B$111,"<"&$B24)))) -> -49231650 | M24: =IF(OR($A24="",$B24=""),"",L24+G24-J24-K24) -> -41238850 | N24: -41238850 | O24: =IF(OR($A24="",$B24="",N24=""),"",N24-M24) -> 0
A25: Cường Hà | B25: 46235 | C25: -41238850 | D25: 189315350 | E25: 113589210 | F25: 60% | G25: =IF(OR($A25="",$B25=""),"",D25-E25) -> 75726140 | H25: 0 | I25: 0 | J25: =IF(OR($A25="",$B25=""),"",H25-I25) -> 0 | K25: =IF(OR($A25="",$B25=""),"",SUMIFS('THANH TOÁN'!$D$5:$D$305,'THANH TOÁN'!$A$5:$A$305,$A25,'THANH TOÁN'!$B$5:$B$305,$B25,'THANH TOÁN'!$E$5:$E$305,"Có")) -> 30000000 | L25: =IF(OR($A25="",$B25=""),"",IF(_xlfn.MAXIFS('SỔ CÔNG NỢ'!$B$5:$B$111,'SỔ CÔNG NỢ'!$A$5:$A$111,$A25,'SỔ CÔNG NỢ'!$B$5:$B$111,"<"&$B25)=0,C25,SUMIFS('SỔ CÔNG NỢ'!$M$5:$M$111,'SỔ CÔNG NỢ'!$A$5:$A$111,$A25,'SỔ CÔNG NỢ'!$B$5:$B$111,_xlfn.MAXIFS('SỔ CÔNG NỢ'!$B$5:$B$111,'SỔ CÔNG NỢ'!$A$5:$A$111,$A25,'SỔ CÔNG NỢ'!$B$5:$B$111,"<"&$B25)))) -> -41238850 | M25: =IF(OR($A25="",$B25=""),"",L25+G25-J25-K25) -> 4487290 | N25: 4487290 | O25: =IF(OR($A25="",$B25="",N25=""),"",N25-M25) -> 0
A26: Cường Hà | B26: 46266 | C26: 4487290 | D26: 37868000 | E26: 21206080 | F26: 60% | G26: =IF(OR($A26="",$B26=""),"",D26-E26) -> 16661920 | H26: 0 | I26: 0 | J26: =IF(OR($A26="",$B26=""),"",H26-I26) -> 0 | K26: =IF(OR($A26="",$B26=""),"",SUMIFS('THANH TOÁN'!$D$5:$D$305,'THANH TOÁN'!$A$5:$A$305,$A26,'THANH TOÁN'!$B$5:$B$305,$B26,'THANH TOÁN'!$E$5:$E$305,"Có")) -> 0 | L26: =IF(OR($A26="",$B26=""),"",IF(_xlfn.MAXIFS('SỔ CÔNG NỢ'!$B$5:$B$111,'SỔ CÔNG NỢ'!$A$5:$A$111,$A26,'SỔ CÔNG NỢ'!$B$5:$B$111,"<"&$B26)=0,C26,SUMIFS('SỔ CÔNG NỢ'!$M$5:$M$111,'SỔ CÔNG NỢ'!$A$5:$A$111,$A26,'SỔ CÔNG NỢ'!$B$5:$B$111,_xlfn.MAXIFS('SỔ CÔNG NỢ'!$B$5:$B$111,'SỔ CÔNG NỢ'!$A$5:$A$111,$A26,'SỔ CÔNG NỢ'!$B$5:$B$111,"<"&$B26)))) -> 4487290 | M26: =IF(OR($A26="",$B26=""),"",L26+G26-J26-K26) -> 21149210 | N26: 21149210 | O26: =IF(OR($A26="",$B26="",N26=""),"",N26-M26) -> 0
A27: Hiền Xuân | B27: 46204 | C27: 63600 | D27: 83852350 | E27: 51988457 | F27: 62% | G27: =IF(OR($A27="",$B27=""),"",D27-E27) -> 31863893 | H27: 4597000 | I27: 2850140 | J27: =IF(OR($A27="",$B27=""),"",H27-I27) -> 1746860 | K27: =IF(OR($A27="",$B27=""),"",SUMIFS('THANH TOÁN'!$D$5:$D$305,'THANH TOÁN'!$A$5:$A$305,$A27,'THANH TOÁN'!$B$5:$B$305,$B27,'THANH TOÁN'!$E$5:$E$305,"Có")) -> 30060000 | L27: =IF(OR($A27="",$B27=""),"",IF(_xlfn.MAXIFS('SỔ CÔNG NỢ'!$B$5:$B$111,'SỔ CÔNG NỢ'!$A$5:$A$111,$A27,'SỔ CÔNG NỢ'!$B$5:$B$111,"<"&$B27)=0,C27,SUMIFS('SỔ CÔNG NỢ'!$M$5:$M$111,'SỔ CÔNG NỢ'!$A$5:$A$111,$A27,'SỔ CÔNG NỢ'!$B$5:$B$111,_xlfn.MAXIFS('SỔ CÔNG NỢ'!$B$5:$B$111,'SỔ CÔNG NỢ'!$A$5:$A$111,$A27,'SỔ CÔNG NỢ'!$B$5:$B$111,"<"&$B27)))) -> 63600 | M27: =IF(OR($A27="",$B27=""),"",L27+G27-J27-K27) -> 120633 | N27: 120633 | O27: =IF(OR($A27="",$B27="",N27=""),"",N27-M27) -> 0
A28: Hà Liên | B28: 46174 | C28: 890150 | D28: 22971000 | E28: 13782600 | F28: 60% | G28: =IF(OR($A28="",$B28=""),"",D28-E28) -> 9188400 | H28: 0 | I28: 0 | J28: =IF(OR($A28="",$B28=""),"",H28-I28) -> 0 | K28: =IF(OR($A28="",$B28=""),"",SUMIFS('THANH TOÁN'!$D$5:$D$305,'THANH TOÁN'!$A$5:$A$305,$A28,'THANH TOÁN'!$B$5:$B$305,$B28,'THANH TOÁN'!$E$5:$E$305,"Có")) -> 0 | L28: =IF(OR($A28="",$B28=""),"",IF(_xlfn.MAXIFS('SỔ CÔNG NỢ'!$B$5:$B$111,'SỔ CÔNG NỢ'!$A$5:$A$111,$A28,'SỔ CÔNG NỢ'!$B$5:$B$111,"<"&$B28)=0,C28,SUMIFS('SỔ CÔNG NỢ'!$M$5:$M$111,'SỔ CÔNG NỢ'!$A$5:$A$111,$A28,'SỔ CÔNG NỢ'!$B$5:$B$111,_xlfn.MAXIFS('SỔ CÔNG NỢ'!$B$5:$B$111,'SỔ CÔNG NỢ'!$A$5:$A$111,$A28,'SỔ CÔNG NỢ'!$B$5:$B$111,"<"&$B28)))) -> 890150 | M28: =IF(OR($A28="",$B28=""),"",L28+G28-J28-K28) -> 10078550 | N28: 10078550 | O28: =IF(OR($A28="",$B28="",N28=""),"",N28-M28) -> 0
A29: Hà Liên | B29: 46204 | C29: 10078550 | D29: 39225100 | E29: 23535060 | F29: 60% | G29: =IF(OR($A29="",$B29=""),"",D29-E29) -> 15690040 | H29: 0 | I29: 0 | J29: =IF(OR($A29="",$B29=""),"",H29-I29) -> 0 | K29: =IF(OR($A29="",$B29=""),"",SUMIFS('THANH TOÁN'!$D$5:$D$305,'THANH TOÁN'!$A$5:$A$305,$A29,'THANH TOÁN'!$B$5:$B$305,$B29,'THANH TOÁN'!$E$5:$E$305,"Có")) -> 15290000 | L29: =IF(OR($A29="",$B29=""),"",IF(_xlfn.MAXIFS('SỔ CÔNG NỢ'!$B$5:$B$111,'SỔ CÔNG NỢ'!$A$5:$A$111,$A29,'SỔ CÔNG NỢ'!$B$5:$B$111,"<"&$B29)=0,C29,SUMIFS('SỔ CÔNG NỢ'!$M$5:$M$111,'SỔ CÔNG NỢ'!$A$5:$A$111,$A29,'SỔ CÔNG NỢ'!$B$5:$B$111,_xlfn.MAXIFS('SỔ CÔNG NỢ'!$B$5:$B$111,'SỔ CÔNG NỢ'!$A$5:$A$111,$A29,'SỔ CÔNG NỢ'!$B$5:$B$111,"<"&$B29)))) -> 10078550 | M29: =IF(OR($A29="",$B29=""),"",L29+G29-J29-K29) -> 10478590 | N29: 10478590 | O29: =IF(OR($A29="",$B29="",N29=""),"",N29-M29) -> 0
A30: Hà Liên | B30: 46235 | C30: 10478590 | D30: 39165000 | E30: 23499000 | F30: 60% | G30: =IF(OR($A30="",$B30=""),"",D30-E30) -> 15666000 | H30: 0 | I30: 0 | J30: =IF(OR($A30="",$B30=""),"",H30-I30) -> 0 | K30: =IF(OR($A30="",$B30=""),"",SUMIFS('THANH TOÁN'!$D$5:$D$305,'THANH TOÁN'!$A$5:$A$305,$A30,'THANH TOÁN'!$B$5:$B$305,$B30,'THANH TOÁN'!$E$5:$E$305,"Có")) -> 33240000 | L30: =IF(OR($A30="",$B30=""),"",IF(_xlfn.MAXIFS('SỔ CÔNG NỢ'!$B$5:$B$111,'SỔ CÔNG NỢ'!$A$5:$A$111,$A30,'SỔ CÔNG NỢ'!$B$5:$B$111,"<"&$B30)=0,C30,SUMIFS('SỔ CÔNG NỢ'!$M$5:$M$111,'SỔ CÔNG NỢ'!$A$5:$A$111,$A30,'SỔ CÔNG NỢ'!$B$5:$B$111,_xlfn.MAXIFS('SỔ CÔNG NỢ'!$B$5:$B$111,'SỔ CÔNG NỢ'!$A$5:$A$111,$A30,'SỔ CÔNG NỢ'!$B$5:$B$111,"<"&$B30)))) -> 10478590 | M30: =IF(OR($A30="",$B30=""),"",L30+G30-J30-K30) -> -7095410 | N30: -7095410 | O30: =IF(OR($A30="",$B30="",N30=""),"",N30-M30) -> 0
A31: Hà Liên | B31: 46266 | C31: -7095410 | D31: 100434400 | E31: 60260640 | F31: 60% | G31: =IF(OR($A31="",$B31=""),"",D31-E31) -> 40173760 | H31: 0 | I31: 0 | J31: =IF(OR($A31="",$B31=""),"",H31-I31) -> 0 | K31: =IF(OR($A31="",$B31=""),"",SUMIFS('THANH TOÁN'!$D$5:$D$305,'THANH TOÁN'!$A$5:$A$305,$A31,'THANH TOÁN'!$B$5:$B$305,$B31,'THANH TOÁN'!$E$5:$E$305,"Có")) -> 0 | L31: =IF(OR($A31="",$B31=""),"",IF(_xlfn.MAXIFS('SỔ CÔNG NỢ'!$B$5:$B$111,'SỔ CÔNG NỢ'!$A$5:$A$111,$A31,'SỔ CÔNG NỢ'!$B$5:$B$111,"<"&$B31)=0,C31,SUMIFS('SỔ CÔNG NỢ'!$M$5:$M$111,'SỔ CÔNG NỢ'!$A$5:$A$111,$A31,'SỔ CÔNG NỢ'!$B$5:$B$111,_xlfn.MAXIFS('SỔ CÔNG NỢ'!$B$5:$B$111,'SỔ CÔNG NỢ'!$A$5:$A$111,$A31,'SỔ CÔNG NỢ'!$B$5:$B$111,"<"&$B31)))) -> -7095410 | M31: =IF(OR($A31="",$B31=""),"",L31+G31-J31-K31) -> 33078350 | N31: 33078350 | O31: =IF(OR($A31="",$B31="",N31=""),"",N31-M31) -> 0
A32: Hòa Hiệp | B32: 46174 | C32: 0 | D32: 3750000 | E32: 2362500 | F32: 63% | G32: =IF(OR($A32="",$B32=""),"",D32-E32) -> 1387500 | H32: 0 | I32: 0 | J32: =IF(OR($A32="",$B32=""),"",H32-I32) -> 0 | K32: =IF(OR($A32="",$B32=""),"",SUMIFS('THANH TOÁN'!$D$5:$D$305,'THANH TOÁN'!$A$5:$A$305,$A32,'THANH TOÁN'!$B$5:$B$305,$B32,'THANH TOÁN'!$E$5:$E$305,"Có")) -> 1500000 | L32: =IF(OR($A32="",$B32=""),"",IF(_xlfn.MAXIFS('SỔ CÔNG NỢ'!$B$5:$B$111,'SỔ CÔNG NỢ'!$A$5:$A$111,$A32,'SỔ CÔNG NỢ'!$B$5:$B$111,"<"&$B32)=0,C32,SUMIFS('SỔ CÔNG NỢ'!$M$5:$M$111,'SỔ CÔNG NỢ'!$A$5:$A$111,$A32,'SỔ CÔNG NỢ'!$B$5:$B$111,_xlfn.MAXIFS('SỔ CÔNG NỢ'!$B$5:$B$111,'SỔ CÔNG NỢ'!$A$5:$A$111,$A32,'SỔ CÔNG NỢ'!$B$5:$B$111,"<"&$B32)))) -> 0 | M32: =IF(OR($A32="",$B32=""),"",L32+G32-J32-K32) -> -112500 | N32: -112500 | O32: =IF(OR($A32="",$B32="",N32=""),"",N32-M32) -> 0
A33: Nghị Hậu | B33: 46174 | C33: 33678000 | D33: 75055500 | E33: 47284965 | F33: 63% | G33: =IF(OR($A33="",$B33=""),"",D33-E33) -> 27770535 | H33: 0 | I33: 0 | J33: =IF(OR($A33="",$B33=""),"",H33-I33) -> 0 | K33: =IF(OR($A33="",$B33=""),"",SUMIFS('THANH TOÁN'!$D$5:$D$305,'THANH TOÁN'!$A$5:$A$305,$A33,'THANH TOÁN'!$B$5:$B$305,$B33,'THANH TOÁN'!$E$5:$E$305,"Có")) -> 28000000 | L33: =IF(OR($A33="",$B33=""),"",IF(_xlfn.MAXIFS('SỔ CÔNG NỢ'!$B$5:$B$111,'SỔ CÔNG NỢ'!$A$5:$A$111,$A33,'SỔ CÔNG NỢ'!$B$5:$B$111,"<"&$B33)=0,C33,SUMIFS('SỔ CÔNG NỢ'!$M$5:$M$111,'SỔ CÔNG NỢ'!$A$5:$A$111,$A33,'SỔ CÔNG NỢ'!$B$5:$B$111,_xlfn.MAXIFS('SỔ CÔNG NỢ'!$B$5:$B$111,'SỔ CÔNG NỢ'!$A$5:$A$111,$A33,'SỔ CÔNG NỢ'!$B$5:$B$111,"<"&$B33)))) -> 33678000 | M33: =IF(OR($A33="",$B33=""),"",L33+G33-J33-K33) -> 33448535 | N33: 33448535 | O33: =IF(OR($A33="",$B33="",N33=""),"",N33-M33) -> 0
A34: Quân Sen | B34: 46174 | C34: 11687706 | D34: 49288900 | E34: 31052007 | F34: 63% | G34: =IF(OR($A34="",$B34=""),"",D34-E34) -> 18236893 | H34: 0 | I34: 0 | J34: =IF(OR($A34="",$B34=""),"",H34-I34) -> 0 | K34: =IF(OR($A34="",$B34=""),"",SUMIFS('THANH TOÁN'!$D$5:$D$305,'THANH TOÁN'!$A$5:$A$305,$A34,'THANH TOÁN'!$B$5:$B$305,$B34,'THANH TOÁN'!$E$5:$E$305,"Có")) -> 17100000 | L34: =IF(OR($A34="",$B34=""),"",IF(_xlfn.MAXIFS('SỔ CÔNG NỢ'!$B$5:$B$111,'SỔ CÔNG NỢ'!$A$5:$A$111,$A34,'SỔ CÔNG NỢ'!$B$5:$B$111,"<"&$B34)=0,C34,SUMIFS('SỔ CÔNG NỢ'!$M$5:$M$111,'SỔ CÔNG NỢ'!$A$5:$A$111,$A34,'SỔ CÔNG NỢ'!$B$5:$B$111,_xlfn.MAXIFS('SỔ CÔNG NỢ'!$B$5:$B$111,'SỔ CÔNG NỢ'!$A$5:$A$111,$A34,'SỔ CÔNG NỢ'!$B$5:$B$111,"<"&$B34)))) -> 11687706 | M34: =IF(OR($A34="",$B34=""),"",L34+G34-J34-K34) -> 12824599 | N34: 12824599 | O34: =IF(OR($A34="",$B34="",N34=""),"",N34-M34) -> 0
