Workbook

Sheet TỔNG QUAN
A1: ĐƯA KHO THỰC TẾ VÀ KHO HÓA ĐƠN VỀ MỘT KHO
A2: Kho thực tế: kiểm kê 09/10/2026. Kho hóa đơn: phần mềm Tổng hợp tồn kho 01/01–10/10/2026. Tồn thống nhất = số nhỏ hơn của hai kho.
A4: MẶT HÀNG ĐỐI CHIẾU | D4: KHỚP | G4: THỰC TẾ NHIỀU HƠN HĐ | J4: HĐ NHIỀU HƠN THỰC TẾ
A5: =COUNTA('ĐỐI CHIẾU'!$C$5:$C$71) -> 67 | D5: =COUNTIF('ĐỐI CHIẾU'!$M$5:$M$71,"Khớp") -> 3 | G5: =COUNTIF('ĐỐI CHIẾU'!$M$5:$M$71,"Thực*") -> 12 | J5: =COUNTIF('ĐỐI CHIẾU'!$M$5:$M$71,"HĐ*") -> 52
A7: ▶ THEO DUNG TÍCH
A8: Dung tích | C8: Kho thực tế | D8: Kho hóa đơn | E8: Chênh lệch (TT − HĐ) | F8: Xuất từ kho thực tế | G8: Xuất từ kho hóa đơn | H8: Tồn thống nhất
A9: 18L | C9: =SUMIFS('ĐỐI CHIẾU'!$J$5:$J$71,'ĐỐI CHIẾU'!$E$5:$E$71,$A9) -> 1272 | D9: =SUMIFS('ĐỐI CHIẾU'!$K$5:$K$71,'ĐỐI CHIẾU'!$E$5:$E$71,$A9) -> 2807 | E9: =SUMIFS('ĐỐI CHIẾU'!$L$5:$L$71,'ĐỐI CHIẾU'!$E$5:$E$71,$A9) -> -1535 | F9: =SUMIFS('ĐỐI CHIẾU'!$N$5:$N$71,'ĐỐI CHIẾU'!$E$5:$E$71,$A9) -> 172 | G9: =SUMIFS('ĐỐI CHIẾU'!$O$5:$O$71,'ĐỐI CHIẾU'!$E$5:$E$71,$A9) -> 1707 | H9: =SUMIFS('ĐỐI CHIẾU'!$R$5:$R$71,'ĐỐI CHIẾU'!$E$5:$E$71,$A9) -> 1100
A10: 5L | C10: =SUMIFS('ĐỐI CHIẾU'!$J$5:$J$71,'ĐỐI CHIẾU'!$E$5:$E$71,$A10) -> 761 | D10: =SUMIFS('ĐỐI CHIẾU'!$K$5:$K$71,'ĐỐI CHIẾU'!$E$5:$E$71,$A10) -> 1524 | E10: =SUMIFS('ĐỐI CHIẾU'!$L$5:$L$71,'ĐỐI CHIẾU'!$E$5:$E$71,$A10) -> -763 | F10: =SUMIFS('ĐỐI CHIẾU'!$N$5:$N$71,'ĐỐI CHIẾU'!$E$5:$E$71,$A10) -> 53 | G10: =SUMIFS('ĐỐI CHIẾU'!$O$5:$O$71,'ĐỐI CHIẾU'!$E$5:$E$71,$A10) -> 816 | H10: =SUMIFS('ĐỐI CHIẾU'!$R$5:$R$71,'ĐỐI CHIẾU'!$E$5:$E$71,$A10) -> 708
A11: 1L | C11: =SUMIFS('ĐỐI CHIẾU'!$J$5:$J$71,'ĐỐI CHIẾU'!$E$5:$E$71,$A11) -> 350 | D11: =SUMIFS('ĐỐI CHIẾU'!$K$5:$K$71,'ĐỐI CHIẾU'!$E$5:$E$71,$A11) -> 740 | E11: =SUMIFS('ĐỐI CHIẾU'!$L$5:$L$71,'ĐỐI CHIẾU'!$E$5:$E$71,$A11) -> -390 | F11: =SUMIFS('ĐỐI CHIẾU'!$N$5:$N$71,'ĐỐI CHIẾU'!$E$5:$E$71,$A11) -> 15 | G11: =SUMIFS('ĐỐI CHIẾU'!$O$5:$O$71,'ĐỐI CHIẾU'!$E$5:$E$71,$A11) -> 405 | H11: =SUMIFS('ĐỐI CHIẾU'!$R$5:$R$71,'ĐỐI CHIẾU'!$E$5:$E$71,$A11) -> 335
A12: Bao | C12: =SUMIFS('ĐỐI CHIẾU'!$J$5:$J$71,'ĐỐI CHIẾU'!$E$5:$E$71,$A12) -> 29 | D12: =SUMIFS('ĐỐI CHIẾU'!$K$5:$K$71,'ĐỐI CHIẾU'!$E$5:$E$71,$A12) -> 256 | E12: =SUMIFS('ĐỐI CHIẾU'!$L$5:$L$71,'ĐỐI CHIẾU'!$E$5:$E$71,$A12) -> -227 | F12: =SUMIFS('ĐỐI CHIẾU'!$N$5:$N$71,'ĐỐI CHIẾU'!$E$5:$E$71,$A12) -> 0 | G12: =SUMIFS('ĐỐI CHIẾU'!$O$5:$O$71,'ĐỐI CHIẾU'!$E$5:$E$71,$A12) -> 227 | H12: =SUMIFS('ĐỐI CHIẾU'!$R$5:$R$71,'ĐỐI CHIẾU'!$E$5:$E$71,$A12) -> 29
A13: 5kg | C13: =SUMIFS('ĐỐI CHIẾU'!$J$5:$J$71,'ĐỐI CHIẾU'!$E$5:$E$71,$A13) -> 0 | D13: =SUMIFS('ĐỐI CHIẾU'!$K$5:$K$71,'ĐỐI CHIẾU'!$E$5:$E$71,$A13) -> 32 | E13: =SUMIFS('ĐỐI CHIẾU'!$L$5:$L$71,'ĐỐI CHIẾU'!$E$5:$E$71,$A13) -> -32 | F13: =SUMIFS('ĐỐI CHIẾU'!$N$5:$N$71,'ĐỐI CHIẾU'!$E$5:$E$71,$A13) -> 0 | G13: =SUMIFS('ĐỐI CHIẾU'!$O$5:$O$71,'ĐỐI CHIẾU'!$E$5:$E$71,$A13) -> 32 | H13: =SUMIFS('ĐỐI CHIẾU'!$R$5:$R$71,'ĐỐI CHIẾU'!$E$5:$E$71,$A13) -> 0
A14: Tổng (tham khảo) | C14: =SUM(C9:C13) -> 2412 | D14: =SUM(D9:D13) -> 5359 | E14: =SUM(E9:E13) -> -2947 | F14: =SUM(F9:F13) -> 240 | G14: =SUM(G9:G13) -> 3187 | H14: =SUM(H9:H13) -> 2172
A16: ▶ GIÁ TRỊ (theo đơn giá bình quân phần mềm)
A17: Giá trị xuất từ kho thực tế (thực tế > HĐ) | F17: =SUMPRODUCT('ĐỐI CHIẾU'!$N$5:$N$71,'ĐỐI CHIẾU'!$P$5:$P$71) -> 282824551
A18: Giá trị xuất từ kho hóa đơn (HĐ > thực tế) | F18: =SUMPRODUCT('ĐỐI CHIẾU'!$O$5:$O$71,'ĐỐI CHIẾU'!$P$5:$P$71) -> 1869998922
A19: Giá trị tồn kho thống nhất | F19: =SUM('ĐỐI CHIẾU'!$S$5:$S$71) -> 1685777008
A21: ▶ 10 MẶT HÀNG LỆCH NHIỀU NHẤT (theo số lượng)
A22: # | B22: Mã SP | C22: Dung tích | D22: Base | E22: Kho thực tế | F22: Kho hóa đơn | G22: Chênh lệch | H22: Kết luận
A23: 1 | B23: =IF($J23="","",IF(INDEX('ĐỐI CHIẾU'!$C$5:$C$71,$J23)="","",INDEX('ĐỐI CHIẾU'!$C$5:$C$71,$J23))) -> DECO | C23: =IF($J23="","",IF(INDEX('ĐỐI CHIẾU'!$E$5:$E$71,$J23)="","",INDEX('ĐỐI CHIẾU'!$E$5:$E$71,$J23))) -> 18L | D23: =IF($J23="","",IF(INDEX('ĐỐI CHIẾU'!$F$5:$F$71,$J23)="","",INDEX('ĐỐI CHIẾU'!$F$5:$F$71,$J23))) -> B1 | E23: =IF($J23="","",IF(INDEX('ĐỐI CHIẾU'!$J$5:$J$71,$J23)="","",INDEX('ĐỐI CHIẾU'!$J$5:$J$71,$J23))) -> 61 | F23: =IF($J23="","",IF(INDEX('ĐỐI CHIẾU'!$K$5:$K$71,$J23)="","",INDEX('ĐỐI CHIẾU'!$K$5:$K$71,$J23))) -> 724 | G23: =IF($J23="","",IF(INDEX('ĐỐI CHIẾU'!$L$5:$L$71,$J23)="","",INDEX('ĐỐI CHIẾU'!$L$5:$L$71,$J23))) -> -663 | H23: =IF($J23="","",IF(INDEX('ĐỐI CHIẾU'!$M$5:$M$71,$J23)="","",INDEX('ĐỐI CHIẾU'!$M$5:$M$71,$J23))) -> HĐ nhiều hơn thực tế | J23: =IFERROR(MATCH(LARGE('ĐỐI CHIẾU'!$T$5:$T$71,A23),'ĐỐI CHIẾU'!$T$5:$T$71,0),"") -> 23
A24: 2 | B24: =IF($J24="","",IF(INDEX('ĐỐI CHIẾU'!$C$5:$C$71,$J24)="","",INDEX('ĐỐI CHIẾU'!$C$5:$C$71,$J24))) -> IL5 | C24: =IF($J24="","",IF(INDEX('ĐỐI CHIẾU'!$E$5:$E$71,$J24)="","",INDEX('ĐỐI CHIẾU'!$E$5:$E$71,$J24))) -> 18L | D24: =IF($J24="","",IF(INDEX('ĐỐI CHIẾU'!$F$5:$F$71,$J24)="","",INDEX('ĐỐI CHIẾU'!$F$5:$F$71,$J24))) | E24: =IF($J24="","",IF(INDEX('ĐỐI CHIẾU'!$J$5:$J$71,$J24)="","",INDEX('ĐỐI CHIẾU'!$J$5:$J$71,$J24))) -> 52 | F24: =IF($J24="","",IF(INDEX('ĐỐI CHIẾU'!$K$5:$K$71,$J24)="","",INDEX('ĐỐI CHIẾU'!$K$5:$K$71,$J24))) -> 316 | G24: =IF($J24="","",IF(INDEX('ĐỐI CHIẾU'!$L$5:$L$71,$J24)="","",INDEX('ĐỐI CHIẾU'!$L$5:$L$71,$J24))) -> -264 | H24: =IF($J24="","",IF(INDEX('ĐỐI CHIẾU'!$M$5:$M$71,$J24)="","",INDEX('ĐỐI CHIẾU'!$M$5:$M$71,$J24))) -> HĐ nhiều hơn thực tế | J24: =IFERROR(MATCH(LARGE('ĐỐI CHIẾU'!$T$5:$T$71,A24),'ĐỐI CHIẾU'!$T$5:$T$71,0),"") -> 10
A25: 3 | B25: =IF($J25="","",IF(INDEX('ĐỐI CHIẾU'!$C$5:$C$71,$J25)="","",INDEX('ĐỐI CHIẾU'!$C$5:$C$71,$J25))) -> EG09 | C25: =IF($J25="","",IF(INDEX('ĐỐI CHIẾU'!$E$5:$E$71,$J25)="","",INDEX('ĐỐI CHIẾU'!$E$5:$E$71,$J25))) -> 18L | D25: =IF($J25="","",IF(INDEX('ĐỐI CHIẾU'!$F$5:$F$71,$J25)="","",INDEX('ĐỐI CHIẾU'!$F$5:$F$71,$J25))) -> B1 | E25: =IF($J25="","",IF(INDEX('ĐỐI CHIẾU'!$J$5:$J$71,$J25)="","",INDEX('ĐỐI CHIẾU'!$J$5:$J$71,$J25))) -> 218 | F25: =IF($J25="","",IF(INDEX('ĐỐI CHIẾU'!$K$5:$K$71,$J25)="","",INDEX('ĐỐI CHIẾU'!$K$5:$K$71,$J25))) -> 50 | G25: =IF($J25="","",IF(INDEX('ĐỐI CHIẾU'!$L$5:$L$71,$J25)="","",INDEX('ĐỐI CHIẾU'!$L$5:$L$71,$J25))) -> 168 | H25: =IF($J25="","",IF(INDEX('ĐỐI CHIẾU'!$M$5:$M$71,$J25)="","",INDEX('ĐỐI CHIẾU'!$M$5:$M$71,$J25))) -> Thực tế nhiều hơn HĐ | J25: =IFERROR(MATCH(LARGE('ĐỐI CHIẾU'!$T$5:$T$71,A25),'ĐỐI CHIẾU'!$T$5:$T$71,0),"") -> 45
A26: 4 | B26: =IF($J26="","",IF(INDEX('ĐỐI CHIẾU'!$C$5:$C$71,$J26)="","",INDEX('ĐỐI CHIẾU'!$C$5:$C$71,$J26))) -> ISI | C26: =IF($J26="","",IF(INDEX('ĐỐI CHIẾU'!$E$5:$E$71,$J26)="","",INDEX('ĐỐI CHIẾU'!$E$5:$E$71,$J26))) -> 18L | D26: =IF($J26="","",IF(INDEX('ĐỐI CHIẾU'!$F$5:$F$71,$J26)="","",INDEX('ĐỐI CHIẾU'!$F$5:$F$71,$J26))) -> B1 | E26: =IF($J26="","",IF(INDEX('ĐỐI CHIẾU'!$J$5:$J$71,$J26)="","",INDEX('ĐỐI CHIẾU'!$J$5:$J$71,$J26))) -> 57 | F26: =IF($J26="","",IF(INDEX('ĐỐI CHIẾU'!$K$5:$K$71,$J26)="","",INDEX('ĐỐI CHIẾU'!$K$5:$K$71,$J26))) -> 202 | G26: =IF($J26="","",IF(INDEX('ĐỐI CHIẾU'!$L$5:$L$71,$J26)="","",INDEX('ĐỐI CHIẾU'!$L$5:$L$71,$J26))) -> -145 | H26: =IF($J26="","",IF(INDEX('ĐỐI CHIẾU'!$M$5:$M$71,$J26)="","",INDEX('ĐỐI CHIẾU'!$M$5:$M$71,$J26))) -> HĐ nhiều hơn thực tế | J26: =IFERROR(MATCH(LARGE('ĐỐI CHIẾU'!$T$5:$T$71,A26),'ĐỐI CHIẾU'!$T$5:$T$71,0),"") -> 16
A27: 5 | B27: =IF($J27="","",IF(INDEX('ĐỐI CHIẾU'!$C$5:$C$71,$J27)="","",INDEX('ĐỐI CHIẾU'!$C$5:$C$71,$J27))) -> ISG06 | C27: =IF($J27="","",IF(INDEX('ĐỐI CHIẾU'!$E$5:$E$71,$J27)="","",INDEX('ĐỐI CHIẾU'!$E$5:$E$71,$J27))) -> 18L | D27: =IF($J27="","",IF(INDEX('ĐỐI CHIẾU'!$F$5:$F$71,$J27)="","",INDEX('ĐỐI CHIẾU'!$F$5:$F$71,$J27))) -> B1 | E27: =IF($J27="","",IF(INDEX('ĐỐI CHIẾU'!$J$5:$J$71,$J27)="","",INDEX('ĐỐI CHIẾU'!$J$5:$J$71,$J27))) -> 53 | F27: =IF($J27="","",IF(INDEX('ĐỐI CHIẾU'!$K$5:$K$71,$J27)="","",INDEX('ĐỐI CHIẾU'!$K$5:$K$71,$J27))) -> 172 | G27: =IF($J27="","",IF(INDEX('ĐỐI CHIẾU'!$L$5:$L$71,$J27)="","",INDEX('ĐỐI CHIẾU'!$L$5:$L$71,$J27))) -> -119 | H27: =IF($J27="","",IF(INDEX('ĐỐI CHIẾU'!$M$5:$M$71,$J27)="","",INDEX('ĐỐI CHIẾU'!$M$5:$M$71,$J27))) -> HĐ nhiều hơn thực tế | J27: =IFERROR(MATCH(LARGE('ĐỐI CHIẾU'!$T$5:$T$71,A27),'ĐỐI CHIẾU'!$T$5:$T$71,0),"") -> 18
A28: 6 | B28: =IF($J28="","",IF(INDEX('ĐỐI CHIẾU'!$C$5:$C$71,$J28)="","",INDEX('ĐỐI CHIẾU'!$C$5:$C$71,$J28))) -> ICL | C28: =IF($J28="","",IF(INDEX('ĐỐI CHIẾU'!$E$5:$E$71,$J28)="","",INDEX('ĐỐI CHIẾU'!$E$5:$E$71,$J28))) -> 1L | D28: =IF($J28="","",IF(INDEX('ĐỐI CHIẾU'!$F$5:$F$71,$J28)="","",INDEX('ĐỐI CHIẾU'!$F$5:$F$71,$J28))) | E28: =IF($J28="","",IF(INDEX('ĐỐI CHIẾU'!$J$5:$J$71,$J28)="","",INDEX('ĐỐI CHIẾU'!$J$5:$J$71,$J28))) -> 18 | F28: =IF($J28="","",IF(INDEX('ĐỐI CHIẾU'!$K$5:$K$71,$J28)="","",INDEX('ĐỐI CHIẾU'!$K$5:$K$71,$J28))) -> 120 | G28: =IF($J28="","",IF(INDEX('ĐỐI CHIẾU'!$L$5:$L$71,$J28)="","",INDEX('ĐỐI CHIẾU'!$L$5:$L$71,$J28))) -> -102 | H28: =IF($J28="","",IF(INDEX('ĐỐI CHIẾU'!$M$5:$M$71,$J28)="","",INDEX('ĐỐI CHIẾU'!$M$5:$M$71,$J28))) -> HĐ nhiều hơn thực tế | J28: =IFERROR(MATCH(LARGE('ĐỐI CHIẾU'!$T$5:$T$71,A28),'ĐỐI CHIẾU'!$T$5:$T$71,0),"") -> 24
A29: 7 | B29: =IF($J29="","",IF(INDEX('ĐỐI CHIẾU'!$C$5:$C$71,$J29)="","",INDEX('ĐỐI CHIẾU'!$C$5:$C$71,$J29))) -> IEW | C29: =IF($J29="","",IF(INDEX('ĐỐI CHIẾU'!$E$5:$E$71,$J29)="","",INDEX('ĐỐI CHIẾU'!$E$5:$E$71,$J29))) -> 18L | D29: =IF($J29="","",IF(INDEX('ĐỐI CHIẾU'!$F$5:$F$71,$J29)="","",INDEX('ĐỐI CHIẾU'!$F$5:$F$71,$J29))) | E29: =IF($J29="","",IF(INDEX('ĐỐI CHIẾU'!$J$5:$J$71,$J29)="","",INDEX('ĐỐI CHIẾU'!$J$5:$J$71,$J29))) -> 1 | F29: =IF($J29="","",IF(INDEX('ĐỐI CHIẾU'!$K$5:$K$71,$J29)="","",INDEX('ĐỐI CHIẾU'!$K$5:$K$71,$J29))) -> 99 | G29: =IF($J29="","",IF(INDEX('ĐỐI CHIẾU'!$L$5:$L$71,$J29)="","",INDEX('ĐỐI CHIẾU'!$L$5:$L$71,$J29))) -> -98 | H29: =IF($J29="","",IF(INDEX('ĐỐI CHIẾU'!$M$5:$M$71,$J29)="","",INDEX('ĐỐI CHIẾU'!$M$5:$M$71,$J29))) -> HĐ nhiều hơn thực tế | J29: =IFERROR(MATCH(LARGE('ĐỐI CHIẾU'!$T$5:$T$71,A29),'ĐỐI CHIẾU'!$T$5:$T$71,0),"") -> 14
A30: 8 | B30: =IF($J30="","",IF(INDEX('ĐỐI CHIẾU'!$C$5:$C$71,$J30)="","",INDEX('ĐỐI CHIẾU'!$C$5:$C$71,$J30))) -> CTS | C30: =IF($J30="","",IF(INDEX('ĐỐI CHIẾU'!$E$5:$E$71,$J30)="","",INDEX('ĐỐI CHIẾU'!$E$5:$E$71,$J30))) -> 18L | D30: =IF($J30="","",IF(INDEX('ĐỐI CHIẾU'!$F$5:$F$71,$J30)="","",INDEX('ĐỐI CHIẾU'!$F$5:$F$71,$J30))) | E30: =IF($J30="","",IF(INDEX('ĐỐI CHIẾU'!$J$5:$J$71,$J30)="","",INDEX('ĐỐI CHIẾU'!$J$5:$J$71,$J30))) -> 4 | F30: =IF($J30="","",IF(INDEX('ĐỐI CHIẾU'!$K$5:$K$71,$J30)="","",INDEX('ĐỐI CHIẾU'!$K$5:$K$71,$J30))) -> 101 | G30: =IF($J30="","",IF(INDEX('ĐỐI CHIẾU'!$L$5:$L$71,$J30)="","",INDEX('ĐỐI CHIẾU'!$L$5:$L$71,$J30))) -> -97 | H30: =IF($J30="","",IF(INDEX('ĐỐI CHIẾU'!$M$5:$M$71,$J30)="","",INDEX('ĐỐI CHIẾU'!$M$5:$M$71,$J30))) -> HĐ nhiều hơn thực tế | J30: =IFERROR(MATCH(LARGE('ĐỐI CHIẾU'!$T$5:$T$71,A30),'ĐỐI CHIẾU'!$T$5:$T$71,0),"") -> 62
A31: 9 | B31: =IF($J31="","",IF(INDEX('ĐỐI CHIẾU'!$C$5:$C$71,$J31)="","",INDEX('ĐỐI CHIẾU'!$C$5:$C$71,$J31))) -> BA-NOI | C31: =IF($J31="","",IF(INDEX('ĐỐI CHIẾU'!$E$5:$E$71,$J31)="","",INDEX('ĐỐI CHIẾU'!$E$5:$E$71,$J31))) -> Bao | D31: =IF($J31="","",IF(INDEX('ĐỐI CHIẾU'!$F$5:$F$71,$J31)="","",INDEX('ĐỐI CHIẾU'!$F$5:$F$71,$J31))) | E31: =IF($J31="","",IF(INDEX('ĐỐI CHIẾU'!$J$5:$J$71,$J31)="","",INDEX('ĐỐI CHIẾU'!$J$5:$J$71,$J31))) -> 0 | F31: =IF($J31="","",IF(INDEX('ĐỐI CHIẾU'!$K$5:$K$71,$J31)="","",INDEX('ĐỐI CHIẾU'!$K$5:$K$71,$J31))) -> 85 | G31: =IF($J31="","",IF(INDEX('ĐỐI CHIẾU'!$L$5:$L$71,$J31)="","",INDEX('ĐỐI CHIẾU'!$L$5:$L$71,$J31))) -> -85 | H31: =IF($J31="","",IF(INDEX('ĐỐI CHIẾU'!$M$5:$M$71,$J31)="","",INDEX('ĐỐI CHIẾU'!$M$5:$M$71,$J31))) -> HĐ nhiều hơn thực tế | J31: =IFERROR(MATCH(LARGE('ĐỐI CHIẾU'!$T$5:$T$71,A31),'ĐỐI CHIẾU'!$T$5:$T$71,0),"") -> 65
A32: 10 | B32: =IF($J32="","",IF(INDEX('ĐỐI CHIẾU'!$C$5:$C$71,$J32)="","",INDEX('ĐỐI CHIẾU'!$C$5:$C$71,$J32))) -> ISG06 | C32: =IF($J32="","",IF(INDEX('ĐỐI CHIẾU'!$E$5:$E$71,$J32)="","",INDEX('ĐỐI CHIẾU'!$E$5:$E$71,$J32))) -> 5L | D32: =IF($J32="","",IF(INDEX('ĐỐI CHIẾU'!$F$5:$F$71,$J32)="","",INDEX('ĐỐI CHIẾU'!$F$5:$F$71,$J32))) -> B1 | E32: =IF($J32="","",IF(INDEX('ĐỐI CHIẾU'!$J$5:$J$71,$J32)="","",INDEX('ĐỐI CHIẾU'!$J$5:$J$71,$J32))) -> 26 | F32: =IF($J32="","",IF(INDEX('ĐỐI CHIẾU'!$K$5:$K$71,$J32)="","",INDEX('ĐỐI CHIẾU'!$K$5:$K$71,$J32))) -> 108 | G32: =IF($J32="","",IF(INDEX('ĐỐI CHIẾU'!$L$5:$L$71,$J32)="","",INDEX('ĐỐI CHIẾU'!$L$5:$L$71,$J32))) -> -82 | H32: =IF($J32="","",IF(INDEX('ĐỐI CHIẾU'!$M$5:$M$71,$J32)="","",INDEX('ĐỐI CHIẾU'!$M$5:$M$71,$J32))) -> HĐ nhiều hơn thực tế | J32: =IFERROR(MATCH(LARGE('ĐỐI CHIẾU'!$T$5:$T$71,A32),'ĐỐI CHIẾU'!$T$5:$T$71,0),"") -> 17

Sheet ĐỐI CHIẾU
A1: ĐỐI CHIẾU KHO THỰC TẾ (kiểm kê 09/10/2026) VÀ KHO THEO HÓA ĐƠN (phần mềm, đến 10/10/2026)
A2: Tồn thống nhất = số nhỏ hơn của hai kho; bên nào nhiều hơn thì xuất phần chênh để hai kho bằng nhau. Cột vàng = số lấy từ 2 file chị gửi.
A4: STT | B4: Nhóm | C4: Mã SP | D4: Tên hàng hoá | E4: Dung tích | F4: Base | G4: Mã trên phần mềm | H4: Thực tế tại nhà | I4: Thực tế tại Việt | J4: KHO THỰC TẾ | K4: KHO HÓA ĐƠN | L4: Chênh lệch (TT − HĐ) | M4: Kết luận | N4: Xuất từ kho THỰC TẾ | O4: Xuất từ kho HÓA ĐƠN | P4: Đơn giá BQ (phần mềm) | Q4: Giá trị xuất (VNĐ) | R4: TỒN THỐNG NHẤT | S4: Giá trị tồn thống nhất | T4: (hỗ trợ) | U4: Ghi chú
A5: 1 | B5: Sơn lót | C5: PI04 | D5: Sơn lót nội thất kháng kiềm cao cấp Imperia PI04 | E5: 5L | H5: 2 | J5: 2 | K5: 0 | L5: =J5-K5 -> 2 | M5: =IF(L5>0,"Thực tế nhiều hơn HĐ",IF(L5<0,"HĐ nhiều hơn thực tế","Khớp")) -> Thực tế nhiều hơn HĐ | N5: =MAX(L5,0) -> 2 | O5: =MAX(-L5,0) -> 0 | Q5: =IF(P5="","",(N5+O5)*P5) | R5: =MIN(J5,K5) -> 0 | S5: =IF(P5="","",R5*P5) | T5: =IF(L5=0,"",ABS(L5)+ROW()/100000) -> 2.00005 | U5: Không có trong phần mềm (hóa đơn); Chưa có đơn giá vốn
A6: 2 | B6: Sơn lót | C6: PI04 | D6: Sơn lót nội thất kháng kiềm cao cấp Imperia PI04 | E6: 18L | G6: PI04 18L | H6: 118 | I6: 89 | J6: 207 | K6: 221 | L6: =J6-K6 -> -14 | M6: =IF(L6>0,"Thực tế nhiều hơn HĐ",IF(L6<0,"HĐ nhiều hơn thực tế","Khớp")) -> HĐ nhiều hơn thực tế | N6: =MAX(L6,0) -> 0 | O6: =MAX(-L6,0) -> 14 | P6: 947240 | Q6: =IF(P6="","",(N6+O6)*P6) -> 13261360 | R6: =MIN(J6,K6) -> 207 | S6: =IF(P6="","",R6*P6) -> 196078680 | T6: =IF(L6=0,"",ABS(L6)+ROW()/100000) -> 14.00006
A7: 3 | B7: Sơn lót | C7: PE02 | D7: Sơn lót ngoại thất kháng kiềm cao cấp Imperia PE02 | E7: 5L | G7: PE02 05L 00 | J7: 0 | K7: 60 | L7: =J7-K7 -> -60 | M7: =IF(L7>0,"Thực tế nhiều hơn HĐ",IF(L7<0,"HĐ nhiều hơn thực tế","Khớp")) -> HĐ nhiều hơn thực tế | N7: =MAX(L7,0) -> 0 | O7: =MAX(-L7,0) -> 60 | P7: 420746 | Q7: =IF(P7="","",(N7+O7)*P7) -> 25244760 | R7: =MIN(J7,K7) -> 0 | S7: =IF(P7="","",R7*P7) -> 0 | T7: =IF(L7=0,"",ABS(L7)+ROW()/100000) -> 60.00007
A8: 4 | B8: Sơn lót | C8: PE02 | D8: Sơn lót ngoại thất kháng kiềm cao cấp Imperia PE02 | E8: 18L | G8: PE02 18L | H8: 187 | I8: 30 | J8: 217 | K8: 240 | L8: =J8-K8 -> -23 | M8: =IF(L8>0,"Thực tế nhiều hơn HĐ",IF(L8<0,"HĐ nhiều hơn thực tế","Khớp")) -> HĐ nhiều hơn thực tế | N8: =MAX(L8,0) -> 0 | O8: =MAX(-L8,0) -> 23 | P8: 1163020 | Q8: =IF(P8="","",(N8+O8)*P8) -> 26749460 | R8: =MIN(J8,K8) -> 217 | S8: =IF(P8="","",R8*P8) -> 252375340 | T8: =IF(L8=0,"",ABS(L8)+ROW()/100000) -> 23.00008
A9: 5 | B9: Sơn lót | C9: SPI03 | D9: Sơn lót nội thất kháng kiềm siêu cao cấp SPI03 | E9: 5L | H9: 7 | J9: 7 | K9: 0 | L9: =J9-K9 -> 7 | M9: =IF(L9>0,"Thực tế nhiều hơn HĐ",IF(L9<0,"HĐ nhiều hơn thực tế","Khớp")) -> Thực tế nhiều hơn HĐ | N9: =MAX(L9,0) -> 7 | O9: =MAX(-L9,0) -> 0 | Q9: =IF(P9="","",(N9+O9)*P9) | R9: =MIN(J9,K9) -> 0 | S9: =IF(P9="","",R9*P9) | T9: =IF(L9=0,"",ABS(L9)+ROW()/100000) -> 7.00009 | U9: Không có trong phần mềm (hóa đơn); Chưa có đơn giá vốn
A10: 6 | B10: Sơn lót | C10: SPI03 | D10: Sơn lót nội thất kháng kiềm siêu cao cấp SPI03 | E10: 18L | G10: IMP-SPI03 18L | H10: 10 | I10: 10 | J10: 20 | K10: 20 | L10: =J10-K10 -> 0 | M10: =IF(L10>0,"Thực tế nhiều hơn HĐ",IF(L10<0,"HĐ nhiều hơn thực tế","Khớp")) -> Khớp | N10: =MAX(L10,0) -> 0 | O10: =MAX(-L10,0) -> 0 | P10: 1059398 | Q10: =IF(P10="","",(N10+O10)*P10) -> 0 | R10: =MIN(J10,K10) -> 20 | S10: =IF(P10="","",R10*P10) -> 21187960 | T10: =IF(L10=0,"",ABS(L10)+ROW()/100000)
A11: 7 | B11: Sơn lót | C11: SPE01 | D11: Sơn lót ngoại thất kháng kiềm siêu cao cấp SPE01 | E11: 5L | H11: 4 | J11: 4 | K11: 0 | L11: =J11-K11 -> 4 | M11: =IF(L11>0,"Thực tế nhiều hơn HĐ",IF(L11<0,"HĐ nhiều hơn thực tế","Khớp")) -> Thực tế nhiều hơn HĐ | N11: =MAX(L11,0) -> 4 | O11: =MAX(-L11,0) -> 0 | Q11: =IF(P11="","",(N11+O11)*P11) | R11: =MIN(J11,K11) -> 0 | S11: =IF(P11="","",R11*P11) | T11: =IF(L11=0,"",ABS(L11)+ROW()/100000) -> 4.00011 | U11: Không có trong phần mềm (hóa đơn); Chưa có đơn giá vốn
A12: 8 | B12: Sơn lót | C12: SPE01 | D12: Sơn lót ngoại thất kháng kiềm siêu cao cấp SPE01 | E12: 18L | G12: IMP-SPE01 18L 00 | H12: 4 | I12: 10 | J12: 14 | K12: 35 | L12: =J12-K12 -> -21 | M12: =IF(L12>0,"Thực tế nhiều hơn HĐ",IF(L12<0,"HĐ nhiều hơn thực tế","Khớp")) -> HĐ nhiều hơn thực tế | N12: =MAX(L12,0) -> 0 | O12: =MAX(-L12,0) -> 21 | P12: 1642549 | Q12: =IF(P12="","",(N12+O12)*P12) -> 34493529 | R12: =MIN(J12,K12) -> 14 | S12: =IF(P12="","",R12*P12) -> 22995686 | T12: =IF(L12=0,"",ABS(L12)+ROW()/100000) -> 21.00012
A13: 9 | B13: Sơn lót | C13: IL5 | D13: Sơn lót nội thất kháng kiềm Silver IL5 | E13: 5L | G13: IL5 05L 00 | H13: 19 | J13: 19 | K13: 76 | L13: =J13-K13 -> -57 | M13: =IF(L13>0,"Thực tế nhiều hơn HĐ",IF(L13<0,"HĐ nhiều hơn thực tế","Khớp")) -> HĐ nhiều hơn thực tế | N13: =MAX(L13,0) -> 0 | O13: =MAX(-L13,0) -> 57 | P13: 230602 | Q13: =IF(P13="","",(N13+O13)*P13) -> 13144314 | R13: =MIN(J13,K13) -> 19 | S13: =IF(P13="","",R13*P13) -> 4381438 | T13: =IF(L13=0,"",ABS(L13)+ROW()/100000) -> 57.00013
A14: 10 | B14: Sơn lót | C14: IL5 | D14: Sơn lót nội thất kháng kiềm Silver IL5 | E14: 18L | G14: Ipaint IL5 18L 00 | H14: 32 | I14: 20 | J14: 52 | K14: 316 | L14: =J14-K14 -> -264 | M14: =IF(L14>0,"Thực tế nhiều hơn HĐ",IF(L14<0,"HĐ nhiều hơn thực tế","Khớp")) -> HĐ nhiều hơn thực tế | N14: =MAX(L14,0) -> 0 | O14: =MAX(-L14,0) -> 264 | P14: 730646 | Q14: =IF(P14="","",(N14+O14)*P14) -> 192890544 | R14: =MIN(J14,K14) -> 52 | S14: =IF(P14="","",R14*P14) -> 37993592 | T14: =IF(L14=0,"",ABS(L14)+ROW()/100000) -> 264.00014
A15: 11 | B15: Sơn lót | C15: EL5 | D15: Sơn lót ngoại thất kháng kiềm Silver EL5 | E15: 5L | G15: EL5 05L | H15: 21 | J15: 21 | K15: 72 | L15: =J15-K15 -> -51 | M15: =IF(L15>0,"Thực tế nhiều hơn HĐ",IF(L15<0,"HĐ nhiều hơn thực tế","Khớp")) -> HĐ nhiều hơn thực tế | N15: =MAX(L15,0) -> 0 | O15: =MAX(-L15,0) -> 51 | P15: 288074 | Q15: =IF(P15="","",(N15+O15)*P15) -> 14691774 | R15: =MIN(J15,K15) -> 21 | S15: =IF(P15="","",R15*P15) -> 6049554 | T15: =IF(L15=0,"",ABS(L15)+ROW()/100000) -> 51.00015
A16: 12 | B16: Sơn lót | C16: EL5 | D16: Sơn lót ngoại thất kháng kiềm Silver EL5 | E16: 18L | G16: EL5 18L | H16: 53 | J16: 53 | K16: 132 | L16: =J16-K16 -> -79 | M16: =IF(L16>0,"Thực tế nhiều hơn HĐ",IF(L16<0,"HĐ nhiều hơn thực tế","Khớp")) -> HĐ nhiều hơn thực tế | N16: =MAX(L16,0) -> 0 | O16: =MAX(-L16,0) -> 79 | P16: 1032709 | Q16: =IF(P16="","",(N16+O16)*P16) -> 81584011 | R16: =MIN(J16,K16) -> 53 | S16: =IF(P16="","",R16*P16) -> 54733577 | T16: =IF(L16=0,"",ABS(L16)+ROW()/100000) -> 79.00016
A17: 13 | B17: Nội thất | C17: IEW | D17: Sơn nội thất siêu trắng Imperia IEW | E17: 5L | G17: IEW 05L | H17: 5 | I17: 12 | J17: 17 | K17: 72 | L17: =J17-K17 -> -55 | M17: =IF(L17>0,"Thực tế nhiều hơn HĐ",IF(L17<0,"HĐ nhiều hơn thực tế","Khớp")) -> HĐ nhiều hơn thực tế | N17: =MAX(L17,0) -> 0 | O17: =MAX(-L17,0) -> 55 | P17: 298196 | Q17: =IF(P17="","",(N17+O17)*P17) -> 16400780 | R17: =MIN(J17,K17) -> 17 | S17: =IF(P17="","",R17*P17) -> 5069332 | T17: =IF(L17=0,"",ABS(L17)+ROW()/100000) -> 55.00017
A18: 14 | B18: Nội thất | C18: IEW | D18: Sơn nội thất siêu trắng Imperia IEW | E18: 18L | G18: IEW 18L | I18: 1 | J18: 1 | K18: 99 | L18: =J18-K18 -> -98 | M18: =IF(L18>0,"Thực tế nhiều hơn HĐ",IF(L18<0,"HĐ nhiều hơn thực tế","Khớp")) -> HĐ nhiều hơn thực tế | N18: =MAX(L18,0) -> 0 | O18: =MAX(-L18,0) -> 98 | P18: 832340 | Q18: =IF(P18="","",(N18+O18)*P18) -> 81569320 | R18: =MIN(J18,K18) -> 1 | S18: =IF(P18="","",R18*P18) -> 832340 | T18: =IF(L18=0,"",ABS(L18)+ROW()/100000) -> 98.00018
A19: 15 | B19: Nội thất | C19: ISI | D19: Sơn nội thất bền màu Silver ISI | E19: 5L | F19: B1 | G19: ISI 05L B1 | H19: 21 | J19: 21 | K19: 46 | L19: =J19-K19 -> -25 | M19: =IF(L19>0,"Thực tế nhiều hơn HĐ",IF(L19<0,"HĐ nhiều hơn thực tế","Khớp")) -> HĐ nhiều hơn thực tế | N19: =MAX(L19,0) -> 0 | O19: =MAX(-L19,0) -> 25 | P19: 181063 | Q19: =IF(P19="","",(N19+O19)*P19) -> 4526575 | R19: =MIN(J19,K19) -> 21 | S19: =IF(P19="","",R19*P19) -> 3802323 | T19: =IF(L19=0,"",ABS(L19)+ROW()/100000) -> 25.00019
A20: 16 | B20: Nội thất | C20: ISI | D20: Sơn nội thất bền màu Silver ISI | E20: 18L | F20: B1 | G20: ISI 18L B1 | H20: 57 | J20: 57 | K20: 202 | L20: =J20-K20 -> -145 | M20: =IF(L20>0,"Thực tế nhiều hơn HĐ",IF(L20<0,"HĐ nhiều hơn thực tế","Khớp")) -> HĐ nhiều hơn thực tế | N20: =MAX(L20,0) -> 0 | O20: =MAX(-L20,0) -> 145 | P20: 714890 | Q20: =IF(P20="","",(N20+O20)*P20) -> 103659050 | R20: =MIN(J20,K20) -> 57 | S20: =IF(P20="","",R20*P20) -> 40748730 | T20: =IF(L20=0,"",ABS(L20)+ROW()/100000) -> 145.0002
A21: 17 | B21: Nội thất | C21: ISG06 | D21: Sơn nội thất cao cấp bóng mờ Imperia ISG06 | E21: 5L | F21: B1 | G21: ISG06 05L B1 | H21: 6 | I21: 20 | J21: 26 | K21: 108 | L21: =J21-K21 -> -82 | M21: =IF(L21>0,"Thực tế nhiều hơn HĐ",IF(L21<0,"HĐ nhiều hơn thực tế","Khớp")) -> HĐ nhiều hơn thực tế | N21: =MAX(L21,0) -> 0 | O21: =MAX(-L21,0) -> 82 | P21: 440079 | Q21: =IF(P21="","",(N21+O21)*P21) -> 36086478 | R21: =MIN(J21,K21) -> 26 | S21: =IF(P21="","",R21*P21) -> 11442054 | T21: =IF(L21=0,"",ABS(L21)+ROW()/100000) -> 82.00021
A22: 18 | B22: Nội thất | C22: ISG06 | D22: Sơn nội thất cao cấp bóng mờ Imperia ISG06 | E22: 18L | F22: B1 | G22: ISG06 18L B1 | H22: 23 | I22: 30 | J22: 53 | K22: 172 | L22: =J22-K22 -> -119 | M22: =IF(L22>0,"Thực tế nhiều hơn HĐ",IF(L22<0,"HĐ nhiều hơn thực tế","Khớp")) -> HĐ nhiều hơn thực tế | N22: =MAX(L22,0) -> 0 | O22: =MAX(-L22,0) -> 119 | P22: 1395975 | Q22: =IF(P22="","",(N22+O22)*P22) -> 166121025 | R22: =MIN(J22,K22) -> 53 | S22: =IF(P22="","",R22*P22) -> 73986675 | T22: =IF(L22=0,"",ABS(L22)+ROW()/100000) -> 119.00022
A23: 19 | B23: Nội thất | C23: IG05 | D23: Sơn nội thất siêu bóng cao cấp Imperia IG05 | E23: 5L | F23: B1 | G23: IG05 05L B1 | H23: 54 | I23: 40 | J23: 94 | K23: 152 | L23: =J23-K23 -> -58 | M23: =IF(L23>0,"Thực tế nhiều hơn HĐ",IF(L23<0,"HĐ nhiều hơn thực tế","Khớp")) -> HĐ nhiều hơn thực tế | N23: =MAX(L23,0) -> 0 | O23: =MAX(-L23,0) -> 58 | P23: 605192 | Q23: =IF(P23="","",(N23+O23)*P23) -> 35101136 | R23: =MIN(J23,K23) -> 94 | S23: =IF(P23="","",R23*P23) -> 56888048 | T23: =IF(L23=0,"",ABS(L23)+ROW()/100000) -> 58.00023
A24: 20 | B24: Nội thất | C24: IG05 | D24: Sơn nội thất siêu bóng cao cấp Imperia IG05 | E24: 18L | F24: B1 | G24: IG05 18L B1 | H24: 62 | I24: 40 | J24: 102 | K24: 156 | L24: =J24-K24 -> -54 | M24: =IF(L24>0,"Thực tế nhiều hơn HĐ",IF(L24<0,"HĐ nhiều hơn thực tế","Khớp")) -> HĐ nhiều hơn thực tế | N24: =MAX(L24,0) -> 0 | O24: =MAX(-L24,0) -> 54 | P24: 1599746 | Q24: =IF(P24="","",(N24+O24)*P24) -> 86386284 | R24: =MIN(J24,K24) -> 102 | S24: =IF(P24="","",R24*P24) -> 163174092 | T24: =IF(L24=0,"",ABS(L24)+ROW()/100000) -> 54.00024
A25: 21 | B25: Nội thất | C25: I9 | D25: Sơn nội thất siêu bóng cao cấp Saphir I9 | E25: 5L | F25: B1 | G25: I9 05L B1 | H25: 11 | J25: 11 | K25: 4 | L25: =J25-K25 -> 7 | M25: =IF(L25>0,"Thực tế nhiều hơn HĐ",IF(L25<0,"HĐ nhiều hơn thực tế","Khớp")) -> Thực tế nhiều hơn HĐ | N25: =MAX(L25,0) -> 7 | O25: =MAX(-L25,0) -> 0 | P25: 568486 | Q25: =IF(P25="","",(N25+O25)*P25) -> 3979402 | R25: =MIN(J25,K25) -> 4 | S25: =IF(P25="","",R25*P25) -> 2273944 | T25: =IF(L25=0,"",ABS(L25)+ROW()/100000) -> 7.00025
A26: 22 | B26: Nội thất | C26: I9 | D26: Sơn nội thất siêu bóng cao cấp Saphir I9 | E26: 18L | F26: B1 | G26: I9 18L B1 | H26: 9 | I26: 15 | J26: 24 | K26: 24 | L26: =J26-K26 -> 0 | M26: =IF(L26>0,"Thực tế nhiều hơn HĐ",IF(L26<0,"HĐ nhiều hơn thực tế","Khớp")) -> Khớp | N26: =MAX(L26,0) -> 0 | O26: =MAX(-L26,0) -> 0 | P26: 1699766 | Q26: =IF(P26="","",(N26+O26)*P26) -> 0 | R26: =MIN(J26,K26) -> 24 | S26: =IF(P26="","",R26*P26) -> 40794384 | T26: =IF(L26=0,"",ABS(L26)+ROW()/100000)
A27: 23 | B27: Nội thất | C27: DECO | D27: Sơn nội thất kinh tế Deco IDC | E27: 18L | F27: B1 | G27: DECO 18L B1, IDC 18L B1 | H27: 61 | J27: 61 | K27: 724 | L27: =J27-K27 -> -663 | M27: =IF(L27>0,"Thực tế nhiều hơn HĐ",IF(L27<0,"HĐ nhiều hơn thực tế","Khớp")) -> HĐ nhiều hơn thực tế | N27: =MAX(L27,0) -> 0 | O27: =MAX(-L27,0) -> 663 | P27: 325693 | Q27: =IF(P27="","",(N27+O27)*P27) -> 215934459 | R27: =MIN(J27,K27) -> 61 | S27: =IF(P27="","",R27*P27) -> 19867273 | T27: =IF(L27=0,"",ABS(L27)+ROW()/100000) -> 663.00027 | U27: Phần mềm có 2 mã gộp lại
A28: 24 | B28: Nội thất | C28: ICL | D28: Sơn phủ nội thất bóng cao cấp ICL | E28: 1L | G28: ICL 1L | J28: 18 | K28: 120 | L28: =J28-K28 -> -102 | M28: =IF(L28>0,"Thực tế nhiều hơn HĐ",IF(L28<0,"HĐ nhiều hơn thực tế","Khớp")) -> HĐ nhiều hơn thực tế | N28: =MAX(L28,0) -> 0 | O28: =MAX(-L28,0) -> 102 | P28: 162365 | Q28: =IF(P28="","",(N28+O28)*P28) -> 16561230 | R28: =MIN(J28,K28) -> 18 | S28: =IF(P28="","",R28*P28) -> 2922570 | T28: =IF(L28=0,"",ABS(L28)+ROW()/100000) -> 102.00028
A29: 25 | B29: Ngoại thất | C29: ESI | D29: Sơn ngoại thất bền màu Silver ESI | E29: 5L | F29: B1 | G29: ESI 05L B1 | H29: 27 | J29: 27 | K29: 62 | L29: =J29-K29 -> -35 | M29: =IF(L29>0,"Thực tế nhiều hơn HĐ",IF(L29<0,"HĐ nhiều hơn thực tế","Khớp")) -> HĐ nhiều hơn thực tế | N29: =MAX(L29,0) -> 0 | O29: =MAX(-L29,0) -> 35 | P29: 278872 | Q29: =IF(P29="","",(N29+O29)*P29) -> 9760520 | R29: =MIN(J29,K29) -> 27 | S29: =IF(P29="","",R29*P29) -> 7529544 | T29: =IF(L29=0,"",ABS(L29)+ROW()/100000) -> 35.00029
A30: 26 | B30: Ngoại thất | C30: ESI | D30: Sơn ngoại thất bền màu Silver ESI | E30: 5L | F30: B2 | G30: ESI 05L B2 | J30: 0 | K30: 16 | L30: =J30-K30 -> -16 | M30: =IF(L30>0,"Thực tế nhiều hơn HĐ",IF(L30<0,"HĐ nhiều hơn thực tế","Khớp")) -> HĐ nhiều hơn thực tế | N30: =MAX(L30,0) -> 0 | O30: =MAX(-L30,0) -> 16 | P30: 299792 | Q30: =IF(P30="","",(N30+O30)*P30) -> 4796672 | R30: =MIN(J30,K30) -> 0 | S30: =IF(P30="","",R30*P30) -> 0 | T30: =IF(L30=0,"",ABS(L30)+ROW()/100000) -> 16.0003
A31: 27 | B31: Ngoại thất | C31: ESI | D31: Sơn ngoại thất bền màu Silver ESI | E31: 18L | F31: B1 | G31: ESI 18L B1 | H31: 67 | J31: 67 | K31: 63 | L31: =J31-K31 -> 4 | M31: =IF(L31>0,"Thực tế nhiều hơn HĐ",IF(L31<0,"HĐ nhiều hơn thực tế","Khớp")) -> Thực tế nhiều hơn HĐ | N31: =MAX(L31,0) -> 4 | O31: =MAX(-L31,0) -> 0 | P31: 948051 | Q31: =IF(P31="","",(N31+O31)*P31) -> 3792204 | R31: =MIN(J31,K31) -> 63 | S31: =IF(P31="","",R31*P31) -> 59727213 | T31: =IF(L31=0,"",ABS(L31)+ROW()/100000) -> 4.00031
A32: 28 | B32: Ngoại thất | C32: ESG10 | D32: Sơn ngoại thất cao cấp bóng mờ Imperia ESG10 | E32: 1L | F32: B1 | G32: IMP- ESG10 01L B1 | J32: 68 | K32: 85 | L32: =J32-K32 -> -17 | M32: =IF(L32>0,"Thực tế nhiều hơn HĐ",IF(L32<0,"HĐ nhiều hơn thực tế","Khớp")) -> HĐ nhiều hơn thực tế | N32: =MAX(L32,0) -> 0 | O32: =MAX(-L32,0) -> 17 | P32: 129341 | Q32: =IF(P32="","",(N32+O32)*P32) -> 2198797 | R32: =MIN(J32,K32) -> 68 | S32: =IF(P32="","",R32*P32) -> 8795188 | T32: =IF(L32=0,"",ABS(L32)+ROW()/100000) -> 17.00032
A33: 29 | B33: Ngoại thất | C33: ESG10 | D33: Sơn ngoại thất cao cấp bóng mờ Imperia ESG10 | E33: 1L | F33: B2 | G33: IMP- ESG10 01L B2 | J33: 45 | K33: 36 | L33: =J33-K33 -> 9 | M33: =IF(L33>0,"Thực tế nhiều hơn HĐ",IF(L33<0,"HĐ nhiều hơn thực tế","Khớp")) -> Thực tế nhiều hơn HĐ | N33: =MAX(L33,0) -> 9 | O33: =MAX(-L33,0) -> 0 | P33: 131852 | Q33: =IF(P33="","",(N33+O33)*P33) -> 1186668 | R33: =MIN(J33,K33) -> 36 | S33: =IF(P33="","",R33*P33) -> 4746672 | T33: =IF(L33=0,"",ABS(L33)+ROW()/100000) -> 9.00033
A34: 30 | B34: Ngoại thất | C34: ESG10 | D34: Sơn ngoại thất cao cấp bóng mờ Imperia ESG10 | E34: 1L | F34: B3 | G34: ESG10 01L B3 | J34: 44 | K34: 60 | L34: =J34-K34 -> -16 | M34: =IF(L34>0,"Thực tế nhiều hơn HĐ",IF(L34<0,"HĐ nhiều hơn thực tế","Khớp")) -> HĐ nhiều hơn thực tế | N34: =MAX(L34,0) -> 0 | O34: =MAX(-L34,0) -> 16 | P34: 121898 | Q34: =IF(P34="","",(N34+O34)*P34) -> 1950368 | R34: =MIN(J34,K34) -> 44 | S34: =IF(P34="","",R34*P34) -> 5363512 | T34: =IF(L34=0,"",ABS(L34)+ROW()/100000) -> 16.00034
A35: 31 | B35: Ngoại thất | C35: ESG10 | D35: Sơn ngoại thất cao cấp bóng mờ Imperia ESG10 | E35: 1L | F35: B4 | G35: IMP- ESG10 01L B4 | J35: 32 | K35: 44 | L35: =J35-K35 -> -12 | M35: =IF(L35>0,"Thực tế nhiều hơn HĐ",IF(L35<0,"HĐ nhiều hơn thực tế","Khớp")) -> HĐ nhiều hơn thực tế | N35: =MAX(L35,0) -> 0 | O35: =MAX(-L35,0) -> 12 | P35: 123426 | Q35: =IF(P35="","",(N35+O35)*P35) -> 1481112 | R35: =MIN(J35,K35) -> 32 | S35: =IF(P35="","",R35*P35) -> 3949632 | T35: =IF(L35=0,"",ABS(L35)+ROW()/100000) -> 12.00035
A36: 32 | B36: Ngoại thất | C36: ESG10 | D36: Sơn ngoại thất cao cấp bóng mờ Imperia ESG10 | E36: 5L | F36: B1 | G36: IMP- ESG10 05L B1 | H36: 11 | I36: 12 | J36: 23 | K36: 64 | L36: =J36-K36 -> -41 | M36: =IF(L36>0,"Thực tế nhiều hơn HĐ",IF(L36<0,"HĐ nhiều hơn thực tế","Khớp")) -> HĐ nhiều hơn thực tế | N36: =MAX(L36,0) -> 0 | O36: =MAX(-L36,0) -> 41 | P36: 526458 | Q36: =IF(P36="","",(N36+O36)*P36) -> 21584778 | R36: =MIN(J36,K36) -> 23 | S36: =IF(P36="","",R36*P36) -> 12108534 | T36: =IF(L36=0,"",ABS(L36)+ROW()/100000) -> 41.00036
A37: 33 | B37: Ngoại thất | C37: ESG10 | D37: Sơn ngoại thất cao cấp bóng mờ Imperia ESG10 | E37: 5L | F37: B2 | G37: IMP- ESG10 05L B2 | H37: 16 | I37: 12 | J37: 28 | K37: 44 | L37: =J37-K37 -> -16 | M37: =IF(L37>0,"Thực tế nhiều hơn HĐ",IF(L37<0,"HĐ nhiều hơn thực tế","Khớp")) -> HĐ nhiều hơn thực tế | N37: =MAX(L37,0) -> 0 | O37: =MAX(-L37,0) -> 16 | P37: 468097 | Q37: =IF(P37="","",(N37+O37)*P37) -> 7489552 | R37: =MIN(J37,K37) -> 28 | S37: =IF(P37="","",R37*P37) -> 13106716 | T37: =IF(L37=0,"",ABS(L37)+ROW()/100000) -> 16.00037
A38: 34 | B38: Ngoại thất | C38: ESG10 | D38: Sơn ngoại thất cao cấp bóng mờ Imperia ESG10 | E38: 5L | F38: B3 | G38: ESG10 05L B3 | H38: 30 | J38: 30 | K38: 56 | L38: =J38-K38 -> -26 | M38: =IF(L38>0,"Thực tế nhiều hơn HĐ",IF(L38<0,"HĐ nhiều hơn thực tế","Khớp")) -> HĐ nhiều hơn thực tế | N38: =MAX(L38,0) -> 0 | O38: =MAX(-L38,0) -> 26 | P38: 461819 | Q38: =IF(P38="","",(N38+O38)*P38) -> 12007294 | R38: =MIN(J38,K38) -> 30 | S38: =IF(P38="","",R38*P38) -> 13854570 | T38: =IF(L38=0,"",ABS(L38)+ROW()/100000) -> 26.00038
A39: 35 | B39: Ngoại thất | C39: ESG10 | D39: Sơn ngoại thất cao cấp bóng mờ Imperia ESG10 | E39: 5L | F39: B4 | G39: IMP- ESG10 05L B4 | H39: 14 | J39: 14 | K39: 56 | L39: =J39-K39 -> -42 | M39: =IF(L39>0,"Thực tế nhiều hơn HĐ",IF(L39<0,"HĐ nhiều hơn thực tế","Khớp")) -> HĐ nhiều hơn thực tế | N39: =MAX(L39,0) -> 0 | O39: =MAX(-L39,0) -> 42 | P39: 505278 | Q39: =IF(P39="","",(N39+O39)*P39) -> 21221676 | R39: =MIN(J39,K39) -> 14 | S39: =IF(P39="","",R39*P39) -> 7073892 | T39: =IF(L39=0,"",ABS(L39)+ROW()/100000) -> 42.00039
A40: 36 | B40: Ngoại thất | C40: ESG10 | D40: Sơn ngoại thất cao cấp bóng mờ Imperia ESG10 | E40: 18L | F40: B1 | G40: IMP- ESG10 18L B1 | H40: 20 | J40: 20 | K40: 30 | L40: =J40-K40 -> -10 | M40: =IF(L40>0,"Thực tế nhiều hơn HĐ",IF(L40<0,"HĐ nhiều hơn thực tế","Khớp")) -> HĐ nhiều hơn thực tế | N40: =MAX(L40,0) -> 0 | O40: =MAX(-L40,0) -> 10 | P40: 1753540 | Q40: =IF(P40="","",(N40+O40)*P40) -> 17535400 | R40: =MIN(J40,K40) -> 20 | S40: =IF(P40="","",R40*P40) -> 35070800 | T40: =IF(L40=0,"",ABS(L40)+ROW()/100000) -> 10.0004
A41: 37 | B41: Ngoại thất | C41: EG09 | D41: Sơn ngoại thất siêu bóng cao cấp Imperia EG09 | E41: 1L | F41: B1 | G41: EG09 01L B1 | J41: 30 | K41: 103 | L41: =J41-K41 -> -73 | M41: =IF(L41>0,"Thực tế nhiều hơn HĐ",IF(L41<0,"HĐ nhiều hơn thực tế","Khớp")) -> HĐ nhiều hơn thực tế | N41: =MAX(L41,0) -> 0 | O41: =MAX(-L41,0) -> 73 | P41: 147432 | Q41: =IF(P41="","",(N41+O41)*P41) -> 10762536 | R41: =MIN(J41,K41) -> 30 | S41: =IF(P41="","",R41*P41) -> 4422960 | T41: =IF(L41=0,"",ABS(L41)+ROW()/100000) -> 73.00041
...

Sheet PHIẾU XUẤT KHỚP KHO
A1: PHIẾU XUẤT ĐIỀU CHỈNH ĐỂ KHỚP KHO
A2: Số liệu lấy từ sheet ĐỐI CHIẾU. Phần A: kho thực tế nhiều hơn hóa đơn. Phần B: kho hóa đơn (phần mềm) nhiều hơn thực tế – em để riêng vì chị chưa nói cách xử lý.
A4: A. KHO THỰC TẾ NHIỀU HƠN HÓA ĐƠN → xuất khỏi kho thực tế (theo yêu cầu của chị)
A5: STT | B5: Mã SP | C5: Tên hàng hoá | D5: Dung tích | E5: Base | F5: Kho thực tế | G5: Kho hóa đơn | H5: SỐ LƯỢNG XUẤT | I5: Đơn giá BQ | J5: Giá trị (VNĐ)
A6: 1 | B6: =IF('ĐỐI CHIẾU'!C5="","",'ĐỐI CHIẾU'!C5) -> PI04 | C6: =IF('ĐỐI CHIẾU'!D5="","",'ĐỐI CHIẾU'!D5) -> Sơn lót nội thất kháng kiềm cao cấp Imperia PI04 | D6: =IF('ĐỐI CHIẾU'!E5="","",'ĐỐI CHIẾU'!E5) -> 5L | E6: =IF('ĐỐI CHIẾU'!F5="","",'ĐỐI CHIẾU'!F5) | F6: =IF('ĐỐI CHIẾU'!J5="","",'ĐỐI CHIẾU'!J5) -> 2 | G6: =IF('ĐỐI CHIẾU'!K5="","",'ĐỐI CHIẾU'!K5) -> 0 | H6: =IF('ĐỐI CHIẾU'!N5="","",'ĐỐI CHIẾU'!N5) -> 2 | I6: =IF('ĐỐI CHIẾU'!P5="","",'ĐỐI CHIẾU'!P5) | J6: =IF(I6="","",H6*I6)
A7: 2 | B7: =IF('ĐỐI CHIẾU'!C9="","",'ĐỐI CHIẾU'!C9) -> SPI03 | C7: =IF('ĐỐI CHIẾU'!D9="","",'ĐỐI CHIẾU'!D9) -> Sơn lót nội thất kháng kiềm siêu cao cấp SPI03 | D7: =IF('ĐỐI CHIẾU'!E9="","",'ĐỐI CHIẾU'!E9) -> 5L | E7: =IF('ĐỐI CHIẾU'!F9="","",'ĐỐI CHIẾU'!F9) | F7: =IF('ĐỐI CHIẾU'!J9="","",'ĐỐI CHIẾU'!J9) -> 7 | G7: =IF('ĐỐI CHIẾU'!K9="","",'ĐỐI CHIẾU'!K9) -> 0 | H7: =IF('ĐỐI CHIẾU'!N9="","",'ĐỐI CHIẾU'!N9) -> 7 | I7: =IF('ĐỐI CHIẾU'!P9="","",'ĐỐI CHIẾU'!P9) | J7: =IF(I7="","",H7*I7)
A8: 3 | B8: =IF('ĐỐI CHIẾU'!C11="","",'ĐỐI CHIẾU'!C11) -> SPE01 | C8: =IF('ĐỐI CHIẾU'!D11="","",'ĐỐI CHIẾU'!D11) -> Sơn lót ngoại thất kháng kiềm siêu cao cấp SPE01 | D8: =IF('ĐỐI CHIẾU'!E11="","",'ĐỐI CHIẾU'!E11) -> 5L | E8: =IF('ĐỐI CHIẾU'!F11="","",'ĐỐI CHIẾU'!F11) | F8: =IF('ĐỐI CHIẾU'!J11="","",'ĐỐI CHIẾU'!J11) -> 4 | G8: =IF('ĐỐI CHIẾU'!K11="","",'ĐỐI CHIẾU'!K11) -> 0 | H8: =IF('ĐỐI CHIẾU'!N11="","",'ĐỐI CHIẾU'!N11) -> 4 | I8: =IF('ĐỐI CHIẾU'!P11="","",'ĐỐI CHIẾU'!P11) | J8: =IF(I8="","",H8*I8)
A9: 4 | B9: =IF('ĐỐI CHIẾU'!C25="","",'ĐỐI CHIẾU'!C25) -> I9 | C9: =IF('ĐỐI CHIẾU'!D25="","",'ĐỐI CHIẾU'!D25) -> Sơn nội thất siêu bóng cao cấp Saphir I9 | D9: =IF('ĐỐI CHIẾU'!E25="","",'ĐỐI CHIẾU'!E25) -> 5L | E9: =IF('ĐỐI CHIẾU'!F25="","",'ĐỐI CHIẾU'!F25) -> B1 | F9: =IF('ĐỐI CHIẾU'!J25="","",'ĐỐI CHIẾU'!J25) -> 11 | G9: =IF('ĐỐI CHIẾU'!K25="","",'ĐỐI CHIẾU'!K25) -> 4 | H9: =IF('ĐỐI CHIẾU'!N25="","",'ĐỐI CHIẾU'!N25) -> 7 | I9: =IF('ĐỐI CHIẾU'!P25="","",'ĐỐI CHIẾU'!P25) -> 568486 | J9: =IF(I9="","",H9*I9) -> 3979402
A10: 5 | B10: =IF('ĐỐI CHIẾU'!C31="","",'ĐỐI CHIẾU'!C31) -> ESI | C10: =IF('ĐỐI CHIẾU'!D31="","",'ĐỐI CHIẾU'!D31) -> Sơn ngoại thất bền màu Silver ESI | D10: =IF('ĐỐI CHIẾU'!E31="","",'ĐỐI CHIẾU'!E31) -> 18L | E10: =IF('ĐỐI CHIẾU'!F31="","",'ĐỐI CHIẾU'!F31) -> B1 | F10: =IF('ĐỐI CHIẾU'!J31="","",'ĐỐI CHIẾU'!J31) -> 67 | G10: =IF('ĐỐI CHIẾU'!K31="","",'ĐỐI CHIẾU'!K31) -> 63 | H10: =IF('ĐỐI CHIẾU'!N31="","",'ĐỐI CHIẾU'!N31) -> 4 | I10: =IF('ĐỐI CHIẾU'!P31="","",'ĐỐI CHIẾU'!P31) -> 948051 | J10: =IF(I10="","",H10*I10) -> 3792204
A11: 6 | B11: =IF('ĐỐI CHIẾU'!C33="","",'ĐỐI CHIẾU'!C33) -> ESG10 | C11: =IF('ĐỐI CHIẾU'!D33="","",'ĐỐI CHIẾU'!D33) -> Sơn ngoại thất cao cấp bóng mờ Imperia ESG10 | D11: =IF('ĐỐI CHIẾU'!E33="","",'ĐỐI CHIẾU'!E33) -> 1L | E11: =IF('ĐỐI CHIẾU'!F33="","",'ĐỐI CHIẾU'!F33) -> B2 | F11: =IF('ĐỐI CHIẾU'!J33="","",'ĐỐI CHIẾU'!J33) -> 45 | G11: =IF('ĐỐI CHIẾU'!K33="","",'ĐỐI CHIẾU'!K33) -> 36 | H11: =IF('ĐỐI CHIẾU'!N33="","",'ĐỐI CHIẾU'!N33) -> 9 | I11: =IF('ĐỐI CHIẾU'!P33="","",'ĐỐI CHIẾU'!P33) -> 131852 | J11: =IF(I11="","",H11*I11) -> 1186668
A12: 7 | B12: =IF('ĐỐI CHIẾU'!C49="","",'ĐỐI CHIẾU'!C49) -> EG09 | C12: =IF('ĐỐI CHIẾU'!D49="","",'ĐỐI CHIẾU'!D49) -> Sơn ngoại thất siêu bóng cao cấp Imperia EG09 | D12: =IF('ĐỐI CHIẾU'!E49="","",'ĐỐI CHIẾU'!E49) -> 18L | E12: =IF('ĐỐI CHIẾU'!F49="","",'ĐỐI CHIẾU'!F49) -> B1 | F12: =IF('ĐỐI CHIẾU'!J49="","",'ĐỐI CHIẾU'!J49) -> 218 | G12: =IF('ĐỐI CHIẾU'!K49="","",'ĐỐI CHIẾU'!K49) -> 50 | H12: =IF('ĐỐI CHIẾU'!N49="","",'ĐỐI CHIẾU'!N49) -> 168 | I12: =IF('ĐỐI CHIẾU'!P49="","",'ĐỐI CHIẾU'!P49) -> 1589834 | J12: =IF(I12="","",H12*I12) -> 267092112
A13: 8 | B13: =IF('ĐỐI CHIẾU'!C51="","",'ĐỐI CHIẾU'!C51) -> E9 | C13: =IF('ĐỐI CHIẾU'!D51="","",'ĐỐI CHIẾU'!D51) -> Sơn ngoại thất siêu bóng cao cấp Saphir E9 | D13: =IF('ĐỐI CHIẾU'!E51="","",'ĐỐI CHIẾU'!E51) -> 1L | E13: =IF('ĐỐI CHIẾU'!F51="","",'ĐỐI CHIẾU'!F51) -> B1 | F13: =IF('ĐỐI CHIẾU'!J51="","",'ĐỐI CHIẾU'!J51) -> 1 | G13: =IF('ĐỐI CHIẾU'!K51="","",'ĐỐI CHIẾU'!K51) -> 0 | H13: =IF('ĐỐI CHIẾU'!N51="","",'ĐỐI CHIẾU'!N51) -> 1 | I13: =IF('ĐỐI CHIẾU'!P51="","",'ĐỐI CHIẾU'!P51) | J13: =IF(I13="","",H13*I13)
A14: 9 | B14: =IF('ĐỐI CHIẾU'!C52="","",'ĐỐI CHIẾU'!C52) -> E9 | C14: =IF('ĐỐI CHIẾU'!D52="","",'ĐỐI CHIẾU'!D52) -> Sơn ngoại thất siêu bóng cao cấp Saphir E9 | D14: =IF('ĐỐI CHIẾU'!E52="","",'ĐỐI CHIẾU'!E52) -> 1L | E14: =IF('ĐỐI CHIẾU'!F52="","",'ĐỐI CHIẾU'!F52) -> B4 | F14: =IF('ĐỐI CHIẾU'!J52="","",'ĐỐI CHIẾU'!J52) -> 5 | G14: =IF('ĐỐI CHIẾU'!K52="","",'ĐỐI CHIẾU'!K52) -> 0 | H14: =IF('ĐỐI CHIẾU'!N52="","",'ĐỐI CHIẾU'!N52) -> 5 | I14: =IF('ĐỐI CHIẾU'!P52="","",'ĐỐI CHIẾU'!P52) | J14: =IF(I14="","",H14*I14)
A15: 10 | B15: =IF('ĐỐI CHIẾU'!C55="","",'ĐỐI CHIẾU'!C55) -> E9 | C15: =IF('ĐỐI CHIẾU'!D55="","",'ĐỐI CHIẾU'!D55) -> Sơn ngoại thất siêu bóng cao cấp Saphir E9 | D15: =IF('ĐỐI CHIẾU'!E55="","",'ĐỐI CHIẾU'!E55) -> 5L | E15: =IF('ĐỐI CHIẾU'!F55="","",'ĐỐI CHIẾU'!F55) -> B3 | F15: =IF('ĐỐI CHIẾU'!J55="","",'ĐỐI CHIẾU'!J55) -> 13 | G15: =IF('ĐỐI CHIẾU'!K55="","",'ĐỐI CHIẾU'!K55) -> 12 | H15: =IF('ĐỐI CHIẾU'!N55="","",'ĐỐI CHIẾU'!N55) -> 1 | I15: =IF('ĐỐI CHIẾU'!P55="","",'ĐỐI CHIẾU'!P55) -> 805774 | J15: =IF(I15="","",H15*I15) -> 805774
A16: 11 | B16: =IF('ĐỐI CHIẾU'!C56="","",'ĐỐI CHIẾU'!C56) -> E9 | C16: =IF('ĐỐI CHIẾU'!D56="","",'ĐỐI CHIẾU'!D56) -> Sơn ngoại thất siêu bóng cao cấp Saphir E9 | D16: =IF('ĐỐI CHIẾU'!E56="","",'ĐỐI CHIẾU'!E56) -> 5L | E16: =IF('ĐỐI CHIẾU'!F56="","",'ĐỐI CHIẾU'!F56) -> B4 | F16: =IF('ĐỐI CHIẾU'!J56="","",'ĐỐI CHIẾU'!J56) -> 19 | G16: =IF('ĐỐI CHIẾU'!K56="","",'ĐỐI CHIẾU'!K56) -> 0 | H16: =IF('ĐỐI CHIẾU'!N56="","",'ĐỐI CHIẾU'!N56) -> 19 | I16: =IF('ĐỐI CHIẾU'!P56="","",'ĐỐI CHIẾU'!P56) | J16: =IF(I16="","",H16*I16)
A17: 12 | B17: =IF('ĐỐI CHIẾU'!C59="","",'ĐỐI CHIẾU'!C59) -> ETM-309 | C17: =IF('ĐỐI CHIẾU'!D59="","",'ĐỐI CHIẾU'!D59) -> Sơn chống thấm màu ETM 309 (ghi đậm) | D17: =IF('ĐỐI CHIẾU'!E59="","",'ĐỐI CHIẾU'!E59) -> 5L | E17: =IF('ĐỐI CHIẾU'!F59="","",'ĐỐI CHIẾU'!F59) | F17: =IF('ĐỐI CHIẾU'!J59="","",'ĐỐI CHIẾU'!J59) -> 44 | G17: =IF('ĐỐI CHIẾU'!K59="","",'ĐỐI CHIẾU'!K59) -> 31 | H17: =IF('ĐỐI CHIẾU'!N59="","",'ĐỐI CHIẾU'!N59) -> 13 | I17: =IF('ĐỐI CHIẾU'!P59="","",'ĐỐI CHIẾU'!P59) -> 459107 | J17: =IF(I17="","",H17*I17) -> 5968391
C18: TỔNG | F18: =SUM(F6:F17) -> 436 | G18: =SUM(G6:G17) -> 196 | H18: =SUM(H6:H17) -> 240 | J18: =SUM(J6:J17) -> 282824551
A21: B. KHO HÓA ĐƠN NHIỀU HƠN THỰC TẾ → xuất điều chỉnh trên phần mềm (cần chị xác nhận)
A22: STT | B22: Mã SP | C22: Tên hàng hoá | D22: Dung tích | E22: Base | F22: Kho thực tế | G22: Kho hóa đơn | H22: SỐ LƯỢNG XUẤT | I22: Đơn giá BQ | J22: Giá trị (VNĐ)
A23: 1 | B23: =IF('ĐỐI CHIẾU'!C6="","",'ĐỐI CHIẾU'!C6) -> PI04 | C23: =IF('ĐỐI CHIẾU'!D6="","",'ĐỐI CHIẾU'!D6) -> Sơn lót nội thất kháng kiềm cao cấp Imperia PI04 | D23: =IF('ĐỐI CHIẾU'!E6="","",'ĐỐI CHIẾU'!E6) -> 18L | E23: =IF('ĐỐI CHIẾU'!F6="","",'ĐỐI CHIẾU'!F6) | F23: =IF('ĐỐI CHIẾU'!J6="","",'ĐỐI CHIẾU'!J6) -> 207 | G23: =IF('ĐỐI CHIẾU'!K6="","",'ĐỐI CHIẾU'!K6) -> 221 | H23: =IF('ĐỐI CHIẾU'!O6="","",'ĐỐI CHIẾU'!O6) -> 14 | I23: =IF('ĐỐI CHIẾU'!P6="","",'ĐỐI CHIẾU'!P6) -> 947240 | J23: =IF(I23="","",H23*I23) -> 13261360
A24: 2 | B24: =IF('ĐỐI CHIẾU'!C7="","",'ĐỐI CHIẾU'!C7) -> PE02 | C24: =IF('ĐỐI CHIẾU'!D7="","",'ĐỐI CHIẾU'!D7) -> Sơn lót ngoại thất kháng kiềm cao cấp Imperia PE02 | D24: =IF('ĐỐI CHIẾU'!E7="","",'ĐỐI CHIẾU'!E7) -> 5L | E24: =IF('ĐỐI CHIẾU'!F7="","",'ĐỐI CHIẾU'!F7) | F24: =IF('ĐỐI CHIẾU'!J7="","",'ĐỐI CHIẾU'!J7) -> 0 | G24: =IF('ĐỐI CHIẾU'!K7="","",'ĐỐI CHIẾU'!K7) -> 60 | H24: =IF('ĐỐI CHIẾU'!O7="","",'ĐỐI CHIẾU'!O7) -> 60 | I24: =IF('ĐỐI CHIẾU'!P7="","",'ĐỐI CHIẾU'!P7) -> 420746 | J24: =IF(I24="","",H24*I24) -> 25244760
A25: 3 | B25: =IF('ĐỐI CHIẾU'!C8="","",'ĐỐI CHIẾU'!C8) -> PE02 | C25: =IF('ĐỐI CHIẾU'!D8="","",'ĐỐI CHIẾU'!D8) -> Sơn lót ngoại thất kháng kiềm cao cấp Imperia PE02 | D25: =IF('ĐỐI CHIẾU'!E8="","",'ĐỐI CHIẾU'!E8) -> 18L | E25: =IF('ĐỐI CHIẾU'!F8="","",'ĐỐI CHIẾU'!F8) | F25: =IF('ĐỐI CHIẾU'!J8="","",'ĐỐI CHIẾU'!J8) -> 217 | G25: =IF('ĐỐI CHIẾU'!K8="","",'ĐỐI CHIẾU'!K8) -> 240 | H25: =IF('ĐỐI CHIẾU'!O8="","",'ĐỐI CHIẾU'!O8) -> 23 | I25: =IF('ĐỐI CHIẾU'!P8="","",'ĐỐI CHIẾU'!P8) -> 1163020 | J25: =IF(I25="","",H25*I25) -> 26749460
A26: 4 | B26: =IF('ĐỐI CHIẾU'!C12="","",'ĐỐI CHIẾU'!C12) -> SPE01 | C26: =IF('ĐỐI CHIẾU'!D12="","",'ĐỐI CHIẾU'!D12) -> Sơn lót ngoại thất kháng kiềm siêu cao cấp SPE01 | D26: =IF('ĐỐI CHIẾU'!E12="","",'ĐỐI CHIẾU'!E12) -> 18L | E26: =IF('ĐỐI CHIẾU'!F12="","",'ĐỐI CHIẾU'!F12) | F26: =IF('ĐỐI CHIẾU'!J12="","",'ĐỐI CHIẾU'!J12) -> 14 | G26: =IF('ĐỐI CHIẾU'!K12="","",'ĐỐI CHIẾU'!K12) -> 35 | H26: =IF('ĐỐI CHIẾU'!O12="","",'ĐỐI CHIẾU'!O12) -> 21 | I26: =IF('ĐỐI CHIẾU'!P12="","",'ĐỐI CHIẾU'!P12) -> 1642549 | J26: =IF(I26="","",H26*I26) -> 34493529
A27: 5 | B27: =IF('ĐỐI CHIẾU'!C13="","",'ĐỐI CHIẾU'!C13) -> IL5 | C27: =IF('ĐỐI CHIẾU'!D13="","",'ĐỐI CHIẾU'!D13) -> Sơn lót nội thất kháng kiềm Silver IL5 | D27: =IF('ĐỐI CHIẾU'!E13="","",'ĐỐI CHIẾU'!E13) -> 5L | E27: =IF('ĐỐI CHIẾU'!F13="","",'ĐỐI CHIẾU'!F13) | F27: =IF('ĐỐI CHIẾU'!J13="","",'ĐỐI CHIẾU'!J13) -> 19 | G27: =IF('ĐỐI CHIẾU'!K13="","",'ĐỐI CHIẾU'!K13) -> 76 | H27: =IF('ĐỐI CHIẾU'!O13="","",'ĐỐI CHIẾU'!O13) -> 57 | I27: =IF('ĐỐI CHIẾU'!P13="","",'ĐỐI CHIẾU'!P13) -> 230602 | J27: =IF(I27="","",H27*I27) -> 13144314
A28: 6 | B28: =IF('ĐỐI CHIẾU'!C14="","",'ĐỐI CHIẾU'!C14) -> IL5 | C28: =IF('ĐỐI CHIẾU'!D14="","",'ĐỐI CHIẾU'!D14) -> Sơn lót nội thất kháng kiềm Silver IL5 | D28: =IF('ĐỐI CHIẾU'!E14="","",'ĐỐI CHIẾU'!E14) -> 18L | E28: =IF('ĐỐI CHIẾU'!F14="","",'ĐỐI CHIẾU'!F14) | F28: =IF('ĐỐI CHIẾU'!J14="","",'ĐỐI CHIẾU'!J14) -> 52 | G28: =IF('ĐỐI CHIẾU'!K14="","",'ĐỐI CHIẾU'!K14) -> 316 | H28: =IF('ĐỐI CHIẾU'!O14="","",'ĐỐI CHIẾU'!O14) -> 264 | I28: =IF('ĐỐI CHIẾU'!P14="","",'ĐỐI CHIẾU'!P14) -> 730646 | J28: =IF(I28="","",H28*I28) -> 192890544
A29: 7 | B29: =IF('ĐỐI CHIẾU'!C15="","",'ĐỐI CHIẾU'!C15) -> EL5 | C29: =IF('ĐỐI CHIẾU'!D15="","",'ĐỐI CHIẾU'!D15) -> Sơn lót ngoại thất kháng kiềm Silver EL5 | D29: =IF('ĐỐI CHIẾU'!E15="","",'ĐỐI CHIẾU'!E15) -> 5L | E29: =IF('ĐỐI CHIẾU'!F15="","",'ĐỐI CHIẾU'!F15) | F29: =IF('ĐỐI CHIẾU'!J15="","",'ĐỐI CHIẾU'!J15) -> 21 | G29: =IF('ĐỐI CHIẾU'!K15="","",'ĐỐI CHIẾU'!K15) -> 72 | H29: =IF('ĐỐI CHIẾU'!O15="","",'ĐỐI CHIẾU'!O15) -> 51 | I29: =IF('ĐỐI CHIẾU'!P15="","",'ĐỐI CHIẾU'!P15) -> 288074 | J29: =IF(I29="","",H29*I29) -> 14691774
A30: 8 | B30: =IF('ĐỐI CHIẾU'!C16="","",'ĐỐI CHIẾU'!C16) -> EL5 | C30: =IF('ĐỐI CHIẾU'!D16="","",'ĐỐI CHIẾU'!D16) -> Sơn lót ngoại thất kháng kiềm Silver EL5 | D30: =IF('ĐỐI CHIẾU'!E16="","",'ĐỐI CHIẾU'!E16) -> 18L | E30: =IF('ĐỐI CHIẾU'!F16="","",'ĐỐI CHIẾU'!F16) | F30: =IF('ĐỐI CHIẾU'!J16="","",'ĐỐI CHIẾU'!J16) -> 53 | G30: =IF('ĐỐI CHIẾU'!K16="","",'ĐỐI CHIẾU'!K16) -> 132 | H30: =IF('ĐỐI CHIẾU'!O16="","",'ĐỐI CHIẾU'!O16) -> 79 | I30: =IF('ĐỐI CHIẾU'!P16="","",'ĐỐI CHIẾU'!P16) -> 1032709 | J30: =IF(I30="","",H30*I30) -> 81584011
A31: 9 | B31: =IF('ĐỐI CHIẾU'!C17="","",'ĐỐI CHIẾU'!C17) -> IEW | C31: =IF('ĐỐI CHIẾU'!D17="","",'ĐỐI CHIẾU'!D17) -> Sơn nội thất siêu trắng Imperia IEW | D31: =IF('ĐỐI CHIẾU'!E17="","",'ĐỐI CHIẾU'!E17) -> 5L | E31: =IF('ĐỐI CHIẾU'!F17="","",'ĐỐI CHIẾU'!F17) | F31: =IF('ĐỐI CHIẾU'!J17="","",'ĐỐI CHIẾU'!J17) -> 17 | G31: =IF('ĐỐI CHIẾU'!K17="","",'ĐỐI CHIẾU'!K17) -> 72 | H31: =IF('ĐỐI CHIẾU'!O17="","",'ĐỐI CHIẾU'!O17) -> 55 | I31: =IF('ĐỐI CHIẾU'!P17="","",'ĐỐI CHIẾU'!P17) -> 298196 | J31: =IF(I31="","",H31*I31) -> 16400780
A32: 10 | B32: =IF('ĐỐI CHIẾU'!C18="","",'ĐỐI CHIẾU'!C18) -> IEW | C32: =IF('ĐỐI CHIẾU'!D18="","",'ĐỐI CHIẾU'!D18) -> Sơn nội thất siêu trắng Imperia IEW | D32: =IF('ĐỐI CHIẾU'!E18="","",'ĐỐI CHIẾU'!E18) -> 18L | E32: =IF('ĐỐI CHIẾU'!F18="","",'ĐỐI CHIẾU'!F18) | F32: =IF('ĐỐI CHIẾU'!J18="","",'ĐỐI CHIẾU'!J18) -> 1 | G32: =IF('ĐỐI CHIẾU'!K18="","",'ĐỐI CHIẾU'!K18) -> 99 | H32: =IF('ĐỐI CHIẾU'!O18="","",'ĐỐI CHIẾU'!O18) -> 98 | I32: =IF('ĐỐI CHIẾU'!P18="","",'ĐỐI CHIẾU'!P18) -> 832340 | J32: =IF(I32="","",H32*I32) -> 81569320
A33: 11 | B33: =IF('ĐỐI CHIẾU'!C19="","",'ĐỐI CHIẾU'!C19) -> ISI | C33: =IF('ĐỐI CHIẾU'!D19="","",'ĐỐI CHIẾU'!D19) -> Sơn nội thất bền màu Silver ISI | D33: =IF('ĐỐI CHIẾU'!E19="","",'ĐỐI CHIẾU'!E19) -> 5L | E33: =IF('ĐỐI CHIẾU'!F19="","",'ĐỐI CHIẾU'!F19) -> B1 | F33: =IF('ĐỐI CHIẾU'!J19="","",'ĐỐI CHIẾU'!J19) -> 21 | G33: =IF('ĐỐI CHIẾU'!K19="","",'ĐỐI CHIẾU'!K19) -> 46 | H33: =IF('ĐỐI CHIẾU'!O19="","",'ĐỐI CHIẾU'!O19) -> 25 | I33: =IF('ĐỐI CHIẾU'!P19="","",'ĐỐI CHIẾU'!P19) -> 181063 | J33: =IF(I33="","",H33*I33) -> 4526575
A34: 12 | B34: =IF('ĐỐI CHIẾU'!C20="","",'ĐỐI CHIẾU'!C20) -> ISI | C34: =IF('ĐỐI CHIẾU'!D20="","",'ĐỐI CHIẾU'!D20) -> Sơn nội thất bền màu Silver ISI | D34: =IF('ĐỐI CHIẾU'!E20="","",'ĐỐI CHIẾU'!E20) -> 18L | E34: =IF('ĐỐI CHIẾU'!F20="","",'ĐỐI CHIẾU'!F20) -> B1 | F34: =IF('ĐỐI CHIẾU'!J20="","",'ĐỐI CHIẾU'!J20) -> 57 | G34: =IF('ĐỐI CHIẾU'!K20="","",'ĐỐI CHIẾU'!K20) -> 202 | H34: =IF('ĐỐI CHIẾU'!O20="","",'ĐỐI CHIẾU'!O20) -> 145 | I34: =IF('ĐỐI CHIẾU'!P20="","",'ĐỐI CHIẾU'!P20) -> 714890 | J34: =IF(I34="","",H34*I34) -> 103659050
A35: 13 | B35: =IF('ĐỐI CHIẾU'!C21="","",'ĐỐI CHIẾU'!C21) -> ISG06 | C35: =IF('ĐỐI CHIẾU'!D21="","",'ĐỐI CHIẾU'!D21) -> Sơn nội thất cao cấp bóng mờ Imperia ISG06 | D35: =IF('ĐỐI CHIẾU'!E21="","",'ĐỐI CHIẾU'!E21) -> 5L | E35: =IF('ĐỐI CHIẾU'!F21="","",'ĐỐI CHIẾU'!F21) -> B1 | F35: =IF('ĐỐI CHIẾU'!J21="","",'ĐỐI CHIẾU'!J21) -> 26 | G35: =IF('ĐỐI CHIẾU'!K21="","",'ĐỐI CHIẾU'!K21) -> 108 | H35: =IF('ĐỐI CHIẾU'!O21="","",'ĐỐI CHIẾU'!O21) -> 82 | I35: =IF('ĐỐI CHIẾU'!P21="","",'ĐỐI CHIẾU'!P21) -> 440079 | J35: =IF(I35="","",H35*I35) -> 36086478
A36: 14 | B36: =IF('ĐỐI CHIẾU'!C22="","",'ĐỐI CHIẾU'!C22) -> ISG06 | C36: =IF('ĐỐI CHIẾU'!D22="","",'ĐỐI CHIẾU'!D22) -> Sơn nội thất cao cấp bóng mờ Imperia ISG06 | D36: =IF('ĐỐI CHIẾU'!E22="","",'ĐỐI CHIẾU'!E22) -> 18L | E36: =IF('ĐỐI CHIẾU'!F22="","",'ĐỐI CHIẾU'!F22) -> B1 | F36: =IF('ĐỐI CHIẾU'!J22="","",'ĐỐI CHIẾU'!J22) -> 53 | G36: =IF('ĐỐI CHIẾU'!K22="","",'ĐỐI CHIẾU'!K22) -> 172 | H36: =IF('ĐỐI CHIẾU'!O22="","",'ĐỐI CHIẾU'!O22) -> 119 | I36: =IF('ĐỐI CHIẾU'!P22="","",'ĐỐI CHIẾU'!P22) -> 1395975 | J36: =IF(I36="","",H36*I36) -> 166121025
A37: 15 | B37: =IF('ĐỐI CHIẾU'!C23="","",'ĐỐI CHIẾU'!C23) -> IG05 | C37: =IF('ĐỐI CHIẾU'!D23="","",'ĐỐI CHIẾU'!D23) -> Sơn nội thất siêu bóng cao cấp Imperia IG05 | D37: =IF('ĐỐI CHIẾU'!E23="","",'ĐỐI CHIẾU'!E23) -> 5L | E37: =IF('ĐỐI CHIẾU'!F23="","",'ĐỐI CHIẾU'!F23) -> B1 | F37: =IF('ĐỐI CHIẾU'!J23="","",'ĐỐI CHIẾU'!J23) -> 94 | G37: =IF('ĐỐI CHIẾU'!K23="","",'ĐỐI CHIẾU'!K23) -> 152 | H37: =IF('ĐỐI CHIẾU'!O23="","",'ĐỐI CHIẾU'!O23) -> 58 | I37: =IF('ĐỐI CHIẾU'!P23="","",'ĐỐI CHIẾU'!P23) -> 605192 | J37: =IF(I37="","",H37*I37) -> 35101136
A38: 16 | B38: =IF('ĐỐI CHIẾU'!C24="","",'ĐỐI CHIẾU'!C24) -> IG05 | C38: =IF('ĐỐI CHIẾU'!D24="","",'ĐỐI CHIẾU'!D24) -> Sơn nội thất siêu bóng cao cấp Imperia IG05 | D38: =IF('ĐỐI CHIẾU'!E24="","",'ĐỐI CHIẾU'!E24) -> 18L | E38: =IF('ĐỐI CHIẾU'!F24="","",'ĐỐI CHIẾU'!F24) -> B1 | F38: =IF('ĐỐI CHIẾU'!J24="","",'ĐỐI CHIẾU'!J24) -> 102 | G38: =IF('ĐỐI CHIẾU'!K24="","",'ĐỐI CHIẾU'!K24) -> 156 | H38: =IF('ĐỐI CHIẾU'!O24="","",'ĐỐI CHIẾU'!O24) -> 54 | I38: =IF('ĐỐI CHIẾU'!P24="","",'ĐỐI CHIẾU'!P24) -> 1599746 | J38: =IF(I38="","",H38*I38) -> 86386284
A39: 17 | B39: =IF('ĐỐI CHIẾU'!C27="","",'ĐỐI CHIẾU'!C27) -> DECO | C39: =IF('ĐỐI CHIẾU'!D27="","",'ĐỐI CHIẾU'!D27) -> Sơn nội thất kinh tế Deco IDC | D39: =IF('ĐỐI CHIẾU'!E27="","",'ĐỐI CHIẾU'!E27) -> 18L | E39: =IF('ĐỐI CHIẾU'!F27="","",'ĐỐI CHIẾU'!F27) -> B1 | F39: =IF('ĐỐI CHIẾU'!J27="","",'ĐỐI CHIẾU'!J27) -> 61 | G39: =IF('ĐỐI CHIẾU'!K27="","",'ĐỐI CHIẾU'!K27) -> 724 | H39: =IF('ĐỐI CHIẾU'!O27="","",'ĐỐI CHIẾU'!O27) -> 663 | I39: =IF('ĐỐI CHIẾU'!P27="","",'ĐỐI CHIẾU'!P27) -> 325693 | J39: =IF(I39="","",H39*I39) -> 215934459
A40: 18 | B40: =IF('ĐỐI CHIẾU'!C28="","",'ĐỐI CHIẾU'!C28) -> ICL | C40: =IF('ĐỐI CHIẾU'!D28="","",'ĐỐI CHIẾU'!D28) -> Sơn phủ nội thất bóng cao cấp ICL | D40: =IF('ĐỐI CHIẾU'!E28="","",'ĐỐI CHIẾU'!E28) -> 1L | E40: =IF('ĐỐI CHIẾU'!F28="","",'ĐỐI CHIẾU'!F28) | F40: =IF('ĐỐI CHIẾU'!J28="","",'ĐỐI CHIẾU'!J28) -> 18 | G40: =IF('ĐỐI CHIẾU'!K28="","",'ĐỐI CHIẾU'!K28) -> 120 | H40: =IF('ĐỐI CHIẾU'!O28="","",'ĐỐI CHIẾU'!O28) -> 102 | I40: =IF('ĐỐI CHIẾU'!P28="","",'ĐỐI CHIẾU'!P28) -> 162365 | J40: =IF(I40="","",H40*I40) -> 16561230
A41: 19 | B41: =IF('ĐỐI CHIẾU'!C29="","",'ĐỐI CHIẾU'!C29) -> ESI | C41: =IF('ĐỐI CHIẾU'!D29="","",'ĐỐI CHIẾU'!D29) -> Sơn ngoại thất bền màu Silver ESI | D41: =IF('ĐỐI CHIẾU'!E29="","",'ĐỐI CHIẾU'!E29) -> 5L | E41: =IF('ĐỐI CHIẾU'!F29="","",'ĐỐI CHIẾU'!F29) -> B1 | F41: =IF('ĐỐI CHIẾU'!J29="","",'ĐỐI CHIẾU'!J29) -> 27 | G41: =IF('ĐỐI CHIẾU'!K29="","",'ĐỐI CHIẾU'!K29) -> 62 | H41: =IF('ĐỐI CHIẾU'!O29="","",'ĐỐI CHIẾU'!O29) -> 35 | I41: =IF('ĐỐI CHIẾU'!P29="","",'ĐỐI CHIẾU'!P29) -> 278872 | J41: =IF(I41="","",H41*I41) -> 9760520
A42: 20 | B42: =IF('ĐỐI CHIẾU'!C30="","",'ĐỐI CHIẾU'!C30) -> ESI | C42: =IF('ĐỐI CHIẾU'!D30="","",'ĐỐI CHIẾU'!D30) -> Sơn ngoại thất bền màu Silver ESI | D42: =IF('ĐỐI CHIẾU'!E30="","",'ĐỐI CHIẾU'!E30) -> 5L | E42: =IF('ĐỐI CHIẾU'!F30="","",'ĐỐI CHIẾU'!F30) -> B2 | F42: =IF('ĐỐI CHIẾU'!J30="","",'ĐỐI CHIẾU'!J30) -> 0 | G42: =IF('ĐỐI CHIẾU'!K30="","",'ĐỐI CHIẾU'!K30) -> 16 | H42: =IF('ĐỐI CHIẾU'!O30="","",'ĐỐI CHIẾU'!O30) -> 16 | I42: =IF('ĐỐI CHIẾU'!P30="","",'ĐỐI CHIẾU'!P30) -> 299792 | J42: =IF(I42="","",H42*I42) -> 4796672
A43: 21 | B43: =IF('ĐỐI CHIẾU'!C32="","",'ĐỐI CHIẾU'!C32) -> ESG10 | C43: =IF('ĐỐI CHIẾU'!D32="","",'ĐỐI CHIẾU'!D32) -> Sơn ngoại thất cao cấp bóng mờ Imperia ESG10 | D43: =IF('ĐỐI CHIẾU'!E32="","",'ĐỐI CHIẾU'!E32) -> 1L | E43: =IF('ĐỐI CHIẾU'!F32="","",'ĐỐI CHIẾU'!F32) -> B1 | F43: =IF('ĐỐI CHIẾU'!J32="","",'ĐỐI CHIẾU'!J32) -> 68 | G43: =IF('ĐỐI CHIẾU'!K32="","",'ĐỐI CHIẾU'!K32) -> 85 | H43: =IF('ĐỐI CHIẾU'!O32="","",'ĐỐI CHIẾU'!O32) -> 17 | I43: =IF('ĐỐI CHIẾU'!P32="","",'ĐỐI CHIẾU'!P32) -> 129341 | J43: =IF(I43="","",H43*I43) -> 2198797
...

Sheet MÀU TINTING
A1: MÀU TINTING (TINH MÀU)
A2: Kiểm kê tính theo "1 lon" còn phần mềm tính theo Lít – em coi 1 lon = 1 lít (AXX: 7 lon = 7 lít khớp nhau).
A4: STT | B4: Mã màu | C4: Tên màu trên phần mềm | D4: Thực tế (lon) | E4: Hóa đơn (lít) | F4: Chênh lệch (TT − HĐ) | G4: Kết luận | H4: Xuất từ kho thực tế | I4: Xuất từ kho hóa đơn | J4: Đơn giá BQ | K4: Giá trị xuất
A5: 1 | B5: AN | D5: 14 | E5: 0 | F5: =D5-E5 -> 14 | G5: =IF(F5>0,"Thực tế nhiều hơn HĐ",IF(F5<0,"HĐ nhiều hơn thực tế","Khớp")) -> Thực tế nhiều hơn HĐ | H5: =MAX(F5,0) -> 14 | I5: =MAX(-F5,0) -> 0 | K5: =IF(J5="","",(H5+I5)*J5)
A6: 2 | B6: AXX | C6: Màu tinting AXX Organic Yellow | D6: 7 | E6: 7 | F6: =D6-E6 -> 0 | G6: =IF(F6>0,"Thực tế nhiều hơn HĐ",IF(F6<0,"HĐ nhiều hơn thực tế","Khớp")) -> Khớp | H6: =MAX(F6,0) -> 0 | I6: =MAX(-F6,0) -> 0 | J6: 807804 | K6: =IF(J6="","",(H6+I6)*J6) -> 0
A7: 3 | B7: B | C7: Màu tinting B Lamp Black | D7: 6 | E7: 47 | F7: =D7-E7 -> -41 | G7: =IF(F7>0,"Thực tế nhiều hơn HĐ",IF(F7<0,"HĐ nhiều hơn thực tế","Khớp")) -> HĐ nhiều hơn thực tế | H7: =MAX(F7,0) -> 0 | I7: =MAX(-F7,0) -> 41 | J7: 229650 | K7: =IF(J7="","",(H7+I7)*J7) -> 9415650
A8: 4 | B8: C | C8: Màu tinting C Yellow Oxide | D8: 11 | E8: 40 | F8: =D8-E8 -> -29 | G8: =IF(F8>0,"Thực tế nhiều hơn HĐ",IF(F8<0,"HĐ nhiều hơn thực tế","Khớp")) -> HĐ nhiều hơn thực tế | H8: =MAX(F8,0) -> 0 | I8: =MAX(-F8,0) -> 29 | J8: 331833 | K8: =IF(J8="","",(H8+I8)*J8) -> 9623157
A9: 5 | B9: D | D9: 8 | E9: 0 | F9: =D9-E9 -> 8 | G9: =IF(F9>0,"Thực tế nhiều hơn HĐ",IF(F9<0,"HĐ nhiều hơn thực tế","Khớp")) -> Thực tế nhiều hơn HĐ | H9: =MAX(F9,0) -> 8 | I9: =MAX(-F9,0) -> 0 | K9: =IF(J9="","",(H9+I9)*J9)
A10: 6 | B10: E | C10: Màu tinting E Phathalo blue | D10: 16 | E10: 48 | F10: =D10-E10 -> -32 | G10: =IF(F10>0,"Thực tế nhiều hơn HĐ",IF(F10<0,"HĐ nhiều hơn thực tế","Khớp")) -> HĐ nhiều hơn thực tế | H10: =MAX(F10,0) -> 0 | I10: =MAX(-F10,0) -> 32 | J10: 382741 | K10: =IF(J10="","",(H10+I10)*J10) -> 12247712
A11: 7 | B11: F | C11: Màu tinting F Red Oxide | D11: 6 | E11: 2 | F11: =D11-E11 -> 4 | G11: =IF(F11>0,"Thực tế nhiều hơn HĐ",IF(F11<0,"HĐ nhiều hơn thực tế","Khớp")) -> Thực tế nhiều hơn HĐ | H11: =MAX(F11,0) -> 4 | I11: =MAX(-F11,0) -> 0 | J11: 510185 | K11: =IF(J11="","",(H11+I11)*J11) -> 2040740
A12: 8 | B12: I | D12: 10 | E12: 0 | F12: =D12-E12 -> 10 | G12: =IF(F12>0,"Thực tế nhiều hơn HĐ",IF(F12<0,"HĐ nhiều hơn thực tế","Khớp")) -> Thực tế nhiều hơn HĐ | H12: =MAX(F12,0) -> 10 | I12: =MAX(-F12,0) -> 0 | K12: =IF(J12="","",(H12+I12)*J12)
A13: 9 | B13: KXX | D13: 0 | E13: 0 | F13: =D13-E13 -> 0 | G13: =IF(F13>0,"Thực tế nhiều hơn HĐ",IF(F13<0,"HĐ nhiều hơn thực tế","Khớp")) -> Khớp | H13: =MAX(F13,0) -> 0 | I13: =MAX(-F13,0) -> 0 | K13: =IF(J13="","",(H13+I13)*J13)
A14: 10 | B14: KX | C14: Màu tinting KX Titanum White | D14: 8 | E14: 9 | F14: =D14-E14 -> -1 | G14: =IF(F14>0,"Thực tế nhiều hơn HĐ",IF(F14<0,"HĐ nhiều hơn thực tế","Khớp")) -> HĐ nhiều hơn thực tế | H14: =MAX(F14,0) -> 0 | I14: =MAX(-F14,0) -> 1 | J14: 445987 | K14: =IF(J14="","",(H14+I14)*J14) -> 445987
A15: 11 | B15: L | C15: Màu tinting L Raw umber | D15: 7 | E15: 6 | F15: =D15-E15 -> 1 | G15: =IF(F15>0,"Thực tế nhiều hơn HĐ",IF(F15<0,"HĐ nhiều hơn thực tế","Khớp")) -> Thực tế nhiều hơn HĐ | H15: =MAX(F15,0) -> 1 | I15: =MAX(-F15,0) -> 0 | J15: 382407 | K15: =IF(J15="","",(H15+I15)*J15) -> 382407
A16: 12 | B16: R | D16: 17 | E16: 0 | F16: =D16-E16 -> 17 | G16: =IF(F16>0,"Thực tế nhiều hơn HĐ",IF(F16<0,"HĐ nhiều hơn thực tế","Khớp")) -> Thực tế nhiều hơn HĐ | H16: =MAX(F16,0) -> 17 | I16: =MAX(-F16,0) -> 0 | K16: =IF(J16="","",(H16+I16)*J16)
A17: 13 | B17: RN | D17: 11 | E17: 0 | F17: =D17-E17 -> 11 | G17: =IF(F17>0,"Thực tế nhiều hơn HĐ",IF(F17<0,"HĐ nhiều hơn thực tế","Khớp")) -> Thực tế nhiều hơn HĐ | H17: =MAX(F17,0) -> 11 | I17: =MAX(-F17,0) -> 0 | K17: =IF(J17="","",(H17+I17)*J17)
A18: 14 | B18: T | C18: Màu tinting T Medium Yellow | D18: 15 | E18: 8 | F18: =D18-E18 -> 7 | G18: =IF(F18>0,"Thực tế nhiều hơn HĐ",IF(F18<0,"HĐ nhiều hơn thực tế","Khớp")) -> Thực tế nhiều hơn HĐ | H18: =MAX(F18,0) -> 7 | I18: =MAX(-F18,0) -> 0 | J18: 1037037 | K18: =IF(J18="","",(H18+I18)*J18) -> 7259259
A19: 15 | B19: V | D19: 5 | E19: 0 | F19: =D19-E19 -> 5 | G19: =IF(F19>0,"Thực tế nhiều hơn HĐ",IF(F19<0,"HĐ nhiều hơn thực tế","Khớp")) -> Thực tế nhiều hơn HĐ | H19: =MAX(F19,0) -> 5 | I19: =MAX(-F19,0) -> 0 | K19: =IF(J19="","",(H19+I19)*J19)
B20: TỔNG | D20: =SUM(D5:D19) -> 141 | E20: =SUM(E5:E19) -> 167 | F20: =SUM(F5:F19) -> -26 | H20: =SUM(H5:H19) -> 77 | I20: =SUM(I5:I19) -> 103 | K20: =SUM(K5:K19) -> 41414912
A22: Mã AN, D, I, KXX, R, RN, V chỉ có trong kiểm kê, phần mềm không có mã tương ứng. Chưa rõ tên màu của các mã đó nên em để trống phần mềm = 0.

Sheet MÀU ĐÃ PHA
A1: MÀU ĐÃ PHA (đã pha sẵn, chưa bán) – KHÔNG tính vào đối chiếu
A2: Kiểm kê thực tế ngày 09/10/2026. Đây là sơn thành phẩm đã pha màu; chưa rõ trên phần mềm đã trừ base hay chưa nên em để riêng.
A4: STT | B4: Chủng loại / mã màu | C4: 18L | D4: 5L | E4: 1L | F4: Ghi chú
A5: 1 | B5: DECO-079 | C5: 1
A6: 2 | B6: ISI-099 | C6: 1 | F6: xanh
A7: 3 | B7: EG09 135 | C7: 3
A8: 4 | B8: IG05-057 | C8: 2
A9: 5 | B9: IG05-134 | C9: 5
A10: 6 | B10: IG06-182 | C10: 1 | F10: vàng
A11: 7 | B11: EG09 (Trắng sứ) | C11: 1
A12: 8 | B12: IG05-211 | D12: 2
A13: 9 | B13: IG05- 333 | D13: 1
A14: 10 | B14: IG05-138 | D14: 1
A15: 11 | B15: ESI-343 | D15: 1
A16: 12 | B16: E9-013 | E16: 1
A17: 13 | B17: EG09 128-6 | E17: 1
B18: TỔNG | C18: =SUM(C5:C17) -> 14 | D18: =SUM(D5:D17) -> 5 | E18: =SUM(E5:E17) -> 2

Sheet GHI CHÚ
A1: CÁCH LÀM VÀ CÁC ĐIỂM CẦN CHỊ XÁC NHẬN
A4: Cách đối chiếu | B4: So từng mặt hàng theo Mã SP + Dung tích + Base (B1–B4). Kho thực tế lấy từ các sheet "18 LÍT", "5 LÍT", "1 LÍT" (nhà + Việt cộng lại). Kho hóa đơn lấy từ file Tổng hợp tồn kho (cột Cuối kỳ).
A5: Quy tắc đưa về 1 kho | B5: Tồn thống nhất = số NHỎ HƠN của hai kho. Thực tế nhiều hơn hóa đơn → xuất phần dư khỏi kho thực tế (đúng yêu cầu của chị). Hóa đơn nhiều hơn thực tế → em xếp vào Phần B của PHIẾU XUẤT (xuất điều chỉnh trên phần mềm) vì chị chưa nói cách xử lý trường hợp này – chị xác nhận giúp em.
A6: Hầu hết là hóa đơn nhiều hơn thực tế | B6: Trong ~70 dòng, phần lớn kho phần mềm nhiều hơn kiểm kê (xem TỔNG QUAN). Chỉ có vài dòng thực tế nhiều hơn, lớn nhất là EG09 18L B1 (thực tế 218, hóa đơn 50, dư 168 thùng).
A7: DECO 18L | B7: Phần mềm có 2 mã DECO 18L B1 (314 thùng) và IDC 18L B1 (410 thùng) = 724, kiểm kê chỉ có 61 thùng → lệch 663 thùng. Chị kiểm lại đây có phải nhập nhầm số lượng không.
A8: Bột bả | B8: Phần mềm: IP15 85 bao, EP14 91 bao, IP201 80 bao. Kiểm kê chỉ có 29 bao bả ngoại. Mã IP201 không có trong bảng kiểm kê.
A9: Các mã chỉ có ở một bên | B9: Chỉ có trên phần mềm: ETM 05kg AP128-5 (32 lon), ETM IP320 (6 thùng), bả IP201 (80 bao). Chỉ có trong kiểm kê (phần mềm không có dòng): PI04 5L, SPI03 5L, SPE01 5L, E9 5L B4, E9 1L B1/B4.
A10: Dung tích 5L ETM-309 | B10: Kiểm kê 18L = 77, 5L = 44; phần mềm 18L = 90, 5L = 31. Đối chiếu này cũng cho thấy số tồn đầu kỳ ETM-309 18L = 120 ở file trước là đúng (đã đảo trong sheet DMHH_Gộp).
A11: Màu đã pha | B11: 14 thùng 18L, 5 lon 5L, 2 lon 1L sơn đã pha màu chưa bán. Em không cộng vào kho thực tế (đúng như sheet "Tồn cuối" của chị) và để riêng ở sheet MÀU ĐÃ PHA. Nếu phần mềm chưa trừ base cho các thùng này thì thực tế nên cộng thêm.
A12: Màu tinting | B12: Kiểm kê tính "lon", phần mềm tính "Lít" → coi 1 lon = 1 lít. Mã AN, D, I, KXX, R, RN, V không có mã tương ứng trên phần mềm.
A13: Ngày số liệu | B13: Thực tế 09/10/2026; hóa đơn đến 10/10/2026. Sheet "5 LÍT" trong file kiểm kê vẫn ghi tiêu đề "hết 18/7/2026" nhưng số liệu em dùng như số 09/10 (cùng file kiểm kê). Chị kiểm tra lại giúp em.
