Workbook

Sheet Tồn cuối
B2: Tồn kho sơn tường Thực tế 9/10/2026 | F2: Tồn Phần mềm | I2: Chênh | L2: Đặt sơn
A3: Số TT | B3: Chủng loại | C3: Đến hết ngày 09/10/2026 | F3: Hết ngày 10/10/2026 | I3: Thực tế − Phần mềm
C4: 18L | D4: 5L | E4: 1L | F4: 18L | G4: 5L | H4: 1L | I4: 18L | J4: 5L | K4: 1L | L4: 18L | M4: 5L | N4: 1L
C6: =SUM(C7:C57) -> 1301 | D6: =SUM(D7:D57) -> 750 | E6: =SUM(E7:E57) -> 350 | F6: =SUM(F7:F57) -> 3063 | G6: =SUM(G7:G57) -> 1556 | H6: =SUM(H7:H57) -> 740 | I6: =SUM(I7:I57) -> -1762 | J6: =SUM(J7:J57) -> -806 | ... N6: =SUM(N7:N57) -> 0
A7: 1 | B7: PI04 | C7: ='18 LÍT'!C7 -> 207 | D7: ='5 LÍT'!C7 -> 2 | F7: 221 | G7: 0 | I7: =N(C7)-F7 -> -14 | J7: =N(D7)-G7 -> 2
A8: 2 | B8: PE02 | C8: ='18 LÍT'!C8 -> 217 | D8: ='5 LÍT'!C8 -> 0 | F8: 240 | G8: 60 | I8: =N(C8)-F8 -> -23 | J8: =N(D8)-G8 -> -60
A9: 3 | B9: SPI03 | C9: ='18 LÍT'!C9 -> 20 | D9: ='5 LÍT'!C9 -> 7 | F9: 20 | G9: 0 | I9: =N(C9)-F9 -> 0 | J9: =N(D9)-G9 -> 7
A10: 4 | B10: SPE01 | C10: ='18 LÍT'!C10 -> 14 | D10: ='5 LÍT'!C10 -> 4 | F10: 35 | G10: 0 | I10: =N(C10)-F10 -> -21 | J10: =N(D10)-G10 -> 4
A11: 5 | B11: IEW | C11: ='18 LÍT'!C11 -> 1 | D11: ='5 LÍT'!C11 -> 17 | F11: 99 | G11: 72 | I11: =N(C11)-F11 -> -98 | J11: =N(D11)-G11 -> -55
A12: 6 | B12: CT12 | C12: ='18 LÍT'!C12 -> 24 | D12: ='5 LÍT'!C12 -> 29 | F12: 80 | G12: 70 | I12: =N(C12)-F12 -> -56 | J12: =N(D12)-G12 -> -41
A13: 7 | B13: ETM-309 | C13: ='18 LÍT'!C13 -> 77 | D13: ='5 LÍT'!C13 -> 44 | F13: 90 | G13: 31 | I13: =N(C13)-F13 -> -13 | J13: =N(D13)-G13 -> 13
A14: 8 | B14: CTS | C14: ='18 LÍT'!C14 -> 4 | D14: ='5 LÍT'!C14 -> 11 | F14: 101 | G14: 21 | I14: =N(C14)-F14 -> -97 | J14: =N(D14)-G14 -> -10
A15: 9 | B15: ISI B1 | C15: ='18 LÍT'!C15 -> 57 | D15: ='5 LÍT'!C15 -> 21 | F15: 202 | G15: 46 | I15: =N(C15)-F15 -> -145 | J15: =N(D15)-G15 -> -25
A16: 10 | B16: ISI B2 | C16: ='18 LÍT'!C16 -> 0 | D16: ='5 LÍT'!C16 -> 0 | F16: 0 | G16: 0 | I16: =N(C16)-F16 -> 0 | J16: =N(D16)-G16 -> 0
A17: 11 | B17: ISI B3 | C17: ='18 LÍT'!C17 -> 0 | D17: ='5 LÍT'!C17 -> 0 | F17: 0 | G17: 0 | I17: =N(C17)-F17 -> 0 | J17: =N(D17)-G17 -> 0
A18: 12 | B18: ISI B4 | C18: ='18 LÍT'!C18 -> 0 | D18: ='5 LÍT'!C18 -> 0 | F18: 0 | G18: 0 | I18: =N(C18)-F18 -> 0 | J18: =N(D18)-G18 -> 0
... A32: 26 | B32: IG06 B4 | C32: ='18 LÍT'!C32 -> 0 | D32: ='5 LÍT'!C32 -> 0 | F32: 0 | G32: 0 | I32: =N(C32)-F32 -> 0 | J32: =N(D32)-G32 -> 0
A33: 27 | B33: EG09-B1 | C33: ='18 LÍT'!C33 -> 218 | D33: ='5 LÍT'!C33 -> 62 | E33: ='1 LÍT'!C33 -> 30 | F33: 50 | G33: 104 | H33: 103 | I33: =N(C33)-F33 -> 168 | J33: =N(D33)-G33 -> -42 | K33: =N(E33)-H33 -> -73
A34: 28 | B34: EG09-B2 | C34: ='18 LÍT'!C34 -> 0 | D34: ='5 LÍT'!C34 -> 53 | E34: ='1 LÍT'!C34 -> 36 | F34: 0 | G34: 79 | H34: 86 | I34: =N(C34)-F34 -> 0 | J34: =N(D34)-G34 -> -26 | K34: =N(E34)-H34 -> -50
A35: 29 | B35: EG09-B3 | C35: ='18 LÍT'!C35 -> 0 | D35: ='5 LÍT'!C35 -> 64 | E35: ='1 LÍT'!C35 -> 34 | F35: 5 | G35: 86 | H35: 110 | I35: =N(C35)-F35 -> -5 | J35: =N(D35)-G35 -> -22 | K35: =N(E35)-H35 -> -76
A36: 30 | B36: EG09-B4 | C36: ='18 LÍT'!C36 -> 0 | D36: ='5 LÍT'!C36 -> 58 | E36: ='1 LÍT'!C36 -> 37 | F36: 0 | G36: 78 | H36: 96 | I36: =N(C36)-F36 -> 0 | J36: =N(D36)-G36 -> -20 | K36: =N(E36)-H36 -> -59
A37: 31 | B37: ESG10-B1 | C37: ='18 LÍT'!C37 -> 20 | D37: ='5 LÍT'!C37 -> 23 | E37: ='1 LÍT'!C37 -> 68 | F37: 30 | G37: 64 | H37: 85 | I37: =N(C37)-F37 -> -10 | J37: =N(D37)-G37 -> -41 | K37: =N(E37)-H37 -> -17
A38: 32 | B38: ESG10-B2 | C38: ='18 LÍT'!C38 -> 0 | D38: ='5 LÍT'!C38 -> 28 | E38: ='1 LÍT'!C38 -> 45 | F38: 0 | G38: 44 | H38: 36 | I38: =N(C38)-F38 -> 0 | J38: =N(D38)-G38 -> -16 | K38: =N(E38)-H38 -> 9
A39: 33 | B39: ESG10-B3 | C39: ='18 LÍT'!C39 -> 0 | D39: ='5 LÍT'!C39 -> 30 | E39: ='1 LÍT'!C39 -> 44 | F39: 0 | G39: 56 | H39: 60 | I39: =N(C39)-F39 -> 0 | J39: =N(D39)-G39 -> -26 | K39: =N(E39)-H39 -> -16
A40: 34 | B40: ESG10-B4 | C40: ='18 LÍT'!C40 -> 0 | D40: ='5 LÍT'!C40 -> 14 | E40: ='1 LÍT'!C40 -> 32 | F40: 0 | G40: 56 | H40: 44 | I40: =N(C40)-F40 -> 0 | J40: =N(D40)-G40 -> -42 | K40: =N(E40)-H40 -> -12
A41: 35 | B41: I9-B1 | C41: ='18 LÍT'!C41 -> 24 | D41: ='5 LÍT'!C41 -> 11 | E41: ='1 LÍT'!C41 -> 0 | F41: 24 | G41: 4 | H41: 0 | I41: =N(C41)-F41 -> 0 | J41: =N(D41)-G41 -> 7 | K41: =N(E41)-H41 -> 0
A42: 36 | B42: I9-B2 | C42: ='18 LÍT'!C42 -> 0 | D42: ='5 LÍT'!C42 -> 0 | E42: ='1 LÍT'!C42 -> 0 | F42: 0 | G42: 0 | H42: 0 | I42: =N(C42)-F42 -> 0 | J42: =N(D42)-G42 -> 0 | K42: =N(E42)-H42 -> 0
A43: 37 | B43: I9-B3 | C43: ='18 LÍT'!C43 -> 0 | D43: ='5 LÍT'!C43 -> 0 | E43: ='1 LÍT'!C43 -> 0 | F43: 0 | G43: 0 | H43: 0 | I43: =N(C43)-F43 -> 0 | J43: =N(D43)-G43 -> 0 | K43: =N(E43)-H43 -> 0
A44: 38 | B44: I9-B4 | C44: ='18 LÍT'!C44 -> 0 | D44: ='5 LÍT'!C44 -> 0 | E44: ='1 LÍT'!C44 -> 0 | F44: 0 | G44: 0 | H44: 0 | I44: =N(C44)-F44 -> 0 | J44: =N(D44)-G44 -> 0 | K44: =N(E44)-H44 -> 0
... A52: 46 | B52: ETM-303 | C52: ='18 LÍT'!C52 -> 0 | D52: ='5 LÍT'!C52 -> 0 | E52: ='1 LÍT'!C52 -> 0 | F52: 3 | G52: 2 | H52: 0 | I52: =N(C52)-F52 -> -3 | J52: =N(D52)-G52 -> -2 | K52: =N(E52)-H52 -> 0
A53: 47 | B53: Bả nội | C53: ='18 LÍT'!C53 -> 0 | D53: ='5 LÍT'!C53 -> 0 | E53: ='1 LÍT'!C53 -> 0 | F53: 85 | I53: =N(C53)-F53 -> -85
A54: 48 | B54: Bả ngoại | C54: ='18 LÍT'!C54 -> 29 | D54: ='5 LÍT'!C54 -> 0 | E54: ='1 LÍT'!C54 -> 0 | F54: 91 | I54: =N(C54)-F54 -> -62
A55: 49 | B55: ETM 05kg AP128-5 | D55: 0 | G55: 32 | J55: =N(D55)-G55 -> -32
A56: 50 | B56: ETM 18L IP320 | C56: 0 | F56: 6 | I56: =N(C56)-F56 -> -6
A57: 51 | B57: Bả IP201 (nội ngoại) | C57: 0 | F57: 80 | I57: =N(C57)-F57 -> -80
B59: Ghi chú: ô Phần mềm lấy từ file Tổng hợp tồn kho 01/01–10/10/2026 (cột Cuối kỳ). Chênh = Thực tế − Phần mềm (dương: thực tế nhiều hơn; âm đỏ: phần mềm nhiều hơn). Bột bả ghi ở cột 18L (bao 40kg). ETM 05kg AP128-5 ghi ở cột 5L.
B69: ETM-206 | C69: ='18 lít'!#ref! -> #VALUE! | F69: ='18 lít'!#ref! -> #VALUE! | I69: ='18 lít'!#ref! -> #VALUE!

Sheet TINH MÀU
A2: Tồn kho Tinh MÀU | D2: Thực tế hết ngày 9-10 | E2: Phần mềm hết ngày 10/10/2026 | F2: Chênh (Thực tế − Phần mềm) | J2: Đặt tinh màu
A3: ST+A3:AN21T | C3: MÃ | D3: 1 Lon | E3: 1 Lon | F3: 1 Lon | H3: STT | J3: MÃ | K3: 1 lon
D5: =SUM(D6:D21) -> 141 | E5: =SUM(E6:E21) -> 167 | F5: =SUM(F6:F21) -> -26 | G5: =SUM(G6:G21) -> 0 | K5: =SUM(K6:K19) -> 0
A6: 1 | B6: 1 | C6: AN | D6: 14 | E6: 0 | F6: =N(D6)-E6 -> 14 | I6: 1 | J6: AN
A7: 2 | B7: 2 | C7: AXX | D7: 7 | E7: 7 | F7: =N(D7)-E7 -> 0 | I7: 2 | J7: AXX
A8: 3 | B8: 3 | C8: B | D8: 6 | E8: 47 | F8: =N(D8)-E8 -> -41 | I8: 3 | J8: B
A9: 4 | B9: 4 | C9: C | D9: 11 | E9: 40 | F9: =N(D9)-E9 -> -29 | I9: 4 | J9: C
A10: 5 | B10: 5 | C10: D | D10: 8 | E10: 0 | F10: =N(D10)-E10 -> 8 | I10: 5 | J10: D
A11: 6 | B11: 6 | C11: E | D11: 16 | E11: 48 | F11: =N(D11)-E11 -> -32 | I11: 6 | J11: E
A12: 7 | B12: 7 | C12: F | D12: 6 | E12: 2 | F12: =N(D12)-E12 -> 4 | I12: 7 | J12: F
A13: 8 | B13: 8 | C13: I | D13: 10 | E13: 0 | F13: =N(D13)-E13 -> 10 | I13: 8 | J13: I
A14: 9 | B14: 9 | C14: KXX | D14: 0 | E14: 0 | F14: =N(D14)-E14 -> 0 | I14: 9 | J14: KXX
A15: 10 | B15: 10 | C15: L | D15: 7 | E15: 6 | F15: =N(D15)-E15 -> 1 | I15: 10 | J15: L
A16: 11 | B16: 11 | C16: R | D16: 17 | E16: 0 | F16: =N(D16)-E16 -> 17 | I16: 11 | J16: R
A17: 12 | B17: 12 | C17: RN | D17: 11 | E17: 0 | F17: =N(D17)-E17 -> 11 | I17: 12 | J17: RN
... A19: 14 | B19: 14 | C19: V | D19: 5 | E19: 0 | F19: =N(D19)-E19 -> 5 | I19: 14 | J19: V
A20: 15 | C20: KX | D20: 8 | E20: 9 | F20: =N(D20)-E20 -> -1
C23: Phần mềm tính theo Lít, kiểm kê tính theo lon (coi 1 lon = 1 lít). Mã AN, D, I, KXX, R, RN, V không có mã trên phần mềm → ghi 0.

Sheet Màu đã pha
B2: Đã Pha hết 9/10/2026
A4: Số TT | B4: Chủng loại | C4: 18L | D4: 5L | E4: 1L | F4: Màu
C6: =SUM(C7:C19) -> 14 | D6: =SUM(D7:D19) -> 5 | E6: =SUM(E7:E19) -> 2 | F6: =SUM(F7:F19) -> 0
A7: 1 | B7: DECO-079 | C7: 1
A8: 2 | B8: ISI-099 | C8: 1 | F8: xanh
A9: 3 | B9: EG09 135 | C9: 3
A10: 4 | B10: IG05-057 | C10: 2
A11: 5 | B11: IG05-134 | C11: 5
A12: 6 | B12: IG06-182 | C12: 1 | F12: vàng
A13: 7 | B13: EG09 (Trắng sứ) | C13: 1
A14: 8 | B14: IG05-211 | D14: 2
A15: 9 | B15: IG05- 333 | D15: 1
A16: 10 | B16: IG05-138 | D16: 1
A17: 11 | B17: ESI-343 | D17: 1
A18: 12 | B18: E9-013 | E18: 1
A19: 13 | B19: EG09 128-6 | E19: 1

Sheet 18 LÍT
B2: Tồn kho sơn tường hết 9/10/2026
A4: Số TT | B4: Chủng loại | C4: 18L | D4: NHÀ | E4: Việt | F4: 1 | G4: 2 | H4: 3 | I4: 4 | J4: 5 | K4: 6 | L4: 7 | M4: 8 | N4: 9 | O4: 10 | P4: 11 | Q4: 12 | R4: 13 | S4: 14 | T4: 15 | U4: 16 | V4: 17 | W4: 18 | X4: 19 | Y4: 20 | Z4: 21 | AA4: 22 | AB4: 23 | AC4: 24 | AD4: 25 | AE4: 26 | AF4: 27 | AG4: 28 | AH4: 29 | AI4: 30 | AJ4: 31 | AK4: Tổng xuất | AL4: C Dung 3/1 | AS4: Tồn cuối
C6: =SUM(C7:C52) -> 1272 | F6: =SUM(F7:F52) -> 0 | G6: =SUM(G7:G52) -> 0 | H6: =SUM(H7:H52) -> 0 | I6: =SUM(I7:I52) -> 0 | J6: =SUM(J7:J52) -> 0 | K6: =SUM(K7:K52) -> 0 | L6: =SUM(L7:L52) -> 0 | M6: =SUM(M7:M52) -> 0 | ... AS6: =SUM(AS7:AS52) -> 1272
A7: 1 | B7: PI04 | C7: =D7+E7 -> 207 | D7: 118 | E7: 89 | AS7: =C7-AK7+AL7+AM7+AN7+AO7+AP7+AQ7+AR7 -> 207
A8: 2 | B8: PE02 | C8: =D8+E8 -> 217 | D8: 187 | E8: 30 | AS8: =C8-AK8+AL8+AM8+AN8+AO8+AP8+AQ8+AR8 -> 217
A9: 3 | B9: SPI03 | C9: =D9+E9 -> 20 | D9: 10 | E9: 10 | AS9: =C9-AK9+AL9+AM9+AN9+AO9+AP9+AQ9+AR9 -> 20
A10: 4 | B10: SPE01 | C10: =D10+E10 -> 14 | D10: 4 | E10: 10 | AS10: =C10-AK10+AL10+AM10+AN10+AO10+AP10+AQ10+AR10 -> 14
A11: 5 | B11: IEW | C11: =D11+E11 -> 1 | D11: 0 | E11: 1 | AS11: =C11-AK11+AL11+AM11+AN11+AO11+AP11+AQ11+AR11 -> 1
A12: 6 | B12: CT12 | C12: =D12+E12 -> 24 | D12: 4 | E12: 20 | AS12: =C12-AK12+AL12+AM12+AN12+AO12+AP12+AQ12+AR12 -> 24
A13: 7 | B13: ETM-309 | C13: =D13+E13 -> 77 | D13: 77 | AS13: =C13-AK13+AL13+AM13+AN13+AO13+AP13+AQ13+AR13 -> 77
A14: 8 | B14: CTS | C14: =D14+E14 -> 4 | D14: 4 | AS14: =C14-AK14+AL14+AM14+AN14+AO14+AP14+AQ14+AR14 -> 4
A15: 9 | B15: ISI B1 | C15: =D15+E15 -> 57 | D15: 57 | AS15: =C15-AK15+AL15+AM15+AN15+AO15+AP15+AQ15+AR15 -> 57
A16: 10 | B16: ISI B2 | C16: =D16+E16 -> 0 | AS16: =C16-AK16+AL16+AM16+AN16+AO16+AP16+AQ16+AR16 -> 0
A17: 11 | B17: ISI B3 | C17: =D17+E17 -> 0 | AS17: =C17-AK17+AL17+AM17+AN17+AO17+AP17+AQ17+AR17 -> 0
A18: 12 | B18: ISI B4 | C18: =D18+E18 -> 0 | AS18: =C18-AK18+AL18+AM18+AN18+AO18+AP18+AQ18+AR18 -> 0
A19: 13 | B19: ESI B1 | C19: =D19+E19 -> 67 | D19: 67 | AS19: =C19-AK19+AL19+AM19+AN19+AO19+AP19+AQ19+AR19 -> 67
A20: 14 | B20: ESI B2 | C20: =D20+E20 -> 0 | AS20: =C20-AK20+AL20+AM20+AN20+AO20+AP20+AQ20+AR20 -> 0
A21: 15 | B21: ESI B3 | C21: =D21+E21 -> 0 | AS21: =C21-AK21+AL21+AM21+AN21+AO21+AP21+AQ21+AR21 -> 0
A22: 16 | B22: ESI B4 | C22: =D22+E22 -> 0 | AS22: =C22-AK22+AL22+AM22+AN22+AO22+AP22+AQ22+AR22 -> 0
A23: 17 | B23: IL5 | C23: =D23+E23 -> 52 | D23: 32 | E23: 20 | AS23: =C23-AK23+AL23+AM23+AN23+AO23+AP23+AQ23+AR23 -> 52
A24: 18 | B24: EL5 | C24: =D24+E24 -> 53 | D24: 53 | AS24: =C24-AK24+AL24+AM24+AN24+AO24+AP24+AQ24+AR24 -> 53
A25: 19 | B25: IG05-B1 | C25: =D25+E25 -> 102 | D25: 62 | E25: 40 | AS25: =C25-AK25+AL25+AM25+AN25+AO25+AP25+AQ25+AR25 -> 102
A26: 20 | B26: IG05-B2 | C26: =D26+E26 -> 0 | AS26: =C26-AK26+AL26+AM26+AN26+AO26+AP26+AQ26+AR26 -> 0
A27: 21 | B27: IG05-B3 | C27: =D27+E27 -> 0 | AS27: =C27-AK27+AL27+AM27+AN27+AO27+AP27+AQ27+AR27 -> 0
A28: 22 | B28: IG05-B4 | C28: =D28+E28 -> 0 | AS28: =C28-AK28+AL28+AM28+AN28+AO28+AP28+AQ28+AR28 -> 0
A29: 23 | B29: IG06 B1 | C29: =D29+E29 -> 53 | D29: 23 | E29: 30 | AS29: =C29-AK29+AL29+AM29+AN29+AO29+AP29+AQ29+AR29 -> 53
A30: 24 | B30: IG06 B2 | C30: =D30+E30 -> 0 | AS30: =C30-AK30+AL30+AM30+AN30+AO30+AP30+AQ30+AR30 -> 0
A31: 25 | B31: IG06 B3 | C31: =D31+E31 -> 0 | AS31: =C31-AK31+AL31+AM31+AN31+AO31+AP31+AQ31+AR31 -> 0
A32: 26 | B32: IG06 B4 | C32: =D32+E32 -> 0 | AS32: =C32-AK32+AL32+AM32+AN32+AO32+AP32+AQ32+AR32 -> 0
A33: 27 | B33: EG09-B1 | C33: =D33+E33 -> 218 | D33: 218 | AS33: =C33-AK33+AL33+AM33+AN33+AO33+AP33+AQ33+AR33 -> 218
A34: 28 | B34: EG09-B2 | C34: =D34+E34 -> 0 | AS34: =C34-AK34+AL34+AM34+AN34+AO34+AP34+AQ34+AR34 -> 0
A35: 29 | B35: EG09-B3 | C35: =D35+E35 -> 0 | AS35: =C35-AK35+AL35+AM35+AN35+AO35+AP35+AQ35+AR35 -> 0
A36: 30 | B36: EG09-B4 | C36: =D36+E36 -> 0 | AS36: =C36-AK36+AL36+AM36+AN36+AO36+AP36+AQ36+AR36 -> 0
A37: 31 | B37: ESG10-B1 | C37: =D37+E37 -> 20 | D37: 20 | AS37: =C37-AK37+AL37+AM37+AN37+AO37+AP37+AQ37+AR37 -> 20
A38: 32 | B38: ESG10-B2 | C38: =D38+E38 -> 0 | AS38: =C38-AK38+AL38+AM38+AN38+AO38+AP38+AQ38+AR38 -> 0
A39: 33 | B39: ESG10-B3 | C39: =D39+E39 -> 0 | AS39: =C39-AK39+AL39+AM39+AN39+AO39+AP39+AQ39+AR39 -> 0
A40: 34 | B40: ESG10-B4 | C40: =D40+E40 -> 0 | AS40: =C40-AK40+AL40+AM40+AN40+AO40+AP40+AQ40+AR40 -> 0
A41: 35 | B41: I9-B1 | C41: =D41+E41 -> 24 | D41: 9 | E41: 15 | AS41: =C41-AK41+AL41+AM41+AN41+AO41+AP41+AQ41+AR41 -> 24
A42: 36 | B42: I9-B2 | C42: =D42+E42 -> 0 | AS42: =C42-AK42+AL42+AM42+AN42+AO42+AP42+AQ42+AR42 -> 0
A43: 37 | B43: I9-B3 | C43: =D43+E43 -> 0 | AS43: =C43-AK43+AL43+AM43+AN43+AO43+AP43+AQ43+AR43 -> 0
...

Sheet 5 LÍT
B2: Tồn kho sơn tường hết 18/7/2026
A4: Số TT | B4: Chủng loại | C4: 5l | D4: NHÀ | E4: Việt | F4: 1 | G4: 2 | H4: 3 | I4: 4 | J4: 5 | K4: 6 | L4: 7 | M4: 8 | N4: 9 | O4: 10 | P4: 11 | Q4: 12 | R4: 13 | S4: 14 | T4: 15 | U4: 16 | V4: 17 | W4: 18 | X4: 19 | Y4: 20 | Z4: 21 | AA4: 22 | AB4: 23 | AC4: 24 | AD4: 25 | AE4: 26 | AF4: 27 | AG4: 28 | AH4: 29 | AI4: 30 | AJ4: 31 | AK4: Tổng xuất | AQ4: Tồn cuối
C6: =SUM(C7:C50) -> 750 | F6: =SUM(F7:F50) -> 0 | G6: =SUM(G7:G50) -> 0 | H6: =SUM(H7:H50) -> 0 | I6: =SUM(I7:I50) -> 0 | J6: =SUM(J7:J50) -> 0 | K6: =SUM(K7:K50) -> 0 | L6: =SUM(L7:L50) -> 0 | M6: =SUM(M7:M50) -> 0 | ... AQ6: =SUM(AQ7:AQ50) -> 750
A7: 1 | B7: PI04 | C7: =D7+E7 -> 2 | D7: 2 | AQ7: =C7-AK7+AL7+AM7+AN7+AO7+AP7 -> 2
A8: 2 | B8: PE02 | C8: =D8+E8 -> 0 | AQ8: =C8-AK8+AL8+AM8+AN8+AO8+AP8 -> 0
A9: 3 | B9: SPI03 | C9: =D9+E9 -> 7 | D9: 7 | AQ9: =C9-AK9+AL9+AM9+AN9+AO9+AP9 -> 7
A10: 4 | B10: SPE01 | C10: =D10+E10 -> 4 | D10: 4 | AQ10: =C10-AK10+AL10+AM10+AN10+AO10+AP10 -> 4
A11: 5 | B11: IEW | C11: =D11+E11 -> 17 | D11: 5 | E11: 12 | AQ11: =C11-AK11+AL11+AM11+AN11+AO11+AP11 -> 17
A12: 6 | B12: CT12 | C12: =D12+E12 -> 29 | D12: 29 | AQ12: =C12-AK12+AL12+AM12+AN12+AO12+AP12 -> 29
A13: 7 | B13: ETM-309 | C13: =D13+E13 -> 44 | D13: 44 | AQ13: =C13-AK13+AL13+AM13+AN13+AO13+AP13 -> 44
A14: 8 | B14: CTS | C14: =D14+E14 -> 11 | D14: 11 | AQ14: =C14-AK14+AL14+AM14+AN14+AO14+AP14 -> 11
A15: 9 | B15: ISI B1 | C15: =D15+E15 -> 21 | D15: 21 | AQ15: =C15-AK15+AL15+AM15+AN15+AO15+AP15 -> 21
A16: 10 | B16: ISI B2 | C16: 0 | AK16: =SUM(F16:AJ16) -> 0 | AQ16: =C16-AK16+AL16+AM16+AN16+AO16+AP16 -> 0
A17: 11 | B17: ISI B3 | C17: 0 | AK17: =SUM(F17:AJ17) -> 0 | AQ17: =C17-AK17+AL17+AM17+AN17+AO17+AP17 -> 0
A18: 12 | B18: ISI B4 | C18: 0 | AK18: =SUM(F18:AJ18) -> 0 | AQ18: =C18-AK18+AL18+AM18+AN18+AO18+AP18 -> 0
A19: 13 | B19: ESI B1 | C19: =D19+E19 -> 27 | D19: 27 | AQ19: =C19-AK19+AL19+AM19+AN19+AO19+AP19 -> 27
A20: 14 | B20: ESI B2 | C20: 0 | AK20: =SUM(F20:AJ20) -> 0 | AQ20: =C20-AK20+AL20+AM20+AN20+AO20+AP20 -> 0
A21: 15 | B21: ESI B3 | C21: 0 | AK21: =SUM(F21:AJ21) -> 0 | AQ21: =C21-AK21+AL21+AM21+AN21+AO21+AP21 -> 0
A22: 16 | B22: ESI B4 | C22: 0 | AK22: =SUM(F22:AJ22) -> 0 | AQ22: =C22-AK22+AL22+AM22+AN22+AO22+AP22 -> 0
A23: 17 | B23: IL5 | C23: =D23+E23 -> 19 | D23: 19 | AQ23: =C23-AK23+AL23+AM23+AN23+AO23+AP23 -> 19
A24: 18 | B24: EL5 | C24: =D24+E24 -> 21 | D24: 21 | AQ24: =C24-AK24+AL24+AM24+AN24+AO24+AP24 -> 21
A25: 19 | B25: IG05-B1 | C25: =D25+E25 -> 94 | D25: 54 | E25: 40 | AQ25: =C25-AK25+AL25+AM25+AN25+AO25+AP25 -> 94
A26: 20 | B26: IG05-B2 | C26: 0 | AK26: =SUM(F26:AJ26) -> 0 | AQ26: =C26-AK26+AL26+AM26+AN26+AO26+AP26 -> 0
A27: 21 | B27: IG05-B3 | C27: 0 | AK27: =SUM(F27:AJ27) -> 0 | AQ27: =C27-AK27+AL27+AM27+AN27+AO27+AP27 -> 0
A28: 22 | B28: IG05-B4 | C28: 0 | AK28: =SUM(F28:AJ28) -> 0 | AQ28: =C28-AK28+AL28+AM28+AN28+AO28+AP28 -> 0
A29: 23 | B29: IG06 B1 | C29: =D29+E29 -> 26 | D29: 6 | E29: 20 | AQ29: =C29-AK29+AL29+AM29+AN29+AO29+AP29 -> 26
A30: 24 | B30: IG06 B2 | C30: 0 | AK30: =SUM(F30:AJ30) -> 0 | AQ30: =C30-AK30+AL30+AM30+AN30+AO30+AP30 -> 0
A31: 25 | B31: IG06 B3 | C31: 0 | AK31: =SUM(F31:AJ31) -> 0 | AQ31: =C31-AK31+AL31+AM31+AN31+AO31+AP31 -> 0
A32: 26 | B32: IG06 B4 | C32: 0 | AK32: =SUM(F32:AJ32) -> 0 | AQ32: =C32-AK32+AL32+AM32+AN32+AO32+AP32 -> 0
A33: 27 | B33: EG09-B1 | C33: =D33+E33 -> 62 | D33: 42 | E33: 20 | AQ33: =C33-AK33+AL33+AM33+AN33+AO33+AP33 -> 62
A34: 28 | B34: EG09-B2 | C34: =D34+E34 -> 53 | D34: 21 | E34: 32 | AQ34: =C34-AK34+AL34+AM34+AN34+AO34+AP34 -> 53
A35: 29 | B35: EG09-B3 | C35: =D35+E35 -> 64 | D35: 44 | E35: 20 | AQ35: =C35-AK35+AL35+AM35+AN35+AO35+AP35 -> 64
A36: 30 | B36: EG09-B4 | C36: =D36+E36 -> 58 | D36: 26 | E36: 32 | AQ36: =C36-AK36+AL36+AM36+AN36+AO36+AP36 -> 58
A37: 31 | B37: ESG10-B1 | C37: =D37+E37 -> 23 | D37: 11 | E37: 12 | AQ37: =C37-AK37+AL37+AM37+AN37+AO37+AP37 -> 23
A38: 32 | B38: ESG10-B2 | C38: =D38+E38 -> 28 | D38: 16 | E38: 12 | AQ38: =C38-AK38+AL38+AM38+AN38+AO38+AP38 -> 28
A39: 33 | B39: ESG10-B3 | C39: =D39+E39 -> 30 | D39: 30 | AQ39: =C39-AK39+AL39+AM39+AN39+AO39+AP39 -> 30
A40: 34 | B40: ESG10-B4 | C40: =D40+E40 -> 14 | D40: 14 | AQ40: =C40-AK40+AL40+AM40+AN40+AO40+AP40 -> 14
A41: 35 | B41: I9-B1 | C41: =D41+E41 -> 11 | D41: 11 | AQ41: =C41-AK41+AL41+AM41+AN41+AO41+AP41 -> 11
A42: 36 | B42: I9-B2 | C42: 0 | AK42: =SUM(F42:AJ42) -> 0 | AQ42: =C42-AK42+AL42+AM42+AN42+AO42+AP42 -> 0
A43: 37 | B43: I9-B3 | C43: 0 | AK43: =SUM(F43:AJ43) -> 0 | AQ43: =C43-AK43+AL43+AM43+AN43+AO43+AP43 -> 0
...

Sheet 1 LÍT
B2: Tồn kho sơn tường hết 9/10/2026
A4: Số TT | B4: Chủng loại | C4: 1L | D4: 1 | E4: 2 | F4: 3 | G4: 4 | H4: 5 | I4: 6 | J4: 7 | K4: 8 | L4: 9 | M4: 10 | N4: 11 | O4: 12 | P4: 13 | Q4: 14 | R4: 15 | S4: 16 | T4: 17 | U4: 18 | V4: 19 | W4: 20 | X4: 21 | Y4: 22 | Z4: 23 | AA4: 24 | AB4: 25 | AC4: 26 | AD4: 27 | AE4: 28 | AF4: 29 | AG4: 30 | AH4: 31 | AI4: Tổng xuất | AJ4: Nhập NM 23/12 | AN4: Tồn cuối
C6: =SUM(C7:C50) -> 350 | D6: =SUM(D7:D50) -> 0 | E6: =SUM(E7:E50) -> 0 | F6: =SUM(F7:F50) -> 0 | G6: =SUM(G7:G50) -> 0 | H6: =SUM(H7:H50) -> 0 | I6: =SUM(I7:I50) -> 0 | J6: =SUM(J7:J50) -> 0 | ... AN6: =SUM(AN7:AN50) -> 350
A7: 1 | B7: PI04 | C7: 0 | AI7: =SUM(D7:AH7) -> 0 | AN7: =C7-AI7+AJ7+AK7+AL7+AM7 -> 0
A8: 2 | B8: PE02 | C8: 0 | AI8: =SUM(D8:AH8) -> 0 | AN8: =C8-AI8+AJ8+AK8+AL8+AM8 -> 0
A9: 3 | B9: SPI03 | C9: 0 | AI9: =SUM(D9:AH9) -> 0 | AN9: =C9-AI9+AJ9+AK9+AL9+AM9 -> 0
A10: 4 | B10: SPE01 | C10: 0 | AI10: =SUM(D10:AH10) -> 0 | AN10: =C10-AI10+AJ10+AK10+AL10+AM10 -> 0
A11: 5 | B11: IEW | C11: 0 | AI11: =SUM(D11:AH11) -> 0 | AN11: =C11-AI11+AJ11+AK11+AL11+AM11 -> 0
A12: 6 | B12: CT12 | C12: 0 | AI12: =SUM(D12:AH12) -> 0 | AN12: =C12-AI12+AJ12+AK12+AL12+AM12 -> 0
A13: 7 | B13: ETM-309 | C13: 0 | AI13: =SUM(D13:AH13) -> 0 | AN13: =C13-AI13+AJ13+AK13+AL13+AM13 -> 0
A14: 8 | B14: CTS | C14: 0 | AI14: =SUM(D14:AH14) -> 0 | AN14: =C14-AI14+AJ14+AK14+AL14+AM14 -> 0
A15: 9 | B15: ISI B1 | C15: 0 | AI15: =SUM(D15:AH15) -> 0 | AN15: =C15-AI15+AJ15+AK15+AL15+AM15 -> 0
A16: 10 | B16: ISI B2 | C16: 0 | AI16: =SUM(D16:AH16) -> 0 | AN16: =C16-AI16+AJ16+AK16+AL16+AM16 -> 0
A17: 11 | B17: ISI B3 | C17: 0 | AI17: =SUM(D17:AH17) -> 0 | AN17: =C17-AI17+AJ17+AK17+AL17+AM17 -> 0
A18: 12 | B18: ISI B4 | C18: 0 | AI18: =SUM(D18:AH18) -> 0 | AN18: =C18-AI18+AJ18+AK18+AL18+AM18 -> 0
... A45: 39 | B45: E9-B1 | C45: 1 | AI45: =SUM(D45:AH45) -> 0 | AN45: =C45-AI45+AJ45+AK45+AL45+AM45 -> 1
A46: 40 | B46: E9-B2 | AI46: =SUM(D46:AH46) -> 0 | AN46: =C46-AI46+AJ46+AK46+AL46+AM46 -> 0
A47: 41 | B47: E9-B3 | C47: 0 | AI47: =SUM(D47:AH47) -> 0 | AN47: =C47-AI47+AJ47+AK47+AL47+AM47 -> 0
A48: 42 | B48: E9-B4 | C48: 5 | AI48: =SUM(D48:AH48) -> 0 | AN48: =C48-AI48+AJ48+AK48+AL48+AM48 -> 5
A49: 43 | B49: ICL | C49: 18 | AI49: =SUM(D49:AH49) -> 0 | AN49: =C49-AI49+AJ49+AK49+AL49+AM49 -> 18
A50: 44 | B50: DECO | C50: 0 | AI50: =SUM(D50:AH50) -> 0 | AN50: =C50-AI50+AJ50+AK50+AL50+AM50 -> 0
A51: 45 | B51: Bả nội | C51: 0 | AI51: =SUM(D51:AH51) -> 0 | AN51: =C51-AI51+AJ51+AK51+AL51+AM51 -> 0
A52: 46 | B52: Bả ngoại | C52: 0 | AI52: =SUM(D52:AH52) -> 0 | AN52: =C52-AI52+AJ52+AK52+AL52+AM52 -> 0
