Workbook

Sheet TỔNG QUAN
A1: THEO DÕI KHO SƠN
A2: ="Số liệu đến ngày "&TEXT('TỒN KHO'!$E$3,"dd/mm/yyyy")&" | Tồn đầu kỳ hết "&TEXT('TỒN KHO'!$E$4,"dd/mm/yyyy")&" | Đã ghi "&TEXT(SUMIFS('NHẬP KHO'!$E$5:$E$2004,'NHẬP KHO'!$A$5:$A$2004,">"&'TỒN KHO'!$E$4),"#,##0")&" thùng/lon nhập sau đó" -> Số liệu đến ngày 29/09/2026 | Tồn đầu kỳ hết 07/06/2026 | Đã ghi 19 thùng/lon nhập sau đó
A3: ='TỒN KHO'!G8
A4: TỔNG TỒN (thùng/lon/bao) | C4: GIÁ TRỊ TỒN (theo giá KN) | E4: MÃ HẾT HÀNG | G4: MÃ SẮP HẾT | I4: MÃ ÂM KHO (cần kiểm)
A5: =SUM('TỒN KHO'!$J$11:$J$76) -> 2143 | C5: =SUM('TỒN KHO'!$O$11:$O$76) -> 6388899000 | E5: =COUNTIF('TỒN KHO'!$P$11:$P$76,"HẾT HÀNG") -> 0 | G5: =COUNTIF('TỒN KHO'!$P$11:$P$76,"SẮP HẾT") -> 1 | I5: =COUNTIF('TỒN KHO'!$P$11:$P$76,"ÂM*") -> 3
A7: ▶ CẦN ĐẶT HÀNG NGAY (hết hàng / sắp hết – xếp theo mức khẩn cấp)
A8: # | B8: Mã SP | C8: Dung tích | D8: Tên sản phẩm | E8: Tồn | F8: Bán TB/ngày | G8: Đủ bán (ngày) | H8: Gợi ý đặt thêm | I8: Trạng thái | L8: (hỗ trợ)
A9: 1 | B9: =IF($L9="","",INDEX('TỒN KHO'!$C$11:$C$76,$L9)) -> IEW | C9: =IF($L9="","",INDEX('TỒN KHO'!$E$11:$E$76,$L9)) -> 18L | D9: =IF($L9="","",INDEX('TỒN KHO'!$D$11:$D$76,$L9)) -> Sơn nội thất siêu trắng Imperia IEW | E9: =IF($L9="","",INDEX('TỒN KHO'!$J$11:$J$76,$L9)) -> 3 | F9: =IF($L9="","",INDEX('TỒN KHO'!$L$11:$L$76,$L9)) -> 0.22222222 | G9: =IF($L9="","",INDEX('TỒN KHO'!$M$11:$M$76,$L9)) -> 13.5 | H9: =IF($L9="","",INDEX('TỒN KHO'!$N$11:$N$76,$L9)) -> 7 | I9: =IF($L9="","",INDEX('TỒN KHO'!$P$11:$P$76,$L9)) -> SẮP HẾT | L9: =IFERROR(MATCH(SMALL('TỒN KHO'!$Q$11:$Q$76,A9),'TỒN KHO'!$Q$11:$Q$76,0),"") -> 14
A10: 2 | B10: =IF($L10="","",INDEX('TỒN KHO'!$C$11:$C$76,$L10)) | C10: =IF($L10="","",INDEX('TỒN KHO'!$E$11:$E$76,$L10)) | D10: =IF($L10="","",INDEX('TỒN KHO'!$D$11:$D$76,$L10)) | E10: =IF($L10="","",INDEX('TỒN KHO'!$J$11:$J$76,$L10)) | F10: =IF($L10="","",INDEX('TỒN KHO'!$L$11:$L$76,$L10)) | G10: =IF($L10="","",INDEX('TỒN KHO'!$M$11:$M$76,$L10)) | H10: =IF($L10="","",INDEX('TỒN KHO'!$N$11:$N$76,$L10)) | I10: =IF($L10="","",INDEX('TỒN KHO'!$P$11:$P$76,$L10)) | L10: =IFERROR(MATCH(SMALL('TỒN KHO'!$Q$11:$Q$76,A10),'TỒN KHO'!$Q$11:$Q$76,0),"")
A11: 3 | B11: =IF($L11="","",INDEX('TỒN KHO'!$C$11:$C$76,$L11)) | C11: =IF($L11="","",INDEX('TỒN KHO'!$E$11:$E$76,$L11)) | D11: =IF($L11="","",INDEX('TỒN KHO'!$D$11:$D$76,$L11)) | E11: =IF($L11="","",INDEX('TỒN KHO'!$J$11:$J$76,$L11)) | F11: =IF($L11="","",INDEX('TỒN KHO'!$L$11:$L$76,$L11)) | G11: =IF($L11="","",INDEX('TỒN KHO'!$M$11:$M$76,$L11)) | H11: =IF($L11="","",INDEX('TỒN KHO'!$N$11:$N$76,$L11)) | I11: =IF($L11="","",INDEX('TỒN KHO'!$P$11:$P$76,$L11)) | L11: =IFERROR(MATCH(SMALL('TỒN KHO'!$Q$11:$Q$76,A11),'TỒN KHO'!$Q$11:$Q$76,0),"")
A12: 4 | B12: =IF($L12="","",INDEX('TỒN KHO'!$C$11:$C$76,$L12)) | C12: =IF($L12="","",INDEX('TỒN KHO'!$E$11:$E$76,$L12)) | D12: =IF($L12="","",INDEX('TỒN KHO'!$D$11:$D$76,$L12)) | E12: =IF($L12="","",INDEX('TỒN KHO'!$J$11:$J$76,$L12)) | F12: =IF($L12="","",INDEX('TỒN KHO'!$L$11:$L$76,$L12)) | G12: =IF($L12="","",INDEX('TỒN KHO'!$M$11:$M$76,$L12)) | H12: =IF($L12="","",INDEX('TỒN KHO'!$N$11:$N$76,$L12)) | I12: =IF($L12="","",INDEX('TỒN KHO'!$P$11:$P$76,$L12)) | L12: =IFERROR(MATCH(SMALL('TỒN KHO'!$Q$11:$Q$76,A12),'TỒN KHO'!$Q$11:$Q$76,0),"")
A13: 5 | B13: =IF($L13="","",INDEX('TỒN KHO'!$C$11:$C$76,$L13)) | C13: =IF($L13="","",INDEX('TỒN KHO'!$E$11:$E$76,$L13)) | D13: =IF($L13="","",INDEX('TỒN KHO'!$D$11:$D$76,$L13)) | E13: =IF($L13="","",INDEX('TỒN KHO'!$J$11:$J$76,$L13)) | F13: =IF($L13="","",INDEX('TỒN KHO'!$L$11:$L$76,$L13)) | G13: =IF($L13="","",INDEX('TỒN KHO'!$M$11:$M$76,$L13)) | H13: =IF($L13="","",INDEX('TỒN KHO'!$N$11:$N$76,$L13)) | I13: =IF($L13="","",INDEX('TỒN KHO'!$P$11:$P$76,$L13)) | L13: =IFERROR(MATCH(SMALL('TỒN KHO'!$Q$11:$Q$76,A13),'TỒN KHO'!$Q$11:$Q$76,0),"")
A14: 6 | B14: =IF($L14="","",INDEX('TỒN KHO'!$C$11:$C$76,$L14)) | C14: =IF($L14="","",INDEX('TỒN KHO'!$E$11:$E$76,$L14)) | D14: =IF($L14="","",INDEX('TỒN KHO'!$D$11:$D$76,$L14)) | E14: =IF($L14="","",INDEX('TỒN KHO'!$J$11:$J$76,$L14)) | F14: =IF($L14="","",INDEX('TỒN KHO'!$L$11:$L$76,$L14)) | G14: =IF($L14="","",INDEX('TỒN KHO'!$M$11:$M$76,$L14)) | H14: =IF($L14="","",INDEX('TỒN KHO'!$N$11:$N$76,$L14)) | I14: =IF($L14="","",INDEX('TỒN KHO'!$P$11:$P$76,$L14)) | L14: =IFERROR(MATCH(SMALL('TỒN KHO'!$Q$11:$Q$76,A14),'TỒN KHO'!$Q$11:$Q$76,0),"")
A15: 7 | B15: =IF($L15="","",INDEX('TỒN KHO'!$C$11:$C$76,$L15)) | C15: =IF($L15="","",INDEX('TỒN KHO'!$E$11:$E$76,$L15)) | D15: =IF($L15="","",INDEX('TỒN KHO'!$D$11:$D$76,$L15)) | E15: =IF($L15="","",INDEX('TỒN KHO'!$J$11:$J$76,$L15)) | F15: =IF($L15="","",INDEX('TỒN KHO'!$L$11:$L$76,$L15)) | G15: =IF($L15="","",INDEX('TỒN KHO'!$M$11:$M$76,$L15)) | H15: =IF($L15="","",INDEX('TỒN KHO'!$N$11:$N$76,$L15)) | I15: =IF($L15="","",INDEX('TỒN KHO'!$P$11:$P$76,$L15)) | L15: =IFERROR(MATCH(SMALL('TỒN KHO'!$Q$11:$Q$76,A15),'TỒN KHO'!$Q$11:$Q$76,0),"")
A16: 8 | B16: =IF($L16="","",INDEX('TỒN KHO'!$C$11:$C$76,$L16)) | C16: =IF($L16="","",INDEX('TỒN KHO'!$E$11:$E$76,$L16)) | D16: =IF($L16="","",INDEX('TỒN KHO'!$D$11:$D$76,$L16)) | E16: =IF($L16="","",INDEX('TỒN KHO'!$J$11:$J$76,$L16)) | F16: =IF($L16="","",INDEX('TỒN KHO'!$L$11:$L$76,$L16)) | G16: =IF($L16="","",INDEX('TỒN KHO'!$M$11:$M$76,$L16)) | H16: =IF($L16="","",INDEX('TỒN KHO'!$N$11:$N$76,$L16)) | I16: =IF($L16="","",INDEX('TỒN KHO'!$P$11:$P$76,$L16)) | L16: =IFERROR(MATCH(SMALL('TỒN KHO'!$Q$11:$Q$76,A16),'TỒN KHO'!$Q$11:$Q$76,0),"")
A17: 9 | B17: =IF($L17="","",INDEX('TỒN KHO'!$C$11:$C$76,$L17)) | C17: =IF($L17="","",INDEX('TỒN KHO'!$E$11:$E$76,$L17)) | D17: =IF($L17="","",INDEX('TỒN KHO'!$D$11:$D$76,$L17)) | E17: =IF($L17="","",INDEX('TỒN KHO'!$J$11:$J$76,$L17)) | F17: =IF($L17="","",INDEX('TỒN KHO'!$L$11:$L$76,$L17)) | G17: =IF($L17="","",INDEX('TỒN KHO'!$M$11:$M$76,$L17)) | H17: =IF($L17="","",INDEX('TỒN KHO'!$N$11:$N$76,$L17)) | I17: =IF($L17="","",INDEX('TỒN KHO'!$P$11:$P$76,$L17)) | L17: =IFERROR(MATCH(SMALL('TỒN KHO'!$Q$11:$Q$76,A17),'TỒN KHO'!$Q$11:$Q$76,0),"")
A18: 10 | B18: =IF($L18="","",INDEX('TỒN KHO'!$C$11:$C$76,$L18)) | C18: =IF($L18="","",INDEX('TỒN KHO'!$E$11:$E$76,$L18)) | D18: =IF($L18="","",INDEX('TỒN KHO'!$D$11:$D$76,$L18)) | E18: =IF($L18="","",INDEX('TỒN KHO'!$J$11:$J$76,$L18)) | F18: =IF($L18="","",INDEX('TỒN KHO'!$L$11:$L$76,$L18)) | G18: =IF($L18="","",INDEX('TỒN KHO'!$M$11:$M$76,$L18)) | H18: =IF($L18="","",INDEX('TỒN KHO'!$N$11:$N$76,$L18)) | I18: =IF($L18="","",INDEX('TỒN KHO'!$P$11:$P$76,$L18)) | L18: =IFERROR(MATCH(SMALL('TỒN KHO'!$Q$11:$Q$76,A18),'TỒN KHO'!$Q$11:$Q$76,0),"")
A19: 11 | B19: =IF($L19="","",INDEX('TỒN KHO'!$C$11:$C$76,$L19)) | C19: =IF($L19="","",INDEX('TỒN KHO'!$E$11:$E$76,$L19)) | D19: =IF($L19="","",INDEX('TỒN KHO'!$D$11:$D$76,$L19)) | E19: =IF($L19="","",INDEX('TỒN KHO'!$J$11:$J$76,$L19)) | F19: =IF($L19="","",INDEX('TỒN KHO'!$L$11:$L$76,$L19)) | G19: =IF($L19="","",INDEX('TỒN KHO'!$M$11:$M$76,$L19)) | H19: =IF($L19="","",INDEX('TỒN KHO'!$N$11:$N$76,$L19)) | I19: =IF($L19="","",INDEX('TỒN KHO'!$P$11:$P$76,$L19)) | L19: =IFERROR(MATCH(SMALL('TỒN KHO'!$Q$11:$Q$76,A19),'TỒN KHO'!$Q$11:$Q$76,0),"")
A20: 12 | B20: =IF($L20="","",INDEX('TỒN KHO'!$C$11:$C$76,$L20)) | C20: =IF($L20="","",INDEX('TỒN KHO'!$E$11:$E$76,$L20)) | D20: =IF($L20="","",INDEX('TỒN KHO'!$D$11:$D$76,$L20)) | E20: =IF($L20="","",INDEX('TỒN KHO'!$J$11:$J$76,$L20)) | F20: =IF($L20="","",INDEX('TỒN KHO'!$L$11:$L$76,$L20)) | G20: =IF($L20="","",INDEX('TỒN KHO'!$M$11:$M$76,$L20)) | H20: =IF($L20="","",INDEX('TỒN KHO'!$N$11:$N$76,$L20)) | I20: =IF($L20="","",INDEX('TỒN KHO'!$P$11:$P$76,$L20)) | L20: =IFERROR(MATCH(SMALL('TỒN KHO'!$Q$11:$Q$76,A20),'TỒN KHO'!$Q$11:$Q$76,0),"")
... A23: 15 | B23: =IF($L23="","",INDEX('TỒN KHO'!$C$11:$C$76,$L23)) | C23: =IF($L23="","",INDEX('TỒN KHO'!$E$11:$E$76,$L23)) | D23: =IF($L23="","",INDEX('TỒN KHO'!$D$11:$D$76,$L23)) | E23: =IF($L23="","",INDEX('TỒN KHO'!$J$11:$J$76,$L23)) | F23: =IF($L23="","",INDEX('TỒN KHO'!$L$11:$L$76,$L23)) | G23: =IF($L23="","",INDEX('TỒN KHO'!$M$11:$M$76,$L23)) | H23: =IF($L23="","",INDEX('TỒN KHO'!$N$11:$N$76,$L23)) | I23: =IF($L23="","",INDEX('TỒN KHO'!$P$11:$P$76,$L23)) | L23: =IFERROR(MATCH(SMALL('TỒN KHO'!$Q$11:$Q$76,A23),'TỒN KHO'!$Q$11:$Q$76,0),"")
A25: ▶ BÁN CHẠY NHẤT (theo số ngày tính tốc độ bán ở sheet TỒN KHO)
A26: # | B26: Mã SP | C26: Dung tích | D26: Tên sản phẩm | E26: Đã bán | F26: Tồn hiện tại | G26: Đủ bán (ngày) | H26: Trạng thái
A27: 1 | B27: =IF($L27="","",INDEX('TỒN KHO'!$C$11:$C$76,$L27)) -> IG05 | C27: =IF($L27="","",INDEX('TỒN KHO'!$E$11:$E$76,$L27)) -> 18L | D27: =IF($L27="","",INDEX('TỒN KHO'!$D$11:$D$76,$L27)) -> Sơn nội thất siêu bóng cao cấp Imperia IG05 | E27: =IF($L27="","",INDEX('TỒN KHO'!$K$11:$K$76,$L27)) -> 56 | F27: =IF($L27="","",INDEX('TỒN KHO'!$J$11:$J$76,$L27)) -> 107 | G27: =IF($L27="","",INDEX('TỒN KHO'!$M$11:$M$76,$L27)) -> 171.96429 | H27: =IF($L27="","",INDEX('TỒN KHO'!$P$11:$P$76,$L27)) -> Đủ hàng | L27: =IFERROR(MATCH(LARGE('TỒN KHO'!$R$11:$R$76,A27),'TỒN KHO'!$R$11:$R$76,0),"") -> 20
A28: 2 | B28: =IF($L28="","",INDEX('TỒN KHO'!$C$11:$C$76,$L28)) -> PI04 | C28: =IF($L28="","",INDEX('TỒN KHO'!$E$11:$E$76,$L28)) -> 18L | D28: =IF($L28="","",INDEX('TỒN KHO'!$D$11:$D$76,$L28)) -> Sơn lót nội thất kháng kiềm cao cấp Imperia PI04 | E28: =IF($L28="","",INDEX('TỒN KHO'!$K$11:$K$76,$L28)) -> 50 | F28: =IF($L28="","",INDEX('TỒN KHO'!$J$11:$J$76,$L28)) -> 117 | G28: =IF($L28="","",INDEX('TỒN KHO'!$M$11:$M$76,$L28)) -> 210.6 | H28: =IF($L28="","",INDEX('TỒN KHO'!$P$11:$P$76,$L28)) -> Đủ hàng | L28: =IFERROR(MATCH(LARGE('TỒN KHO'!$R$11:$R$76,A28),'TỒN KHO'!$R$11:$R$76,0),"") -> 2
A29: 3 | B29: =IF($L29="","",INDEX('TỒN KHO'!$C$11:$C$76,$L29)) -> ETM-309 | C29: =IF($L29="","",INDEX('TỒN KHO'!$E$11:$E$76,$L29)) -> 18L | D29: =IF($L29="","",INDEX('TỒN KHO'!$D$11:$D$76,$L29)) -> Sơn chống thấm màu ETM 309 (ghi đậm) | E29: =IF($L29="","",INDEX('TỒN KHO'!$K$11:$K$76,$L29)) -> 31 | F29: =IF($L29="","",INDEX('TỒN KHO'!$J$11:$J$76,$L29)) -> 81 | G29: =IF($L29="","",INDEX('TỒN KHO'!$M$11:$M$76,$L29)) -> 235.16129 | H29: =IF($L29="","",INDEX('TỒN KHO'!$P$11:$P$76,$L29)) -> Đủ hàng | L29: =IFERROR(MATCH(LARGE('TỒN KHO'!$R$11:$R$76,A29),'TỒN KHO'!$R$11:$R$76,0),"") -> 38
A30: 4 | B30: =IF($L30="","",INDEX('TỒN KHO'!$C$11:$C$76,$L30)) -> BA-NOI | C30: =IF($L30="","",INDEX('TỒN KHO'!$E$11:$E$76,$L30)) -> Bao | D30: =IF($L30="","",INDEX('TỒN KHO'!$D$11:$D$76,$L30)) -> Bột bả nội thất Imperia IP15 (40kg) | E30: =IF($L30="","",INDEX('TỒN KHO'!$K$11:$K$76,$L30)) -> 23 | F30: =IF($L30="","",INDEX('TỒN KHO'!$J$11:$J$76,$L30)) -> -21 | G30: =IF($L30="","",INDEX('TỒN KHO'!$M$11:$M$76,$L30)) -> 0 | H30: =IF($L30="","",INDEX('TỒN KHO'!$P$11:$P$76,$L30)) -> ÂM KHO – kiểm tra | L30: =IFERROR(MATCH(LARGE('TỒN KHO'!$R$11:$R$76,A30),'TỒN KHO'!$R$11:$R$76,0),"") -> 45
A31: 5 | B31: =IF($L31="","",INDEX('TỒN KHO'!$C$11:$C$76,$L31)) -> IEW | C31: =IF($L31="","",INDEX('TỒN KHO'!$E$11:$E$76,$L31)) -> 18L | D31: =IF($L31="","",INDEX('TỒN KHO'!$D$11:$D$76,$L31)) -> Sơn nội thất siêu trắng Imperia IEW | E31: =IF($L31="","",INDEX('TỒN KHO'!$K$11:$K$76,$L31)) -> 20 | F31: =IF($L31="","",INDEX('TỒN KHO'!$J$11:$J$76,$L31)) -> 3 | G31: =IF($L31="","",INDEX('TỒN KHO'!$M$11:$M$76,$L31)) -> 13.5 | H31: =IF($L31="","",INDEX('TỒN KHO'!$P$11:$P$76,$L31)) -> SẮP HẾT | L31: =IFERROR(MATCH(LARGE('TỒN KHO'!$R$11:$R$76,A31),'TỒN KHO'!$R$11:$R$76,0),"") -> 14
A32: 6 | B32: =IF($L32="","",INDEX('TỒN KHO'!$C$11:$C$76,$L32)) -> IL5 | C32: =IF($L32="","",INDEX('TỒN KHO'!$E$11:$E$76,$L32)) -> 18L | D32: =IF($L32="","",INDEX('TỒN KHO'!$D$11:$D$76,$L32)) -> Sơn lót nội thất kháng kiềm Silver IL5 | E32: =IF($L32="","",INDEX('TỒN KHO'!$K$11:$K$76,$L32)) -> 20 | F32: =IF($L32="","",INDEX('TỒN KHO'!$J$11:$J$76,$L32)) -> 62 | G32: =IF($L32="","",INDEX('TỒN KHO'!$M$11:$M$76,$L32)) -> 279 | H32: =IF($L32="","",INDEX('TỒN KHO'!$P$11:$P$76,$L32)) -> Đủ hàng | L32: =IFERROR(MATCH(LARGE('TỒN KHO'!$R$11:$R$76,A32),'TỒN KHO'!$R$11:$R$76,0),"") -> 10
A33: 7 | B33: =IF($L33="","",INDEX('TỒN KHO'!$C$11:$C$76,$L33)) -> PE02 | C33: =IF($L33="","",INDEX('TỒN KHO'!$E$11:$E$76,$L33)) -> 18L | D33: =IF($L33="","",INDEX('TỒN KHO'!$D$11:$D$76,$L33)) -> Sơn lót ngoại thất kháng kiềm cao cấp Imperia PE02 | E33: =IF($L33="","",INDEX('TỒN KHO'!$K$11:$K$76,$L33)) -> 18 | F33: =IF($L33="","",INDEX('TỒN KHO'!$J$11:$J$76,$L33)) -> 225 | G33: =IF($L33="","",INDEX('TỒN KHO'!$M$11:$M$76,$L33)) -> 1125 | H33: =IF($L33="","",INDEX('TỒN KHO'!$P$11:$P$76,$L33)) -> Đủ hàng | L33: =IFERROR(MATCH(LARGE('TỒN KHO'!$R$11:$R$76,A33),'TỒN KHO'!$R$11:$R$76,0),"") -> 4
A34: 8 | B34: =IF($L34="","",INDEX('TỒN KHO'!$C$11:$C$76,$L34)) -> EG09 | C34: =IF($L34="","",INDEX('TỒN KHO'!$E$11:$E$76,$L34)) -> 5L | D34: =IF($L34="","",INDEX('TỒN KHO'!$D$11:$D$76,$L34)) -> Sơn ngoại thất siêu bóng cao cấp Imperia EG09 | E34: =IF($L34="","",INDEX('TỒN KHO'!$K$11:$K$76,$L34)) -> 17 | F34: =IF($L34="","",INDEX('TỒN KHO'!$J$11:$J$76,$L34)) -> 203 | G34: =IF($L34="","",INDEX('TỒN KHO'!$M$11:$M$76,$L34)) -> 1074.7059 | H34: =IF($L34="","",INDEX('TỒN KHO'!$P$11:$P$76,$L34)) -> Đủ hàng | L34: =IFERROR(MATCH(LARGE('TỒN KHO'!$R$11:$R$76,A34),'TỒN KHO'!$R$11:$R$76,0),"") -> 31
A35: 9 | B35: =IF($L35="","",INDEX('TỒN KHO'!$C$11:$C$76,$L35)) -> ISG06 | C35: =IF($L35="","",INDEX('TỒN KHO'!$E$11:$E$76,$L35)) -> 18L | D35: =IF($L35="","",INDEX('TỒN KHO'!$D$11:$D$76,$L35)) -> Sơn nội thất cao cấp bóng mờ Imperia ISG06 | E35: =IF($L35="","",INDEX('TỒN KHO'!$K$11:$K$76,$L35)) -> 15 | F35: =IF($L35="","",INDEX('TỒN KHO'!$J$11:$J$76,$L35)) -> 29 | G35: =IF($L35="","",INDEX('TỒN KHO'!$M$11:$M$76,$L35)) -> 174 | H35: =IF($L35="","",INDEX('TỒN KHO'!$P$11:$P$76,$L35)) -> Đủ hàng | L35: =IFERROR(MATCH(LARGE('TỒN KHO'!$R$11:$R$76,A35),'TỒN KHO'!$R$11:$R$76,0),"") -> 18
A36: 10 | B36: =IF($L36="","",INDEX('TỒN KHO'!$C$11:$C$76,$L36)) -> CT12 | C36: =IF($L36="","",INDEX('TỒN KHO'!$E$11:$E$76,$L36)) -> 18L | D36: =IF($L36="","",INDEX('TỒN KHO'!$D$11:$D$76,$L36)) -> Sơn chống thấm đa năng Imperia CT12 | E36: =IF($L36="","",INDEX('TỒN KHO'!$K$11:$K$76,$L36)) -> 14 | F36: =IF($L36="","",INDEX('TỒN KHO'!$J$11:$J$76,$L36)) -> 23 | G36: =IF($L36="","",INDEX('TỒN KHO'!$M$11:$M$76,$L36)) -> 147.85714 | H36: =IF($L36="","",INDEX('TỒN KHO'!$P$11:$P$76,$L36)) -> Đủ hàng | L36: =IFERROR(MATCH(LARGE('TỒN KHO'!$R$11:$R$76,A36),'TỒN KHO'!$R$11:$R$76,0),"") -> 36
A39: ▶ TỒN THEO NHÓM HÀNG
B40: Nhóm | E40: Tồn (số lượng) | F40: Giá trị tồn (VNĐ) | G40: Số mã hết / sắp hết
B41: Sơn lót | E41: =SUMIFS('TỒN KHO'!$J$11:$J$76,'TỒN KHO'!$B$11:$B$76,$B41) -> 549 | F41: =SUMIFS('TỒN KHO'!$O$11:$O$76,'TỒN KHO'!$B$11:$B$76,$B41) -> 1793191000 | G41: =COUNTIFS('TỒN KHO'!$B$11:$B$76,$B41,'TỒN KHO'!$P$11:$P$76,"HẾT HÀNG")+COUNTIFS('TỒN KHO'!$B$11:$B$76,$B41,'TỒN KHO'!$P$11:$P$76,"SẮP HẾT") -> 0
B42: Nội thất | E42: =SUMIFS('TỒN KHO'!$J$11:$J$76,'TỒN KHO'!$B$11:$B$76,$B42) -> 398 | F42: =SUMIFS('TỒN KHO'!$O$11:$O$76,'TỒN KHO'!$B$11:$B$76,$B42) -> 1277705000 | G42: =COUNTIFS('TỒN KHO'!$B$11:$B$76,$B42,'TỒN KHO'!$P$11:$P$76,"HẾT HÀNG")+COUNTIFS('TỒN KHO'!$B$11:$B$76,$B42,'TỒN KHO'!$P$11:$P$76,"SẮP HẾT") -> 1
B43: Ngoại thất | E43: =SUMIFS('TỒN KHO'!$J$11:$J$76,'TỒN KHO'!$B$11:$B$76,$B43) -> 1055 | F43: =SUMIFS('TỒN KHO'!$O$11:$O$76,'TỒN KHO'!$B$11:$B$76,$B43) -> 2719271000 | G43: =COUNTIFS('TỒN KHO'!$B$11:$B$76,$B43,'TỒN KHO'!$P$11:$P$76,"HẾT HÀNG")+COUNTIFS('TỒN KHO'!$B$11:$B$76,$B43,'TỒN KHO'!$P$11:$P$76,"SẮP HẾT") -> 0
B44: Chống thấm | E44: =SUMIFS('TỒN KHO'!$J$11:$J$76,'TỒN KHO'!$B$11:$B$76,$B44) -> 158 | F44: =SUMIFS('TỒN KHO'!$O$11:$O$76,'TỒN KHO'!$B$11:$B$76,$B44) -> 596356000 | G44: =COUNTIFS('TỒN KHO'!$B$11:$B$76,$B44,'TỒN KHO'!$P$11:$P$76,"HẾT HÀNG")+COUNTIFS('TỒN KHO'!$B$11:$B$76,$B44,'TỒN KHO'!$P$11:$P$76,"SẮP HẾT") -> 0
B45: Bột bả | E45: =SUMIFS('TỒN KHO'!$J$11:$J$76,'TỒN KHO'!$B$11:$B$76,$B45) -> -17 | F45: =SUMIFS('TỒN KHO'!$O$11:$O$76,'TỒN KHO'!$B$11:$B$76,$B45) -> 2376000 | G45: =COUNTIFS('TỒN KHO'!$B$11:$B$76,$B45,'TỒN KHO'!$P$11:$P$76,"HẾT HÀNG")+COUNTIFS('TỒN KHO'!$B$11:$B$76,$B45,'TỒN KHO'!$P$11:$P$76,"SẮP HẾT") -> 0

Sheet TỒN KHO
A1: TỒN KHO – NHẬP / XUẤT / TỒN
A2: Tồn hiện tại = Tồn đầu kỳ + Nhập − Xuất (chỉ tính phiếu SAU ngày chốt tồn đầu kỳ). Các ô vàng là thông số chị có thể đổi.
A3: Ngày chốt báo cáo (tự lấy ngày phiếu mới nhất, có thể gõ đè) | E3: =MAX(MAX('XUẤT KHO'!$A$5:$A$2004),MAX('NHẬP KHO'!$A$5:$A$2004)) -> 46294
A4: Tồn đầu kỳ tính đến hết ngày | E4: 46180
A5: Tính tốc độ bán theo (số ngày gần nhất) | E5: 90
A6: Cảnh báo SẮP HẾT khi đủ bán dưới (ngày) | E6: 30
A7: Gợi ý đặt hàng để đủ bán (ngày) | E7: 45
G8: =IF(ABS(SUMIFS('XUẤT KHO'!$E$5:$E$2004,'XUẤT KHO'!$A$5:$A$2004,">"&$E$4)-I77)+ABS(SUMIFS('NHẬP KHO'!$E$5:$E$2004,'NHẬP KHO'!$A$5:$A$2004,">"&$E$4)-H77)>0,"⚠ Có phiếu XUẤT/NHẬP ghi mã hoặc dung tích chưa có trong bảng dưới (số lượng lệch: "&TEXT(SUMIFS('XUẤT KHO'!$E$5:$E$2004,'XUẤT KHO'!$A$5:$A$2004,">"&$E$4)-I77,"#,##0")&" xuất, "&TEXT(SUMIFS('NHẬP KHO'!$E$5:$E$2004,'NHẬP KHO'!$A$5:$A$2004,">"&$E$4)-H77,"#,##0")&" nhập) – thêm dòng mới ở TỒN KHO","")
A10: STT | B10: Nhóm | C10: Mã SP | D10: Tên sản phẩm | E10: Dung tích | F10: Giá KN (VNĐ) | G10: Tồn đầu kỳ | H10: Nhập | I10: Xuất | J10: TỒN HIỆN TẠI | K10: Xuất trong kỳ tính tốc độ | L10: Bán TB / ngày | M10: Đủ bán (ngày) | N10: Gợi ý đặt thêm | O10: Giá trị tồn (theo giá KN) | P10: TRẠNG THÁI | Q10: (hỗ trợ đặt hàng) | R10: (hỗ trợ bán chạy)
A11: =IF(C11="","",ROW()-10) -> 1 | B11: =IF(C11="","",IFERROR(INDEX('DANH MỤC'!$C$5:$C$200,MATCH(C11,'DANH MỤC'!$A$5:$A$200,0)),"⚠ Mã chưa có trong DANH MỤC")) -> Sơn lót | C11: PI04 | D11: =IF(C11="","",IFERROR(INDEX('DANH MỤC'!$B$5:$B$200,MATCH(C11,'DANH MỤC'!$A$5:$A$200,0)),"⚠ Mã chưa có trong DANH MỤC")) -> Sơn lót nội thất kháng kiềm cao cấp Imperia PI04 | E11: 5L | F11: 999000 | G11: =IF($C11="","",SUMIFS('TỒN ĐẦU KỲ'!$E$5:$E$123,'TỒN ĐẦU KỲ'!$B$5:$B$123,$C11,'TỒN ĐẦU KỲ'!$D$5:$D$123,$E11)) -> 6 | H11: =IF($C11="","",SUMIFS('NHẬP KHO'!$E$5:$E$2004,'NHẬP KHO'!$C$5:$C$2004,$C11,'NHẬP KHO'!$D$5:$D$2004,$E11,'NHẬP KHO'!$A$5:$A$2004,">"&$E$4)) -> 0 | I11: =IF($C11="","",SUMIFS('XUẤT KHO'!$E$5:$E$2004,'XUẤT KHO'!$C$5:$C$2004,$C11,'XUẤT KHO'!$D$5:$D$2004,$E11,'XUẤT KHO'!$A$5:$A$2004,">"&$E$4)) -> 4 | J11: =IF($C11="","",G11+H11-I11) -> 2 | K11: =IF($C11="","",SUMIFS('XUẤT KHO'!$E$5:$E$2004,'XUẤT KHO'!$C$5:$C$2004,$C11,'XUẤT KHO'!$D$5:$D$2004,$E11,'XUẤT KHO'!$A$5:$A$2004,">"&($E$3-$E$5),'XUẤT KHO'!$A$5:$A$2004,"<="&$E$3)) -> 0 | L11: =IF($C11="","",K11/$E$5) -> 0 | M11: =IF($C11="","",IF(L11=0,"-",IF(J11<=0,0,J11/L11))) -> - | N11: =IF($C11="","",IF(L11=0,0,MAX(0,ROUNDUP(L11*$E$7,0)-J11))) -> 0 | O11: =IF($C11="","",IF(F11="",0,MAX(J11,0)*F11)) -> 1998000 | P11: =IF($C11="","",IF(J11<0,"ÂM KHO – kiểm tra",IF(AND(J11=0,K11>0),"HẾT HÀNG",IF(J11=0,"Hết (ít bán)",IF(K11=0,"Chậm bán",IF(M11<$E$6,"SẮP HẾT","Đủ hàng")))))) -> Chậm bán | Q11: =IF(OR(P11="HẾT HÀNG",P11="SẮP HẾT"),IF(ISNUMBER(M11),M11,0)+ROW()/100000,"") | R11: =IF(N(K11)>0,K11+ROW()/100000,"")
A12: =IF(C12="","",ROW()-10) -> 2 | B12: =IF(C12="","",IFERROR(INDEX('DANH MỤC'!$C$5:$C$200,MATCH(C12,'DANH MỤC'!$A$5:$A$200,0)),"⚠ Mã chưa có trong DANH MỤC")) -> Sơn lót | C12: PI04 | D12: =IF(C12="","",IFERROR(INDEX('DANH MỤC'!$B$5:$B$200,MATCH(C12,'DANH MỤC'!$A$5:$A$200,0)),"⚠ Mã chưa có trong DANH MỤC")) -> Sơn lót nội thất kháng kiềm cao cấp Imperia PI04 | E12: 18L | F12: 3012000 | G12: =IF($C12="","",SUMIFS('TỒN ĐẦU KỲ'!$E$5:$E$123,'TỒN ĐẦU KỲ'!$B$5:$B$123,$C12,'TỒN ĐẦU KỲ'!$D$5:$D$123,$E12)) -> 195 | H12: =IF($C12="","",SUMIFS('NHẬP KHO'!$E$5:$E$2004,'NHẬP KHO'!$C$5:$C$2004,$C12,'NHẬP KHO'!$D$5:$D$2004,$E12,'NHẬP KHO'!$A$5:$A$2004,">"&$E$4)) -> 5 | I12: =IF($C12="","",SUMIFS('XUẤT KHO'!$E$5:$E$2004,'XUẤT KHO'!$C$5:$C$2004,$C12,'XUẤT KHO'!$D$5:$D$2004,$E12,'XUẤT KHO'!$A$5:$A$2004,">"&$E$4)) -> 83 | J12: =IF($C12="","",G12+H12-I12) -> 117 | K12: =IF($C12="","",SUMIFS('XUẤT KHO'!$E$5:$E$2004,'XUẤT KHO'!$C$5:$C$2004,$C12,'XUẤT KHO'!$D$5:$D$2004,$E12,'XUẤT KHO'!$A$5:$A$2004,">"&($E$3-$E$5),'XUẤT KHO'!$A$5:$A$2004,"<="&$E$3)) -> 50 | L12: =IF($C12="","",K12/$E$5) -> 0.55555556 | M12: =IF($C12="","",IF(L12=0,"-",IF(J12<=0,0,J12/L12))) -> 210.6 | N12: =IF($C12="","",IF(L12=0,0,MAX(0,ROUNDUP(L12*$E$7,0)-J12))) -> 0 | O12: =IF($C12="","",IF(F12="",0,MAX(J12,0)*F12)) -> 352404000 | P12: =IF($C12="","",IF(J12<0,"ÂM KHO – kiểm tra",IF(AND(J12=0,K12>0),"HẾT HÀNG",IF(J12=0,"Hết (ít bán)",IF(K12=0,"Chậm bán",IF(M12<$E$6,"SẮP HẾT","Đủ hàng")))))) -> Đủ hàng | Q12: =IF(OR(P12="HẾT HÀNG",P12="SẮP HẾT"),IF(ISNUMBER(M12),M12,0)+ROW()/100000,"") | R12: =IF(N(K12)>0,K12+ROW()/100000,"") -> 50.00012
A13: =IF(C13="","",ROW()-10) -> 3 | B13: =IF(C13="","",IFERROR(INDEX('DANH MỤC'!$C$5:$C$200,MATCH(C13,'DANH MỤC'!$A$5:$A$200,0)),"⚠ Mã chưa có trong DANH MỤC")) -> Sơn lót | C13: PE02 | D13: =IF(C13="","",IFERROR(INDEX('DANH MỤC'!$B$5:$B$200,MATCH(C13,'DANH MỤC'!$A$5:$A$200,0)),"⚠ Mã chưa có trong DANH MỤC")) -> Sơn lót ngoại thất kháng kiềm cao cấp Imperia PE02 | E13: 5L | F13: 1419000 | G13: =IF($C13="","",SUMIFS('TỒN ĐẦU KỲ'!$E$5:$E$123,'TỒN ĐẦU KỲ'!$B$5:$B$123,$C13,'TỒN ĐẦU KỲ'!$D$5:$D$123,$E13)) -> 0 | H13: =IF($C13="","",SUMIFS('NHẬP KHO'!$E$5:$E$2004,'NHẬP KHO'!$C$5:$C$2004,$C13,'NHẬP KHO'!$D$5:$D$2004,$E13,'NHẬP KHO'!$A$5:$A$2004,">"&$E$4)) -> 0 | I13: =IF($C13="","",SUMIFS('XUẤT KHO'!$E$5:$E$2004,'XUẤT KHO'!$C$5:$C$2004,$C13,'XUẤT KHO'!$D$5:$D$2004,$E13,'XUẤT KHO'!$A$5:$A$2004,">"&$E$4)) -> 4 | J13: =IF($C13="","",G13+H13-I13) -> -4 | K13: =IF($C13="","",SUMIFS('XUẤT KHO'!$E$5:$E$2004,'XUẤT KHO'!$C$5:$C$2004,$C13,'XUẤT KHO'!$D$5:$D$2004,$E13,'XUẤT KHO'!$A$5:$A$2004,">"&($E$3-$E$5),'XUẤT KHO'!$A$5:$A$2004,"<="&$E$3)) -> 4 | L13: =IF($C13="","",K13/$E$5) -> 0.044444444 | M13: =IF($C13="","",IF(L13=0,"-",IF(J13<=0,0,J13/L13))) -> 0 | N13: =IF($C13="","",IF(L13=0,0,MAX(0,ROUNDUP(L13*$E$7,0)-J13))) -> 6 | O13: =IF($C13="","",IF(F13="",0,MAX(J13,0)*F13)) -> 0 | P13: =IF($C13="","",IF(J13<0,"ÂM KHO – kiểm tra",IF(AND(J13=0,K13>0),"HẾT HÀNG",IF(J13=0,"Hết (ít bán)",IF(K13=0,"Chậm bán",IF(M13<$E$6,"SẮP HẾT","Đủ hàng")))))) -> ÂM KHO – kiểm tra | Q13: =IF(OR(P13="HẾT HÀNG",P13="SẮP HẾT"),IF(ISNUMBER(M13),M13,0)+ROW()/100000,"") | R13: =IF(N(K13)>0,K13+ROW()/100000,"") -> 4.00013
A14: =IF(C14="","",ROW()-10) -> 4 | B14: =IF(C14="","",IFERROR(INDEX('DANH MỤC'!$C$5:$C$200,MATCH(C14,'DANH MỤC'!$A$5:$A$200,0)),"⚠ Mã chưa có trong DANH MỤC")) -> Sơn lót | C14: PE02 | D14: =IF(C14="","",IFERROR(INDEX('DANH MỤC'!$B$5:$B$200,MATCH(C14,'DANH MỤC'!$A$5:$A$200,0)),"⚠ Mã chưa có trong DANH MỤC")) -> Sơn lót ngoại thất kháng kiềm cao cấp Imperia PE02 | E14: 18L | F14: 4106000 | G14: =IF($C14="","",SUMIFS('TỒN ĐẦU KỲ'!$E$5:$E$123,'TỒN ĐẦU KỲ'!$B$5:$B$123,$C14,'TỒN ĐẦU KỲ'!$D$5:$D$123,$E14)) -> 253 | H14: =IF($C14="","",SUMIFS('NHẬP KHO'!$E$5:$E$2004,'NHẬP KHO'!$C$5:$C$2004,$C14,'NHẬP KHO'!$D$5:$D$2004,$E14,'NHẬP KHO'!$A$5:$A$2004,">"&$E$4)) -> 1 | I14: =IF($C14="","",SUMIFS('XUẤT KHO'!$E$5:$E$2004,'XUẤT KHO'!$C$5:$C$2004,$C14,'XUẤT KHO'!$D$5:$D$2004,$E14,'XUẤT KHO'!$A$5:$A$2004,">"&$E$4)) -> 29 | J14: =IF($C14="","",G14+H14-I14) -> 225 | K14: =IF($C14="","",SUMIFS('XUẤT KHO'!$E$5:$E$2004,'XUẤT KHO'!$C$5:$C$2004,$C14,'XUẤT KHO'!$D$5:$D$2004,$E14,'XUẤT KHO'!$A$5:$A$2004,">"&($E$3-$E$5),'XUẤT KHO'!$A$5:$A$2004,"<="&$E$3)) -> 18 | L14: =IF($C14="","",K14/$E$5) -> 0.2 | M14: =IF($C14="","",IF(L14=0,"-",IF(J14<=0,0,J14/L14))) -> 1125 | N14: =IF($C14="","",IF(L14=0,0,MAX(0,ROUNDUP(L14*$E$7,0)-J14))) -> 0 | O14: =IF($C14="","",IF(F14="",0,MAX(J14,0)*F14)) -> 923850000 | P14: =IF($C14="","",IF(J14<0,"ÂM KHO – kiểm tra",IF(AND(J14=0,K14>0),"HẾT HÀNG",IF(J14=0,"Hết (ít bán)",IF(K14=0,"Chậm bán",IF(M14<$E$6,"SẮP HẾT","Đủ hàng")))))) -> Đủ hàng | Q14: =IF(OR(P14="HẾT HÀNG",P14="SẮP HẾT"),IF(ISNUMBER(M14),M14,0)+ROW()/100000,"") | R14: =IF(N(K14)>0,K14+ROW()/100000,"") -> 18.00014
A15: =IF(C15="","",ROW()-10) -> 5 | B15: =IF(C15="","",IFERROR(INDEX('DANH MỤC'!$C$5:$C$200,MATCH(C15,'DANH MỤC'!$A$5:$A$200,0)),"⚠ Mã chưa có trong DANH MỤC")) -> Sơn lót | C15: SPI03 | D15: =IF(C15="","",IFERROR(INDEX('DANH MỤC'!$B$5:$B$200,MATCH(C15,'DANH MỤC'!$A$5:$A$200,0)),"⚠ Mã chưa có trong DANH MỤC")) -> Sơn lót nội thất kháng kiềm siêu cao cấp SPI03 | E15: 5L | F15: 1181000 | G15: =IF($C15="","",SUMIFS('TỒN ĐẦU KỲ'!$E$5:$E$123,'TỒN ĐẦU KỲ'!$B$5:$B$123,$C15,'TỒN ĐẦU KỲ'!$D$5:$D$123,$E15)) -> 7 | H15: =IF($C15="","",SUMIFS('NHẬP KHO'!$E$5:$E$2004,'NHẬP KHO'!$C$5:$C$2004,$C15,'NHẬP KHO'!$D$5:$D$2004,$E15,'NHẬP KHO'!$A$5:$A$2004,">"&$E$4)) -> 0 | I15: =IF($C15="","",SUMIFS('XUẤT KHO'!$E$5:$E$2004,'XUẤT KHO'!$C$5:$C$2004,$C15,'XUẤT KHO'!$D$5:$D$2004,$E15,'XUẤT KHO'!$A$5:$A$2004,">"&$E$4)) -> 0 | J15: =IF($C15="","",G15+H15-I15) -> 7 | K15: =IF($C15="","",SUMIFS('XUẤT KHO'!$E$5:$E$2004,'XUẤT KHO'!$C$5:$C$2004,$C15,'XUẤT KHO'!$D$5:$D$2004,$E15,'XUẤT KHO'!$A$5:$A$2004,">"&($E$3-$E$5),'XUẤT KHO'!$A$5:$A$2004,"<="&$E$3)) -> 0 | L15: =IF($C15="","",K15/$E$5) -> 0 | M15: =IF($C15="","",IF(L15=0,"-",IF(J15<=0,0,J15/L15))) -> - | N15: =IF($C15="","",IF(L15=0,0,MAX(0,ROUNDUP(L15*$E$7,0)-J15))) -> 0 | O15: =IF($C15="","",IF(F15="",0,MAX(J15,0)*F15)) -> 8267000 | P15: =IF($C15="","",IF(J15<0,"ÂM KHO – kiểm tra",IF(AND(J15=0,K15>0),"HẾT HÀNG",IF(J15=0,"Hết (ít bán)",IF(K15=0,"Chậm bán",IF(M15<$E$6,"SẮP HẾT","Đủ hàng")))))) -> Chậm bán | Q15: =IF(OR(P15="HẾT HÀNG",P15="SẮP HẾT"),IF(ISNUMBER(M15),M15,0)+ROW()/100000,"") | R15: =IF(N(K15)>0,K15+ROW()/100000,"")
A16: =IF(C16="","",ROW()-10) -> 6 | B16: =IF(C16="","",IFERROR(INDEX('DANH MỤC'!$C$5:$C$200,MATCH(C16,'DANH MỤC'!$A$5:$A$200,0)),"⚠ Mã chưa có trong DANH MỤC")) -> Sơn lót | C16: SPI03 | D16: =IF(C16="","",IFERROR(INDEX('DANH MỤC'!$B$5:$B$200,MATCH(C16,'DANH MỤC'!$A$5:$A$200,0)),"⚠ Mã chưa có trong DANH MỤC")) -> Sơn lót nội thất kháng kiềm siêu cao cấp SPI03 | E16: 18L | F16: 3596000 | G16: =IF($C16="","",SUMIFS('TỒN ĐẦU KỲ'!$E$5:$E$123,'TỒN ĐẦU KỲ'!$B$5:$B$123,$C16,'TỒN ĐẦU KỲ'!$D$5:$D$123,$E16)) -> 25 | H16: =IF($C16="","",SUMIFS('NHẬP KHO'!$E$5:$E$2004,'NHẬP KHO'!$C$5:$C$2004,$C16,'NHẬP KHO'!$D$5:$D$2004,$E16,'NHẬP KHO'!$A$5:$A$2004,">"&$E$4)) -> 0 | I16: =IF($C16="","",SUMIFS('XUẤT KHO'!$E$5:$E$2004,'XUẤT KHO'!$C$5:$C$2004,$C16,'XUẤT KHO'!$D$5:$D$2004,$E16,'XUẤT KHO'!$A$5:$A$2004,">"&$E$4)) -> 0 | J16: =IF($C16="","",G16+H16-I16) -> 25 | K16: =IF($C16="","",SUMIFS('XUẤT KHO'!$E$5:$E$2004,'XUẤT KHO'!$C$5:$C$2004,$C16,'XUẤT KHO'!$D$5:$D$2004,$E16,'XUẤT KHO'!$A$5:$A$2004,">"&($E$3-$E$5),'XUẤT KHO'!$A$5:$A$2004,"<="&$E$3)) -> 0 | L16: =IF($C16="","",K16/$E$5) -> 0 | M16: =IF($C16="","",IF(L16=0,"-",IF(J16<=0,0,J16/L16))) -> - | N16: =IF($C16="","",IF(L16=0,0,MAX(0,ROUNDUP(L16*$E$7,0)-J16))) -> 0 | O16: =IF($C16="","",IF(F16="",0,MAX(J16,0)*F16)) -> 89900000 | P16: =IF($C16="","",IF(J16<0,"ÂM KHO – kiểm tra",IF(AND(J16=0,K16>0),"HẾT HÀNG",IF(J16=0,"Hết (ít bán)",IF(K16=0,"Chậm bán",IF(M16<$E$6,"SẮP HẾT","Đủ hàng")))))) -> Chậm bán | Q16: =IF(OR(P16="HẾT HÀNG",P16="SẮP HẾT"),IF(ISNUMBER(M16),M16,0)+ROW()/100000,"") | R16: =IF(N(K16)>0,K16+ROW()/100000,"")
A17: =IF(C17="","",ROW()-10) -> 7 | B17: =IF(C17="","",IFERROR(INDEX('DANH MỤC'!$C$5:$C$200,MATCH(C17,'DANH MỤC'!$A$5:$A$200,0)),"⚠ Mã chưa có trong DANH MỤC")) -> Sơn lót | C17: SPE01 | D17: =IF(C17="","",IFERROR(INDEX('DANH MỤC'!$B$5:$B$200,MATCH(C17,'DANH MỤC'!$A$5:$A$200,0)),"⚠ Mã chưa có trong DANH MỤC")) -> Sơn lót ngoại thất kháng kiềm siêu cao cấp SPE01 | E17: 5L | F17: 1555000 | G17: =IF($C17="","",SUMIFS('TỒN ĐẦU KỲ'!$E$5:$E$123,'TỒN ĐẦU KỲ'!$B$5:$B$123,$C17,'TỒN ĐẦU KỲ'!$D$5:$D$123,$E17)) -> 4 | H17: =IF($C17="","",SUMIFS('NHẬP KHO'!$E$5:$E$2004,'NHẬP KHO'!$C$5:$C$2004,$C17,'NHẬP KHO'!$D$5:$D$2004,$E17,'NHẬP KHO'!$A$5:$A$2004,">"&$E$4)) -> 0 | I17: =IF($C17="","",SUMIFS('XUẤT KHO'!$E$5:$E$2004,'XUẤT KHO'!$C$5:$C$2004,$C17,'XUẤT KHO'!$D$5:$D$2004,$E17,'XUẤT KHO'!$A$5:$A$2004,">"&$E$4)) -> 0 | J17: =IF($C17="","",G17+H17-I17) -> 4 | K17: =IF($C17="","",SUMIFS('XUẤT KHO'!$E$5:$E$2004,'XUẤT KHO'!$C$5:$C$2004,$C17,'XUẤT KHO'!$D$5:$D$2004,$E17,'XUẤT KHO'!$A$5:$A$2004,">"&($E$3-$E$5),'XUẤT KHO'!$A$5:$A$2004,"<="&$E$3)) -> 0 | L17: =IF($C17="","",K17/$E$5) -> 0 | M17: =IF($C17="","",IF(L17=0,"-",IF(J17<=0,0,J17/L17))) -> - | N17: =IF($C17="","",IF(L17=0,0,MAX(0,ROUNDUP(L17*$E$7,0)-J17))) -> 0 | O17: =IF($C17="","",IF(F17="",0,MAX(J17,0)*F17)) -> 6220000 | P17: =IF($C17="","",IF(J17<0,"ÂM KHO – kiểm tra",IF(AND(J17=0,K17>0),"HẾT HÀNG",IF(J17=0,"Hết (ít bán)",IF(K17=0,"Chậm bán",IF(M17<$E$6,"SẮP HẾT","Đủ hàng")))))) -> Chậm bán | Q17: =IF(OR(P17="HẾT HÀNG",P17="SẮP HẾT"),IF(ISNUMBER(M17),M17,0)+ROW()/100000,"") | R17: =IF(N(K17)>0,K17+ROW()/100000,"")
A18: =IF(C18="","",ROW()-10) -> 8 | B18: =IF(C18="","",IFERROR(INDEX('DANH MỤC'!$C$5:$C$200,MATCH(C18,'DANH MỤC'!$A$5:$A$200,0)),"⚠ Mã chưa có trong DANH MỤC")) -> Sơn lót | C18: SPE01 | D18: =IF(C18="","",IFERROR(INDEX('DANH MỤC'!$B$5:$B$200,MATCH(C18,'DANH MỤC'!$A$5:$A$200,0)),"⚠ Mã chưa có trong DANH MỤC")) -> Sơn lót ngoại thất kháng kiềm siêu cao cấp SPE01 | E18: 18L | F18: 4725000 | G18: =IF($C18="","",SUMIFS('TỒN ĐẦU KỲ'!$E$5:$E$123,'TỒN ĐẦU KỲ'!$B$5:$B$123,$C18,'TỒN ĐẦU KỲ'!$D$5:$D$123,$E18)) -> 14 | H18: =IF($C18="","",SUMIFS('NHẬP KHO'!$E$5:$E$2004,'NHẬP KHO'!$C$5:$C$2004,$C18,'NHẬP KHO'!$D$5:$D$2004,$E18,'NHẬP KHO'!$A$5:$A$2004,">"&$E$4)) -> 0 | I18: =IF($C18="","",SUMIFS('XUẤT KHO'!$E$5:$E$2004,'XUẤT KHO'!$C$5:$C$2004,$C18,'XUẤT KHO'!$D$5:$D$2004,$E18,'XUẤT KHO'!$A$5:$A$2004,">"&$E$4)) -> 0 | J18: =IF($C18="","",G18+H18-I18) -> 14 | K18: =IF($C18="","",SUMIFS('XUẤT KHO'!$E$5:$E$2004,'XUẤT KHO'!$C$5:$C$2004,$C18,'XUẤT KHO'!$D$5:$D$2004,$E18,'XUẤT KHO'!$A$5:$A$2004,">"&($E$3-$E$5),'XUẤT KHO'!$A$5:$A$2004,"<="&$E$3)) -> 0 | L18: =IF($C18="","",K18/$E$5) -> 0 | M18: =IF($C18="","",IF(L18=0,"-",IF(J18<=0,0,J18/L18))) -> - | N18: =IF($C18="","",IF(L18=0,0,MAX(0,ROUNDUP(L18*$E$7,0)-J18))) -> 0 | O18: =IF($C18="","",IF(F18="",0,MAX(J18,0)*F18)) -> 66150000 | P18: =IF($C18="","",IF(J18<0,"ÂM KHO – kiểm tra",IF(AND(J18=0,K18>0),"HẾT HÀNG",IF(J18=0,"Hết (ít bán)",IF(K18=0,"Chậm bán",IF(M18<$E$6,"SẮP HẾT","Đủ hàng")))))) -> Chậm bán | Q18: =IF(OR(P18="HẾT HÀNG",P18="SẮP HẾT"),IF(ISNUMBER(M18),M18,0)+ROW()/100000,"") | R18: =IF(N(K18)>0,K18+ROW()/100000,"")
A19: =IF(C19="","",ROW()-10) -> 9 | B19: =IF(C19="","",IFERROR(INDEX('DANH MỤC'!$C$5:$C$200,MATCH(C19,'DANH MỤC'!$A$5:$A$200,0)),"⚠ Mã chưa có trong DANH MỤC")) -> Sơn lót | C19: IL5 | D19: =IF(C19="","",IFERROR(INDEX('DANH MỤC'!$B$5:$B$200,MATCH(C19,'DANH MỤC'!$A$5:$A$200,0)),"⚠ Mã chưa có trong DANH MỤC")) -> Sơn lót nội thất kháng kiềm Silver IL5 | E19: 5L | F19: 767000 | G19: =IF($C19="","",SUMIFS('TỒN ĐẦU KỲ'!$E$5:$E$123,'TỒN ĐẦU KỲ'!$B$5:$B$123,$C19,'TỒN ĐẦU KỲ'!$D$5:$D$123,$E19)) -> 21 | H19: =IF($C19="","",SUMIFS('NHẬP KHO'!$E$5:$E$2004,'NHẬP KHO'!$C$5:$C$2004,$C19,'NHẬP KHO'!$D$5:$D$2004,$E19,'NHẬP KHO'!$A$5:$A$2004,">"&$E$4)) -> 0 | I19: =IF($C19="","",SUMIFS('XUẤT KHO'!$E$5:$E$2004,'XUẤT KHO'!$C$5:$C$2004,$C19,'XUẤT KHO'!$D$5:$D$2004,$E19,'XUẤT KHO'!$A$5:$A$2004,">"&$E$4)) -> 1 | J19: =IF($C19="","",G19+H19-I19) -> 20 | K19: =IF($C19="","",SUMIFS('XUẤT KHO'!$E$5:$E$2004,'XUẤT KHO'!$C$5:$C$2004,$C19,'XUẤT KHO'!$D$5:$D$2004,$E19,'XUẤT KHO'!$A$5:$A$2004,">"&($E$3-$E$5),'XUẤT KHO'!$A$5:$A$2004,"<="&$E$3)) -> 0 | L19: =IF($C19="","",K19/$E$5) -> 0 | M19: =IF($C19="","",IF(L19=0,"-",IF(J19<=0,0,J19/L19))) -> - | N19: =IF($C19="","",IF(L19=0,0,MAX(0,ROUNDUP(L19*$E$7,0)-J19))) -> 0 | O19: =IF($C19="","",IF(F19="",0,MAX(J19,0)*F19)) -> 15340000 | P19: =IF($C19="","",IF(J19<0,"ÂM KHO – kiểm tra",IF(AND(J19=0,K19>0),"HẾT HÀNG",IF(J19=0,"Hết (ít bán)",IF(K19=0,"Chậm bán",IF(M19<$E$6,"SẮP HẾT","Đủ hàng")))))) -> Chậm bán | Q19: =IF(OR(P19="HẾT HÀNG",P19="SẮP HẾT"),IF(ISNUMBER(M19),M19,0)+ROW()/100000,"") | R19: =IF(N(K19)>0,K19+ROW()/100000,"")
A20: =IF(C20="","",ROW()-10) -> 10 | B20: =IF(C20="","",IFERROR(INDEX('DANH MỤC'!$C$5:$C$200,MATCH(C20,'DANH MỤC'!$A$5:$A$200,0)),"⚠ Mã chưa có trong DANH MỤC")) -> Sơn lót | C20: IL5 | D20: =IF(C20="","",IFERROR(INDEX('DANH MỤC'!$B$5:$B$200,MATCH(C20,'DANH MỤC'!$A$5:$A$200,0)),"⚠ Mã chưa có trong DANH MỤC")) -> Sơn lót nội thất kháng kiềm Silver IL5 | E20: 18L | F20: 2185000 | G20: =IF($C20="","",SUMIFS('TỒN ĐẦU KỲ'!$E$5:$E$123,'TỒN ĐẦU KỲ'!$B$5:$B$123,$C20,'TỒN ĐẦU KỲ'!$D$5:$D$123,$E20)) -> 94 | H20: =IF($C20="","",SUMIFS('NHẬP KHO'!$E$5:$E$2004,'NHẬP KHO'!$C$5:$C$2004,$C20,'NHẬP KHO'!$D$5:$D$2004,$E20,'NHẬP KHO'!$A$5:$A$2004,">"&$E$4)) -> 0 | I20: =IF($C20="","",SUMIFS('XUẤT KHO'!$E$5:$E$2004,'XUẤT KHO'!$C$5:$C$2004,$C20,'XUẤT KHO'!$D$5:$D$2004,$E20,'XUẤT KHO'!$A$5:$A$2004,">"&$E$4)) -> 32 | J20: =IF($C20="","",G20+H20-I20) -> 62 | K20: =IF($C20="","",SUMIFS('XUẤT KHO'!$E$5:$E$2004,'XUẤT KHO'!$C$5:$C$2004,$C20,'XUẤT KHO'!$D$5:$D$2004,$E20,'XUẤT KHO'!$A$5:$A$2004,">"&($E$3-$E$5),'XUẤT KHO'!$A$5:$A$2004,"<="&$E$3)) -> 20 | L20: =IF($C20="","",K20/$E$5) -> 0.22222222 | M20: =IF($C20="","",IF(L20=0,"-",IF(J20<=0,0,J20/L20))) -> 279 | N20: =IF($C20="","",IF(L20=0,0,MAX(0,ROUNDUP(L20*$E$7,0)-J20))) -> 0 | O20: =IF($C20="","",IF(F20="",0,MAX(J20,0)*F20)) -> 135470000 | P20: =IF($C20="","",IF(J20<0,"ÂM KHO – kiểm tra",IF(AND(J20=0,K20>0),"HẾT HÀNG",IF(J20=0,"Hết (ít bán)",IF(K20=0,"Chậm bán",IF(M20<$E$6,"SẮP HẾT","Đủ hàng")))))) -> Đủ hàng | Q20: =IF(OR(P20="HẾT HÀNG",P20="SẮP HẾT"),IF(ISNUMBER(M20),M20,0)+ROW()/100000,"") | R20: =IF(N(K20)>0,K20+ROW()/100000,"") -> 20.0002
A21: =IF(C21="","",ROW()-10) -> 11 | B21: =IF(C21="","",IFERROR(INDEX('DANH MỤC'!$C$5:$C$200,MATCH(C21,'DANH MỤC'!$A$5:$A$200,0)),"⚠ Mã chưa có trong DANH MỤC")) -> Sơn lót | C21: EL5 | D21: =IF(C21="","",IFERROR(INDEX('DANH MỤC'!$B$5:$B$200,MATCH(C21,'DANH MỤC'!$A$5:$A$200,0)),"⚠ Mã chưa có trong DANH MỤC")) -> Sơn lót ngoại thất kháng kiềm Silver EL5 | E21: 5L | F21: 960000 | G21: =IF($C21="","",SUMIFS('TỒN ĐẦU KỲ'!$E$5:$E$123,'TỒN ĐẦU KỲ'!$B$5:$B$123,$C21,'TỒN ĐẦU KỲ'!$D$5:$D$123,$E21)) -> 21 | H21: =IF($C21="","",SUMIFS('NHẬP KHO'!$E$5:$E$2004,'NHẬP KHO'!$C$5:$C$2004,$C21,'NHẬP KHO'!$D$5:$D$2004,$E21,'NHẬP KHO'!$A$5:$A$2004,">"&$E$4)) -> 2 | I21: =IF($C21="","",SUMIFS('XUẤT KHO'!$E$5:$E$2004,'XUẤT KHO'!$C$5:$C$2004,$C21,'XUẤT KHO'!$D$5:$D$2004,$E21,'XUẤT KHO'!$A$5:$A$2004,">"&$E$4)) -> 2 | J21: =IF($C21="","",G21+H21-I21) -> 21 | K21: =IF($C21="","",SUMIFS('XUẤT KHO'!$E$5:$E$2004,'XUẤT KHO'!$C$5:$C$2004,$C21,'XUẤT KHO'!$D$5:$D$2004,$E21,'XUẤT KHO'!$A$5:$A$2004,">"&($E$3-$E$5),'XUẤT KHO'!$A$5:$A$2004,"<="&$E$3)) -> 0 | L21: =IF($C21="","",K21/$E$5) -> 0 | M21: =IF($C21="","",IF(L21=0,"-",IF(J21<=0,0,J21/L21))) -> - | N21: =IF($C21="","",IF(L21=0,0,MAX(0,ROUNDUP(L21*$E$7,0)-J21))) -> 0 | O21: =IF($C21="","",IF(F21="",0,MAX(J21,0)*F21)) -> 20160000 | P21: =IF($C21="","",IF(J21<0,"ÂM KHO – kiểm tra",IF(AND(J21=0,K21>0),"HẾT HÀNG",IF(J21=0,"Hết (ít bán)",IF(K21=0,"Chậm bán",IF(M21<$E$6,"SẮP HẾT","Đủ hàng")))))) -> Chậm bán | Q21: =IF(OR(P21="HẾT HÀNG",P21="SẮP HẾT"),IF(ISNUMBER(M21),M21,0)+ROW()/100000,"") | R21: =IF(N(K21)>0,K21+ROW()/100000,"")
A22: =IF(C22="","",ROW()-10) -> 12 | B22: =IF(C22="","",IFERROR(INDEX('DANH MỤC'!$C$5:$C$200,MATCH(C22,'DANH MỤC'!$A$5:$A$200,0)),"⚠ Mã chưa có trong DANH MỤC")) -> Sơn lót | C22: EL5 | D22: =IF(C22="","",IFERROR(INDEX('DANH MỤC'!$B$5:$B$200,MATCH(C22,'DANH MỤC'!$A$5:$A$200,0)),"⚠ Mã chưa có trong DANH MỤC")) -> Sơn lót ngoại thất kháng kiềm Silver EL5 | E22: 18L | F22: 3097000 | G22: =IF($C22="","",SUMIFS('TỒN ĐẦU KỲ'!$E$5:$E$123,'TỒN ĐẦU KỲ'!$B$5:$B$123,$C22,'TỒN ĐẦU KỲ'!$D$5:$D$123,$E22)) -> 68 | H22: =IF($C22="","",SUMIFS('NHẬP KHO'!$E$5:$E$2004,'NHẬP KHO'!$C$5:$C$2004,$C22,'NHẬP KHO'!$D$5:$D$2004,$E22,'NHẬP KHO'!$A$5:$A$2004,">"&$E$4)) -> 0 | I22: =IF($C22="","",SUMIFS('XUẤT KHO'!$E$5:$E$2004,'XUẤT KHO'!$C$5:$C$2004,$C22,'XUẤT KHO'!$D$5:$D$2004,$E22,'XUẤT KHO'!$A$5:$A$2004,">"&$E$4)) -> 12 | J22: =IF($C22="","",G22+H22-I22) -> 56 | K22: =IF($C22="","",SUMIFS('XUẤT KHO'!$E$5:$E$2004,'XUẤT KHO'!$C$5:$C$2004,$C22,'XUẤT KHO'!$D$5:$D$2004,$E22,'XUẤT KHO'!$A$5:$A$2004,">"&($E$3-$E$5),'XUẤT KHO'!$A$5:$A$2004,"<="&$E$3)) -> 10 | L22: =IF($C22="","",K22/$E$5) -> 0.11111111 | M22: =IF($C22="","",IF(L22=0,"-",IF(J22<=0,0,J22/L22))) -> 504 | N22: =IF($C22="","",IF(L22=0,0,MAX(0,ROUNDUP(L22*$E$7,0)-J22))) -> 0 | O22: =IF($C22="","",IF(F22="",0,MAX(J22,0)*F22)) -> 173432000 | P22: =IF($C22="","",IF(J22<0,"ÂM KHO – kiểm tra",IF(AND(J22=0,K22>0),"HẾT HÀNG",IF(J22=0,"Hết (ít bán)",IF(K22=0,"Chậm bán",IF(M22<$E$6,"SẮP HẾT","Đủ hàng")))))) -> Đủ hàng | Q22: =IF(OR(P22="HẾT HÀNG",P22="SẮP HẾT"),IF(ISNUMBER(M22),M22,0)+ROW()/100000,"") | R22: =IF(N(K22)>0,K22+ROW()/100000,"") -> 10.00022
... A56: =IF(C56="","",ROW()-10) -> 46 | B56: =IF(C56="","",IFERROR(INDEX('DANH MỤC'!$C$5:$C$200,MATCH(C56,'DANH MỤC'!$A$5:$A$200,0)),"⚠ Mã chưa có trong DANH MỤC")) -> Bột bả | C56: BA-NGOAI | D56: =IF(C56="","",IFERROR(INDEX('DANH MỤC'!$B$5:$B$200,MATCH(C56,'DANH MỤC'!$A$5:$A$200,0)),"⚠ Mã chưa có trong DANH MỤC")) -> Bột bả ngoại thất Imperia EP14 (40kg) | E56: Bao | F56: 594000 | G56: =IF($C56="","",SUMIFS('TỒN ĐẦU KỲ'!$E$5:$E$123,'TỒN ĐẦU KỲ'!$B$5:$B$123,$C56,'TỒN ĐẦU KỲ'!$D$5:$D$123,$E56)) -> 13 | H56: =IF($C56="","",SUMIFS('NHẬP KHO'!$E$5:$E$2004,'NHẬP KHO'!$C$5:$C$2004,$C56,'NHẬP KHO'!$D$5:$D$2004,$E56,'NHẬP KHO'!$A$5:$A$2004,">"&$E$4)) -> 0 | I56: =IF($C56="","",SUMIFS('XUẤT KHO'!$E$5:$E$2004,'XUẤT KHO'!$C$5:$C$2004,$C56,'XUẤT KHO'!$D$5:$D$2004,$E56,'XUẤT KHO'!$A$5:$A$2004,">"&$E$4)) -> 9 | J56: =IF($C56="","",G56+H56-I56) -> 4 | K56: =IF($C56="","",SUMIFS('XUẤT KHO'!$E$5:$E$2004,'XUẤT KHO'!$C$5:$C$2004,$C56,'XUẤT KHO'!$D$5:$D$2004,$E56,'XUẤT KHO'!$A$5:$A$2004,">"&($E$3-$E$5),'XUẤT KHO'!$A$5:$A$2004,"<="&$E$3)) -> 9 | L56: =IF($C56="","",K56/$E$5) -> 0.1 | M56: =IF($C56="","",IF(L56=0,"-",IF(J56<=0,0,J56/L56))) -> 40 | N56: =IF($C56="","",IF(L56=0,0,MAX(0,ROUNDUP(L56*$E$7,0)-J56))) -> 1 | O56: =IF($C56="","",IF(F56="",0,MAX(J56,0)*F56)) -> 2376000 | P56: =IF($C56="","",IF(J56<0,"ÂM KHO – kiểm tra",IF(AND(J56=0,K56>0),"HẾT HÀNG",IF(J56=0,"Hết (ít bán)",IF(K56=0,"Chậm bán",IF(M56<$E$6,"SẮP HẾT","Đủ hàng")))))) -> Đủ hàng | Q56: =IF(OR(P56="HẾT HÀNG",P56="SẮP HẾT"),IF(ISNUMBER(M56),M56,0)+ROW()/100000,"") | R56: =IF(N(K56)>0,K56+ROW()/100000,"") -> 9.00056
A57: =IF(C57="","",ROW()-10) | B57: =IF(C57="","",IFERROR(INDEX('DANH MỤC'!$C$5:$C$200,MATCH(C57,'DANH MỤC'!$A$5:$A$200,0)),"⚠ Mã chưa có trong DANH MỤC")) | D57: =IF(C57="","",IFERROR(INDEX('DANH MỤC'!$B$5:$B$200,MATCH(C57,'DANH MỤC'!$A$5:$A$200,0)),"⚠ Mã chưa có trong DANH MỤC")) | G57: =IF($C57="","",SUMIFS('TỒN ĐẦU KỲ'!$E$5:$E$123,'TỒN ĐẦU KỲ'!$B$5:$B$123,$C57,'TỒN ĐẦU KỲ'!$D$5:$D$123,$E57)) | H57: =IF($C57="","",SUMIFS('NHẬP KHO'!$E$5:$E$2004,'NHẬP KHO'!$C$5:$C$2004,$C57,'NHẬP KHO'!$D$5:$D$2004,$E57,'NHẬP KHO'!$A$5:$A$2004,">"&$E$4)) | I57: =IF($C57="","",SUMIFS('XUẤT KHO'!$E$5:$E$2004,'XUẤT KHO'!$C$5:$C$2004,$C57,'XUẤT KHO'!$D$5:$D$2004,$E57,'XUẤT KHO'!$A$5:$A$2004,">"&$E$4)) | J57: =IF($C57="","",G57+H57-I57) | K57: =IF($C57="","",SUMIFS('XUẤT KHO'!$E$5:$E$2004,'XUẤT KHO'!$C$5:$C$2004,$C57,'XUẤT KHO'!$D$5:$D$2004,$E57,'XUẤT KHO'!$A$5:$A$2004,">"&($E$3-$E$5),'XUẤT KHO'!$A$5:$A$2004,"<="&$E$3)) | L57: =IF($C57="","",K57/$E$5) | M57: =IF($C57="","",IF(L57=0,"-",IF(J57<=0,0,J57/L57))) | N57: =IF($C57="","",IF(L57=0,0,MAX(0,ROUNDUP(L57*$E$7,0)-J57))) | O57: =IF($C57="","",IF(F57="",0,MAX(J57,0)*F57)) | P57: =IF($C57="","",IF(J57<0,"ÂM KHO – kiểm tra",IF(AND(J57=0,K57>0),"HẾT HÀNG",IF(J57=0,"Hết (ít bán)",IF(K57=0,"Chậm bán",IF(M57<$E$6,"SẮP HẾT","Đủ hàng")))))) | Q57: =IF(OR(P57="HẾT HÀNG",P57="SẮP HẾT"),IF(ISNUMBER(M57),M57,0)+ROW()/100000,"") | R57: =IF(N(K57)>0,K57+ROW()/100000,"")
A58: =IF(C58="","",ROW()-10) | B58: =IF(C58="","",IFERROR(INDEX('DANH MỤC'!$C$5:$C$200,MATCH(C58,'DANH MỤC'!$A$5:$A$200,0)),"⚠ Mã chưa có trong DANH MỤC")) | D58: =IF(C58="","",IFERROR(INDEX('DANH MỤC'!$B$5:$B$200,MATCH(C58,'DANH MỤC'!$A$5:$A$200,0)),"⚠ Mã chưa có trong DANH MỤC")) | G58: =IF($C58="","",SUMIFS('TỒN ĐẦU KỲ'!$E$5:$E$123,'TỒN ĐẦU KỲ'!$B$5:$B$123,$C58,'TỒN ĐẦU KỲ'!$D$5:$D$123,$E58)) | H58: =IF($C58="","",SUMIFS('NHẬP KHO'!$E$5:$E$2004,'NHẬP KHO'!$C$5:$C$2004,$C58,'NHẬP KHO'!$D$5:$D$2004,$E58,'NHẬP KHO'!$A$5:$A$2004,">"&$E$4)) | I58: =IF($C58="","",SUMIFS('XUẤT KHO'!$E$5:$E$2004,'XUẤT KHO'!$C$5:$C$2004,$C58,'XUẤT KHO'!$D$5:$D$2004,$E58,'XUẤT KHO'!$A$5:$A$2004,">"&$E$4)) | J58: =IF($C58="","",G58+H58-I58) | K58: =IF($C58="","",SUMIFS('XUẤT KHO'!$E$5:$E$2004,'XUẤT KHO'!$C$5:$C$2004,$C58,'XUẤT KHO'!$D$5:$D$2004,$E58,'XUẤT KHO'!$A$5:$A$2004,">"&($E$3-$E$5),'XUẤT KHO'!$A$5:$A$2004,"<="&$E$3)) | L58: =IF($C58="","",K58/$E$5) | M58: =IF($C58="","",IF(L58=0,"-",IF(J58<=0,0,J58/L58))) | N58: =IF($C58="","",IF(L58=0,0,MAX(0,ROUNDUP(L58*$E$7,0)-J58))) | O58: =IF($C58="","",IF(F58="",0,MAX(J58,0)*F58)) | P58: =IF($C58="","",IF(J58<0,"ÂM KHO – kiểm tra",IF(AND(J58=0,K58>0),"HẾT HÀNG",IF(J58=0,"Hết (ít bán)",IF(K58=0,"Chậm bán",IF(M58<$E$6,"SẮP HẾT","Đủ hàng")))))) | Q58: =IF(OR(P58="HẾT HÀNG",P58="SẮP HẾT"),IF(ISNUMBER(M58),M58,0)+ROW()/100000,"") | R58: =IF(N(K58)>0,K58+ROW()/100000,"")
A59: =IF(C59="","",ROW()-10) | B59: =IF(C59="","",IFERROR(INDEX('DANH MỤC'!$C$5:$C$200,MATCH(C59,'DANH MỤC'!$A$5:$A$200,0)),"⚠ Mã chưa có trong DANH MỤC")) | D59: =IF(C59="","",IFERROR(INDEX('DANH MỤC'!$B$5:$B$200,MATCH(C59,'DANH MỤC'!$A$5:$A$200,0)),"⚠ Mã chưa có trong DANH MỤC")) | G59: =IF($C59="","",SUMIFS('TỒN ĐẦU KỲ'!$E$5:$E$123,'TỒN ĐẦU KỲ'!$B$5:$B$123,$C59,'TỒN ĐẦU KỲ'!$D$5:$D$123,$E59)) | H59: =IF($C59="","",SUMIFS('NHẬP KHO'!$E$5:$E$2004,'NHẬP KHO'!$C$5:$C$2004,$C59,'NHẬP KHO'!$D$5:$D$2004,$E59,'NHẬP KHO'!$A$5:$A$2004,">"&$E$4)) | I59: =IF($C59="","",SUMIFS('XUẤT KHO'!$E$5:$E$2004,'XUẤT KHO'!$C$5:$C$2004,$C59,'XUẤT KHO'!$D$5:$D$2004,$E59,'XUẤT KHO'!$A$5:$A$2004,">"&$E$4)) | J59: =IF($C59="","",G59+H59-I59) | K59: =IF($C59="","",SUMIFS('XUẤT KHO'!$E$5:$E$2004,'XUẤT KHO'!$C$5:$C$2004,$C59,'XUẤT KHO'!$D$5:$D$2004,$E59,'XUẤT KHO'!$A$5:$A$2004,">"&($E$3-$E$5),'XUẤT KHO'!$A$5:$A$2004,"<="&$E$3)) | L59: =IF($C59="","",K59/$E$5) | M59: =IF($C59="","",IF(L59=0,"-",IF(J59<=0,0,J59/L59))) | N59: =IF($C59="","",IF(L59=0,0,MAX(0,ROUNDUP(L59*$E$7,0)-J59))) | O59: =IF($C59="","",IF(F59="",0,MAX(J59,0)*F59)) | P59: =IF($C59="","",IF(J59<0,"ÂM KHO – kiểm tra",IF(AND(J59=0,K59>0),"HẾT HÀNG",IF(J59=0,"Hết (ít bán)",IF(K59=0,"Chậm bán",IF(M59<$E$6,"SẮP HẾT","Đủ hàng")))))) | Q59: =IF(OR(P59="HẾT HÀNG",P59="SẮP HẾT"),IF(ISNUMBER(M59),M59,0)+ROW()/100000,"") | R59: =IF(N(K59)>0,K59+ROW()/100000,"")
A60: =IF(C60="","",ROW()-10) | B60: =IF(C60="","",IFERROR(INDEX('DANH MỤC'!$C$5:$C$200,MATCH(C60,'DANH MỤC'!$A$5:$A$200,0)),"⚠ Mã chưa có trong DANH MỤC")) | D60: =IF(C60="","",IFERROR(INDEX('DANH MỤC'!$B$5:$B$200,MATCH(C60,'DANH MỤC'!$A$5:$A$200,0)),"⚠ Mã chưa có trong DANH MỤC")) | G60: =IF($C60="","",SUMIFS('TỒN ĐẦU KỲ'!$E$5:$E$123,'TỒN ĐẦU KỲ'!$B$5:$B$123,$C60,'TỒN ĐẦU KỲ'!$D$5:$D$123,$E60)) | H60: =IF($C60="","",SUMIFS('NHẬP KHO'!$E$5:$E$2004,'NHẬP KHO'!$C$5:$C$2004,$C60,'NHẬP KHO'!$D$5:$D$2004,$E60,'NHẬP KHO'!$A$5:$A$2004,">"&$E$4)) | I60: =IF($C60="","",SUMIFS('XUẤT KHO'!$E$5:$E$2004,'XUẤT KHO'!$C$5:$C$2004,$C60,'XUẤT KHO'!$D$5:$D$2004,$E60,'XUẤT KHO'!$A$5:$A$2004,">"&$E$4)) | J60: =IF($C60="","",G60+H60-I60) | K60: =IF($C60="","",SUMIFS('XUẤT KHO'!$E$5:$E$2004,'XUẤT KHO'!$C$5:$C$2004,$C60,'XUẤT KHO'!$D$5:$D$2004,$E60,'XUẤT KHO'!$A$5:$A$2004,">"&($E$3-$E$5),'XUẤT KHO'!$A$5:$A$2004,"<="&$E$3)) | L60: =IF($C60="","",K60/$E$5) | M60: =IF($C60="","",IF(L60=0,"-",IF(J60<=0,0,J60/L60))) | N60: =IF($C60="","",IF(L60=0,0,MAX(0,ROUNDUP(L60*$E$7,0)-J60))) | O60: =IF($C60="","",IF(F60="",0,MAX(J60,0)*F60)) | P60: =IF($C60="","",IF(J60<0,"ÂM KHO – kiểm tra",IF(AND(J60=0,K60>0),"HẾT HÀNG",IF(J60=0,"Hết (ít bán)",IF(K60=0,"Chậm bán",IF(M60<$E$6,"SẮP HẾT","Đủ hàng")))))) | Q60: =IF(OR(P60="HẾT HÀNG",P60="SẮP HẾT"),IF(ISNUMBER(M60),M60,0)+ROW()/100000,"") | R60: =IF(N(K60)>0,K60+ROW()/100000,"")
A61: =IF(C61="","",ROW()-10) | B61: =IF(C61="","",IFERROR(INDEX('DANH MỤC'!$C$5:$C$200,MATCH(C61,'DANH MỤC'!$A$5:$A$200,0)),"⚠ Mã chưa có trong DANH MỤC")) | D61: =IF(C61="","",IFERROR(INDEX('DANH MỤC'!$B$5:$B$200,MATCH(C61,'DANH MỤC'!$A$5:$A$200,0)),"⚠ Mã chưa có trong DANH MỤC")) | G61: =IF($C61="","",SUMIFS('TỒN ĐẦU KỲ'!$E$5:$E$123,'TỒN ĐẦU KỲ'!$B$5:$B$123,$C61,'TỒN ĐẦU KỲ'!$D$5:$D$123,$E61)) | H61: =IF($C61="","",SUMIFS('NHẬP KHO'!$E$5:$E$2004,'NHẬP KHO'!$C$5:$C$2004,$C61,'NHẬP KHO'!$D$5:$D$2004,$E61,'NHẬP KHO'!$A$5:$A$2004,">"&$E$4)) | I61: =IF($C61="","",SUMIFS('XUẤT KHO'!$E$5:$E$2004,'XUẤT KHO'!$C$5:$C$2004,$C61,'XUẤT KHO'!$D$5:$D$2004,$E61,'XUẤT KHO'!$A$5:$A$2004,">"&$E$4)) | J61: =IF($C61="","",G61+H61-I61) | K61: =IF($C61="","",SUMIFS('XUẤT KHO'!$E$5:$E$2004,'XUẤT KHO'!$C$5:$C$2004,$C61,'XUẤT KHO'!$D$5:$D$2004,$E61,'XUẤT KHO'!$A$5:$A$2004,">"&($E$3-$E$5),'XUẤT KHO'!$A$5:$A$2004,"<="&$E$3)) | L61: =IF($C61="","",K61/$E$5) | M61: =IF($C61="","",IF(L61=0,"-",IF(J61<=0,0,J61/L61))) | N61: =IF($C61="","",IF(L61=0,0,MAX(0,ROUNDUP(L61*$E$7,0)-J61))) | O61: =IF($C61="","",IF(F61="",0,MAX(J61,0)*F61)) | P61: =IF($C61="","",IF(J61<0,"ÂM KHO – kiểm tra",IF(AND(J61=0,K61>0),"HẾT HÀNG",IF(J61=0,"Hết (ít bán)",IF(K61=0,"Chậm bán",IF(M61<$E$6,"SẮP HẾT","Đủ hàng")))))) | Q61: =IF(OR(P61="HẾT HÀNG",P61="SẮP HẾT"),IF(ISNUMBER(M61),M61,0)+ROW()/100000,"") | R61: =IF(N(K61)>0,K61+ROW()/100000,"")
A62: =IF(C62="","",ROW()-10) | B62: =IF(C62="","",IFERROR(INDEX('DANH MỤC'!$C$5:$C$200,MATCH(C62,'DANH MỤC'!$A$5:$A$200,0)),"⚠ Mã chưa có trong DANH MỤC")) | D62: =IF(C62="","",IFERROR(INDEX('DANH MỤC'!$B$5:$B$200,MATCH(C62,'DANH MỤC'!$A$5:$A$200,0)),"⚠ Mã chưa có trong DANH MỤC")) | G62: =IF($C62="","",SUMIFS('TỒN ĐẦU KỲ'!$E$5:$E$123,'TỒN ĐẦU KỲ'!$B$5:$B$123,$C62,'TỒN ĐẦU KỲ'!$D$5:$D$123,$E62)) | H62: =IF($C62="","",SUMIFS('NHẬP KHO'!$E$5:$E$2004,'NHẬP KHO'!$C$5:$C$2004,$C62,'NHẬP KHO'!$D$5:$D$2004,$E62,'NHẬP KHO'!$A$5:$A$2004,">"&$E$4)) | I62: =IF($C62="","",SUMIFS('XUẤT KHO'!$E$5:$E$2004,'XUẤT KHO'!$C$5:$C$2004,$C62,'XUẤT KHO'!$D$5:$D$2004,$E62,'XUẤT KHO'!$A$5:$A$2004,">"&$E$4)) | J62: =IF($C62="","",G62+H62-I62) | K62: =IF($C62="","",SUMIFS('XUẤT KHO'!$E$5:$E$2004,'XUẤT KHO'!$C$5:$C$2004,$C62,'XUẤT KHO'!$D$5:$D$2004,$E62,'XUẤT KHO'!$A$5:$A$2004,">"&($E$3-$E$5),'XUẤT KHO'!$A$5:$A$2004,"<="&$E$3)) | L62: =IF($C62="","",K62/$E$5) | M62: =IF($C62="","",IF(L62=0,"-",IF(J62<=0,0,J62/L62))) | N62: =IF($C62="","",IF(L62=0,0,MAX(0,ROUNDUP(L62*$E$7,0)-J62))) | O62: =IF($C62="","",IF(F62="",0,MAX(J62,0)*F62)) | P62: =IF($C62="","",IF(J62<0,"ÂM KHO – kiểm tra",IF(AND(J62=0,K62>0),"HẾT HÀNG",IF(J62=0,"Hết (ít bán)",IF(K62=0,"Chậm bán",IF(M62<$E$6,"SẮP HẾT","Đủ hàng")))))) | Q62: =IF(OR(P62="HẾT HÀNG",P62="SẮP HẾT"),IF(ISNUMBER(M62),M62,0)+ROW()/100000,"") | R62: =IF(N(K62)>0,K62+ROW()/100000,"")
A63: =IF(C63="","",ROW()-10) | B63: =IF(C63="","",IFERROR(INDEX('DANH MỤC'!$C$5:$C$200,MATCH(C63,'DANH MỤC'!$A$5:$A$200,0)),"⚠ Mã chưa có trong DANH MỤC")) | D63: =IF(C63="","",IFERROR(INDEX('DANH MỤC'!$B$5:$B$200,MATCH(C63,'DANH MỤC'!$A$5:$A$200,0)),"⚠ Mã chưa có trong DANH MỤC")) | G63: =IF($C63="","",SUMIFS('TỒN ĐẦU KỲ'!$E$5:$E$123,'TỒN ĐẦU KỲ'!$B$5:$B$123,$C63,'TỒN ĐẦU KỲ'!$D$5:$D$123,$E63)) | H63: =IF($C63="","",SUMIFS('NHẬP KHO'!$E$5:$E$2004,'NHẬP KHO'!$C$5:$C$2004,$C63,'NHẬP KHO'!$D$5:$D$2004,$E63,'NHẬP KHO'!$A$5:$A$2004,">"&$E$4)) | I63: =IF($C63="","",SUMIFS('XUẤT KHO'!$E$5:$E$2004,'XUẤT KHO'!$C$5:$C$2004,$C63,'XUẤT KHO'!$D$5:$D$2004,$E63,'XUẤT KHO'!$A$5:$A$2004,">"&$E$4)) | J63: =IF($C63="","",G63+H63-I63) | K63: =IF($C63="","",SUMIFS('XUẤT KHO'!$E$5:$E$2004,'XUẤT KHO'!$C$5:$C$2004,$C63,'XUẤT KHO'!$D$5:$D$2004,$E63,'XUẤT KHO'!$A$5:$A$2004,">"&($E$3-$E$5),'XUẤT KHO'!$A$5:$A$2004,"<="&$E$3)) | L63: =IF($C63="","",K63/$E$5) | M63: =IF($C63="","",IF(L63=0,"-",IF(J63<=0,0,J63/L63))) | N63: =IF($C63="","",IF(L63=0,0,MAX(0,ROUNDUP(L63*$E$7,0)-J63))) | O63: =IF($C63="","",IF(F63="",0,MAX(J63,0)*F63)) | P63: =IF($C63="","",IF(J63<0,"ÂM KHO – kiểm tra",IF(AND(J63=0,K63>0),"HẾT HÀNG",IF(J63=0,"Hết (ít bán)",IF(K63=0,"Chậm bán",IF(M63<$E$6,"SẮP HẾT","Đủ hàng")))))) | Q63: =IF(OR(P63="HẾT HÀNG",P63="SẮP HẾT"),IF(ISNUMBER(M63),M63,0)+ROW()/100000,"") | R63: =IF(N(K63)>0,K63+ROW()/100000,"")
A64: =IF(C64="","",ROW()-10) | B64: =IF(C64="","",IFERROR(INDEX('DANH MỤC'!$C$5:$C$200,MATCH(C64,'DANH MỤC'!$A$5:$A$200,0)),"⚠ Mã chưa có trong DANH MỤC")) | D64: =IF(C64="","",IFERROR(INDEX('DANH MỤC'!$B$5:$B$200,MATCH(C64,'DANH MỤC'!$A$5:$A$200,0)),"⚠ Mã chưa có trong DANH MỤC")) | G64: =IF($C64="","",SUMIFS('TỒN ĐẦU KỲ'!$E$5:$E$123,'TỒN ĐẦU KỲ'!$B$5:$B$123,$C64,'TỒN ĐẦU KỲ'!$D$5:$D$123,$E64)) | H64: =IF($C64="","",SUMIFS('NHẬP KHO'!$E$5:$E$2004,'NHẬP KHO'!$C$5:$C$2004,$C64,'NHẬP KHO'!$D$5:$D$2004,$E64,'NHẬP KHO'!$A$5:$A$2004,">"&$E$4)) | I64: =IF($C64="","",SUMIFS('XUẤT KHO'!$E$5:$E$2004,'XUẤT KHO'!$C$5:$C$2004,$C64,'XUẤT KHO'!$D$5:$D$2004,$E64,'XUẤT KHO'!$A$5:$A$2004,">"&$E$4)) | J64: =IF($C64="","",G64+H64-I64) | K64: =IF($C64="","",SUMIFS('XUẤT KHO'!$E$5:$E$2004,'XUẤT KHO'!$C$5:$C$2004,$C64,'XUẤT KHO'!$D$5:$D$2004,$E64,'XUẤT KHO'!$A$5:$A$2004,">"&($E$3-$E$5),'XUẤT KHO'!$A$5:$A$2004,"<="&$E$3)) | L64: =IF($C64="","",K64/$E$5) | M64: =IF($C64="","",IF(L64=0,"-",IF(J64<=0,0,J64/L64))) | N64: =IF($C64="","",IF(L64=0,0,MAX(0,ROUNDUP(L64*$E$7,0)-J64))) | O64: =IF($C64="","",IF(F64="",0,MAX(J64,0)*F64)) | P64: =IF($C64="","",IF(J64<0,"ÂM KHO – kiểm tra",IF(AND(J64=0,K64>0),"HẾT HÀNG",IF(J64=0,"Hết (ít bán)",IF(K64=0,"Chậm bán",IF(M64<$E$6,"SẮP HẾT","Đủ hàng")))))) | Q64: =IF(OR(P64="HẾT HÀNG",P64="SẮP HẾT"),IF(ISNUMBER(M64),M64,0)+ROW()/100000,"") | R64: =IF(N(K64)>0,K64+ROW()/100000,"")
A65: =IF(C65="","",ROW()-10) | B65: =IF(C65="","",IFERROR(INDEX('DANH MỤC'!$C$5:$C$200,MATCH(C65,'DANH MỤC'!$A$5:$A$200,0)),"⚠ Mã chưa có trong DANH MỤC")) | D65: =IF(C65="","",IFERROR(INDEX('DANH MỤC'!$B$5:$B$200,MATCH(C65,'DANH MỤC'!$A$5:$A$200,0)),"⚠ Mã chưa có trong DANH MỤC")) | G65: =IF($C65="","",SUMIFS('TỒN ĐẦU KỲ'!$E$5:$E$123,'TỒN ĐẦU KỲ'!$B$5:$B$123,$C65,'TỒN ĐẦU KỲ'!$D$5:$D$123,$E65)) | H65: =IF($C65="","",SUMIFS('NHẬP KHO'!$E$5:$E$2004,'NHẬP KHO'!$C$5:$C$2004,$C65,'NHẬP KHO'!$D$5:$D$2004,$E65,'NHẬP KHO'!$A$5:$A$2004,">"&$E$4)) | I65: =IF($C65="","",SUMIFS('XUẤT KHO'!$E$5:$E$2004,'XUẤT KHO'!$C$5:$C$2004,$C65,'XUẤT KHO'!$D$5:$D$2004,$E65,'XUẤT KHO'!$A$5:$A$2004,">"&$E$4)) | J65: =IF($C65="","",G65+H65-I65) | K65: =IF($C65="","",SUMIFS('XUẤT KHO'!$E$5:$E$2004,'XUẤT KHO'!$C$5:$C$2004,$C65,'XUẤT KHO'!$D$5:$D$2004,$E65,'XUẤT KHO'!$A$5:$A$2004,">"&($E$3-$E$5),'XUẤT KHO'!$A$5:$A$2004,"<="&$E$3)) | L65: =IF($C65="","",K65/$E$5) | M65: =IF($C65="","",IF(L65=0,"-",IF(J65<=0,0,J65/L65))) | N65: =IF($C65="","",IF(L65=0,0,MAX(0,ROUNDUP(L65*$E$7,0)-J65))) | O65: =IF($C65="","",IF(F65="",0,MAX(J65,0)*F65)) | P65: =IF($C65="","",IF(J65<0,"ÂM KHO – kiểm tra",IF(AND(J65=0,K65>0),"HẾT HÀNG",IF(J65=0,"Hết (ít bán)",IF(K65=0,"Chậm bán",IF(M65<$E$6,"SẮP HẾT","Đủ hàng")))))) | Q65: =IF(OR(P65="HẾT HÀNG",P65="SẮP HẾT"),IF(ISNUMBER(M65),M65,0)+ROW()/100000,"") | R65: =IF(N(K65)>0,K65+ROW()/100000,"")
A66: =IF(C66="","",ROW()-10) | B66: =IF(C66="","",IFERROR(INDEX('DANH MỤC'!$C$5:$C$200,MATCH(C66,'DANH MỤC'!$A$5:$A$200,0)),"⚠ Mã chưa có trong DANH MỤC")) | D66: =IF(C66="","",IFERROR(INDEX('DANH MỤC'!$B$5:$B$200,MATCH(C66,'DANH MỤC'!$A$5:$A$200,0)),"⚠ Mã chưa có trong DANH MỤC")) | G66: =IF($C66="","",SUMIFS('TỒN ĐẦU KỲ'!$E$5:$E$123,'TỒN ĐẦU KỲ'!$B$5:$B$123,$C66,'TỒN ĐẦU KỲ'!$D$5:$D$123,$E66)) | H66: =IF($C66="","",SUMIFS('NHẬP KHO'!$E$5:$E$2004,'NHẬP KHO'!$C$5:$C$2004,$C66,'NHẬP KHO'!$D$5:$D$2004,$E66,'NHẬP KHO'!$A$5:$A$2004,">"&$E$4)) | I66: =IF($C66="","",SUMIFS('XUẤT KHO'!$E$5:$E$2004,'XUẤT KHO'!$C$5:$C$2004,$C66,'XUẤT KHO'!$D$5:$D$2004,$E66,'XUẤT KHO'!$A$5:$A$2004,">"&$E$4)) | J66: =IF($C66="","",G66+H66-I66) | K66: =IF($C66="","",SUMIFS('XUẤT KHO'!$E$5:$E$2004,'XUẤT KHO'!$C$5:$C$2004,$C66,'XUẤT KHO'!$D$5:$D$2004,$E66,'XUẤT KHO'!$A$5:$A$2004,">"&($E$3-$E$5),'XUẤT KHO'!$A$5:$A$2004,"<="&$E$3)) | L66: =IF($C66="","",K66/$E$5) | M66: =IF($C66="","",IF(L66=0,"-",IF(J66<=0,0,J66/L66))) | N66: =IF($C66="","",IF(L66=0,0,MAX(0,ROUNDUP(L66*$E$7,0)-J66))) | O66: =IF($C66="","",IF(F66="",0,MAX(J66,0)*F66)) | P66: =IF($C66="","",IF(J66<0,"ÂM KHO – kiểm tra",IF(AND(J66=0,K66>0),"HẾT HÀNG",IF(J66=0,"Hết (ít bán)",IF(K66=0,"Chậm bán",IF(M66<$E$6,"SẮP HẾT","Đủ hàng")))))) | Q66: =IF(OR(P66="HẾT HÀNG",P66="SẮP HẾT"),IF(ISNUMBER(M66),M66,0)+ROW()/100000,"") | R66: =IF(N(K66)>0,K66+ROW()/100000,"")
A67: =IF(C67="","",ROW()-10) | B67: =IF(C67="","",IFERROR(INDEX('DANH MỤC'!$C$5:$C$200,MATCH(C67,'DANH MỤC'!$A$5:$A$200,0)),"⚠ Mã chưa có trong DANH MỤC")) | D67: =IF(C67="","",IFERROR(INDEX('DANH MỤC'!$B$5:$B$200,MATCH(C67,'DANH MỤC'!$A$5:$A$200,0)),"⚠ Mã chưa có trong DANH MỤC")) | G67: =IF($C67="","",SUMIFS('TỒN ĐẦU KỲ'!$E$5:$E$123,'TỒN ĐẦU KỲ'!$B$5:$B$123,$C67,'TỒN ĐẦU KỲ'!$D$5:$D$123,$E67)) | H67: =IF($C67="","",SUMIFS('NHẬP KHO'!$E$5:$E$2004,'NHẬP KHO'!$C$5:$C$2004,$C67,'NHẬP KHO'!$D$5:$D$2004,$E67,'NHẬP KHO'!$A$5:$A$2004,">"&$E$4)) | I67: =IF($C67="","",SUMIFS('XUẤT KHO'!$E$5:$E$2004,'XUẤT KHO'!$C$5:$C$2004,$C67,'XUẤT KHO'!$D$5:$D$2004,$E67,'XUẤT KHO'!$A$5:$A$2004,">"&$E$4)) | J67: =IF($C67="","",G67+H67-I67) | K67: =IF($C67="","",SUMIFS('XUẤT KHO'!$E$5:$E$2004,'XUẤT KHO'!$C$5:$C$2004,$C67,'XUẤT KHO'!$D$5:$D$2004,$E67,'XUẤT KHO'!$A$5:$A$2004,">"&($E$3-$E$5),'XUẤT KHO'!$A$5:$A$2004,"<="&$E$3)) | L67: =IF($C67="","",K67/$E$5) | M67: =IF($C67="","",IF(L67=0,"-",IF(J67<=0,0,J67/L67))) | N67: =IF($C67="","",IF(L67=0,0,MAX(0,ROUNDUP(L67*$E$7,0)-J67))) | O67: =IF($C67="","",IF(F67="",0,MAX(J67,0)*F67)) | P67: =IF($C67="","",IF(J67<0,"ÂM KHO – kiểm tra",IF(AND(J67=0,K67>0),"HẾT HÀNG",IF(J67=0,"Hết (ít bán)",IF(K67=0,"Chậm bán",IF(M67<$E$6,"SẮP HẾT","Đủ hàng")))))) | Q67: =IF(OR(P67="HẾT HÀNG",P67="SẮP HẾT"),IF(ISNUMBER(M67),M67,0)+ROW()/100000,"") | R67: =IF(N(K67)>0,K67+ROW()/100000,"")
A68: =IF(C68="","",ROW()-10) | B68: =IF(C68="","",IFERROR(INDEX('DANH MỤC'!$C$5:$C$200,MATCH(C68,'DANH MỤC'!$A$5:$A$200,0)),"⚠ Mã chưa có trong DANH MỤC")) | D68: =IF(C68="","",IFERROR(INDEX('DANH MỤC'!$B$5:$B$200,MATCH(C68,'DANH MỤC'!$A$5:$A$200,0)),"⚠ Mã chưa có trong DANH MỤC")) | G68: =IF($C68="","",SUMIFS('TỒN ĐẦU KỲ'!$E$5:$E$123,'TỒN ĐẦU KỲ'!$B$5:$B$123,$C68,'TỒN ĐẦU KỲ'!$D$5:$D$123,$E68)) | H68: =IF($C68="","",SUMIFS('NHẬP KHO'!$E$5:$E$2004,'NHẬP KHO'!$C$5:$C$2004,$C68,'NHẬP KHO'!$D$5:$D$2004,$E68,'NHẬP KHO'!$A$5:$A$2004,">"&$E$4)) | I68: =IF($C68="","",SUMIFS('XUẤT KHO'!$E$5:$E$2004,'XUẤT KHO'!$C$5:$C$2004,$C68,'XUẤT KHO'!$D$5:$D$2004,$E68,'XUẤT KHO'!$A$5:$A$2004,">"&$E$4)) | J68: =IF($C68="","",G68+H68-I68) | K68: =IF($C68="","",SUMIFS('XUẤT KHO'!$E$5:$E$2004,'XUẤT KHO'!$C$5:$C$2004,$C68,'XUẤT KHO'!$D$5:$D$2004,$E68,'XUẤT KHO'!$A$5:$A$2004,">"&($E$3-$E$5),'XUẤT KHO'!$A$5:$A$2004,"<="&$E$3)) | L68: =IF($C68="","",K68/$E$5) | M68: =IF($C68="","",IF(L68=0,"-",IF(J68<=0,0,J68/L68))) | N68: =IF($C68="","",IF(L68=0,0,MAX(0,ROUNDUP(L68*$E$7,0)-J68))) | O68: =IF($C68="","",IF(F68="",0,MAX(J68,0)*F68)) | P68: =IF($C68="","",IF(J68<0,"ÂM KHO – kiểm tra",IF(AND(J68=0,K68>0),"HẾT HÀNG",IF(J68=0,"Hết (ít bán)",IF(K68=0,"Chậm bán",IF(M68<$E$6,"SẮP HẾT","Đủ hàng")))))) | Q68: =IF(OR(P68="HẾT HÀNG",P68="SẮP HẾT"),IF(ISNUMBER(M68),M68,0)+ROW()/100000,"") | R68: =IF(N(K68)>0,K68+ROW()/100000,"")
... A76: =IF(C76="","",ROW()-10) | B76: =IF(C76="","",IFERROR(INDEX('DANH MỤC'!$C$5:$C$200,MATCH(C76,'DANH MỤC'!$A$5:$A$200,0)),"⚠ Mã chưa có trong DANH MỤC")) | D76: =IF(C76="","",IFERROR(INDEX('DANH MỤC'!$B$5:$B$200,MATCH(C76,'DANH MỤC'!$A$5:$A$200,0)),"⚠ Mã chưa có trong DANH MỤC")) | G76: =IF($C76="","",SUMIFS('TỒN ĐẦU KỲ'!$E$5:$E$123,'TỒN ĐẦU KỲ'!$B$5:$B$123,$C76,'TỒN ĐẦU KỲ'!$D$5:$D$123,$E76)) | H76: =IF($C76="","",SUMIFS('NHẬP KHO'!$E$5:$E$2004,'NHẬP KHO'!$C$5:$C$2004,$C76,'NHẬP KHO'!$D$5:$D$2004,$E76,'NHẬP KHO'!$A$5:$A$2004,">"&$E$4)) | I76: =IF($C76="","",SUMIFS('XUẤT KHO'!$E$5:$E$2004,'XUẤT KHO'!$C$5:$C$2004,$C76,'XUẤT KHO'!$D$5:$D$2004,$E76,'XUẤT KHO'!$A$5:$A$2004,">"&$E$4)) | J76: =IF($C76="","",G76+H76-I76) | K76: =IF($C76="","",SUMIFS('XUẤT KHO'!$E$5:$E$2004,'XUẤT KHO'!$C$5:$C$2004,$C76,'XUẤT KHO'!$D$5:$D$2004,$E76,'XUẤT KHO'!$A$5:$A$2004,">"&($E$3-$E$5),'XUẤT KHO'!$A$5:$A$2004,"<="&$E$3)) | L76: =IF($C76="","",K76/$E$5) | M76: =IF($C76="","",IF(L76=0,"-",IF(J76<=0,0,J76/L76))) | N76: =IF($C76="","",IF(L76=0,0,MAX(0,ROUNDUP(L76*$E$7,0)-J76))) | O76: =IF($C76="","",IF(F76="",0,MAX(J76,0)*F76)) | P76: =IF($C76="","",IF(J76<0,"ÂM KHO – kiểm tra",IF(AND(J76=0,K76>0),"HẾT HÀNG",IF(J76=0,"Hết (ít bán)",IF(K76=0,"Chậm bán",IF(M76<$E$6,"SẮP HẾT","Đủ hàng")))))) | Q76: =IF(OR(P76="HẾT HÀNG",P76="SẮP HẾT"),IF(ISNUMBER(M76),M76,0)+ROW()/100000,"") | R76: =IF(N(K76)>0,K76+ROW()/100000,"")
B77: TỔNG | G77: =SUM(G11:G76) -> 2730 | H77: =SUM(H11:H76) -> 19 | I77: =SUM(I11:I76) -> 606 | J77: =SUM(J11:J76) -> 2143 | K77: =SUM(K11:K76) -> 375 | O77: =SUM(O11:O76) -> 6388899000
A79: Giá trị tồn tính theo giá khuyến nghị 01/4/2026 (không phải giá vốn). Tồn chỉ trừ phiếu xuất sau ngày chốt đầu kỳ; hàng về thì ghi ở sheet NHẬP KHO.
A80: Sản phẩm / dung tích mới: nhập Mã SP + Dung tích + Giá ở một trong 20 dòng vàng bên trên (mã phải có trong DANH MỤC). Tên và nhóm tự hiện.

Sheet NXT THÁNG
A1: BÁO CÁO NHẬP – XUẤT – TỒN THEO THÁNG
A2: Chọn tháng ở 2 ô vàng, bảng tự tính: tồn đầu tháng + nhập − xuất = tồn cuối tháng. Sang tháng mới chị chỉ cần đổi tháng.
A3: Tháng | B3: 9 | D3: Từ ngày | E3: =DATE($B$4,$B$3,1) -> 46266 | G3: =IF($E$3<='TỒN KHO'!$E$4,"Lưu ý: tồn đầu kỳ chốt hết ngày "&TEXT('TỒN KHO'!$E$4,"dd/mm/yyyy")&" nên tháng này chỉ tính phiếu sau ngày đó.","")
A4: Năm | B4: 2026 | D4: Đến ngày | E4: =EOMONTH(E3,0) -> 46295
A7: STT | B7: Nhóm | C7: Mã SP | D7: Tên hàng hoá | E7: Dung tích | F7: TỒN ĐẦU THÁNG | G7: Nhập trong tháng | H7: Xuất trong tháng | I7: TỒN CUỐI THÁNG | J7: Giá KN (VNĐ) | K7: Giá trị tồn cuối tháng | L7: Doanh thu xuất (VNĐ)
A8: =IF('TỒN KHO'!$C11="","",'TỒN KHO'!A11) -> 1 | B8: =IF('TỒN KHO'!$C11="","",'TỒN KHO'!B11) -> Sơn lót | C8: =IF('TỒN KHO'!$C11="","",'TỒN KHO'!C11) -> PI04 | D8: =IF('TỒN KHO'!$C11="","",'TỒN KHO'!D11) -> Sơn lót nội thất kháng kiềm cao cấp Imperia PI04 | E8: =IF('TỒN KHO'!$C11="","",'TỒN KHO'!E11) -> 5L | F8: =IF($C8="","",'TỒN KHO'!G11+SUMIFS('NHẬP KHO'!$E$5:$E$2004,'NHẬP KHO'!$C$5:$C$2004,$C8,'NHẬP KHO'!$D$5:$D$2004,$E8,'NHẬP KHO'!$A$5:$A$2004,">"&'TỒN KHO'!$E$4,'NHẬP KHO'!$A$5:$A$2004,"<"&$E$3)-SUMIFS('XUẤT KHO'!$E$5:$E$2004,'XUẤT KHO'!$C$5:$C$2004,$C8,'XUẤT KHO'!$D$5:$D$2004,$E8,'XUẤT KHO'!$A$5:$A$2004,">"&'TỒN KHO'!$E$4,'XUẤT KHO'!$A$5:$A$2004,"<"&$E$3)) -> 2 | G8: =IF($C8="","",SUMIFS('NHẬP KHO'!$E$5:$E$2004,'NHẬP KHO'!$C$5:$C$2004,$C8,'NHẬP KHO'!$D$5:$D$2004,$E8,'NHẬP KHO'!$A$5:$A$2004,">"&MAX($E$3-1,'TỒN KHO'!$E$4),'NHẬP KHO'!$A$5:$A$2004,"<"&EDATE($E$3,1))) -> 0 | H8: =IF($C8="","",SUMIFS('XUẤT KHO'!$E$5:$E$2004,'XUẤT KHO'!$C$5:$C$2004,$C8,'XUẤT KHO'!$D$5:$D$2004,$E8,'XUẤT KHO'!$A$5:$A$2004,">"&MAX($E$3-1,'TỒN KHO'!$E$4),'XUẤT KHO'!$A$5:$A$2004,"<"&EDATE($E$3,1))) -> 0 | I8: =IF($C8="","",F8+G8-H8) -> 2 | J8: =IF($C8="","",IF('TỒN KHO'!F11="","",'TỒN KHO'!F11)) -> 999000 | K8: =IF($C8="","",IF(J8="",0,MAX(I8,0)*J8)) -> 1998000 | L8: =IF($C8="","",SUMIFS('XUẤT KHO'!$H$5:$H$2004,'XUẤT KHO'!$C$5:$C$2004,$C8,'XUẤT KHO'!$D$5:$D$2004,$E8,'XUẤT KHO'!$A$5:$A$2004,">="&$E$3,'XUẤT KHO'!$A$5:$A$2004,"<"&EDATE($E$3,1))) -> 0
